File: data/A1.dat
MTS793|MPT|ENU|1|2|.|/|:|1|0|0|A

Data Acquisition						Time:	10.012695	s	2/4/2020 9:51:25 AM
Axial Displacement	Axial Force	Time	Axial Extensometer
mm	N	s	mm
0.00043809414	306.98334	0.020507813	0.00099345017
0.0090479851	760.48193	0.11816406	0.0022336945
0.026540458	1826.3506	0.21582031	0.0056317882
0.04235208	2738.908	0.31347656	0.0084171146
0.059256703	3607.9988	0.41113281	0.010962468
0.074791163	4462.9375	0.50878906	0.013812198
0.090567023	5264.2832	0.60644531	0.016677808
0.10699555	6089.6484	0.70410156	0.019400958
0.12181923	6859.5132	0.80175781	0.022282863
0.13825223	7641.0688	0.89941406	0.025297388
0.15907288	8508.6426	0.99707031	0.0287678
0.176543	9233.0498	1.0947266	0.031984884
0.19211769	9817.6787	1.1923828	0.03476803
0.20778179	10399.332	1.2900391	0.037680689
0.22376329	10967.187	1.3876953	0.040777378
0.24168938	11486.385	1.4853516	0.043956496
0.25774688	11944.845	1.5830078	0.047072042
0.27358308	12386.12	1.6806641	0.050434005
0.29193386	12701.699	1.7783203	0.054102618
0.30787736	12939.009	1.8759766	0.057700407
0.3250882	13174.571	1.9736328	0.061485741
0.34043044	13383.579	2.0712891	0.065257832
0.35724565	13583.443	2.1689453	0.068899065
0.37344396	13772.043	2.2666016	0.072738543
0.38933381	13942.525	2.3642578	0.076567695
0.40602386	14106.002	2.4619141	0.080467783
0.42272061	14242.072	2.5595703	0.084451869
0.43839589	14363.229	2.6572266	0.08826939
0.45431927	14477.655	2.7548828	0.092020951
0.47157481	14590.352	2.8525391	0.096077718
0.48784912	14690.968	2.9501953	0.10020141
0.50406528	14778.154	3.0478516	0.10431226
0.52109063	14868.869	3.1455078	0.10846417
0.53843111	14948.253	3.2431641	0.11253055
0.55341572	15026.173	3.3408203	0.11644936
0.57001638	15115.06	3.4384766	0.12061965
0.58596879	15197.387	3.5361328	0.124648
0.60099363	15278.479	3.6337891	0.12870319
0.61804354	15365.647	3.7314453	0.13269863
0.63395798	15456.459	3.8291016	0.13684888
0.65021664	15525.691	3.9267578	0.14087389
0.66781193	15626.459	4.0244141	0.1447608
0.68376434	15725.382	4.1220703	0.1487812
0.70097077	15821.662	4.2197266	0.15288778
0.7167086	15903.133	4.3173828	0.15669939
0.73161948	15990.552	4.4150391	0.16053347
0.74859333	16082.049	4.5126953	0.16440064
0.76481402	16165.453	4.6103516	0.16826436
0.78026801	16268.278	4.7080078	0.17220275
0.79763758	16379.236	4.8056641	0.17619531
0.81457347	16456.779	4.9033203	0.18012045
0.83005655	16544.725	5.0009766	0.18409489
0.84635764	16626.506	5.0986328	0.18793954
0.86208653	16722.889	5.1962891	0.19181386
0.88046861	16801.324	5.2939453	0.19564128
0.89502406	16878.584	5.3916016	0.19938298
0.91011596	16963.236	5.4892578	0.20310241
0.92848688	17070.021	5.5869141	0.20700125
0.94477463	17151.844	5.6845703	0.21093018
0.96140206	17232.84	5.7822266	0.21477784
0.9771198	17305.727	5.8798828	0.21865878
0.99321079	17385.773	5.9775391	0.22233468
1.009722	17476.68	6.0751953	0.22619696
1.0261036	17544.145	6.1728516	0.23004954
1.0414637	17623.836	6.2705078	0.23385304
1.0565937	17711.689	6.3681641	0.23761164
1.0744863	17778.332	6.4658203	0.24153531
1.0903292	17858.844	6.5634766	0.24532954
1.1078261	17924.379	6.6611328	0.24906752
1.1230208	18009.09	6.7587891	0.25279939
1.1386447	18088.086	6.8564453	0.25657338
1.1554264	18157.914	6.9541016	0.26045021
1.1714883	18236.24	7.0517578	0.26447302
1.1889763	18293.883	7.1494141	0.26815066
1.2053691	18364.279	7.2470703	0.27185854
1.221525	18444.188	7.3447266	0.27564782
1.2369745	18502.402	7.4423828	0.27933875
1.2533493	18582.887	7.5400391	0.28314158
1.2707747	18656.072	7.6376953	0.28725344
1.2865953	18717.184	7.7353516	0.29087615
1.302845	18779.359	7.8330078	0.29464158
1.3196312	18851.613	7.9306641	0.29850399
1.3344682	18908.119	8.0283203	0.30207095
1.3513707	18981.961	8.1259766	0.30592445
1.3685637	19048.441	8.2236328	0.30965319
1.383356	19094.568	8.3212891	0.31343323
1.4005624	19166.711	8.4189453	0.31745631
1.4172726	19227.244	8.5166016	0.32122794
1.4329009	19296.855	8.6142578	0.324931
1.4488555	19353.225	8.7119141	0.32868898
1.4660753	19424.23	8.8095703	0.33267704
1.4822804	19475.107	8.9072266	0.33631486
1.4973186	19526.256	9.0048828	0.33994663
1.5130944	19589.541	9.1025391	0.34363875
1.5299879	19650.576	9.2001953	0.34744793
1.546622	19712.637	9.2978516	0.35131609
1.5627019	19766.018	9.3955078	0.35514551
1.5792198	19837.584	9.4931641	0.35915467
1.5958942	19878.826	9.5908203	0.36288273
1.6117014	19936.635	9.6884766	0.36664692
1.6281031	19989.982	9.7861328	0.37044263
1.6437269	20052.363	9.8837891	0.37417296
1.6609467	20111.834	9.9814453	0.37812555
1.6776569	20163.164	10.079102	0.38205257
1.6940452	20214.85	10.176758	0.38582361
1.7112695	20274.576	10.274414	0.38988742
1.7263211	20316.365	10.37207	0.39358124
1.7421104	20367.996	10.469727	0.39718229
1.7586507	20422.816	10.567383	0.40112698
1.7742254	20481.156	10.665039	0.40492234
1.7901801	20525.67	10.762695	0.40860468
1.8071271	20569.193	10.860352	0.41229719
1.8230237	20630.688	10.958008	0.4161042
1.8399037	20674.676	11.055664	0.41995037
1.856292	20737.676	11.15332	0.42395985
1.8710397	20769.668	11.250977	0.42755798
1.8872179	20830.449	11.348633	0.4314954
1.9054435	20867.969	11.446289	0.435386
1.9198693	20917.313	11.543945	0.43913212
1.938001	20973.084	11.641602	0.44297341
1.9529991	21024.533	11.739258	0.44700241
1.9700266	21061.443	11.836914	0.45080936
1.9863613	21108.225	11.93457	0.45456547
2.0023696	21169.654	12.032227	0.45855811
2.019567	21200.568	12.129883	0.46243009
2.0355575	21236.293	12.227539	0.46597323
2.0505824	21297.756	12.325195	0.46989369
2.067203	21334.434	12.422852	0.47363666
2.0835915	21388.115	12.520508	0.47755897
2.1000423	21422.734	12.618164	0.4813889
2.1166899	21468.678	12.71582	0.48531827
2.1325686	21508.205	12.813477	0.48915687
2.1505036	21555.076	12.911133	0.49314943
2.1657653	21606.998	13.008789	0.49703619
2.1824844	21631.852	13.106445	0.50098443
2.1986179	21672.105	13.204102	0.50465453
2.2148409	21715.873	13.301758	0.50856823
2.230943	21766.555	13.399414	0.51243818
2.246388	21795.598	13.49707	0.51612085
2.2620254	21837.592	13.594727	0.52001023
2.278132	21879.52	13.692383	0.5239163
2.2968538	21928.232	13.790039	0.52772093
2.3121111	21960.092	13.887695	0.5316112
2.3279495	22004.908	13.985352	0.53549087
2.344852	22048.561	14.083008	0.53944051
2.3605697	22080.342	14.180664	0.54343492
2.3770251	22110.48	14.27832	0.54726076
2.3936727	22162.615	14.375977	0.55111021
2.410517	22201.652	14.473633	0.55510801
2.4268827	22236.703	14.571289	0.55915385
2.4425962	22263.223	14.668945	0.56296808
2.4590917	22306.496	14.766602	0.56671
2.4749658	22343.912	14.864258	0.57059145
2.4926775	22383.711	14.961914	0.57456833
2.5074832	22408.619	15.05957	0.57848644
2.5235765	22444.016	15.157227	0.58229512
2.5399559	22489.766	15.254883	0.58614206
2.5563798	22517.699	15.352539	0.59009182
2.5729246	22563.973	15.450195	0.59389281
2.5878825	22577.902	15.547852	0.59775907
2.6037076	22626.098	15.645508	0.60173577
2.622036	22660.254	15.743164	0.60566908
2.6377001	22684.492	15.84082	0.60965943
2.6534445	22725.869	15.938477	0.61349016
2.670651	22758.656	16.036133	0.61744863
2.6870706	22791.018	16.133789	0.62134808
2.7016885	22805.406	16.231445	0.62510043
2.7178087	22847.773	16.329102	0.62886894
2.7348003	22880.119	16.426758	0.63289779
2.7516894	22901.006	16.524414	0.63667589
2.7676351	22939.555	16.62207	0.64062941
2.7830222	22995.471	16.719727	0.64458108
2.8014979	23027.021	16.817383	0.64864171
2.816885	23035.037	16.915039	0.65264666
2.8340333	23077.559	17.012695	0.65645093
2.8488212	23107.607	17.110352	0.66035718
2.8669708	23140.736	17.208008	0.66430753
2.8823264	23163.061	17.305664	0.66837758
2.8985181	23191.457	17.40332	0.67209929
2.9141822	23235.68	17.500977	0.67618752
2.9316387	23257.586	17.598633	0.68023694
2.9464133	23286.797	17.696289	0.68406862
2.9614964	23307.662	17.793945	0.68779248
2.9788413	23342.021	17.891602	0.69177532
2.9951625	23364.59	17.989258	0.69560808
3.0115464	23421.01	18.086914	0.69985199
3.0288198	23431.523	18.18457	0.70368463
3.0436656	23462.848	18.282227	0.70767993
3.060823	23481.564	18.379883	0.71161109
3.0766568	23511.162	18.477539	0.71557897
3.0942433	23545.096	18.575195	0.7194258
3.1091206	23580.822	18.672852	0.72353089
3.1255536	23603.797	18.770508	0.72759217
3.142751	23628.551	18.868164	0.73151702
3.1587951	23649.137	18.96582	0.7354669
3.1749554	23681.52	19.063477	0.73957801
3.1911783	23697.225	19.161133	0.7434445
3.2075129	23736.988	19.258789	0.74756426
3.2225735	23748.818	19.356445	0.75139666
3.2405713	23788.42	19.454102	0.75550878
3.2565124	23799.352	19.551758	0.75947362
3.2730393	23830.129	19.649414	0.76334113
3.2892487	23861.066	19.74707	0.76734847
3.3051186	23879.68	19.844727	0.77124995
3.3209615	23916.025	19.942383	0.77534276
3.3375688	23933.811	20.040039	0.77926433
3.3539035	23965.285	20.137695	0.78318888
3.3702829	23986.299	20.235352	0.78725648
3.3856788	24006.938	20.333008	0.7911948
3.4021609	24026.318	20.430664	0.79521084
3.4192822	24045.391	20.52832	0.79926932
3.4355321	24080.619	20.625977	0.80326837
3.4518757	24106.275	20.723633	0.80720985
3.4686394	24126.568	20.821289	0.81138259
3.4846969	24143.666	20.918945	0.81524605
3.4999006	24166.643	21.016602	0.81924784
3.5169773	24195.879	21.114258	0.82320714
3.5331109	24231.197	21.211914	0.82741636
3.5490296	24236.104	21.30957	0.83125693
3.5656459	24270.459	21.407227	0.83536774
3.5802908	24274.947	21.504883	0.83925331
3.5979934	24294.063	21.602539	0.84331936
3.6130049	24331.248	21.700195	0.84720296
3.6303542	24347.016	21.797852	0.85119754
3.6459603	24371.117	21.895508	0.85507631
3.6623039	24398.518	21.993164	0.85925573
3.6792107	24409.127	22.09082	0.86327416
3.6955633	24439.455	22.188477	0.86729032
3.7114017	24464.355	22.286133	0.87129873
3.7278883	24475.039	22.383789	0.87523705
3.7439234	24496.012	22.481445	0.87921846
3.7594578	24514.727	22.579102	0.88325441
3.7766867	24543.623	22.676758	0.88732529
3.7928424	24564.043	22.774414	0.89142603
3.8099415	24601.764	22.87207	0.89555991
3.8266561	24600.561	22.969727	0.89969575
3.840693	24623.129	23.067383	0.90355372
3.8581989	24654.32	23.165039	0.9078297
3.8750477	24649.443	23.262695	0.91165167
3.8910785	24693.727	23.360352	0.91584933
3.907109	24700.193	23.458008	0.91978687
3.923779	24732.301	23.555664	0.92407632
3.9392688	24735.225	23.65332	0.927926
3.9560637	24773.213	23.750977	0.93210334
3.9732971	24771.891	23.848633	0.93616754
3.9885542	24800.99	23.946289	0.94018364
4.004786	24816.787	24.043945	0.94426972
4.0210271	24840.877	24.141602	0.94835961
4.0365658	24853.416	24.239258	0.95229077
4.0520468	24873.01	24.336914	0.95631278
4.0691147	24902.721	24.43457	0.96061778
4.0866337	24918.717	24.532227	0.96477848
4.1030622	24939.656	24.629883	0.96873087
4.117877	24945.156	24.727539	0.97277683
4.135097	24980.102	24.825195	0.97687411
4.1512976	24985.242	24.922852	0.98101455
4.1673102	24999.48	25.020508	0.98497844
4.1836538	25015.529	25.118164	0.98900199
4.2002878	25059.23	25.21582	0.99318945
4.2185178	25059.496	25.313477	0.99762243
4.2326889	25064.223	25.411133	1.0014977
4.2489657	25090.473	25.508789	1.0055507
4.2642007	25108.494	25.606445	1.0095168
4.2812638	25132.098	25.704102	1.0137277
4.2973971	25143.135	25.801758	1.0177209
4.3131957	25168.486	25.899414	1.022115
4.3290071	25170.854	25.99707	1.0262257
4.3467813	25193.252	26.094727	1.0302956
4.361949	25198.729	26.192383	1.034368
4.3797722	25243.299	26.290039	1.0384753
4.396554	25264.328	26.387695	1.0429087
4.4120708	25253.078	26.485352	1.0468638
4.4282446	25261.834	26.583008	1.0509181
4.4440022	25279.115	26.680664	1.0549053
4.4598675	25315.143	26.77832	1.0591538
4.4759922	25332.041	26.875977	1.0633011
4.493176	25341.043	26.973633	1.0675731
4.5097566	25368.424	27.071289	1.0717189
4.5266366	25366.93	27.168945	1.0757006
4.5419788	25390.758	27.266602	1.0798222
4.5575447	25414.113	27.364258	1.0840962
4.5745587	25413.871	27.461914	1.0882273
4.5907459	25434.547	27.55957	1.0923393
4.6074204	25446.373	27.657227	1.0964625
4.6240816	25465.721	27.754883	1.1005849
4.6397142	25484.279	27.852539	1.1048349
4.6557941	25481.275	27.950195	1.1088094
4.6713777	25496.789	28.047852	1.1127743
4.6885347	25534.398	28.145508	1.1172667
4.7053347	25549.938	28.243164	1.1214309
4.7209182	25549.33	28.34082	1.1256384
4.7376685	25568.645	28.438477	1.1299044
4.7531447	25583.471	28.536133	1.1339467
4.7699714	25603.139	28.633789	1.1381339
4.7866011	25619.793	28.731445	1.1423392
4.8021221	25623.963	28.829102	1.1463836
4.8183942	25640.664	28.926758	1.150653
4.8355246	25661.105	29.024414	1.1547251
4.852972	25673.621	29.12207	1.159034
4.8678985	25675.615	29.219727	1.1630812
4.8838487	25696.219	29.317383	1.1673393
4.9010196	25711.08	29.415039	1.1715654
4.9165225	25722.695	29.512695	1.1756752
4.9331703	25739.398	29.610352	1.1799165
4.9496164	25753.234	29.708008	1.1841561
4.966197	25760.357	29.805664	1.1882012
4.9823394	25776.449	29.90332	1.1923255
4.998178	25793.285	30.000977	1.1965984
5.013659	25801.889	30.098633	1.20075
5.0305209	25817.906	30.196289	1.2050052
5.0464263	25821.896	30.293945	1.2092031
5.0630293	25838.775	30.391602	1.2133648
5.0787916	25856.076	30.489258	1.2176147
5.0962486	25878.266	30.586914	1.2217501
5.11164	25862.297	30.68457	1.2259922
5.1273041	25885.857	30.782227	1.2300012
5.1433792	25906.25	30.879883	1.2342615
5.1606665	25915.148	30.977539	1.2383593
5.175539	25922.787	31.075195	1.2425805
5.192647	25941.578	31.172852	1.2468654
5.2096791	25965.131	31.270508	1.2512186
5.2259912	25979.537	31.368164	1.2554592
5.2423215	25978.422	31.46582	1.2596698
5.2592912	25996.324	31.563477	1.2637621
5.2747674	25996.441	31.661133	1.2680336
5.2916565	26017.336	31.758789	1.2722676
5.3063369	26021.125	31.856445	1.276625
5.3232169	26030.082	31.954102	1.2807829
5.3394666	26045.273	32.051758	1.2850305
5.3552918	26058.086	32.149414	1.2890756
5.3709202	26071.348	32.24707	1.2933738
5.387845	26086.592	32.344727	1.2976655
5.4050155	26090.846	32.442383	1.3019675
5.420362	26113.754	32.540039	1.3061907
5.4367952	26117.295	32.637695	1.3103094
5.4536529	26134.244	32.735352	1.314587
5.469943	26153.711	32.833008	1.3189113
5.4860988	26154.291	32.930664	1.3231057
5.5028133	26155.086	33.02832	1.3273845
5.5181599	26179.734	33.125977	1.3316921
5.5353751	26188.1	33.223633	1.3361348
5.5516114	26191.133	33.321289	1.3402984
5.5667887	26206.01	33.418945	1.3443865
5.5841827	26225.012	33.516602	1.3487195
5.6009955	26233.789	33.614258	1.3530093
5.6158371	26240.338	33.711914	1.3572364
5.6324577	26236.932	33.80957	1.361307
5.6485558	26252.613	33.907227	1.3656497
5.6655073	26269.482	34.004883	1.3700722
5.6818151	26282.104	34.102539	1.3744217
5.6983685	26293.416	34.200195	1.3787702
5.7149758	26307.48	34.297852	1.3829021
5.73001	26310.434	34.395508	1.387192
5.7457767	26314.441	34.493164	1.3913056
5.7624555	26329.65	34.59082	1.3957027
5.7801447	26344.367	34.688477	1.3999578
5.7943559	26344.834	34.786133	1.4040555
5.8126221	26357.619	34.883789	1.4085605
5.8276916	26355.188	34.981445	1.4129496
5.8436503	26379.729	35.079102	1.4169502
5.861094	26387.928	35.176758	1.4213809
5.8762798	26393.104	35.274414	1.4255762
5.892838	26416.736	35.37207	1.4300255
5.9095926	26421.184	35.469727	1.4343032
5.9260211	26431.154	35.567383	1.438538
5.9422307	26436.055	35.665039	1.4427049
5.9583554	26442.207	35.762695	1.4469429
5.9740195	26449.764	35.860352	1.4513205
5.9910603	26475.568	35.958008	1.4556839
6.0061207	26476.119	36.055664	1.4598975
6.0227685	26483.217	36.15332	1.4641564
6.0384684	26497.525	36.250977	1.4684224
6.0540566	26499.441	36.348633	1.4727762
6.0702972	26522.617	36.446289	1.4771856
6.0888624	26517.477	36.543945	1.4815435
6.1057425	26544.066	36.641602	1.4860381
6.1208076	26528.363	36.739258	1.4902393
6.1367936	26527.646	36.836914	1.4943504
6.1526189	26561.779	36.93457	1.4986037
6.1683273	26566.592	37.032227	1.5027549
6.1865754	26577.84	37.129883	1.5073262
6.2012563	26585.355	37.227539	1.5116278
6.2182927	26594.748	37.325195	1.5159774
6.2346587	26597.447	37.422852	1.5204284
6.2513018	26619.912	37.520508	1.5246562
6.2676363	26617.066	37.618164	1.5289487
6.2833452	26628.869	37.71582	1.5332254
6.2988529	26639.594	37.813477	1.5376495
6.3172793	26650.959	37.911133	1.5420902
6.3321075	26646.41	38.008789	1.5464371
6.3486657	26647.643	38.106445	1.5505567
6.3650093	26671.127	38.204102	1.5550634
6.3810534	26680.053	38.301758	1.5593512
6.3970618	26678.051	38.399414	1.5637138
6.4139018	26694.996	38.49707	1.5681784
6.431005	26697.754	38.594727	1.5724909
6.4468703	26717.549	38.692383	1.5769591
6.4632721	26706.055	38.790039	1.5812322
6.4778099	26711.92	38.887695	1.5855159
6.4946852	26728.293	38.985352	1.5896784
6.5111809	26739.779	39.083008	1.5942907
6.5279851	26753.023	39.180664	1.5986567
6.5440154	26750.943	39.27832	1.602901
6.5609984	26757.178	39.375977	1.6074338
6.5767922	26771.703	39.473633	1.6117566
6.5921388	26773.475	39.571289	1.6160835
6.6094122	26797.402	39.668945	1.620482
6.6254473	26782.828	39.766602	1.6248097
6.6402173	26801.473	39.864258	1.6290641
6.6588631	26807.906	39.961914	1.633618
6.674715	26816.709	40.05957	1.6379819
6.6918902	26823.398	40.157227	1.6423687
6.7060299	26840.59	40.254883	1.646719
6.7230172	26835.311	40.352539	1.6511965
6.738945	26855.172	40.450195	1.6555963
6.7566028	26851.641	40.547852	1.6601018
6.7714267	26861.934	40.645508	1.6643949
6.7886643	26868.879	40.743164	1.6688828
6.8054595	26862.621	40.84082	1.673117
6.8200731	26894.461	40.938477	1.6775074
6.8369975	26875.037	41.036133	1.6817881
6.8538733	26905.58	41.133789	1.6862513
6.8705387	26907.148	41.231445	1.6907015
6.8848348	26886.158	41.329102	1.6945636
6.9031634	26930.941	41.426758	1.6994553
6.9189167	26932.127	41.524414	1.7039527
6.9363198	26923.701	41.62207	1.7084315
6.9504194	26922.236	41.719727	1.7126093
6.9673667	26943.4	41.817383	1.716975
6.9823465	26947.814	41.915039	1.7213336
6.9995084	26953.719	42.012695	1.7259178
7.0161691	26964.633	42.110352	1.7304151
7.0327811	26972.34	42.208008	1.7349546
7.0493078	26977.467	42.305664	1.7392865
7.0645967	26967.102	42.40332	1.7436454
7.0806136	26981.031	42.500977	1.747808
7.0967069	26988.938	42.598633	1.7522511
7.1141815	27011.891	42.696289	1.7568116
7.1304045	27003.709	42.793945	1.7614042
7.1458807	27011.934	42.891602	1.7657917
7.1628323	27015.551	42.989258	1.7702529
7.1793103	27021.252	43.086914	1.7747326
7.1952024	27028.787	43.18457	1.779128
7.210835	27032	43.282227	1.7834356
7.2282782	27050.736	43.379883	1.7878737
7.2445774	27064.918	43.477539	1.7925607
7.2615466	27047.814	43.575195	1.7969675
7.2754316	27060.205	43.672852	1.8013664
7.2917395	27067.66	43.770508	1.8057292
7.3081636	27070.76	43.868164	1.8101823
7.3247843	27078.104	43.96582	1.8147118
7.3412442	27081.432	44.063477	1.8190949
7.3578825	27086.793	44.161133	1.8237014
7.3734889	27087.793	44.258789	1.8279868
7.3907442	27106.934	44.356445	1.8326352
7.4062338	27115.471	44.454102	1.8370103
7.4225416	27105.725	44.551758	1.8414509
7.438416	27125.229	44.649414	1.8458182
7.4549785	27127.213	44.74707	1.8502982
7.471756	27122.41	44.844727	1.8547833
7.4882069	27142.773	44.942383	1.8593291
7.5031648	27138.127	45.040039	1.8636712
7.5205183	27146.846	45.137695	1.8680438
7.5374207	27172.436	45.235352	1.8726552
7.5533934	27168.213	45.333008	1.8773611
7.5710783	27162.652	45.430664	1.8818034
7.5860271	27162.48	45.52832	1.8863349
7.6008239	27168.822	45.625977	1.8907912
7.6178513	27176.393	45.723633	1.8952001
7.6352544	27175.986	45.821289	1.8996726
7.6505384	27188.545	45.918945	1.9040805
7.6680622	27215.389	46.016602	1.9087114
7.6836863	27202.32	46.114258	1.9132328
7.6998687	27199.643	46.211914	1.9177521
7.7162886	27212.043	46.30957	1.9221634
7.732203	27219.154	46.407227	1.9267608
7.7491946	27222.369	46.504883	1.9311591
7.7648187	27231.98	46.602539	1.9357133
7.781846	27242.291	46.700195	1.9402413
7.7965045	27231.951	46.797852	1.9445678
7.8141799	27245.158	46.895508	1.9492487
7.8294239	27225.514	46.993164	1.9535242
7.8461385	27258.023	47.09082	1.9581296
7.8614273	27258.814	47.188477	1.9626054
7.8790851	27273.744	47.286133	1.9672492
7.895268	27282.512	47.383789	1.971858
7.9120493	27276.771	47.481445	1.9763147
7.9272666	27284.363	47.579102	1.9809135
7.9457469	27290.426	47.676758	1.9855798
7.9606643	27282.863	47.774414	1.9900874
7.9768872	27295.865	47.87207	1.994434
7.9931235	27291.885	47.969727	1.9989275
8.0085058	27295.961	48.067383	2.0034463
8.022995	27287.721	48.165039	2.0077999
8.0424051	27322.063	48.262695	2.0126073
8.0583286	27323.975	48.360352	2.0172029
8.0750875	27315.6	48.458008	2.0216856
8.0906754	27318.67	48.555664	2.026248
8.1061878	27320.861	48.65332	2.0307117
8.1217575	27337.084	48.750977	2.0352707
8.1384373	27337.891	48.848633	2.0398304
8.1550131	27331.879	48.946289	2.044229
8.171504	27347.607	49.043945	2.0488245
8.1869135	27358.928	49.141602	2.0534723
8.2047415	27360.588	49.239258	2.058074
8.2202482	27355.438	49.336914	2.0626674
8.2360516	27371.158	49.43457	2.0672567
8.2538567	27369.264	49.532227	2.0718327
8.2696009	27358.398	49.629883	2.0762327
8.2851667	27374.24	49.727539	2.0807557
8.3006029	27374.182	49.825195	2.0853765
8.3161201	27382.217	49.922852	2.0898678
8.3341217	27397.742	50.020508	2.0945659
8.3505411	27399.615	50.118164	2.0992839
8.3671894	27381.838	50.21582	2.1037581
8.3823967	27418.359	50.313477	2.1084375
8.3982897	27398.902	50.411133	2.1130052
8.4151154	27410.604	50.508789	2.1175616
8.4318209	27420.895	50.606445	2.1221867
8.4465065	27410.688	50.704102	2.1267221
8.4643211	27429.258	50.801758	2.1315005
8.482604	27419.715	50.899414	2.1361825
8.496726	27419.553	50.99707	2.140636
8.5130167	27427.23	51.094727	2.1451733
8.5288639	27438.836	51.192383	2.1498604
8.545516	27451.527	51.290039	2.1545503
8.5613766	27436.91	51.387695	2.159066
8.5779791	27451.217	51.485352	2.1636899
8.594327	27456.219	51.583008	2.1682906
8.6108904	27468.811	51.680664	2.1730661
8.6278553	27464.305	51.77832	2.1777546
8.644762	27465.324	51.875977	2.182282
8.6601171	27471.619	51.973633	2.1869378
8.6762018	27465.449	52.071289	2.1916578
8.6918745	27465.889	52.168945	2.1961238
8.7071724	27479.297	52.266602	2.2006018
8.7247896	27489.793	52.364258	2.2054052
8.7419519	27489.545	52.461914	2.2101469
8.7567663	27484.564	52.55957	2.2147844
8.7733288	27490.25	52.657227	2.2192969
8.7897711	27502.664	52.754883	2.2240152
8.8057928	27506.514	52.852539	2.2288315
8.8228207	27498.254	52.950195	2.2333858
8.8385115	27502.17	53.047852	2.2378795
8.8552799	27514.016	53.145508	2.2425387
8.8726692	27516.918	53.243164	2.2471693
8.8880072	27525.066	53.34082	2.2519007
8.9055576	27533.707	53.438477	2.2566962
8.9203987	27512.695	53.536133	2.2613559
8.9355135	27524.115	53.633789	2.2658944
8.9515667	27529.633	53.731445	2.2704735
8.9695549	27549.699	53.829102	2.2752914
8.9858541	27538.086	53.926758	2.280097
9.0020857	27527.02	54.024414	2.2845924
9.0186033	27563.018	54.12207	2.2895064
9.0349474	27554.352	54.219727	2.2943656
9.0509329	27550.176	54.317383	2.2990811
9.0665703	27547.064	54.415039	2.3036656
9.0827665	27540.822	54.512695	2.3079686
9.0979881	27562.406	54.610352	2.3128381
9.115633	27562.662	54.708008	2.3176603
9.1315603	27570.951	54.805664	2.3223531
9.1480646	27563.088	54.90332	2.327014
9.1637335	27572.625	55.000977	2.3316853
9.1806049	27573.096	55.098633	2.3364625
9.1971226	27576.436	55.196289	2.3412035
9.2142353	27577.297	55.293945	2.3459063
9.2294254	27584.566	55.391602	2.350678
9.2458496	27590.053	55.489258	2.3555655
9.2622156	27594.115	55.586914	2.3603206
9.2781391	27589.789	55.68457	2.3649104
9.2942905	27599.676	55.782227	2.3697462
9.3101377	27594.816	55.879883	2.3743498
9.3279829	27602.881	55.977539	2.3791234
9.3427982	27598.342	56.075195	2.3837588
9.3593111	27614.693	56.172852	2.3886075
9.3753557	27617.926	56.270508	2.3934247
9.3920164	27618.988	56.368164	2.3983221
9.4083242	27623.492	56.46582	2.4030828
9.4248466	27617.504	56.563477	2.4076915
9.4409132	27608.922	56.661133	2.412329
9.4578781	27625.08	56.758789	2.4172223
9.4738417	27647.109	56.856445	2.4221728
9.4913702	27627.836	56.954102	2.4271154
9.5067749	27613.76	57.051758	2.4318593
9.5216255	27633.293	57.149414	2.4364882
9.5387602	27632.162	57.24707	2.4411087
9.5556583	27645.631	57.344727	2.4462295
9.5713444	27648.992	57.442383	2.4510577
9.5871649	27645.254	57.540039	2.4557307
9.6042824	27668.033	57.637695	2.460803
9.6214123	27649.824	57.735352	2.4656012
9.6359539	27639.432	57.833008	2.4702241
9.6530581	27663.871	57.930664	2.4750462
9.6692991	27661.018	58.02832	2.4800282
9.6850204	27666.506	58.125977	2.4849472
9.7017717	27667.961	58.223633	2.4897981
9.7187634	27667.854	58.321289	2.4946525
9.7356472	27654.936	58.418945	2.4994335
9.7509899	27664.594	58.516602	2.504128
9.7667704	27673.51	58.614258	2.509023
9.7837353	27674.689	58.711914	2.5139122
9.8003645	27682.125	58.80957	2.5188975
9.8148127	27672.674	58.907227	2.5237544
9.8319302	27686.48	59.004883	2.5286651
9.8490868	27682.379	59.102539	2.533483
9.8652296	27685.861	59.200195	2.5382771
9.8802233	27684.465	59.297852	2.542973
9.8975773	27701.844	59.395508	2.5479155
9.9143143	27697.502	59.493164	2.5528286
9.9300766	27690.158	59.59082	2.5576477
9.9452486	27699.904	59.688477	2.5625412
9.9621248	27706.469	59.786133	2.5674832
9.977972	27707.195	59.883789	2.5725694
9.9944448	27705.486	59.981445	2.5774829
10.010882	27705.768	60.079102	2.5823836
10.027847	27708.92	60.176758	2.5871472
10.043485	27709.758	60.274414	2.5921724
10.059917	27711.225	60.37207	2.596936
10.076797	27710.717	60.469727	2.6018653
10.091881	27721.693	60.567383	2.6067545
10.108215	27728.775	60.665039	2.6117282
10.125024	27717.467	60.762695	2.6166067
10.141667	27742.305	60.860352	2.6215632
10.157076	27729.596	60.958008	2.6267288
10.173179	27725.385	61.055664	2.6314342
10.189808	27718.928	61.15332	2.6363897
10.206353	27727.438	61.250977	2.641149
10.221414	27743.773	61.348633	2.6460857
10.238169	27730.125	61.446289	2.6510515
10.25432	27745.928	61.543945	2.6558678
10.270319	27742.357	61.641602	2.6608779
10.286783	27758.887	61.739258	2.6660349
10.303761	27750.152	61.836914	2.6710174
10.320096	27753.553	61.93457	2.6761014
10.337057	27756.344	62.032227	2.6810122
10.353307	27746.756	62.129883	2.6859765
10.367911	27753.678	62.227539	2.6910686
10.385028	27751.555	62.325195	2.695796
10.401774	27762.973	62.422852	2.7008495
10.417211	27759.58	62.520508	2.7057867
10.433424	27764.693	62.618164	2.7110491
10.450322	27745.455	62.71582	2.7158015
10.466702	27773.029	62.813477	2.7208161
10.482419	27761.498	62.911133	2.7258947
10.499246	27758.014	63.008789	2.7308891
10.51579	27780.398	63.106445	2.7358897
10.532465	27769.219	63.204102	2.7409046
10.548062	27772.113	63.301758	2.7460129
10.563632	27783.146	63.399414	2.7509677
10.580213	27784.855	63.49707	2.7561491
10.597781	27791.24	63.594727	2.7610896
10.613508	27780.352	63.692383	2.7662165
10.629033	27783.023	63.790039	2.7711051
10.645243	27781.252	63.887695	2.7761998
10.660674	27780.934	63.985352	2.7812376
10.677219	27784.285	64.083008	2.786289
10.694041	27786.654	64.180664	2.7914073
10.709361	27783.52	64.27832	2.7963388
10.725642	27781.234	64.375977	2.8014255
10.741972	27790.275	64.473633	2.8065312
10.75959	27788.742	64.571289	2.8117459
10.776211	27785.65	64.668945	2.8166554
10.792143	27797.9	64.766602	2.8218141
10.808527	27800.875	64.864258	2.8269875
10.824253	27793.209	64.961914	2.831902
10.839024	27789.367	65.05957	2.8367739
10.856824	27805.42	65.157227	2.8420231
10.873025	27805.725	65.254883	2.847137
10.889852	27809.088	65.352539	2.852354
10.905717	27805.459	65.450195	2.8576472
10.922373	27809.02	65.547852	2.8626232
10.93869	27809.34	65.645508	2.8677871
10.954993	27804.414	65.743164	2.8729646
10.970796	27821.063	65.84082	2.8780968
10.987117	27808.793	65.938477	2.8832226
11.003774	27817.719	66.036133	2.8883998
11.02006	27819.072	66.133789	2.8934712
11.036018	27819.061	66.231445	2.8987775
11.05195	27809.967	66.329102	2.9039359
11.068554	27814.107	66.426758	2.908812
11.083869	27819.453	66.524414	2.9139717
11.102349	27840.119	66.62207	2.9195273
11.117852	27816.678	66.719727	2.9245403
11.134004	27824.09	66.817383	2.9297764
11.150035	27825.283	66.915039	2.9349732
11.167173	27830.734	67.012695	2.9402134
11.183128	27819.016	67.110352	2.9453523
11.198649	27821.363	67.208008	2.9503777
11.214229	27833.365	67.305664	2.9556611
11.232575	27834.703	67.40332	2.9609077
11.247014	27839.639	67.500977	2.9661117
11.263555	27841.135	67.598633	2.9714952
11.280439	27840.854	67.696289	2.9769754
11.296782	27831.189	67.793945	2.9821019
11.313001	27845.469	67.891602	2.9874258
11.329658	27833.096	67.989258	2.9926703
11.346015	27832.938	68.086914	2.9977746
11.363025	27840.846	68.18457	3.0030553
11.378403	27834.668	68.282227	3.0084364
11.395188	27847.338	68.379883	3.013499
11.409758	27841.818	68.477539	3.0187666
11.427889	27862.248	68.575195	3.0242965
11.444148	27851.875	68.672852	3.0297165
11.459638	27841.979	68.770508	3.0348728
11.475435	27834.889	68.868164	3.0401251
11.492611	27857.363	68.96582	3.04545
11.507748	27846.58	69.063477	3.0508795
11.525423	27852.092	69.161133	3.05619
11.542218	27845.648	69.258789	3.061455
11.556394	27847.521	69.356445	3.0667667
11.573215	27846.254	69.454102	3.0720258
11.589648	27857.92	69.551758	3.0774968
11.605724	27857.777	69.649414	3.0827842
11.622403	27852.473	69.74707	3.0881705
11.637946	27851.561	69.844727	3.0934412
11.653481	27858.613	69.942383	3.0989215
11.671912	27863.795	70.040039	3.1043961
11.687219	27875.068	70.137695	3.1101305
11.703146	27842.1	70.235352	3.1153386
11.719472	27861.143	70.333008	3.1206474
11.735994	27856.57	70.430664	3.1261261
11.752168	27859.102	70.52832	3.1314206
11.768364	27869.934	70.625977	3.1369848
11.786528	27868.688	70.723633	3.1424584
11.800877	27854.301	70.821289	3.1477807
11.817412	27861.852	70.918945	3.1531091
11.832911	27861.551	71.016602	3.1585336
11.850167	27866.445	71.114258	3.1639123
11.865898	27869.49	71.211914	3.1694882
11.882389	27873.398	71.30957	3.1748898
11.899139	27868.797	71.407227	3.1804433
11.914272	27875.633	71.504883	3.1859021
11.931246	27860.861	71.602539	3.1913526
11.946632	27870.705	71.700195	3.1968639
11.964026	27870.404	71.797852	3.2023592
11.97978	27873.42	71.895508	3.2077768
11.996231	27887.709	71.993164	3.2135069
12.012423	27872.928	72.09082	3.2190251
12.029397	27859.74	72.188477	3.2246861
12.044976	27866.703	72.286133	3.2300839
12.06169	27884.186	72.383789	3.2357724
12.078374	27869.771	72.481445	3.2413471
12.093631	27874.641	72.579102	3.2468996
12.108897	27872.674	72.676758	3.2524867
12.126426	27888.27	72.774414	3.2582159
12.143091	27871.541	72.87207	3.2638979
12.159349	27874.57	72.969727	3.269311
12.174482	27893.83	73.067383	3.2749922
12.191854	27868.078	73.165039	3.2806466
12.2088	27880.924	73.262695	3.2863193
12.225216	27883.23	73.360352	3.292033
12.239373	27880.459	73.458008	3.2975941
12.256213	27887.305	73.555664	3.3033698
12.274148	27892.502	73.65332	3.3090529
12.289616	27879.146	73.750977	3.3148048
12.305173	27880.719	73.848633	3.3202915
12.322268	27884.023	73.946289	3.3259077
12.339026	27886.803	74.043945	3.3316872
12.355156	27888.047	74.141602	3.3374739
12.369528	27878.689	74.239258	3.3431389
12.386475	27891.75	74.336914	3.3487706
12.402322	27885.371	74.43457	3.3544347
12.419024	27888.723	74.532227	3.3601537
12.435694	27890.969	74.629883	3.3659477
12.453248	27883.701	74.727539	3.3719194
12.469878	27876.992	74.825195	3.3775373
12.485873	27883.311	74.922852	3.3832989
12.500129	27888.551	75.020508	3.3890088
12.517554	27886.283	75.118164	3.394953
12.534126	27885.539	75.21582	3.4006543
12.550506	27883.799	75.313477	3.4066336
12.567193	27887.979	75.411133	3.4124997
12.581784	27878.588	75.508789	3.4180126
12.599661	27885.932	75.606445	3.4240005
12.614758	27881.412	75.704102	3.4297841
12.629389	27888.252	75.801758	3.4354641
12.648258	27893.104	75.899414	3.4414747
12.664155	27891.721	75.99707	3.4475369
12.679006	27880.846	76.094727	3.4532459
12.694786	27882.639	76.192383	3.4589915
12.712426	27892.639	76.290039	3.4650617
12.729449	27890.488	76.387695	3.471055
12.746119	27887.053	76.485352	3.477113
12.760084	27882.883	76.583008	3.4828844
12.777415	27886.551	76.680664	3.4888771
12.79447	27886.217	76.77832	3.4949822
12.811659	27890.762	76.875977	3.5009148
12.827193	27887.994	76.973633	3.5069945
12.842016	27890.801	77.071289	3.5129318
12.859563	27889.787	77.168945	3.5191879
12.87613	27892	77.266602	3.5253038
12.891615	27884.318	77.364258	3.5311415
12.906618	27878.799	77.461914	3.5370009
12.924137	27900.07	77.55957	3.5431049
12.939193	27891.273	77.657227	3.5493321
12.955479	27885.697	77.754883	3.5550985
12.972793	27899.104	77.852539	3.5612431
12.989744	27887.014	77.950195	3.5674784
13.005332	27896.02	78.047852	3.5735559
13.021948	27893.223	78.145508	3.5796313
13.037076	27894.227	78.243164	3.5854802
13.054935	27895.666	78.34082	3.5918825
13.070111	27892.336	78.438477	3.5980477
13.088606	27859.84	78.536133	3.6040151
13.103246	27897.061	78.633789	3.6105413
13.119849	27899.734	78.731445	3.6169364
13.136447	27894.676	78.829102	3.6232677
13.153157	27876.564	78.926758	3.629338
13.167056	27883.082	79.024414	3.6351941
13.184508	27898.082	79.12207	3.641556
13.200216	27886.438	79.219727	3.6478
13.216153	27895.027	79.317383	3.6540637
13.233789	27896.814	79.415039	3.6604793
13.249905	27893.451	79.512695	3.6669543
13.26678	27896.063	79.610352	3.6733904
13.281617	27890.67	79.708008	3.6795447
13.299324	27887.828	79.805664	3.6859632
13.315404	27894.787	79.90332	3.6922367
13.330622	27894.385	80.000977	3.6986177
13.346147	27884.434	80.098633	3.7049592
13.363975	27893.875	80.196289	3.7115395
13.380242	27888.344	80.293945	3.7178938
13.395428	27893.107	80.391602	3.7245138
13.412442	27890.615	80.489258	3.7309699
13.428822	27889.494	80.586914	3.7375987
13.445447	27885.645	80.68457	3.7441077
13.459456	27872.32	80.782227	3.7503188
13.478482	27890.832	80.879883	3.7570233
13.494075	27875.988	80.977539	3.7634275
13.509498	27875.445	81.075195	3.7698014
13.526587	27886.051	81.172852	3.7763143
13.54198	27888.131	81.270508	3.782825
13.557303	27882.244	81.368164	3.7896137
13.575288	27893.223	81.46582	3.7963974
13.591055	27882.705	81.563477	3.8030965
13.608131	27888.023	81.661133	3.8098485
13.62431	27878.361	81.758789	3.8165491
13.640814	27862.285	81.856445	3.8229735
13.655741	27878.455	81.954102	3.8296154
13.672729	27886.311	82.051758	3.8363435
13.688191	27889.479	82.149414	3.8431137
13.705501	27873.777	82.24707	3.8498425
13.722143	27884.371	82.344727	3.8565738
13.738174	27882.652	82.442383	3.8635728
13.754097	27875.117	82.540039	3.8704867
13.771652	27883.359	82.637695	3.8773119
13.787353	27871.672	82.735352	3.8842156
13.803137	27874.65	82.833008	3.8908536
13.819378	27880.939	82.930664	3.8977544
13.835408	27866.324	83.02832	3.9045336
13.851761	27875.652	83.125977	3.9112015
13.867769	27875.234	83.223633	3.9184241
13.883782	27878.977	83.321289	3.9254124
13.899325	27870.402	83.418945	3.9325385
13.917498	27869.15	83.516602	3.9395115
13.932786	27865.855	83.614258	3.9465694
13.94976	27869.217	83.711914	3.9535685
13.964829	27855.141	83.80957	3.9603903
13.981862	27872.521	83.907227	3.9675655
13.998849	27874.205	84.004883	3.9747162
14.013784	27860.184	84.102539	3.9818916
14.030566	27869.709	84.200195	3.9890428
14.047982	27880.795	84.297852	3.9963441
14.064004	27870.49	84.395508	4.0037122
14.079726	27866.063	84.493164	4.0109053
14.095387	27861.053	84.59082	4.0179763
14.113701	27870.658	84.688477	4.0254259
14.127738	27862.322	84.786133	4.0325303
14.143044	27862.4	84.883789	4.0398364
14.160537	27866.324	84.981445	4.047121
14.177162	27864.666	85.079102	4.0545406
14.192638	27862.236	85.176758	4.0618386
14.210287	27858.604	85.274414	4.0691299
14.227395	27866.732	85.37207	4.0765896
14.241607	27857.654	85.469727	4.0840611
14.258894	27855.127	85.567383	4.0915523
14.276471	27867.129	85.665039	4.0992179
14.292046	27848.799	85.762695	4.1064558
14.307688	27850.186	85.860352	4.1139674
14.324139	27858.508	85.958008	4.1217194
14.340795	27862.639	86.055664	4.1293211
14.35603	27858.855	86.15332	4.1368709
14.371971	27847.354	86.250977	4.1443839
14.388677	27851.234	86.348633	4.1518693
14.406299	27854.08	86.446289	4.1595912
14.422159	27847.496	86.543945	4.1673961
14.437926	27856.734	86.641602	4.1752057
14.454655	27853.855	86.739258	4.1831131
14.471083	27839.977	86.836914	4.1907616
14.486828	27853.197	86.93457	4.1985192
14.502214	27845.959	87.032227	4.2063403
14.518665	27843.141	87.129883	4.2140517
14.535362	27844.256	87.227539	4.2218189
14.552157	27839.973	87.325195	4.2299085
14.568068	27845.311	87.422852	4.2377987
14.584706	27841.207	87.520508	4.2457004
14.601966	27839.725	87.618164	4.2538624
14.616186	27819.113	87.71582	4.2617254
14.63223	27843.668	87.813477	4.2696953
14.649817	27833.385	87.911133	4.2780848
14.666406	27830.816	88.008789	4.2860556
14.681274	27816.701	88.106445	4.2938967
14.697783	27824.354	88.204102	4.3017678
14.714542	27838.588	88.301758	4.3101063
14.73035	27832.268	88.399414	4.3184843
14.747529	27822.02	88.49707	4.3266902
14.762733	27819.924	88.594727	4.3349242
14.779881	27830.418	88.692383	4.3435555
14.795326	27811.814	88.790039	4.3518057
14.81171	27823.934	88.887695	4.3600178
14.828469	27829.928	88.985352	4.3686767
14.845261	27822.57	89.083008	4.3773751
14.860942	27811.041	89.180664	4.3861108
14.8786	27817.229	89.27832	4.394455
14.894546	27809.367	89.375977	4.4030752
14.909946	27807.213	89.473633	4.4115028
14.92582	27810.85	89.571289	4.4200253
14.942329	27811.154	89.668945	4.4287028
14.957962	27793.58	89.766602	4.437366
14.975035	27800.371	89.864258	4.4460831
14.992044	27808.09	89.961914	4.4548173
15.008424	27808.238	90.05957	4.4636393
15.024271	27798.1	90.157227	4.472671
15.041289	27810.232	90.254883	4.4813948
15.056802	27807.908	90.352539	4.4905162
15.072953	27790.918	90.450195	4.4992847
15.088796	27790.408	90.547852	4.507822
15.104496	27791.219	90.645508	4.5168376
15.121644	27798.127	90.743164	4.5258584
15.137089	27790.203	90.84082	4.5349536
15.152981	27801.5	90.938477	4.5443029
15.171931	27788.115	91.036133	4.5534749
15.187957	27780.1	91.133789	4.5627637
15.203599	27784.268	91.231445	4.5718989
15.2192	27782.348	91.329102	4.581141
15.235548	27766.168	91.426758	4.5902405
15.251351	27786.813	91.524414	4.5996408
15.267601	27775.518	91.62207	4.609118
15.285044	27779.545	91.719727	4.618804
15.302215	27768.84	91.817383	4.6283631
15.316972	27766.688	91.915039	4.6376748
15.333941	27760.162	92.012695	4.6471024
15.349569	27776.143	92.110352	4.6567998
15.364853	27766.902	92.208008	4.666595
15.382591	27758.436	92.305664	4.6763968
15.397049	27758.758	92.40332	4.686233
15.41324	27751.434	92.500977	4.6957541
15.429522	27753.488	92.598633	4.7055321
15.446232	27756.309	92.696289	4.7154717
15.462584	27760.264	92.793945	4.7257056
15.480501	27761.301	92.891602	4.7358994
15.497077	27754.256	92.989258	4.7463579
15.513313	27742.535	93.086914	4.7565465
15.528728	27743.279	93.18457	4.7665205
15.545822	27739.201	93.282227	4.776823
15.561258	27734.09	93.379883	4.7869458
15.576324	27738.291	93.477539	4.7968893
15.594759	27738.15	93.575195	4.807241
15.610781	27721.371	93.672852	4.8175664
15.625653	27734.65	93.770508	4.8280311
15.641026	27724.375	93.868164	4.8382854
15.657948	27729.383	93.96582	4.8489542
15.674698	27719.158	94.063477	4.8595695
15.691944	27721.732	94.161133	4.8708158
15.707662	27711.262	94.258789	4.8814249
15.723885	27714.602	94.356445	4.8922157
15.740144	27708.123	94.454102	4.903194
15.757162	27707.93	94.551758	4.9139142
15.772991	27697.717	94.649414	4.9249306
15.789528	27699.891	94.74707	4.9359975
15.806059	27695.621	94.844727	4.9470968
15.822161	27703.5	94.942383	4.9583807
15.837088	27680.605	95.040039	4.9690332
15.853203	27691.07	95.137695	4.9801006
15.869452	27694.674	95.235352	4.9915805
15.887611	27688.273	95.333008	5.0032177
15.903111	27679.488	95.430664	5.0147338
15.918144	27669.799	95.52832	5.0260162
15.934997	27672.475	95.625977	5.0373807
15.951748	27672.754	95.723633	5.049037
15.967179	27667.877	95.821289	5.0606456
15.984484	27664.477	95.918945	5.072504
16.000036	27672.225	96.016602	5.0846858
16.017735	27655.744	96.114258	5.0963922
16.033045	27661.861	96.211914	5.1083922
16.049023	27648.029	96.30957	5.1204362
16.065384	27654.992	96.407227	5.1324029
16.08069	27653.51	96.504883	5.1445642
16.098343	27659.936	96.602539	5.1569271
16.115059	27650.766	96.700195	5.1696401
16.131554	27634.146	96.797852	5.1816392
16.148756	27635.164	96.895508	5.194139
16.162668	27635.443	96.993164	5.2065868
16.178711	27610.148	97.09082	5.2186747
16.195351	27629.004	97.188477	5.2311583
16.212378	27629.104	97.286133	5.2441812
16.227774	27622.248	97.383789	5.2572284
16.245213	27608.01	97.481445	5.2700138
16.262365	27614.338	97.579102	5.2827153
16.277609	27615.688	97.676758	5.2962117
16.294109	27602.404	97.774414	5.3094029
16.309961	27589.459	97.87207	5.3220959
16.325947	27584.922	97.969727	5.3350792
16.34247	27589.707	98.067383	5.3479152
16.357275	27586.389	98.165039	5.3614874
16.374914	27577.879	98.262695	5.3747673
16.390696	27563.859	98.360352	5.3879418
16.406515	27573.979	98.458008	5.4015121
16.422287	27560.65	98.555664	5.4151831
16.439941	27567.275	98.65332	5.4294028
16.457054	27551.98	98.750977	5.4429793
16.472771	27553.49	98.848633	5.4570956
16.48827	27546.387	98.946289	5.4710393
16.504354	27527.906	99.043945	5.4846125
16.521112	27538.533	99.141602	5.49859
16.537479	27540.162	99.239258	5.5127134
16.554695	27530.701	99.336914	5.5276041
16.570364	27521.395	99.43457	5.5418763
16.587641	27515.135	99.532227	5.5564132
16.603539	27494.234	99.629883	5.5703702
16.61867	27501.424	99.727539	5.5845199
16.63361	27483.619	99.825195	5.5989299
16.651232	27486.449	99.922852	5.6134109
16.66757	27490.344	100.02051	5.6284714
16.684782	27468.896	100.11816	5.6431775
16.700235	27466.432	100.21582	5.6580138
16.716803	27466.51	100.31348	5.6732836
16.734175	27448.672	100.41113	5.6884117
16.749056	27447.68	100.50879	5.7030511
16.766045	27444.123	100.60645	5.7181191
16.783026	27434.734	100.7041	5.7333746
16.797403	27423.508	100.80176	5.7480578
16.813162	27422.721	100.89941	5.7630982
16.829321	27418.498	100.99707	5.7784224
16.846121	27404.479	101.09473	5.7939253
16.862997	27402.877	101.19238	5.8092937
16.878054	27386.549	101.29004	5.8246388
16.894844	27389.588	101.3877	5.8400593
16.911875	27380.309	101.48535	5.8556995
16.927979	27371.313	101.58301	5.8713861
16.945814	27374.871	101.68066	5.8873529
16.960512	27352.646	101.77832	5.9033017
16.977755	27353.566	101.87598	5.9193158
16.993258	27330.188	101.97363	5.9351339
17.010527	27329.033	102.07129	5.9511929
17.025225	27312.906	102.16895	5.967217
17.043947	27319.898	102.2666	5.9836445
17.058628	27293.352	102.36426	5.999527
17.074028	27286.219	102.46191	6.0152578
17.091909	27282.529	102.55957	6.0310035
17.106894	27265.742	102.65723	6.0472751
17.123028	27257.656	102.75488	6.063365
17.139631	27252.723	102.85254	6.0798626
17.156158	27231.906	102.9502	6.0962496
17.173243	27231.881	103.04785	6.1124816
17.188908	27216.398	103.14551	6.1290703
17.204218	27206.42	103.24316	6.1451006
17.220415	27193.148	103.34082	6.1619902
17.237888	27183.188	103.43848	6.1786962
17.253683	27171.904	103.53613	6.1948571
17.269169	27150.785	103.63379	6.2112651
17.286451	27140.494	103.73145	6.2278142
17.301945	27129.303	103.8291	6.2444839
17.319424	27111.285	103.92676	6.2611585
17.335781	27098.775	104.02441	6.277555
17.351467	27094.42	104.12207	6.2944255
17.366581	27070.064	104.21973	6.311245
17.383381	27058.641	104.31738	6.3279147
17.399748	27039.266	104.41504	6.3447604
17.415747	27025.229	104.5127	6.3611875
17.432434	27016.082	104.61035	6.3777742
17.448835	27010.371	104.70801	6.3945971
17.465702	26989.055	104.80566	6.4115934
17.481647	26967.152	104.90332	6.4287257
17.497429	26959.105	105.00098	6.4449344
17.514326	26940.521	105.09863	6.4619789
17.531801	26927.283	105.19629	6.4798269
17.54772	26889.256	105.29395	6.4965272
17.563316	26886.91	105.3916	6.5130496
17.579018	26868.914	105.48926	6.5299096
17.594454	26839.072	105.58691	6.5461917
17.61162	26834.248	105.68457	6.5627556
17.627743	26816.932	105.78223	6.5802927
17.644485	26798.168	105.87988	6.5979071
17.661455	26768.844	105.97754	6.6147022
17.677418	26761.717	106.0752	6.6315093
17.694168	26740.975	106.17285	6.6488404
17.710659	26720.035	106.27051	6.665957
17.726347	26700.482	106.36816	6.682869
17.741917	26679.484	106.46582	6.6996994
17.758747	26661.258	106.56348	6.7169785
17.773844	26643.873	106.66113	6.7341938
17.791019	26612.895	106.75879	6.7508883
17.809145	26602.715	106.85645	6.7681155
17.823908	26568.484	106.9541	6.7852511
17.840658	26564.395	107.05176	6.8020716
17.85663	26540.445	107.14941	6.8196516
17.873764	26512.857	107.24707	6.8366618
17.88924	26485.342	107.34473	6.8533273
17.904955	26465.449	107.44238	6.8701568
17.921616	26456.834	107.54004	6.8877106
17.938276	26437.875	107.6377	6.9052091
17.954384	26399.436	107.73535	6.9225335
17.970619	26379.412	107.83301	6.9391403
17.987476	26346.969	107.93066	6.9562464
18.002806	26324.957	108.02832	6.9728808
18.019226	26315.123	108.12598	6.9903145
18.035439	26270.781	108.22363	7.0073562
18.050917	26252.758	108.32129	7.0241303
18.066338	26226.721	108.41895	7.0414209
18.083094	26196.086	108.5166	7.0588713
18.099724	26186.203	108.61426	7.0763264
18.116621	26136.141	108.71191	7.0931783
18.132004	26117.268	108.80957	7.1101294
18.148056	26099.414	108.90723	7.1274867
18.165594	26076.301	109.00488	7.1449203
18.180565	26038.328	109.10254	7.1617322
18.197664	26012.813	109.2002	7.1792712
18.214888	25994.494	109.29785	7.1971078
18.23056	25956.223	109.39551	7.2141838
18.247553	25925.783	109.49316	7.2320061
18.2642	25887.844	109.59082	7.2486868
18.279068	25863.115	109.68848	7.2651935
18.295315	25838.064	109.78613	7.2830176
18.312927	25797.484	109.88379	7.3003855
18.327335	25767.516	109.98145	7.3175154
18.345297	25744.971	110.0791	7.3349385
18.361677	25700.434	110.17676	7.3520451
18.376961	25675.703	110.27441	7.3695993
18.393309	25644.941	110.37207	7.3872738
18.409241	25602.852	110.46973	7.4044781
18.426813	25575.67	110.56738	7.4221344
18.44301	25539.768	110.66504	7.4391279
18.458326	25496.523	110.7627	7.456861
18.474834	25463.313	110.86035	7.4737964
18.491428	25428.557	110.95801	7.490777
18.507526	25403.063	111.05566	7.5083609
18.52462	25356.162	111.15332	7.5263977
18.540119	25324.865	111.25098	7.543685
18.557175	25279.496	111.34863	7.5612507
18.572596	25241.041	111.44629	7.5785255
18.588577	25207.348	111.54395	7.5957394
18.605167	25168.881	111.6416	7.6130757
18.620836	25123.734	111.73926	7.630228
18.637823	25089.119	111.83691	7.6477542
18.653639	25054.836	111.93457	7.6653714
18.669205	25010.033	112.03223	7.6831241
18.686384	24955.805	112.12988	7.7004714
18.702755	24921.98	112.22754	7.7176075
18.718571	24871.398	112.3252	7.7355728
18.73538	24830.678	112.42285	7.7535286
18.751253	24778.875	112.52051	7.7712612
18.767097	24737.428	112.61816	7.7887516
18.784142	24694.969	112.71582	7.8062992
18.801098	24647.285	112.81348	7.8245521
18.817102	24588.629	112.91113	7.8424659
18.832037	24541.693	113.00879	7.8597555
18.850084	24486.57	113.10645	7.877759
18.866205	24436.01	113.2041	7.8960567
18.881735	24369.979	113.30176	7.914103
18.896456	24298.793	113.39941	7.9318681
18.913792	24244.365	113.49707	7.9496198
18.930735	24171.658	113.59473	7.9687867
18.947109	24067.576	113.69238	7.9879956
18.965067	23936.688	113.79004	8.0081453
19.011133	-711.85608	113.8877	8.1018343
18.999193	149.74748	113.98535	8.0522099
19.016912	-127.92601	114.08301	8.0751867
19.032032	-28.418842	114.18066	8.0862312
19.046387	61.518162	114.27832	8.0967321
19.063274	-154.2701	114.37598	8.1192064
19.078913	119.47519	114.47363	8.1329546
19.096115	-155.2751	114.57129	8.1479912
19.111954	59.754238	114.66895	8.165987
19.127621	-58.817909	114.7666	8.1818838
19.143419	-42.932457	114.86426	8.197423
19.159218	39.050007	114.96191	8.2146454
19.174524	-118.6498	115.05957	8.2316589
19.190872	79.455551	115.15723	8.2447414
19.190908	-111.65976	115.25488	8.2482204
19.189003	33.208054	115.35254	8.2446394
19.188261	-48.386513	115.4502	8.2445765
19.187748	-36.387005	115.54785	8.2458038
19.189196	56.930588	115.61621	8.244916