File: data/A2.dat
MTS793|MPT|ENU|1|2|.|/|:|1|0|0|A

Data Acquisition						Time:	10.009766	s	2/4/2020 10:04:19 AM
Axial Displacement	Axial Force	Time	Axial Extensometer
mm	N	s	mm
0.00055879354	380.77731	0.018554688	-3.7902282e-05
0.0031895936	491.11316	0.11621094	0.00030617701
0.021214038	1565.1982	0.21386719	0.0035117019
0.038031489	2522.2786	0.31152344	0.0064984863
0.052848458	3371.4888	0.40917969	0.0091991527
0.068928301	4205.5542	0.50683594	0.011967277
0.085260719	5007.5347	0.60449219	0.01467614
0.10195524	5853.5864	0.70214844	0.017764676
0.11809766	6633.0337	0.79980469	0.020698387
0.13634562	7487.5493	0.89746094	0.02401668
0.15376881	8200.5244	0.99511719	0.02706953
0.1697816	8845.083	1.0927734	0.030008117
0.18652081	9445.042	1.1904297	0.032998856
0.20148531	9995.8779	1.2880859	0.036064744
0.21747127	10559.725	1.3857422	0.039375495
0.23573041	11065.263	1.4833984	0.04278123
0.25252104	11509.328	1.5810547	0.046296339
0.26932508	11905.483	1.6787109	0.049823944
0.28536022	12248.219	1.7763672	0.053313415
0.30270293	12572.181	1.8740234	0.056955907
0.31785741	12864.516	1.9716797	0.060605932
0.33506826	13115.272	2.0693359	0.064367093
0.35109892	13340.114	2.1669922	0.06811434
0.36755875	13555.509	2.2646484	0.072015576
0.38461983	13748.006	2.3623047	0.075987175
0.40082708	13913.132	2.4599609	0.080025859
0.41794181	14071.111	2.5576172	0.084077306
0.43449774	14221.708	2.6552734	0.088273808
0.45121238	14348.563	2.7529297	0.092499256
0.46792477	14470.537	2.8505859	0.096641794
0.48351511	14584.161	2.9482422	0.1007999
0.4995279	14698.253	3.0458984	0.10495739
0.51612628	14806.285	3.1435547	0.10902901
0.53074431	14919.427	3.2412109	0.11315768
0.55002046	15007.896	3.3388672	0.11721501
0.56457591	15139.97	3.4365234	0.12125621
0.58078319	15247.858	3.5341797	0.12545715
0.59798288	15355.121	3.6318359	0.12969294
0.61353076	15449.362	3.7294922	0.13365568
0.62923282	15552.885	3.8271484	0.1376543
0.64526349	15660.613	3.9248047	0.14163132
0.66255033	15761.589	4.0224609	0.14563967
0.67842454	15870.322	4.1201172	0.14972085
0.69420266	15959.627	4.2177734	0.15371795
0.71023774	16065.201	4.3154297	0.15775394
0.72741508	16160.396	4.4130859	0.16183837
0.74337423	16259.826	4.5107422	0.16571097
0.76005983	16346.325	4.6083984	0.1698193
0.7762022	16442.859	4.7060547	0.17381735
0.79164732	16543.086	4.8037109	0.17783026
0.80847371	16638.061	4.9013672	0.18189679
0.82452667	16722.881	4.9990234	0.18614019
0.84194314	16810.025	5.0966797	0.19005379
0.85721612	16900.922	5.1943359	0.19402292
0.87536347	16994.074	5.2919922	0.19817418
0.89189482	17081.979	5.3896484	0.20235938
0.90892684	17166.07	5.4873047	0.2064022
0.92456639	17247.215	5.5849609	0.21036823
0.94146204	17325.514	5.6826172	0.21431951
0.95676851	17404.498	5.7802734	0.21806605
0.97245502	17484.744	5.8779297	0.22195593
0.98784196	17564.486	5.9755859	0.22592013
1.0046773	17650.025	6.0732422	0.22985065
1.0208465	17727.09	6.1708984	0.234024
1.0369622	17805.596	6.2685547	0.23799472
1.0534711	17883.865	6.3662109	0.24201967
1.0694124	17956.348	6.4638672	0.24601088
1.0860152	18026.693	6.5615234	0.24991809
1.1013441	18101.092	6.6591797	0.25373617
1.1188544	18179.264	6.7568359	0.25781995
1.1352562	18247.484	6.8544922	0.26182234
1.1513762	18325.729	6.9521484	0.26587346
1.1677288	18401.092	7.0498047	0.26988316
1.1834062	18467.541	7.1474609	0.27389604
1.2004204	18533.041	7.2451172	0.2778393
1.216603	18604.285	7.3427734	0.28178376
1.2321286	18668.617	7.4404297	0.28567559
1.2493395	18735.887	7.5380859	0.28958577
1.2647443	18801.406	7.6357422	0.29358903
1.2800418	18867.484	7.7333984	0.29754966
1.2971632	18932.109	7.8310547	0.30149093
1.3143741	18993.324	7.9287109	0.30532745
1.3296045	19061.119	8.0263672	0.30930772
1.3464935	19126.943	8.1240234	0.31307837
1.3615273	19193.205	8.2216797	0.31710246
1.3782866	19253.543	8.3193359	0.3212204
1.3951265	19321.104	8.4169922	0.32530671
1.4115326	19385.176	8.5146484	0.32946399
1.4295794	19444.795	8.6123047	0.33347559
1.4451139	19505.305	8.7099609	0.33745301
1.4608942	19559.414	8.8076172	0.34143338
1.4766521	19619.42	8.9052734	0.34518442
1.4939703	19673.938	9.0029297	0.34908438
1.5088029	19737.662	9.1005859	0.3530817
1.5252448	19801.309	9.1982422	0.3572059
1.5416957	19852.404	9.2958984	0.36126646
1.5578605	19907.531	9.3935547	0.36510304
1.5730374	19963.402	9.4912109	0.36901754
1.589895	20020.875	9.5888672	0.3729893
1.6065739	20075.184	9.6865234	0.37695628
1.6221888	20132.701	9.7841797	0.3809053
1.6378753	20187.314	9.8818359	0.38506919
1.6560875	20240.309	9.9794922	0.38905832
1.672811	20295.18	10.077148	0.39311993
1.6893066	20342.643	10.174805	0.39695188
1.7048634	20395.018	10.272461	0.40095115
1.720912	20448.584	10.370117	0.40484211
1.7373495	20501.389	10.467773	0.40877318
1.7544664	20551.195	10.56543	0.4128556
1.7706	20604.951	10.663086	0.41691381
1.7868586	20652.484	10.760742	0.42094094
1.8020712	20702.605	10.858398	0.42496303
1.8199973	20754.309	10.956055	0.42896309
1.8343784	20793.365	11.053711	0.43290025
1.8512226	20842.475	11.151367	0.43679261
1.8676691	20895.039	11.249023	0.44088021
1.8835031	20939.537	11.34668	0.44483185
1.8991269	20989.229	11.444336	0.44877064
1.9153141	21035.922	11.541992	0.45276192
1.9316084	21084.221	11.639648	0.45680767
1.9477777	21129.963	11.737305	0.46064565
1.9647874	21177.693	11.834961	0.46479875
1.9814707	21224.834	11.932617	0.46892947
1.9984312	21268.291	12.030273	0.47293535
2.0138316	21311.998	12.12793	0.47687557
2.0303004	21356.807	12.225586	0.48084334
2.0471313	21402.828	12.323242	0.48495343
2.0617268	21449.807	12.420898	0.48891139
2.0790317	21489.227	12.518555	0.49302745
2.0954378	21529.012	12.616211	0.49704915
2.1118441	21573.977	12.713867	0.50103241
2.1277764	21613.35	12.811523	0.50500089
2.1436551	21661.807	12.90918	0.50907981
2.1603696	21698.916	13.006836	0.51305485
2.1769457	21742.766	13.104492	0.5170989
2.1936827	21784.996	13.202148	0.52117354
2.2094271	21824.277	13.299805	0.52528578
2.2251136	21862.373	13.397461	0.52937907
2.2432857	21903.729	13.495117	0.53332996
2.2588871	21939.152	13.592773	0.53745317
2.2752843	21977.836	13.69043	0.54137415
2.2916636	22015.016	13.788086	0.5454604
2.3076096	22053.086	13.885742	0.54941207
2.3237832	22089.355	13.983398	0.55338544
2.3392506	22134.805	14.081055	0.55750072
2.3568728	22171.871	14.178711	0.56156629
2.3717992	22205.023	14.276367	0.56546479
2.3889699	22243.119	14.374023	0.56961763
2.405005	22281.754	14.47168	0.57367837
2.4213262	22319.951	14.569336	0.57779437
2.4380944	22350.627	14.666992	0.58174324
2.4530747	22387.438	14.764648	0.58576733
2.4696193	22420.867	14.862305	0.58970153
2.485136	22454.217	14.959961	0.59370911
2.501797	22498.285	15.057617	0.597709
2.5187798	22529.666	15.155273	0.6018123
2.5341175	22564.494	15.25293	0.60583615
2.5506041	22607.662	15.350586	0.60996693
2.568423	22641.441	15.448242	0.614178
2.5841765	22678.508	15.545898	0.61843556
2.6008286	22705.092	15.643555	0.62252212
2.6184461	22738.91	15.741211	0.62657517
2.6337929	22773.064	15.838867	0.63066328
2.6498907	22805.189	15.936523	0.6346637
2.6655636	22834.16	16.03418	0.63868904
2.6828773	22862.869	16.131836	0.64267933
2.697777	22893.369	16.229492	0.64658844
2.7144558	22922.563	16.327148	0.65064704
2.7300797	22958.863	16.424805	0.65468353
2.7456231	22987.877	16.522461	0.65873849
2.7627938	23018.006	16.620117	0.66278142
2.7783864	23050.309	16.717773	0.66687769
2.7954319	23077.027	16.81543	0.67087626
2.8099873	23115.494	16.913086	0.67496777
2.8276808	23147.643	17.010742	0.67925644
2.845084	23175.863	17.108398	0.68343002
2.8607705	23203.318	17.206055	0.68747038
2.8780215	23239.904	17.303711	0.69171715
2.8946333	23268.184	17.401367	0.69592839
2.9110796	23293.445	17.499023	0.70007747
2.9273338	23317.643	17.59668	0.70417041
2.9442408	23351.248	17.694336	0.70824099
2.9585323	23367.844	17.791992	0.71214253
2.9744425	23402.561	17.889648	0.71627945
2.9904776	23433.191	17.987305	0.72036868
3.0057795	23459.986	18.084961	0.72433025
3.0223467	23488.467	18.182617	0.72830164
3.0392983	23514.979	18.280273	0.73237228
3.0551858	23542.744	18.37793	0.73645389
3.0702553	23573.896	18.475586	0.74053377
3.086724	23600.182	18.573242	0.74465573
3.104923	23626.947	18.670898	0.74879289
3.1204441	23656.037	18.768555	0.75296462
3.1365237	23676.672	18.866211	0.75700557
3.1535559	23703.086	18.963867	0.76120681
3.16943	23730.266	19.061523	0.76531565
3.1849556	23757.896	19.15918	0.76956099
3.2020769	23780.863	19.256836	0.77370363
3.2195964	23806.75	19.354492	0.77789497
3.2347195	23832.537	19.452148	0.78215152
3.251385	23854.092	19.549805	0.78624475
3.2675319	23879.277	19.647461	0.79034644
3.2841525	23901.705	19.745117	0.79444522
3.3002279	23930.59	19.842773	0.79860723
3.3165224	23956.648	19.94043	0.80291295
3.3320301	23981.402	20.038086	0.80708259
3.3491917	24004.875	20.135742	0.81127113
3.3662996	24028.281	20.233398	0.81545699
3.3832378	24049.596	20.331055	0.81968135
3.3983388	24070.076	20.428711	0.82375354
3.4142711	24091.205	20.526367	0.82776374
3.4301453	24116.602	20.624023	0.83185083
3.4459391	24132.434	20.72168	0.83577293
3.4621887	24162.605	20.819336	0.8399083
3.4783981	24187.34	20.916992	0.8439998
3.4942679	24217.6	21.014648	0.84820658
3.5110273	24239.391	21.112305	0.85244465
3.5280771	24264.152	21.209961	0.85670394
3.5437009	24284.076	21.307617	0.86087042
3.560514	24305.75	21.405273	0.86513674
3.5778859	24323.699	21.50293	0.8692984
3.5929732	24344.668	21.600586	0.87344301
3.6095448	24364.561	21.698242	0.87757355
3.6254725	24382.754	21.795898	0.88171971
3.6419413	24412.281	21.893555	0.88597304
3.6583028	24428.906	21.991211	0.89004445
3.67449	24454.451	22.088867	0.89425248
3.6909587	24469.506	22.186523	0.89849752
3.7063413	24492.58	22.28418	0.90276831
3.7224748	24506.605	22.381836	0.90683842
3.7397079	24529.605	22.479492	0.91099268
3.7554839	24553.666	22.577148	0.91514128
3.7716308	24580.441	22.674805	0.91955692
3.7894897	24599.912	22.772461	0.92383701
3.8056724	24618.021	22.870117	0.92810756
3.8209431	24636.125	22.967773	0.93222547
3.8385651	24652.914	23.06543	0.93651587
3.8535676	24673.453	23.163086	0.94067651
3.8702018	24691.08	23.260742	0.94482803
3.8864872	24709.041	23.358398	0.94891268
3.9011636	24735.203	23.456055	0.95321542
3.9192908	24752.971	23.553711	0.95728648
3.9348609	24778.734	23.651367	0.96162778
3.9518528	24799.262	23.749023	0.96597838
3.968545	24812.498	23.84668	0.97022289
3.9835253	24824.766	23.944336	0.97447562
4.0001059	24843.41	24.041992	0.97869426
4.0162301	24863.746	24.139648	0.98286235
4.0319839	24876.479	24.237305	0.98703927
4.0486088	24897.16	24.334961	0.99111247
4.0651093	24920.063	24.432617	0.99531233
4.0810146	24935.203	24.530273	0.99969727
4.0977826	24952.193	24.62793	1.0038371
4.1134024	24978.809	24.725586	1.0081382
4.1304698	24989.336	24.823242	1.0124959
4.1479535	25011.199	24.920898	1.0168002
4.163497	25027.637	25.018555	1.0211502
4.1805782	25043.521	25.116211	1.0254172
4.197257	25054.924	25.213867	1.0297734
4.2123356	25066.35	25.311523	1.0338708
4.2281694	25088.977	25.40918	1.0378281
4.2439318	25111.287	25.506836	1.0420688
4.2604589	25124.15	25.604492	1.0463837
4.2762079	25140.018	25.702148	1.0504547
4.2914696	25158.068	25.799805	1.0547276
4.3087969	25180.35	25.897461	1.0590107
4.324729	25198.357	25.995117	1.0634239
4.342217	25213.904	26.092773	1.0677263
4.3578768	25227.021	26.19043	1.0720394
4.3745689	25243.537	26.288086	1.076316
4.3909659	25255.521	26.385742	1.0805597
4.4066439	25273.693	26.483398	1.0848023
4.4241138	25287.592	26.581055	1.0891837
4.4401937	25298.373	26.678711	1.0934793
4.4566803	25323.455	26.776367	1.097735
4.4725323	25334.262	26.874023	1.102056
4.489162	25348.721	26.97168	1.1062979
4.5048347	25363.662	27.069336	1.1105164
4.5213976	25377.881	27.166992	1.1148106
4.5370975	25391.219	27.264648	1.1191487
4.5539327	25406.254	27.362305	1.1233765
4.5699992	25426.059	27.459961	1.1277504
4.5863023	25443.807	27.557617	1.1321133
4.6022797	25452.744	27.655273	1.136369
4.61869	25466.445	27.75293	1.1405107
4.6347833	25481.756	27.850586	1.1447573
4.6508455	25498.68	27.948242	1.1489607
4.666791	25511.58	28.045898	1.1532377
4.6820617	25527.611	28.143555	1.1575576
4.6995587	25547.541	28.241211	1.1618406
4.7156563	25556.951	28.338867	1.1661642
4.7318258	25577.709	28.436523	1.170585
4.7490454	25591.381	28.53418	1.1749339
4.7649732	25598.615	28.631836	1.1792008
4.7812409	25613.1	28.729492	1.1835594
4.797245	25620.414	28.827148	1.1877924
4.8134813	25640.652	28.924805	1.1920767
4.8295074	25655.754	29.022461	1.1964765
4.8456898	25673.281	29.120117	1.2008369
4.8635578	25683.012	29.217773	1.2052753
4.8785157	25691.025	29.31543	1.2095441
4.8953557	25699.455	29.413086	1.2138948
4.9113326	25713.088	29.510742	1.2179954
4.9266257	25732.301	29.608398	1.2223569
4.9439883	25751.949	29.706055	1.2267736
4.9606853	25755.902	29.803711	1.2311028
4.9766712	25774.07	29.901367	1.2354043
4.9935112	25781.486	29.999023	1.2396798
5.0092688	25797.729	30.09668	1.2441626
5.0262742	25812.477	30.194336	1.2485677
5.0429888	25823.543	30.291992	1.25289
5.0576291	25829.309	30.389648	1.2571546
5.0737581	25848.746	30.487305	1.2614372
5.0909958	25860.756	30.584961	1.2657036
5.1068077	25876.381	30.682617	1.2700132
5.1238084	25884.092	30.780273	1.2743855
5.138413	25901.369	30.87793	1.2786028
5.1553779	25912.654	30.975586	1.2829779
5.1719046	25931.521	31.073242	1.2875143
5.1896787	25940.564	31.170898	1.2920371
5.2053294	25951.234	31.268555	1.2964313
5.2224197	25957.578	31.366211	1.3008225
5.2379541	25965.105	31.463867	1.3051271
5.2544451	25979.842	31.561523	1.3094391
5.2711596	25988.543	31.65918	1.3138022
5.2872086	25995.336	31.756836	1.3181882
5.301898	26006.938	31.854492	1.3224095
5.3189254	26017.605	31.952148	1.3266504
5.3340712	26038.195	32.049805	1.3309057
5.3497934	26044.164	32.147461	1.3353267
5.3661904	26057.479	32.245117	1.339694
5.3829541	26070.1	32.342773	1.343992
5.4009876	26083.113	32.44043	1.3484769
5.4154449	26091.322	32.538086	1.3527824
5.4322219	26104.531	32.635742	1.3572567
5.4484897	26116.209	32.733398	1.3616245
5.4649272	26126.322	32.831055	1.3659732
5.4814587	26136.59	32.928711	1.3703541
5.4971671	26148.775	33.026367	1.3747241
5.514195	26163.561	33.124023	1.3791273
5.5300331	26173.832	33.22168	1.383598
5.5460548	26180.047	33.319336	1.3880279
5.5627069	26191.346	33.416992	1.3923386
5.5788808	26200.426	33.514648	1.3966806
5.5948043	26210.637	33.612305	1.401145
5.6118002	26220.314	33.709961	1.4055443
5.628448	26230.346	33.807617	1.4098873
5.6439509	26237.412	33.905273	1.4143001
5.6606388	26244.465	34.00293	1.4186505
5.6772194	26258.479	34.100586	1.4231142
5.6926513	26266.539	34.198242	1.4274647
5.7085299	26272.789	34.295898	1.4317659
5.7251191	26284.246	34.393555	1.4361906
5.7414317	26298.457	34.491211	1.4405478
5.7582221	26311.244	34.588867	1.4450078
5.7746463	26318.039	34.686523	1.4494745
5.7898097	26329.73	34.78418	1.4538052
5.8064485	26335.652	34.881836	1.4582336
5.8218398	26340.814	34.979492	1.4623717
5.8390641	26357.027	35.077148	1.466951
5.8550186	26347.432	35.174805	1.4712403
5.872632	26387.939	35.272461	1.4758278
5.8887205	26393.734	35.370117	1.4802955
5.9053593	26401.428	35.467773	1.4848816
5.9205718	26405.379	35.56543	1.4891864
5.9376845	26416.518	35.663086	1.493553
5.9542379	26427.664	35.760742	1.498009
5.9691916	26435.773	35.858398	1.5025131
5.985271	26442.898	35.956055	1.5069108
6.0015612	26453.691	36.053711	1.5113564
6.0182891	26460.514	36.151367	1.5158225
6.0342035	26465.879	36.249023	1.5201882
6.0496039	26476.307	36.34668	1.5245239
6.0670385	26490.141	36.444336	1.5291091
6.0824075	26492.053	36.541992	1.5334647
6.0993323	26505.078	36.639648	1.5378619
6.1151257	26511.014	36.737305	1.5423939
6.1323142	26520.338	36.834961	1.5467228
6.1469593	26527.418	36.932617	1.5511893
6.1647601	26537.682	37.030273	1.5556787
6.1816444	26546.797	37.12793	1.5602086
6.1981268	26550.795	37.225586	1.5646108
6.2136703	26560.422	37.323242	1.5690027
6.2293878	26570.264	37.420898	1.5734383
6.2454009	26585.285	37.518555	1.5779966
6.2626114	26587.813	37.616211	1.5825291
6.2802873	26597.705	37.713867	1.5870512
6.2952271	26606.561	37.811523	1.5913788
6.3107839	26612.373	37.90918	1.5959703
6.3274674	26616.83	38.006836	1.6003561
6.344048	26627.842	38.104492	1.6047504
6.3590727	26634.115	38.202148	1.6090851
6.3761673	26642.426	38.299805	1.6135359
6.3923903	26655.389	38.397461	1.6179551
6.4093819	26664.26	38.495117	1.6223707
6.4247737	26670.771	38.592773	1.6268747
6.4406567	26681.344	38.69043	1.6315258
6.4578719	26688.922	38.788086	1.6359442
6.4744124	26693.365	38.885742	1.6404388
6.4903712	26702.576	38.983398	1.645056
6.5059552	26714.52	39.081055	1.649524
6.5222631	26718.652	39.178711	1.6540298
6.540627	26721.691	39.276367	1.6586362
6.5554285	26724.08	39.374023	1.6630869
6.5722322	26735.07	39.47168	1.6674945
6.5883121	26742.697	39.569336	1.6719617
6.6035204	26746.836	39.666992	1.6763195
6.6203332	26757.162	39.764648	1.6807858
6.6363683	26766.469	39.862305	1.6853255
6.6527882	26773.285	39.959961	1.689824
6.669333	26785.113	40.057617	1.694436
6.6856766	26791.473	40.155273	1.6989536
6.7015996	26789.578	40.25293	1.703379
6.7178898	26798.137	40.350586	1.7077906
6.7345419	26807.68	40.448242	1.7123424
6.7504654	26818.91	40.545898	1.7168961
6.7672558	26826.004	40.643555	1.7214297
6.7828798	26831.938	40.741211	1.7259638
6.7995987	26837.531	40.838867	1.7305121
6.8154683	26848.531	40.936523	1.7350081
6.8329563	26853.898	41.03418	1.7396877
6.8486562	26861.799	41.131836	1.7440749
6.8656259	26866.83	41.229492	1.7485827
6.8810353	26875.125	41.327148	1.7532351
6.8975978	26877.889	41.424805	1.7576735
6.9136729	26882.152	41.522461	1.7622446
6.9301462	26893.23	41.620117	1.7666813
6.9455423	26890.42	41.717773	1.7711906
6.9616132	26903.305	41.81543	1.7756159
6.978024	26910.148	41.913086	1.7801752
6.9945464	26916.105	42.010742	1.7847383
7.0113549	26923.016	42.108398	1.7892781
7.0276761	26929.801	42.206055	1.7938203
7.0447125	26934.109	42.303711	1.798299
7.0588698	26944.496	42.401367	1.8028328
7.0756159	26952.035	42.499023	1.8074386
7.0930414	26955.076	42.59668	1.8120409
7.1089735	26962.816	42.694336	1.8165905
7.1253128	26967.611	42.791992	1.8212258
7.141129	26970.533	42.889648	1.8257576
7.1585097	26974.891	42.987305	1.8303313
7.1739459	26982.217	43.084961	1.8347861
7.1898022	26986.018	43.182617	1.839233
7.2055554	26991.268	43.280273	1.8437313
7.2220602	27002.086	43.37793	1.848254
7.2380013	27008.43	43.475586	1.8527914
7.2555342	27014.465	43.573242	1.8574241
7.2713547	27018.719	43.670898	1.8619756
7.2880111	27022.229	43.768555	1.8666025
7.3037601	27029.166	43.866211	1.8710386
7.3197908	27040.426	43.963867	1.875563
7.3357635	27046.604	44.061523	1.8801655
7.3530769	27051.715	44.15918	1.8847731
7.3687053	27059.672	44.256836	1.8893533
7.3865018	27064.158	44.354492	1.8940245
7.4014196	27064.895	44.452148	1.8985083
7.4181833	27065.92	44.549805	1.9030246
7.4340978	27075.5	44.647461	1.9075327
7.4501595	27083.189	44.745117	1.9121629
7.4671159	27089.488	44.842773	1.916644
7.4827576	27095.061	44.94043	1.9213206
7.4993916	27098.916	45.038086	1.9259312
7.5149126	27110.877	45.135742	1.9306029
7.5326552	27111.498	45.233398	1.9350829
7.5494418	27114.02	45.331055	1.9396797
7.5651908	27120.516	45.428711	1.9442582
7.5816951	27127.936	45.526367	1.9489222
7.5966845	27132.771	45.624023	1.9536288
7.6133051	27133.811	45.72168	1.9581367
7.6300688	27139.26	45.819336	1.9628485
7.6456523	27146.432	45.916992	1.9673651
7.6624026	27146.744	46.014648	1.9719343
7.678894	27155.398	46.112305	1.9765756
7.6946521	27157.648	46.209961	1.9810998
7.7116346	27166.039	46.307617	1.9857429
7.7275939	27171.324	46.405273	1.990348
7.7424893	27173.439	46.50293	1.9949882
7.7592173	27187.016	46.600586	1.9994472
7.7760482	27192.863	46.698242	2.004178
7.7922397	27194.289	46.795898	2.0089307
7.8098884	27200.355	46.893555	2.0135872
7.824882	27205.826	46.991211	2.0183053
7.8414044	27211.457	47.088867	2.0229831
7.8586512	27210.064	47.186523	2.0276802
7.8738995	27218.57	47.28418	2.0323033
7.8911552	27217.865	47.381836	2.0367694
7.9067922	27225.83	47.479492	2.041548
7.9233909	27229.328	47.577148	2.0461576
7.9386659	27233.426	47.674805	2.0507441
7.9569855	27238.098	47.772461	2.0553596
7.9718986	27242.75	47.870117	2.0600705
7.9883089	27249.363	47.967773	2.064677
8.0042372	27250.406	48.06543	2.0691319
8.0194273	27254.703	48.163086	2.0737131
8.0351629	27258.355	48.260742	2.0782588
8.052289	27269.313	48.358398	2.0829883
8.0683956	27270.248	48.456055	2.0875149
8.0848236	27274.689	48.553711	2.0921454
8.1009932	27287.313	48.651367	2.0968411
8.1180744	27289.629	48.749023	2.1016626
8.1340332	27291.053	48.84668	2.106308
8.1505785	27291.6	48.944336	2.110996
8.1673374	27298.316	49.041992	2.1156714
8.1829834	27298.137	49.139648	2.1204865
8.1989336	27306.275	49.237305	2.1250913
8.2148123	27305.748	49.334961	2.1297448
8.2322206	27308.01	49.432617	2.1343758
8.2482195	27316.527	49.530273	2.1390915
8.2644873	27324.689	49.62793	2.1438694
8.2808533	27329.697	49.725586	2.1485577
8.2967949	27331.066	49.823242	2.1533399
8.3135586	27332.268	49.920898	2.1580689
8.3297186	27340.262	50.018555	2.1628516
8.3464823	27342.852	50.116211	2.1676035
8.3630714	27344.984	50.213867	2.1722517
8.3785753	27350.234	50.311523	2.1769259
8.3951063	27357.539	50.40918	2.1816597
8.4115839	27357.037	50.506836	2.1863205
8.4276552	27360.191	50.604492	2.190953
8.4434528	27364.861	50.702148	2.1956372
8.4592152	27369.113	50.799805	2.2003741
8.4756308	27381.123	50.897461	2.2051363
8.4928637	27381.412	50.995117	2.2098446
8.5091228	27387.412	51.092773	2.2146659
8.5248537	27393.727	51.19043	2.2194283
8.5413179	27395.145	51.288086	2.2241874
8.5565577	27392.855	51.385742	2.2289574
8.5729589	27397.486	51.483398	2.2335765
8.5895262	27402.592	51.581055	2.2381902
8.6071711	27404.238	51.678711	2.2428865
8.6223927	27411.316	51.776367	2.2477181
8.6391068	27413.676	51.874023	2.252342
8.6545515	27418.602	51.97168	2.2570651
8.6713028	27414.691	52.069336	2.2618814
8.6869221	27425.617	52.166992	2.2665904
8.7034349	27424.494	52.264648	2.2713692
8.720355	27432.949	52.362305	2.2761526
8.7361403	27431.471	52.459961	2.2808485
8.7520142	27436.615	52.557617	2.2856104
8.7689257	27438.916	52.655273	2.2903297
8.7858953	27442.344	52.75293	2.2951109
8.8014116	27451.525	52.850586	2.3000274
8.8179474	27449.121	52.948242	2.3048131
8.833643	27458.865	53.045898	2.3095243
8.8502865	27457.26	53.143555	2.3143566
8.8675547	27455.738	53.241211	2.3191509
8.8825312	27461.309	53.338867	2.3237998
8.8994598	27466.381	53.436523	2.3285344
8.9150887	27466.393	53.53418	2.3333437
8.9309673	27471.615	53.631836	2.3381412
8.948164	27477.705	53.729492	2.3429239
8.9644146	27481.145	53.827148	2.347759
8.9800072	27485.25	53.924805	2.3526113
8.9957829	27489.412	54.022461	2.3574123
9.0137892	27496.633	54.120117	2.3623774
9.0293684	27495.584	54.217773	2.3671582
9.0461006	27497.803	54.31543	2.3720431
9.0622749	27500.631	54.413086	2.3767903
9.07763	27505.383	54.510742	2.3816047
9.0944653	27504.951	54.608398	2.3864653
9.1119804	27513.938	54.706055	2.3913081
9.1282969	27517.25	54.803711	2.3962293
9.1433172	27516.52	54.901367	2.4011598
9.1609087	27511.111	54.999023	2.4059215
9.1755486	27519.783	55.09668	2.4107051
9.1931219	27522.889	55.194336	2.4155946
9.2098942	27524.162	55.291992	2.4204407
9.2244501	27527.26	55.389648	2.4254098
9.2416782	27532.008	55.487305	2.4302464
9.2582006	27531.525	55.584961	2.4350193
9.2746611	27531.803	55.682617	2.4398663
9.2899408	27537.15	55.780273	2.4446211
9.305953	27540.541	55.87793	2.4495406
9.3217154	27546.525	55.975586	2.4542909
9.3382921	27545.162	56.073242	2.4590847
9.3545685	27547.201	56.170898	2.4639833
9.3709297	27553.23	56.268555	2.4688561
9.3871794	27557.73	56.366211	2.473809
9.4030533	27560.188	56.463867	2.4788654
9.4193974	27563.791	56.561523	2.4836578
9.4373322	27567.068	56.65918	2.4887037
9.4529781	27569.064	56.756836	2.4936392
9.4705868	27570.918	56.854492	2.4985266
9.4865284	27571.623	56.952148	2.5034471
9.5022907	27573.547	57.049805	2.508285
9.5176506	27576.57	57.147461	2.513175
9.5340261	27581.002	57.245117	2.5180943
9.5503473	27585.455	57.342773	2.523006
9.5664177	27588.672	57.44043	2.5280285
9.5828915	27589.541	57.538086	2.532953
9.5987339	27593.461	57.635742	2.5377786
9.6161327	27592.326	57.733398	2.542804
9.6319351	27596.014	57.831055	2.547754
9.647953	27599.129	57.928711	2.5527191
9.6640329	27601.631	58.026367	2.5576351
9.6804075	27602.295	58.124023	2.5625856
9.6973009	27603.777	58.22168	2.5676024
9.7131748	27604.17	58.319336	2.5724208
9.7287092	27606.148	58.416992	2.5773103
9.7453575	27617.781	58.514648	2.5823917
9.7618256	27617.938	58.612305	2.5874236
9.7787952	27615.367	58.709961	2.5923841
9.7952461	27613.381	58.807617	2.5973129
9.8102617	27616.979	58.905273	2.6022167
9.826396	27620.203	59.00293	2.6071653
9.8420019	27623.789	59.100586	2.6120806
9.8593645	27625.273	59.198242	2.6169901
9.8757935	27628.377	59.295898	2.6220462
9.8922129	27628.949	59.393555	2.6269708
9.9080915	27628.332	59.491211	2.6319234
9.9229822	27633.623	59.588867	2.6367347
9.9397545	27637.404	59.686523	2.6416829
9.9563618	27643.373	59.78418	2.6468513
9.9722719	27643.695	59.881836	2.6519272
9.9905024	27646.291	59.979492	2.657002
10.00542	27646.736	60.077148	2.6620445
10.023073	27652.293	60.174805	2.6670067
10.037767	27657.756	60.272461	2.6720965
10.054719	27657.236	60.370117	2.6773579
10.072216	27650.506	60.467773	2.6821775
10.088197	27661.936	60.56543	2.6873617
10.104719	27662.266	60.663086	2.6924005
10.119927	27657.457	60.760742	2.6974015
10.135744	27653.566	60.858398	2.7021942
10.152516	27667.645	60.956055	2.7072299
10.16844	27670.227	61.053711	2.7123952
10.184135	27670.541	61.151367	2.7174644
10.201476	27670.939	61.249023	2.7224441
10.217395	27670.35	61.34668	2.727499
10.232656	27671.625	61.444336	2.7324424
10.250234	27678.188	61.541992	2.7376072
10.265437	27672.777	61.639648	2.7425318
10.28073	27675.822	61.737305	2.7476165
10.298393	27685.465	61.834961	2.7528541
10.315179	27687.555	61.932617	2.7579818
10.331304	27685.641	62.030273	2.7630541
10.347974	27683.432	62.12793	2.7681196
10.364393	27690.949	62.225586	2.7733529
10.380862	27690.484	62.323242	2.7784266
10.397183	27696.689	62.420898	2.783623
10.412458	27694.32	62.518555	2.7887728
10.43004	27694.553	62.616211	2.7938294
10.446433	27692.768	62.713867	2.7989957
10.462646	27695.367	62.811523	2.8039794
10.477783	27696.475	62.90918	2.8090401
10.493604	27698.832	63.006836	2.8142052
10.510028	27704.17	63.104492	2.8192441
10.526752	27706.533	63.202148	2.824331
10.543154	27706.516	63.299805	2.8295233
10.56032	27710.469	63.397461	2.8345449
10.575027	27707.805	63.495117	2.839725
10.591558	27710.691	63.592773	2.8449929
10.607858	27717.211	63.69043	2.8500898
10.623955	27718.369	63.788086	2.855319
10.64003	27721.09	63.885742	2.8605413
10.656642	27718.867	63.983398	2.8658342
10.672602	27718.227	64.081055	2.8708918
10.689427	27715.35	64.178711	2.8760276
10.704587	27707.164	64.276367	2.8808978
10.722419	27736.207	64.374023	2.8863738
10.739179	27733.773	64.47168	2.8915937
10.755289	27728.342	64.569336	2.8969903
10.770868	27721.328	64.666992	2.9021437
10.787024	27722.453	64.764648	2.9072797
10.80445	27728.734	64.862305	2.9123957
10.819805	27723.301	64.959961	2.9176159
10.835881	27730.623	65.057617	2.922776
10.852099	27730.33	65.155273	2.9280922
10.868063	27735.941	65.25293	2.9333053
10.884912	27737.566	65.350586	2.9385023
10.902015	27739.533	65.448242	2.9438043
10.917308	27742.551	65.545898	2.9491823
10.934765	27741.93	65.643555	2.9543047
10.950625	27737.703	65.741211	2.9596496
10.967367	27742.416	65.838867	2.9649537
10.983183	27741.01	65.936523	2.9701097
10.998709	27742.146	66.03418	2.9753919
11.015298	27745.762	66.131836	2.980689
11.031981	27747.725	66.229492	2.9859278
11.048866	27748.48	66.327148	2.9911835
11.064137	27751.037	66.424805	2.9965336
11.079984	27751.93	66.522461	3.0018463
11.096569	27749.252	66.620117	3.0071547
11.113534	27749.682	66.717773	3.0124438
11.128939	27756.385	66.81543	3.0176072
11.144916	27758.25	66.913086	3.0229743
11.162208	27759.934	67.010742	3.0282815
11.177849	27761.271	67.108398	3.0336771
11.193209	27761.754	67.206055	3.0389855
11.209884	27758.025	67.303711	3.0443492
11.225977	27761.082	67.401367	3.0497181
11.242602	27763.723	67.499023	3.0550199
11.259701	27766.193	67.59668	3.0604227
11.276733	27763.605	67.694336	3.0658865
11.292782	27765.047	67.791992	3.071239
11.308799	27765.91	67.889648	3.0766592
11.325294	27763.531	67.987305	3.0820134
11.34002	27765.254	68.084961	3.0874145
11.35631	27765.525	68.182617	3.0927515
11.372636	27767.662	68.280273	3.0981576
11.389802	27772.01	68.37793	3.1035898
11.405363	27768.164	68.475586	3.1089265
11.422002	27772.396	68.573242	3.1143775
11.438265	27774.521	68.670898	3.1198361
11.454496	27776.244	68.768555	3.1253693
11.470984	27776.213	68.866211	3.130764
11.486791	27771.684	68.963867	3.1362307
11.503179	27778.07	69.061523	3.1417222
11.519956	27774.816	69.15918	3.1470015
11.535415	27783.354	69.256836	3.1523883
11.551856	27783.572	69.354492	3.1579602
11.568441	27784.977	69.452148	3.1636698
11.584758	27782.512	69.549805	3.1690216
11.60069	27787.051	69.647461	3.1745603
11.616936	27786.633	69.745117	3.1800373
11.633279	27785.203	69.842773	3.1856103
11.649011	27785.063	69.94043	3.1910031
11.66631	27787.865	70.038086	3.1965635
11.681617	27787.449	70.135742	3.2020614
11.6975	27789.844	70.233398	3.2075233
11.714608	27786.012	70.331055	3.2130747
11.730858	27789.037	70.428711	3.2187498
11.747703	27791	70.526367	3.2242692
11.763062	27786.307	70.624023	3.2300038
11.780327	27787.17	70.72168	3.2355523
11.796219	27788.693	70.819336	3.2411592
11.813935	27789.211	70.916992	3.2468355
11.828799	27789.658	71.014648	3.252413
11.846081	27786.098	71.112305	3.2578564
11.860645	27787.891	71.209961	3.2633617
11.877316	27790.146	71.307617	3.268934
11.893793	27790.617	71.405273	3.2745409
11.90994	27793.184	71.50293	3.280139
11.925926	27801.947	71.600586	3.2858994
11.94278	27801.525	71.698242	3.2916288
11.960182	27803.963	71.795898	3.297483
11.975596	27791.98	71.893555	3.3030133
11.991878	27798.938	71.991211	3.3087268
12.009374	27795.959	72.088867	3.3144326
12.023129	27798.998	72.186523	3.3200974
12.040219	27800.1	72.28418	3.3257866
12.058011	27803.488	72.381836	3.3314955
12.073219	27800.318	72.479492	3.3371584
12.089622	27799.355	72.577148	3.3428793
12.105469	27804.102	72.674805	3.3485653
12.121218	27792.84	72.772461	3.3541999
12.1377	27795.15	72.870117	3.3597684
12.153288	27803.75	72.967773	3.3653443
12.17011	27807.113	73.06543	3.3711739
12.187442	27813.756	73.163086	3.3770897
12.203441	27806.611	73.260742	3.3828933
12.219543	27803.771	73.358398	3.3886945
12.236271	27810.512	73.456055	3.394649
12.251935	27804.283	73.553711	3.4004536
12.268632	27808.928	73.651367	3.406311
12.285562	27801.926	73.749023	3.4121628
12.301073	27802.637	73.84668	3.4178715
12.318106	27808.123	73.944336	3.4236145
12.334154	27804.646	74.041992	3.4294577
12.350176	27803.406	74.139648	3.4353085
12.36516	27799.553	74.237305	3.4411314
12.382125	27807.836	74.334961	3.4469705
12.398268	27809.92	74.432617	3.4528937
12.414106	27808.279	74.530273	3.458894
12.431974	27809.041	74.62793	3.4646332
12.447848	27808.23	74.725586	3.4705529
12.46336	27807.504	74.823242	3.4763424
12.479825	27808.154	74.920898	3.4823644
12.495346	27805.797	75.018555	3.488189
12.511707	27806.568	75.116211	3.494041
12.527814	27811.223	75.213867	3.4999282
12.545047	27814.656	75.311523	3.5059917
12.561064	27813.537	75.40918	3.511966
12.576357	27814.484	75.506836	3.5179987
12.593448	27813.162	75.604492	3.5240288
12.609568	27810.063	75.702148	3.530139
12.62622	27813.652	75.799805	3.5361712
12.642674	27813.494	75.897461	3.5423326
12.659381	27808.662	75.995117	3.5483449
12.675054	27812.154	76.092773	3.5544436
12.691383	27813.029	76.19043	3.5604217
12.707759	27813.334	76.288086	3.5665593
12.722046	27806.402	76.385742	3.5725024
12.74079	27807.666	76.483398	3.5785701
12.75746	27814.221	76.581055	3.5847137
12.773044	27811.141	76.678711	3.5908809
12.78991	27808.191	76.776367	3.5970097
12.806759	27804.537	76.874023	3.6030748
12.821431	27808.805	76.97168	3.6091392
12.838556	27804.201	77.069336	3.6152706
12.853791	27808.688	77.166992	3.6213372
12.870032	27813.238	77.264648	3.6274927
12.886997	27812.145	77.362305	3.6337979
12.903596	27807.922	77.459961	3.6400557
12.92006	27808.902	77.557617	3.6461682
12.935635	27813.26	77.655273	3.6523771
12.951951	27812.775	77.75293	3.6585238
12.967472	27811.219	77.850586	3.6646793
12.983297	27816.324	77.948242	3.6710298
13.000545	27815.371	78.045898	3.6775053
13.017035	27808.66	78.143555	3.6837351
13.032673	27806.471	78.241211	3.6899726
13.048502	27807.887	78.338867	3.6963429
13.065735	27805.646	78.436523	3.7026367
13.081372	27807.967	78.53418	3.7088912
13.099558	27814.814	78.631836	3.7154648
13.116152	27804.438	78.729492	3.7218273
13.130631	27801.789	78.827148	3.7281034
13.146756	27804.668	78.924805	3.7344213
13.164463	27804.459	79.022461	3.7407658
13.178853	27807.322	79.120117	3.7472339
13.194732	27804.434	79.217773	3.7536724
13.211093	27799.893	79.31543	3.7600665
13.22796	27804.807	79.413086	3.7664523
13.244831	27804.143	79.510742	3.773113
13.26092	27812.33	79.608398	3.7797
13.278152	27806.68	79.706055	3.7862771
13.293964	27802.443	79.803711	3.7927661
13.30957	27804.043	79.901367	3.7994728
13.326066	27808.051	79.999023	3.8060431
13.342467	27805.338	80.09668	3.8126709
13.359187	27806.668	80.194336	3.8193567
13.376312	27804.521	80.291992	3.8259702
13.391289	27807.18	80.389648	3.832494
13.407735	27803.461	80.487305	3.8390827
13.423963	27802.996	80.584961	3.8455415
13.440457	27809.209	80.682617	3.8523643
13.458169	27806.277	80.780273	3.8589594
13.472733	27800.516	80.87793	3.8657885
13.489533	27802.691	80.975586	3.872499
13.506364	27806.674	81.073242	3.8793392
13.521769	27801.098	81.170898	3.8860793
13.538752	27794.361	81.268555	3.8927684
13.554644	27795.197	81.366211	3.8994391
13.569785	27796.459	81.463867	3.9062934
13.586111	27798.023	81.561523	3.9130244
13.601972	27798.441	81.65918	3.9198527
13.618865	27799.654	81.756836	3.9267395
13.635276	27795.549	81.854492	3.9335608
13.651798	27793.268	81.952148	3.940443
13.668499	27798.293	82.049805	3.9475188
13.684561	27800.285	82.147461	3.9545965
13.701848	27794.797	82.245117	3.96173
13.71837	27796.268	82.342773	3.9687705
13.733194	27788.551	82.44043	3.9755962
13.748648	27798.434	82.538086	3.9826379
13.76687	27783.824	82.635742	3.9895723
13.782596	27791.455	82.733398	3.9965799
13.798599	27791.08	82.831055	4.0035691
13.81409	27788.207	82.928711	4.0105739
13.830053	27790.641	83.026367	4.0175943
13.847626	27790.385	83.124023	4.0247126
13.863152	27788.537	83.22168	4.0318198
13.879509	27787.814	83.319336	4.0388079
13.895513	27789.145	83.416992	4.0460334
13.911624	27787.943	83.514648	4.0531659
13.927748	27785.119	83.612305	4.0605745
13.944168	27787.816	83.709961	4.0676937
13.961767	27783.322	83.807617	4.0749898
13.977351	27782.236	83.905273	4.0821981
13.99319	27780.297	84.00293	4.0895233
14.009395	27780.566	84.100586	4.0969224
14.026521	27780.385	84.198242	4.1042104
14.041523	27775.66	84.295898	4.1115828
14.058734	27775.484	84.393555	4.1190419
14.074094	27775.633	84.491211	4.1265197
14.091353	27773.941	84.588867	4.1338468
14.106834	27768.363	84.686523	4.1410661
14.123468	27773.42	84.78418	4.1485996
14.140536	27778.193	84.881836	4.1560717
14.156192	27776.416	84.979492	4.1636314
14.17406	27771.479	85.077148	4.1712608
14.189478	27773.264	85.174805	4.1787281
14.205142	27771.666	85.272461	4.1863718
14.221262	27774.631	85.370117	4.1937661
14.237172	27763.174	85.467773	4.2011905
14.252542	27770.162	85.56543	4.2088623
14.26964	27770.383	85.663086	4.216392
14.287147	27767.998	85.760742	4.2242045
14.302855	27769.723	85.858398	4.2320614
14.319019	27766.787	85.956055	4.2399168
14.335216	27770.049	86.053711	4.2477407
14.351953	27763.697	86.151367	4.2554417
14.36839	27756.416	86.249023	4.2632322
14.384439	27759.479	86.34668	4.2710323
14.40017	27757.564	86.444336	4.2789183
14.416804	27762.711	86.541992	4.2869906
14.433599	27754.748	86.639648	4.2949233
14.450962	27754.215	86.737305	4.3029122
14.467095	27750.447	86.834961	4.3108721
14.482782	27752.09	86.932617	4.3188963
14.497543	27746.918	87.030273	4.3267808
14.513502	27746.504	87.12793	4.3347664
14.530726	27751.139	87.225586	4.3428798
14.546645	27749.328	87.323242	4.3510394
14.563655	27747.027	87.420898	4.3590684
14.579185	27745.746	87.518555	4.3672009
14.596651	27744.51	87.616211	4.3754787
14.612033	27744.246	87.713867	4.3836102
14.6289	27738.928	87.811523	4.391767
14.644958	27740.484	87.90918	4.4000268
14.661059	27739.549	88.006836	4.4083595
14.677148	27735.279	88.104492	4.4165735
14.692875	27734.293	88.202148	4.4249544
14.709518	27733.65	88.299805	4.433218
14.726479	27739.137	88.397461	4.4417338
14.741056	27732.863	88.495117	4.4501429
14.758312	27729.68	88.592773	4.4586396
14.773306	27729.414	88.69043	4.4670792
14.790668	27730.916	88.788086	4.4758091
14.80771	27729.594	88.885742	4.4844141
14.823284	27724.662	88.983398	4.493175
14.841107	27724.346	89.081055	4.5018878
14.855797	27715.395	89.178711	4.5107112
14.871398	27713.014	89.276367	4.5193563
14.889159	27715.826	89.374023	4.5281324
14.905176	27722.324	89.47168	4.537055
14.923036	27713.822	89.569336	4.5461664
14.938279	27705.645	89.666992	4.5549259
14.95461	27705.701	89.764648	4.5637035
14.969755	27707.67	89.862305	4.5726914
14.987793	27710.447	89.959961	4.5817294
15.002903	27704.83	90.057617	4.5906243
15.018983	27699.699	90.155273	4.5997486
15.034776	27702.832	90.25293	4.6087813
15.051782	27704.801	90.350586	4.6179304
15.067714	27698.24	90.448242	4.6272702
15.085479	27700.359	90.545898	4.6364584
15.101479	27696.639	90.643555	4.6457644
15.117617	27692.648	90.741211	4.6550522
15.131814	27688.316	90.838867	4.6642647
15.149584	27689.033	90.936523	4.6736145
15.164805	27689.115	91.03418	4.6830215
15.182481	27679.305	91.131836	4.6925225
15.198338	27684.836	91.229492	4.7020054
15.21414	27682.209	91.327148	4.7114635
15.230613	27676.314	91.424805	4.7211175
15.246859	27675.996	91.522461	4.7307663
15.263072	27674.695	91.620117	4.7404733
15.279465	27672.385	91.717773	4.7502837
15.295205	27669.871	91.81543	4.7600513
15.312242	27667.221	91.913086	4.7701969
15.328218	27657.096	92.010742	4.7799349
15.344026	27658.061	92.108398	4.7897177
15.361165	27657.918	92.206055	4.7997394
15.376615	27655.764	92.303711	4.8096037
15.394384	27652.729	92.401367	4.8197455
15.410098	27654.709	92.499023	4.8300061
15.425418	27646.197	92.59668	4.8401632
15.441278	27643.273	92.694336	4.8503504
15.457716	27644.629	92.791992	4.8605452
15.475074	27644.889	92.889648	4.8708186
15.4914	27646.686	92.987305	4.8813624
15.507426	27640.635	93.084961	4.8919621
15.524261	27635.592	93.182617	4.9024649
15.540869	27631.539	93.280273	4.9131312
15.556336	27632.053	93.37793	4.9237885
15.573306	27626.273	93.475586	4.9346261
15.589336	27624.65	93.573242	4.9453111
15.604929	27623.174	93.670898	4.956048
15.623145	27618.652	93.768555	4.9668446
15.637804	27608.52	93.866211	4.9777708
15.654988	27605.473	93.963867	4.9884844
15.66966	27607.633	94.061523	4.9993663
15.685372	27605.584	94.15918	5.0104923
15.702347	27599.867	94.256836	5.0216236
15.719352	27598.041	94.354492	5.0327487
15.73553	27595.189	94.452148	5.0440288
15.75072	27585.291	94.549805	5.0552578
15.767292	27587.031	94.647461	5.0666008
15.78431	27587.389	94.745117	5.0782127
15.80022	27583.055	94.842773	5.0898519
15.816989	27573.914	94.94043	5.1014867
15.833856	27577.084	95.038086	5.1132064
15.849117	27562.354	95.135742	5.1246018
15.865045	27566.154	95.233398	5.1363554
15.881755	27556.52	95.331055	5.1481423
15.897575	27547.289	95.428711	5.1594868
15.913352	27565.475	95.526367	5.1718526
15.929918	27556.354	95.624023	5.1838026
15.947031	27553.41	95.72168	5.1962986
15.962776	27544.803	95.819336	5.2088151
15.980889	27539.535	95.916992	5.221045
15.995136	27531.768	96.014648	5.233551
16.012522	27527.686	96.112305	5.245646
16.027203	27525.217	96.209961	5.2579312
16.043797	27519.484	96.307617	5.2703824
16.060354	27518.852	96.405273	5.2831693
16.076023	27512.086	96.50293	5.2958946
16.091745	27510.797	96.600586	5.3088942
16.109161	27502.902	96.698242	5.3218288
16.126091	27499.938	96.795898	5.3351283
16.141777	27492.041	96.893555	5.3482347
16.159781	27485.084	96.991211	5.3615751
16.174772	27482.625	97.088867	5.3748779
16.190866	27471.879	97.186523	5.3882465
16.20746	27468.709	97.28418	5.4018207
16.223196	27458.906	97.381836	5.4149809
16.240067	27455.156	97.479492	5.4285979
16.255726	27451.793	97.577148	5.4419532
16.271847	27449.176	97.674805	5.4557476
16.288338	27441.742	97.772461	5.4696946
16.305759	27434.398	97.870117	5.4836245
16.321405	27428.215	97.967773	5.4976029
16.338961	27418.783	98.06543	5.5115948
16.353422	27421.398	98.163086	5.5258107
16.36964	27408.094	98.260742	5.5399299
16.38657	27403	98.358398	5.5543609
16.402712	27393.656	98.456055	5.5687566
16.418095	27385.551	98.553711	5.5830464
16.43428	27386.844	98.651367	5.5975027
16.449539	27369.678	98.749023	5.6120405
16.467211	27366.072	98.84668	5.6266127
16.483406	27358.941	98.944336	5.6414967
16.499763	27354.936	99.041992	5.6564908
16.516964	27344.613	99.139648	5.6718192
16.532928	27335.674	99.237305	5.6873074
16.550148	27319.398	99.334961	5.7024512
16.56621	27312.447	99.432617	5.7174082
16.581678	27303.637	99.530273	5.7325387
16.596786	27295.695	99.62793	5.7480679
16.613556	27285.545	99.725586	5.7634945
16.631147	27273.393	99.823242	5.7790399
16.646484	27263.865	99.920898	5.7947111
16.662645	27256.924	100.01855	5.8104062
16.679928	27248.48	100.11621	5.8263526
16.695587	27229.395	100.21387	5.8422303
16.71307	27222.492	100.31152	5.8581667
16.729548	27209.764	100.40918	5.8740053
16.745127	27200.869	100.50684	5.8898439
16.760344	27191.398	100.60449	5.9060183
16.777836	27180.828	100.70215	5.9220877
16.792919	27166.354	100.7998	5.9382262
16.810318	27152.262	100.89746	5.9545875
16.82642	27135.344	100.99512	5.9704409
16.841923	27125.918	101.09277	5.9865346
16.858316	27121.336	101.19043	6.0029473
16.874598	27104.314	101.28809	6.0192904
16.890839	27089.152	101.38574	6.035666
16.907879	27079.041	101.4834	6.0522346
16.923521	27059.16	101.58105	6.0684819
16.93936	27046.398	101.67871	6.0850172
16.956663	27030.045	101.77637	6.1014795
16.971756	27018.33	101.87402	6.1181397
16.989565	27000.893	101.97168	6.1350245
17.006397	26984.002	102.06934	6.1519666
17.021301	26968.875	102.16699	6.1688695
17.038801	26950.5	102.26465	6.1856189
17.054483	26935.943	102.3623	6.2023406
17.069925	26917.74	102.45996	6.2188458
17.085798	26900.568	102.55762	6.2355428
17.102049	26887.883	102.65527	6.252378
17.119089	26873.084	102.75293	6.2691522
17.136175	26851.867	102.85059	6.2861481
17.153181	26830.588	102.94824	6.3030343
17.167923	26811.535	103.0459	6.3197899
17.184191	26793.412	103.14355	6.3365479
17.200598	26780.158	103.24121	6.3534803
17.216171	26753.975	103.33887	6.3703632
17.232779	26733.727	103.43652	6.3867598
17.249405	26718.959	103.53418	6.4035378
17.264652	26700.748	103.63184	6.4202976
17.280527	26683.896	103.72949	6.4373412
17.298309	26662.367	103.82715	6.4545269
17.31465	26644.131	103.9248	6.4718142
17.329281	26619.557	104.02246	6.4891839
17.346205	26597.107	104.12012	6.5062485
17.36356	26577.215	104.21777	6.5232577
17.37908	26553.553	104.31543	6.5403547
17.396296	26527.307	104.41309	6.5576372
17.412859	26506.723	104.51074	6.5748396
17.428335	26484.49	104.6084	6.5917296
17.445412	26460.543	104.70605	6.6090269
17.459877	26431.768	104.80371	6.6259022
17.476667	26410.34	104.90137	6.6429667
17.49231	26384.281	104.99902	6.6598969
17.508501	26361.234	105.09668	6.6770334
17.525074	26338.225	105.19434	6.6941309
17.542154	26310.883	105.29199	6.7110777
17.557354	26286.145	105.38965	6.7281461
17.575605	26261.385	105.4873	6.7453947
17.591726	26237.59	105.58496	6.7625623
17.607122	26206.891	105.68262	6.779799
17.623295	26187.021	105.78027	6.7971497
17.640417	26152.816	105.87793	6.8143806
17.656935	26126.453	105.97559	6.8316536
17.673019	26099.248	106.07324	6.8488774
17.689823	26071.238	106.1709	6.8660579
17.704504	26046.025	106.26855	6.883193
17.722765	26019.283	106.36621	6.9004569
17.738161	25986.859	106.46387	6.9174285
17.754232	25958.16	106.56152	6.9347954
17.771193	25926.748	106.65918	6.9521537
17.787085	25899.699	106.75684	6.9694161
17.803392	25866.838	106.85449	6.9867792
17.820618	25832.82	106.95215	7.0040784
17.836098	25800.66	107.0498	7.0209713
17.851418	25766.713	107.14746	7.0377922
17.867489	25736.135	107.24512	7.0547161
17.883421	25704.061	107.34277	7.0717826
17.899935	25672.646	107.44043	7.0889907
17.915514	25635.543	107.53809	7.1058478
17.932327	25604.896	107.63574	7.1230202
17.948736	25571.365	107.7334	7.1402068
17.964657	25535.258	107.83105	7.1573977
17.979551	25497.926	107.92871	7.1747789
17.997759	25463.871	108.02637	7.1922908
18.013758	25427.43	108.12402	7.2097626
18.031269	25389.41	108.22168	7.2271576
18.046902	25350.752	108.31934	7.2445612
18.062798	25314.795	108.41699	7.2620459
18.079664	25273.504	108.51465	7.2795906
18.095507	25230.434	108.6123	7.2968493
18.112053	25194.109	108.70996	7.3141165
18.127087	25155.477	108.80762	7.3315105
18.14456	25112.34	108.90527	7.3486896
18.161249	25071.936	109.00293	7.3661118
18.177042	25032.314	109.10059	7.3835144
18.193586	24989.926	109.19824	7.4009981
18.209309	24942.408	109.2959	7.4184361
18.226095	24899.203	109.39355	7.4359255
18.242962	24853.447	109.49121	7.4534302
18.259113	24805.512	109.58887	7.471005
18.274742	24758.785	109.68652	7.4886417
18.292225	24705.852	109.78418	7.5061951
18.308426	24658.836	109.88184	7.523849
18.324032	24599.641	109.97949	7.541369
18.341078	24551.156	110.07715	7.5589328
18.356562	24492.346	110.1748	7.5763245
18.373175	24435.381	110.27246	7.5940256
18.389866	24370.303	110.37012	7.6114831
18.405951	24299.012	110.46777	7.6293597
18.421888	24169.678	110.56543	7.6481862
18.474083	1131.028	110.66309	8.1035109
18.457243	-313.56152	110.76074	8.0334797
18.473923	-1.9754516	110.8584	8.0491362
18.490328	-172.87466	110.95605	8.0670233
18.504925	138.85123	111.05371	8.0806293
18.518658	-172.41132	111.15137	8.0978947
18.535824	74.402901	111.24902	8.1137743
18.552601	-61.444588	111.34668	8.1311369
18.568291	-50.951145	111.44434	8.1474066
18.584095	55.024864	111.54199	8.1627426
18.599428	-132.97598	111.63965	8.1806564
18.615767	94.060432	111.7373	8.1954842
18.632673	-123.34099	111.83496	8.2139053
18.648928	39.543377	111.93262	8.228507
18.66515	-36.141136	112.03027	8.2462215
18.680784	-47.062172	112.12793	8.263195
18.698097	30.199646	112.22559	8.2795906
18.713966	-97.936142	112.32324	8.2977142
18.731232	59.489044	112.4209	8.3131933
18.74778	-91.69709	112.51855	8.3317347
18.762573	14.868099	112.61621	8.3470221
18.778921	-39.271778	112.71387	8.3637667
18.795631	-39.388893	112.81152	8.3805389
18.811417	12.028264	112.90918	8.3962297
18.827679	-82.041367	113.00684	8.4139528
18.842606	32.859737	113.10449	8.4295292
18.860979	-74.831535	113.20215	8.447361
18.876955	9.0233517	113.2998	8.4630919
18.893282	-34.855564	113.39746	8.4798193
18.908262	-30.397903	113.49512	8.4960985
18.925083	2.1740561	113.59277	8.5128317
18.941387	-64.80352	113.69043	8.5304384
18.958204	16.585108	113.78809	8.5464506
18.974825	-59.71722	113.88574	8.5637445
18.990421	-2.4194596	113.9834	8.5798292
19.006958	-32.541458	114.08105	8.5966434
19.023016	-29.405811	114.17871	8.6132011
19.039072	-6.1646571	114.27637	8.6294689
19.056597	-51.179199	114.37402	8.6463957
19.067179	4.7896757	114.47168	8.6572132
19.064604	-50.895615	114.56934	8.6546965
19.063047	-7.3086705	114.66699	8.6539316
19.063274	-33.119228	114.76465	8.6547174
19.064611	-23.350004	114.8623	8.6549873
19.064075	-4.6911883	114.8916	8.6547222