File: data/A3.dat
MTS793|MPT|ENU|1|2|.|/|:|1|0|0|A

Data Acquisition						Time:	10.009766	s	2/4/2020 10:11:24 AM
Axial Displacement	Axial Force	Time	Axial Extensometer
mm	N	s	mm
-0.0010550022	232.36871	0.018554688	-0.00032720855
0.0017523766	376.33954	0.11621094	0.00010239164
0.021164864	1447.662	0.21386719	0.0031801115
0.037441403	2419.7927	0.31152344	0.0062367795
0.052969158	3256.8389	0.40917969	0.0088397302
0.067180395	4135.6948	0.50683594	0.011608752
0.085817277	4985.2461	0.60449219	0.014549113
0.10154173	5788.9458	0.70214844	0.017460058
0.1190789	6659.0479	0.79980469	0.02063369
0.13660491	7456.6792	0.89746094	0.023838773
0.15337542	8165.5571	0.99511719	0.026632629
0.16781688	8813.9619	1.0927734	0.029546369
0.18439069	9386.1123	1.1904297	0.032167379
0.19925237	9991.3086	1.2880859	0.035166211
0.2169773	10604.926	1.3857422	0.038641956
0.23505092	11150.447	1.4833984	0.042092994
0.25182366	11603.404	1.5810547	0.045652606
0.26904345	11999.939	1.6787109	0.049294733
0.28638169	12349.571	1.7763672	0.053023186
0.30144006	12654.259	1.8740234	0.05687556
0.31930357	12927.462	1.9716797	0.060523521
0.33471733	13164.157	2.0693359	0.064089164
0.35010651	13400.521	2.1669922	0.067782551
0.36803707	13618.364	2.2646484	0.071731232
0.38434714	13808.667	2.3623047	0.075874016
0.40111542	13977.986	2.4599609	0.079942182
0.41786805	14117.785	2.5576172	0.083852962
0.43386519	14252.479	2.6552734	0.088035248
0.45029819	14370.41	2.7529297	0.091935858
0.46557337	14482.313	2.8505859	0.096103504
0.48227683	14585.68	2.9482422	0.10024068
0.49797222	14687.561	3.0458984	0.10459359
0.51400959	14774.803	3.1435547	0.10886665
0.53090525	14868.026	3.2412109	0.11318911
0.54832399	14952.815	3.3388672	0.11742703
0.56316555	15047.661	3.4365234	0.12170961
0.58023334	15138.139	3.5341797	0.12593505
0.5971849	15230.681	3.6318359	0.13022085
0.61301887	15314.393	3.7294922	0.13443354
0.62772632	15408.617	3.8271484	0.13831189
0.64506006	15502.813	3.9248047	0.14245877
0.66124052	15604.72	4.0224609	0.14654915
0.67770481	15703.934	4.1201172	0.15084754
0.69338679	15787.554	4.2177734	0.15487492
0.71014166	15882.781	4.3154297	0.15885814
0.72656798	15977.994	4.4130859	0.16284434
0.74377882	16073.805	4.5107422	0.16683701
0.75897348	16165.035	4.6083984	0.17088102
0.77417046	16258.077	4.7060547	0.17489398
0.79023015	16356.392	4.8037109	0.1789901
0.8082993	16443.678	4.9013672	0.18304865
0.82410645	16538.391	4.9990234	0.18702103
0.84014606	16628.385	5.0966797	0.19110028
0.85690987	16709.152	5.1943359	0.1950866
0.87270808	16800.053	5.2919922	0.19898215
0.88909638	16888.607	5.3896484	0.203172
0.90542662	16976.684	5.4873047	0.20717444
0.92258382	17061.293	5.5849609	0.21117824
0.93837309	17147.139	5.6826172	0.21517235
0.95394325	17226.746	5.7802734	0.21913224
0.97275007	17312.291	5.8779297	0.22324497
0.98747981	17391.486	5.9755859	0.22711949
1.0036893	17476.816	6.0732422	0.23116699
1.0212935	17559.533	6.1708984	0.2352846
1.0378875	17637.629	6.2685547	0.23933975
1.0533549	17714.809	6.3662109	0.24328302
1.0695689	17784.338	6.4638672	0.24727908
1.084996	17857.512	6.5615234	0.25104341
1.1014782	17934.484	6.6591797	0.25501665
1.1176072	18007.717	6.7568359	0.25886503
1.1339284	18075.646	6.8544922	0.2627039
1.1487566	18153.926	6.9521484	0.26656216
1.165498	18236.385	7.0498047	0.27055055
1.1833929	18307.164	7.1474609	0.27465034
1.1997186	18380.889	7.2451172	0.27878651
1.2159549	18446.445	7.3427734	0.28272209
1.2326337	18519.414	7.4404297	0.28678992
1.2486554	18585.264	7.5380859	0.29074931
1.2633808	18651.893	7.6357422	0.29457012
1.2801535	18716.109	7.7333984	0.29861054
1.296658	18782.105	7.8310547	0.30242401
1.3128095	18857.164	7.9287109	0.3063865
1.3287194	18923.051	8.0263672	0.31037235
1.3457335	18990.738	8.1240234	0.31448245
1.363378	19052.123	8.2216797	0.31839883
1.3796277	19113.963	8.3193359	0.3222762
1.3947107	19171.141	8.4169922	0.32629803
1.4111124	19237.229	8.5146484	0.33019742
1.426553	19305.914	8.6123047	0.33419007
1.4426686	19365.35	8.7099609	0.33809155
1.4597677	19422.533	8.8076172	0.34208775
1.4752753	19481.959	8.9052734	0.34592244
1.4919407	19540.551	9.0029297	0.34985673
1.5080117	19606.326	9.1005859	0.35376433
1.5250705	19665.123	9.1982422	0.35780242
1.540149	19728.838	9.2958984	0.3618404
1.5577756	19792.229	9.3935547	0.36602032
1.5737481	19845.5	9.4912109	0.37010995
1.5908248	19897.756	9.5888672	0.37417033
1.6059167	19951.559	9.6865234	0.37809345
1.6241961	20002.971	9.7841797	0.38182566
1.6396903	20053.213	9.8818359	0.38570848
1.6542815	20113.074	9.9794922	0.38964775
1.6712956	20170.506	10.077148	0.39354932
1.6863428	20228.752	10.174805	0.39760363
1.703263	20280.543	10.272461	0.40168509
1.7203487	20334.051	10.370117	0.40573615
1.7364688	20387.701	10.467773	0.40971553
1.7527945	20437.775	10.56543	0.41365433
1.7693169	20489.736	10.663086	0.41764218
1.7854549	20542.951	10.760742	0.42167628
1.8021293	20595.988	10.858398	0.42570969
1.8181152	20645.08	10.956055	0.42969012
1.8334978	20688.381	11.053711	0.43363351
1.8504984	20741.541	11.151367	0.43766433
1.8671728	20795.146	11.249023	0.44158468
1.8828191	20841.416	11.34668	0.4455964
1.8989928	20887.684	11.444336	0.44962287
1.915837	20933.57	11.541992	0.45356137
1.9319839	20984.303	11.639648	0.45776215
1.9473218	21026.885	11.737305	0.46168336
1.9647427	21078.771	11.834961	0.46569091
1.9808002	21115.01	11.932617	0.46963608
1.9956328	21164.525	12.030273	0.47344172
2.0131209	21216.17	12.12793	0.47753125
2.0296164	21262.605	12.225586	0.48155648
2.046617	21303.604	12.323242	0.48566312
2.0612082	21346.559	12.420898	0.48959413
2.078692	21392.785	12.518555	0.49362758
2.0945661	21436.557	12.616211	0.49759474
2.1117368	21478.012	12.713867	0.50169957
2.1279998	21522.117	12.811523	0.50574243
2.1428771	21562.477	12.90918	0.50956321
2.1600299	21613.107	13.006836	0.51369107
2.1753273	21652.711	13.104492	0.51781529
2.1922209	21693.002	13.202148	0.52189958
2.2096105	21731.559	13.299805	0.5258435
2.2255607	21776.92	13.397461	0.52985322
2.2410414	21817.715	13.495117	0.53402424
2.2580557	21857.291	13.592773	0.53808188
2.2748775	21892.439	13.69043	0.54209173
2.2896118	21937.197	13.788086	0.54595441
2.3057542	21981.459	13.885742	0.55009604
2.3234792	22017.775	13.983398	0.55410928
2.3393891	22051.668	14.081055	0.55812496
2.3556345	22093.414	14.178711	0.56212884
2.3719378	22135.182	14.276367	0.56625485
2.388706	22169.006	14.374023	0.57030249
2.4048619	22206.174	14.47168	0.5742932
2.4210713	22249.266	14.569336	0.57831877
2.4354525	22280.877	14.666992	0.58238745
2.4533114	22317.133	14.764648	0.58634782
2.469521	22357.422	14.862305	0.59041256
2.4862132	22393.51	14.959961	0.59451431
2.5022261	22429.879	15.057617	0.59854299
2.5186234	22463.172	15.155273	0.60263079
2.5344081	22499.658	15.25293	0.60666251
2.5507293	22535.475	15.350586	0.61072743
2.5664828	22569.113	15.448242	0.61475021
2.5823035	22602.211	15.545898	0.61890841
2.5987096	22637.873	15.643555	0.62288201
2.6156166	22668.971	15.741211	0.62700725
2.6311018	22702.24	15.838867	0.63101429
2.6477137	22741.395	15.936523	0.63496619
2.6653893	22774.199	16.03418	0.63903087
2.6805975	22806.094	16.131836	0.64316559
2.6971645	22838.4	16.229492	0.64730346
2.7139239	22871.637	16.327148	0.65137291
2.7295568	22903.803	16.424805	0.65551466
2.7460613	22936.814	16.522461	0.65951663
2.7624137	22963.303	16.620117	0.66353196
2.7791553	22997.346	16.717773	0.66758907
2.7940192	23031.521	16.81543	0.67173004
2.8119094	23060.652	16.913086	0.67570472
2.8274038	23088.955	17.010742	0.67979705
2.8428667	23119.236	17.108398	0.6839422
2.8602026	23151.27	17.206055	0.68809593
2.8753617	23184.662	17.303711	0.692164
2.892957	23211.652	17.401367	0.69627553
2.9083393	23240.588	17.499023	0.70049345
2.9249735	23272.152	17.59668	0.70453215
2.9417911	23298.148	17.694336	0.70864689
2.9575222	23329.445	17.791992	0.71270871
2.9743931	23360.465	17.889648	0.71682155
2.9903345	23389.395	17.987305	0.72094816
3.0062535	23417.4	18.084961	0.7251063
3.0222707	23446.361	18.182617	0.72915757
3.0385919	23472.553	18.280273	0.73319876
3.0546091	23499.199	18.37793	0.73731679
3.0705683	23527.563	18.475586	0.74143022
3.0881412	23558.941	18.573242	0.74561584
3.1040065	23584.568	18.670898	0.74990124
3.1204662	23612.453	18.768555	0.75401682
3.1373999	23636.416	18.866211	0.7581901
3.152863	23666.07	18.963867	0.76225609
3.1686611	23693.229	19.061523	0.76641238
3.1856172	23720.283	19.15918	0.77065831
3.2017953	23745.193	19.256836	0.77478516
3.218756	23767.584	19.354492	0.77888137
3.2352202	23795.48	19.452148	0.78312755
3.2517605	23819.58	19.549805	0.78732824
3.2665796	23837.09	19.647461	0.7914198
3.2835894	23866.498	19.745117	0.79528922
3.2984846	23892.365	19.842773	0.79944193
3.31498	23916.305	19.94043	0.80349988
3.3312521	23938.377	20.038086	0.80754346
3.3470504	23963.176	20.135742	0.81172299
3.3635371	23992.748	20.233398	0.81586444
3.3796749	24019.646	20.331055	0.82009524
3.3969216	24042.918	20.428711	0.82428682
3.4124472	24065.303	20.526367	0.82848895
3.4300604	24091.588	20.624023	0.83269006
3.44593	24112.924	20.72168	0.83684719
3.4626088	24136.176	20.819336	0.84099895
3.4786172	24162.814	20.916992	0.84518182
3.4939773	24185.139	21.014648	0.84944201
3.511148	24206.096	21.112305	0.85358161
3.528162	24232.289	21.209961	0.85760158
3.542932	24252.625	21.307617	0.86180419
3.5599775	24274.316	21.405273	0.8659842
3.5759144	24298.143	21.50293	0.87021184
3.5920658	24320.141	21.600586	0.87440193
3.6097326	24343.547	21.698242	0.8786568
3.6247752	24367.889	21.795898	0.88279712
3.6414139	24385.869	21.893555	0.88696545
3.6568723	24411.525	21.991211	0.89108074
3.673815	24431.412	22.088867	0.89525765
3.6886475	24449.49	22.186523	0.8993572
3.705246	24470.193	22.28418	0.90361732
3.7223272	24496.348	22.381836	0.90779012
3.7381568	24515.158	22.479492	0.91209102
3.755162	24539.291	22.577148	0.91623902
3.7711971	24562.16	22.674805	0.92055047
3.7888997	24580.311	22.772461	0.92481172
3.8042507	24598.678	22.870117	0.92903239
3.8213274	24621.039	22.967773	0.93325132
3.8361468	24643	23.06543	0.93752021
3.8533754	24653.447	23.163086	0.94176549
3.8705013	24676.09	23.260742	0.9459998
3.8871222	24695.9	23.358398	0.95024836
3.902612	24711.52	23.456055	0.95440251
3.9186337	24732.578	23.553711	0.95851463
3.9339445	24753.346	23.651367	0.96276194
3.9506502	24769.641	23.749023	0.96685225
3.9666853	24792.367	23.84668	0.97107637
3.9821215	24801.066	23.944336	0.97516155
3.9983132	24849.514	24.041992	0.97954583
4.0166011	24867.361	24.139648	0.98417932
4.0327525	24876.932	24.237305	0.98867387
4.0488148	24881.072	24.334961	0.99271029
4.0654531	24892.752	24.432617	0.99679393
4.0814347	24919.643	24.530273	1.0008618
4.0980959	24936.844	24.62793	1.0050348
4.1128659	24955.457	24.725586	1.009215
4.1286192	24971.801	24.823242	1.0134155
4.1458259	24999.1	24.920898	1.0175191
4.1618161	25016.416	25.018555	1.0218669
4.1785488	25036.768	25.116211	1.0262146
4.1949639	25051.783	25.213867	1.0305398
4.2107887	25066.49	25.311523	1.0348806
4.2275124	25084.955	25.40918	1.0391082
4.2432656	25096.52	25.506836	1.0434211
4.2593994	25116.725	25.604492	1.0475265
4.275269	25135.973	25.702148	1.0518173
4.2918539	25161.256	25.799805	1.0562
4.3087878	25174.367	25.897461	1.0605887
4.3258243	25183.736	25.995117	1.0648726
4.3414884	25198.893	26.092773	1.0690724
4.3577204	25218.605	26.19043	1.0732896
4.3722444	25229.271	26.288086	1.0775162
4.3902016	25243.705	26.385742	1.0817585
4.4055662	25264.262	26.483398	1.0859896
4.4218116	25285.549	26.581055	1.0902241
4.439353	25299.139	26.678711	1.0944266
4.4544764	25312.465	26.776367	1.098798
4.4718571	25332.281	26.874023	1.1030551
4.4881558	25353.428	26.97168	1.1074021
4.5040975	25367.076	27.069336	1.1117599
4.5210533	25381.146	27.166992	1.1161134
4.5381794	25396.338	27.264648	1.1205078
4.5531282	25402.844	27.362305	1.1246777
4.5684299	25417.74	27.459961	1.128865
4.5854578	25436.252	27.557617	1.133148
4.6009431	25451.813	27.655273	1.1373081
4.6171255	25473.064	27.75293	1.1415625
4.6334109	25490.24	27.850586	1.146063
4.6510377	25504.727	27.948242	1.1504004
4.6681099	25519.617	28.045898	1.1547711
4.6824241	25523.961	28.143555	1.1591908
4.6988211	25537.809	28.241211	1.1633016
4.7145524	25554.072	28.338867	1.1674798
4.7319422	25572.02	28.436523	1.171771
4.7478967	25592.113	28.53418	1.1760507
4.7643476	25612.531	28.631836	1.1805098
4.780879	25626.455	28.729492	1.1849688
4.7973742	25628.393	28.827148	1.1893193
4.813262	25645.283	28.924805	1.193572
4.829217	25659.875	29.022461	1.1979908
4.8456588	25676.617	29.120117	1.2023512
4.8632808	25693.752	29.217773	1.2067161
4.878994	25702.988	29.31543	1.2110993
4.8952885	25712.512	29.413086	1.215497
4.9106979	25728.697	29.510742	1.2197815
4.9271216	25742.211	29.608398	1.2239904
4.9432287	25752.705	29.706055	1.2282338
4.9601398	25771.111	29.803711	1.2326967
4.9756699	25782.898	29.901367	1.2368934
4.9917674	25796.018	29.999023	1.2412827
5.0075521	25810.986	30.09668	1.2454953
5.0245843	25827.117	30.194336	1.2499439
5.0417461	25837.586	30.291992	1.2543671
5.0575576	25846.471	30.389648	1.258865
5.0734363	25857.188	30.487305	1.2629943
5.0893774	25873.018	30.584961	1.2673644
5.1059494	25884.604	30.682617	1.2717406
5.1228247	25901.791	30.780273	1.2761251
5.1392713	25912.576	30.87793	1.2806045
5.1546493	25926.691	30.975586	1.2850074
5.1723518	25940.188	31.073242	1.2895392
5.1881499	25950.82	31.170898	1.293856
5.2058034	25956.293	31.268555	1.2983375
5.2203455	25963.211	31.366211	1.3025329
5.2358799	25982.418	31.463867	1.3067962
5.2534885	25992.453	31.561523	1.311106
5.2684197	26005.127	31.65918	1.3154212
5.286283	26018.805	31.756836	1.3198365
5.3017282	26027.09	31.854492	1.3242362
5.317142	26039.51	31.952148	1.3286325
5.3339372	26052.32	32.049805	1.3330061
5.3499141	26061.262	32.147461	1.3373392
5.3664722	26076.84	32.245117	1.3417236
5.3815684	26080.689	32.342773	1.3461027
5.3994274	26095.682	32.44043	1.3504595
5.4150066	26107.949	32.538086	1.3549045
5.4301076	26117.078	32.635742	1.3593695
5.4481902	26127.445	32.733398	1.3636441
5.4626966	26140.127	32.831055	1.3679125
5.4809175	26154.754	32.928711	1.3723238
5.4969082	26170.488	33.026367	1.3768632
5.5136361	26176.709	33.124023	1.3813167
5.5296669	26185.596	33.22168	1.3857368
5.5459299	26198.061	33.319336	1.3902136
5.5621171	26206.965	33.416992	1.3946377
5.5784025	26219.018	33.514648	1.3989874
5.5939326	26227.799	33.612305	1.4034771
5.6111746	26241.295	33.709961	1.4079279
5.6271963	26247.482	33.807617	1.412358
5.6446619	26261.225	33.905273	1.4168404
5.6607733	26272.711	34.00293	1.4211442
5.6763253	26284.443	34.100586	1.425667
5.6923246	26286.332	34.198242	1.4299599
5.7081676	26296.244	34.295898	1.4342155
5.7236085	26307.869	34.393555	1.4385837
5.7407031	26320.598	34.491211	1.4430665
5.7570777	26327.025	34.588867	1.4473314
5.7726345	26336.814	34.686523	1.4516809
5.7880306	26353.756	34.78418	1.4561309
5.8047404	26365.605	34.881836	1.4606252
5.8215804	26377.32	34.979492	1.4651744
5.8379064	26384.371	35.077148	1.4696538
5.8546028	26394.852	35.174805	1.4741129
5.8707676	26404.621	35.272461	1.478691
5.8871603	26412.059	35.370117	1.4831285
5.9052029	26421.586	35.467773	1.4877255
5.9201918	26431.098	35.56543	1.4921175
5.9368081	26433.984	35.663086	1.4964926
5.9526377	26449.547	35.760742	1.500796
5.9690127	26460.406	35.858398	1.5053626
5.9855261	26466.557	35.956055	1.5096674
6.0014896	26471.75	36.053711	1.5140088
6.0171537	26482.086	36.151367	1.5184444
6.0338058	26500.355	36.249023	1.5228585
6.0504355	26508.443	36.34668	1.5274384
6.0651832	26515.977	36.444336	1.5318327
6.0830913	26522.004	36.541992	1.5363303
6.0990596	26530.244	36.639648	1.5409268
6.1150274	26535.775	36.737305	1.5453548
6.1301374	26547.805	36.834961	1.5495842
6.1465034	26542.379	36.932617	1.5537872
6.1630526	26579.529	37.030273	1.5584441
6.1803708	26586.416	37.12793	1.5632237
6.1979303	26586.893	37.225586	1.5677768
6.2140279	26590.74	37.323242	1.5723691
6.2303758	26598.029	37.420898	1.5766981
6.2456422	26604.861	37.518555	1.5811588
6.262361	26613.078	37.616211	1.5854794
6.2780657	26623.734	37.713867	1.5898715
6.2937207	26630.588	37.811523	1.5942734
6.3099122	26645.078	37.90918	1.5988647
6.3267207	26655.342	38.006836	1.6032883
6.3416386	26661.23	38.104492	1.6078129
6.3590951	26668.473	38.202148	1.6122175
6.3749695	26673.893	38.299805	1.6168605
6.3909779	26687.133	38.397461	1.6214416
6.4077997	26690.834	38.495117	1.6259634
6.4244471	26701.295	38.592773	1.6303549
6.4405136	26703.229	38.69043	1.6349006
6.4567008	26713.828	38.788086	1.6393039
6.4728746	26722.301	38.885742	1.6438789
6.489388	26734.314	38.983398	1.6483929
6.5055079	26736.957	39.081055	1.6528038
6.5219722	26744.82	39.178711	1.6573924
6.5378332	26754.523	39.276367	1.6619443
6.5540738	26763.982	39.374023	1.6662869
6.5708423	26767.258	39.47168	1.6708933
6.5874944	26773.926	39.569336	1.6753875
6.6041908	26783.211	39.666992	1.6799253
6.6205883	26788.162	39.764648	1.6843528
6.6352644	26799.867	39.862305	1.6889794
6.652833	26807.359	39.959961	1.6934971
6.6683135	26815.596	40.057617	1.6980482
6.6858063	26822.707	40.155273	1.7026851
6.7021809	26830.09	40.25293	1.7071693
6.7174921	26834.746	40.350586	1.7118144
6.7339649	26841.764	40.448242	1.7163576
6.7495666	26848.744	40.545898	1.7208518
6.7660041	26858.42	40.643555	1.7254616
6.7836261	26864.742	40.741211	1.7298836
6.7988701	26872.828	40.838867	1.7343726
6.8147888	26879.025	40.936523	1.7389417
6.8322101	26883.41	41.03418	1.7434952
6.8475614	26890.809	41.131836	1.7478648
6.8628407	26898.648	41.229492	1.7525098
6.8801904	26906.602	41.327148	1.7570081
6.8972402	26914.588	41.424805	1.761634
6.9127073	26921.809	41.522461	1.766173
6.9298601	26927.758	41.620117	1.7707682
6.9456449	26934.936	41.717773	1.7754188
6.9616222	26943.352	41.81543	1.7799505
6.9773622	26947.891	41.913086	1.7844821
6.9941573	26954.225	42.010742	1.789068
7.0104785	26960.27	42.108398	1.7936043
7.0262814	26967.654	42.206055	1.798233
7.0428171	26979.209	42.303711	1.8027712
7.0607386	26983.057	42.401367	1.8074187
7.0754638	26983.313	42.499023	1.8119575
7.091146	26995.697	42.59668	1.8165401
7.1083212	27004.885	42.694336	1.8210934
7.1246958	27008.18	42.791992	1.8256328
7.1406283	27013.201	42.889648	1.8301989
7.1559749	27016.174	42.987305	1.8347635
7.1728773	27022.67	43.084961	1.8393072
7.1889749	27033.986	43.182617	1.843853
7.2063828	27038.912	43.280273	1.8484622
7.2223196	27043.658	43.37793	1.8530295
7.2381711	27048.846	43.475586	1.8575685
7.2546353	27055.975	43.573242	1.8623246
7.2700715	27062.426	43.670898	1.8668869
7.2872734	27067.271	43.768555	1.8715668
7.303072	27072.994	43.866211	1.8760639
7.3182797	27078.166	43.963867	1.880734
7.335835	27087.738	44.061523	1.8853825
7.3523932	27093.24	44.15918	1.8900038
7.3694696	27098.434	44.256836	1.8946428
7.3857865	27099.637	44.354492	1.8992623
7.4012942	27104.082	44.452148	1.9038041
7.4178481	27109.137	44.549805	1.9084312
7.4336996	27122.648	44.647461	1.9129841
7.4496231	27125.354	44.745117	1.9177175
7.4659576	27131.225	44.842773	1.9222893
7.4823103	27134.891	44.94043	1.9268523
7.499414	27138.33	45.038086	1.9314963
7.5158739	27145.416	45.135742	1.9362029
7.530416	27150.127	45.233398	1.940625
7.5476537	27152.051	45.331055	1.9452018
7.5624237	27156.768	45.428711	1.9497033
7.5790176	27171.115	45.526367	1.954489
7.5961342	27180.254	45.624023	1.9593483
7.6134214	27180.088	45.72168	1.9640083
7.6299391	27177.213	45.819336	1.9685966
7.6438689	27181.061	45.916992	1.9730612
7.660646	27191.406	46.014648	1.9777342
7.6769762	27199.389	46.112305	1.9823817
7.6935344	27202.004	46.209961	1.9871185
7.7104101	27210.072	46.307617	1.9917136
7.7253141	27216.975	46.405273	1.9963522
7.742547	27221.5	46.50293	2.0010436
7.7585196	27229.277	46.600586	2.0057092
7.7748051	27225.732	46.698242	2.0103118
7.792253	27230.404	46.795898	2.0150006
7.8065181	27236.895	46.893555	2.0195134
7.8236794	27245.457	46.991211	2.0241902
7.8399115	27253.164	47.088867	2.0289037
7.8572073	27254.422	47.186523	2.0336144
7.8721871	27259.32	47.28418	2.0383677
7.8896394	27265.9	47.381836	2.0430806
7.9057684	27271.848	47.479492	2.0478225
7.9230332	27274.293	47.577148	2.0525069
7.9383216	27277.711	47.674805	2.0571823
7.9552732	27279.795	47.772461	2.0618701
7.9714961	27290.832	47.870117	2.0665078
7.98632	27295.166	47.967773	2.0712981
8.0021362	27296.889	48.06543	2.075923
8.0196733	27305.09	48.163086	2.0806134
8.0365305	27310.857	48.260742	2.0852578
8.0527763	27313.402	48.358398	2.0900328
8.0688829	27314.693	48.456055	2.0947599
8.0840416	27318.604	48.553711	2.0993736
8.1007786	27325.68	48.651367	2.1040034
8.1179266	27327.229	48.749023	2.1087363
8.1329603	27333.553	48.84668	2.1133771
8.1496038	27339.336	48.944336	2.1181602
8.1661844	27343.77	49.041992	2.1228628
8.1807661	27351.625	49.139648	2.127646
8.1982365	27351.855	49.237305	2.1322622
8.2152557	27360.213	49.334961	2.1370327
8.2307854	27366.801	49.432617	2.14183
8.2468834	27362.52	49.530273	2.1464665
8.2621136	27366.986	49.62793	2.1511023
8.2783585	27372.531	49.725586	2.1557822
8.29426	27378.67	49.823242	2.1604769
8.3123064	27386.176	49.920898	2.1653388
8.3280153	27388.563	50.018555	2.1700733
8.3444796	27392.162	50.116211	2.1748829
8.3611631	27399.717	50.213867	2.1795731
8.3774309	27403.924	50.311523	2.1844864
8.3938637	27404.994	50.40918	2.1893497
8.4104891	27415.574	50.506836	2.1941571
8.4269304	27415.529	50.604492	2.1989446
8.4434357	27414.764	50.702148	2.2036865
8.4595556	27418.5	50.799805	2.2083931
8.4762697	27424.422	50.897461	2.213033
8.4919119	27423.494	50.995117	2.2178385
8.5079556	27427.855	51.092773	2.2225347
8.5254889	27439.926	51.19043	2.2273836
8.540782	27442.389	51.288086	2.2322116
8.5567141	27442.504	51.385742	2.2371171
8.573205	27445.76	51.483398	2.241833
8.5900049	27450.623	51.581055	2.2466443
8.6058073	27457.844	51.678711	2.2514646
8.6226654	27457.439	51.776367	2.25629
8.6383381	27461.162	51.874023	2.2610555
8.6548109	27463.801	51.97168	2.2659028
8.670475	27466.479	52.069336	2.2706752
8.6871319	27470.01	52.166992	2.2753849
8.7035608	27469.455	52.264648	2.2801709
8.7179909	27477.066	52.362305	2.2848372
8.735117	27481.58	52.459961	2.2896254
8.7506962	27484.305	52.557617	2.2945483
8.767683	27492.719	52.655273	2.2993195
8.7847595	27491.152	52.75293	2.3041651
8.7996149	27496.117	52.850586	2.3090906
8.8174601	27500.678	52.948242	2.3139374
8.8330708	27506.141	53.045898	2.318825
8.8510685	27507.984	53.143555	2.3236654
8.865016	27511.305	53.241211	2.3283761
8.8824549	27509.629	53.338867	2.3332014
8.898736	27509.318	53.436523	2.3379195
8.9138947	27519.246	53.53418	2.3427045
8.9305916	27524.135	53.631836	2.3473518
8.9476776	27534.861	53.729492	2.3523965
8.9634438	27538.146	53.827148	2.3573778
8.9803333	27536.773	53.924805	2.3623531
8.9955187	27531.012	54.022461	2.3670671
9.011652	27538.539	54.120117	2.3720131
9.0286398	27548.479	54.217773	2.3768442
9.0447416	27548.969	54.31543	2.3817427
9.0614834	27548.104	54.413086	2.3865135
9.0774107	27552.285	54.510742	2.391438
9.0943899	27558.055	54.608398	2.3963044
9.1094818	27560.195	54.706055	2.4012778
9.1264286	27559.891	54.803711	2.4061842
9.1422892	27561.436	54.901367	2.4108551
9.1581945	27569.496	54.999023	2.4157052
9.1736984	27570.504	55.09668	2.4206557
9.190547	27570.922	55.194336	2.4255188
9.2077618	27579.908	55.291992	2.4303439
9.223444	27591.459	55.389648	2.4353116
9.2396355	27584.023	55.487305	2.4402492
9.2563725	27588.949	55.584961	2.4452167
9.2731409	27595.287	55.682617	2.4500237
9.28965	27596.012	55.780273	2.4550612
9.3054838	27593.432	55.87793	2.4598982
9.3220148	27595.58	55.975586	2.4648981
9.3378401	27596.947	56.073242	2.4696808
9.3523912	27600.051	56.170898	2.4746335
9.3703623	27608.871	56.268555	2.4795885
9.3867102	27610.738	56.366211	2.4845383
9.4016857	27611.637	56.463867	2.4894075
9.4181948	27614.188	56.561523	2.4943144
9.4353161	27619.859	56.65918	2.4994206
9.4503145	27624.641	56.756836	2.5043099
9.4670649	27623.592	56.854492	2.5093377
9.4841366	27625.705	56.952148	2.5142472
9.5021076	27625.727	57.049805	2.5191286
9.516449	27625.041	57.147461	2.5241807
9.5317726	27633.977	57.245117	2.5289974
9.5504723	27637.604	57.342773	2.5340152
9.5646257	27639.559	57.44043	2.5391133
9.5816526	27646.395	57.538086	2.5441041
9.5981169	27645.539	57.635742	2.5491011
9.6152029	27648.52	57.733398	2.5541217
9.6313992	27646.453	57.831055	2.5590966
9.6467686	27653.111	57.928711	2.564086
9.6628304	27654.979	58.026367	2.5690105
9.6791916	27654.5	58.124023	2.5741136
9.695446	27661.191	58.22168	2.5790286
9.7132158	27661.047	58.319336	2.5840201
9.7292948	27660.391	58.416992	2.5890713
9.7445526	27666.477	58.514648	2.5940733
9.7615891	27668.906	58.612305	2.5991764
9.777544	27671.674	58.709961	2.6041608
9.793807	27671.818	58.807617	2.6091096
9.8099003	27674.107	58.905273	2.6142008
9.8262262	27682.398	59.00293	2.6193252
9.842185	27684.848	59.100586	2.624362
9.8589888	27677.047	59.198242	2.6293788
9.8753862	27684.281	59.295898	2.6344128
9.8909206	27686.072	59.393555	2.6392457
9.9065981	27689.689	59.491211	2.6444046
9.9226866	27693.736	59.588867	2.649354
9.939352	27700.908	59.686523	2.6544855
9.9564514	27703.266	59.78418	2.6596103
9.9728975	27703.211	59.881836	2.6647851
9.9884281	27704.182	59.979492	2.6697376
10.006027	27708.359	60.077148	2.674835
10.020427	27706.377	60.174805	2.6798623
10.038576	27710.336	60.272461	2.684972
10.05407	27717.016	60.370117	2.6901076
10.070142	27721.813	60.467773	2.6953864
10.087647	27721.582	60.56543	2.7005484
10.1043	27721.389	60.663086	2.7057867
10.121613	27719.229	60.760742	2.7110033
10.136786	27716.922	60.858398	2.7161155
10.153053	27715.316	60.956055	2.7210505
10.16912	27719.229	61.053711	2.7260039
10.185172	27723.293	61.151367	2.7311273
10.201194	27729	61.249023	2.7361906
10.217175	27727.811	61.34668	2.741183
10.23245	27728.293	61.444336	2.7462442
10.250257	27733.357	61.541992	2.7513754
10.265281	27735.883	61.639648	2.7565215
10.281276	27736.424	61.737305	2.7617424
10.297955	27738.041	61.834961	2.7668202
10.315099	27749.064	61.932617	2.7720726
10.330919	27749.014	62.030273	2.7772222
10.346888	27743.385	62.12793	2.7824976
10.361595	27745.943	62.225586	2.7877071
10.380343	27748.551	62.323242	2.7928097
10.395198	27744.283	62.420898	2.797864
10.412194	27751.086	62.518555	2.8030026
10.428758	27756.846	62.616211	2.8081734
10.444788	27758.107	62.713867	2.8134682
10.461493	27762.256	62.811523	2.8187454
10.475504	27758.264	62.90918	2.8237882
10.493287	27759.49	63.006836	2.8290505
10.510341	27760.645	63.104492	2.8342035
10.525517	27755.883	63.202148	2.8392713
10.542005	27766.775	63.299805	2.8443344
10.55779	27752.426	63.397461	2.8494182
10.574289	27788.582	63.495117	2.8549447
10.592408	27788.342	63.592773	2.8605444
10.608505	27778.934	63.69043	2.8658469
10.623316	27767.197	63.788086	2.8710575
10.639838	27771.955	63.885742	2.8762183
10.656253	27775.543	63.983398	2.8813474
10.671082	27777.965	64.081055	2.8864164
10.687729	27783.453	64.178711	2.891818
10.705319	27791.336	64.276367	2.8970392
10.722141	27788.758	64.374023	2.9023559
10.738119	27785.309	64.47168	2.907748
10.753654	27783.197	64.569336	2.9129705
10.769639	27793.258	64.666992	2.9182887
10.786787	27792.693	64.764648	2.9236846
10.803855	27798.475	64.862305	2.9289596
10.819537	27795.293	64.959961	2.9342155
10.836096	27792.096	65.057617	2.9396753
10.852935	27790.836	65.155273	2.9448388
10.868018	27793.367	65.25293	2.9500759
10.884827	27796.775	65.350586	2.9553893
10.901461	27800.801	65.448242	2.9605863
10.916905	27806.037	65.545898	2.9659722
10.932807	27810.018	65.643555	2.9713881
10.949285	27808.912	65.741211	2.9768233
10.96692	27803.395	65.838867	2.9822457
10.982366	27806.172	65.936523	2.987623
10.999442	27804.15	66.03418	2.9928503
11.01444	27800.496	66.131836	2.9981599
11.029433	27804.973	66.229492	3.0034523
11.045339	27807.682	66.327148	3.008837
11.062139	27812.461	66.424805	3.0141773
11.078523	27815.104	66.522461	3.0195541
11.095617	27819.807	66.620117	3.0250037
11.11306	27825.385	66.717773	3.0305939
11.128456	27822.008	66.81543	3.0359759
11.146517	27819.592	66.913086	3.0415311
11.161291	27819.598	67.010742	3.0468781
11.176293	27816.338	67.108398	3.0523198
11.193178	27820.268	67.206055	3.0576656
11.209682	27822.793	67.303711	3.0629926
11.224457	27822.736	67.401367	3.0684152
11.241976	27828.15	67.499023	3.0739262
11.258937	27829.137	67.59668	3.0792902
11.274596	27825.156	67.694336	3.0846798
11.291409	27829.629	67.791992	3.090107
11.306849	27837.24	67.889648	3.0955179
11.323909	27830.936	67.987305	3.1010134
11.340011	27831.83	68.084961	3.1065214
11.355309	27834.398	68.182617	3.1120784
11.37243	27832.611	68.280273	3.1175129
11.388774	27835.91	68.37793	3.1229305
11.403955	27839.268	68.475586	3.1283691
11.421631	27844.998	68.573242	3.1340666
11.438341	27837.057	68.670898	3.1396179
11.453638	27838.564	68.768555	3.1452112
11.470054	27840.436	68.866211	3.1505818
11.486831	27849.518	68.963867	3.15624
11.50236	27849.742	69.061523	3.1618085
11.519549	27846.398	69.15918	3.1675184
11.535919	27848.836	69.256836	3.173202
11.551633	27843.574	69.354492	3.1787682
11.5674	27846.748	69.452148	3.1842115
11.5847	27844.131	69.549805	3.1898017
11.600306	27848.201	69.647461	3.1952488
11.616171	27843.703	69.745117	3.2008505
11.631938	27848.215	69.842773	3.206351
11.648653	27851.641	69.94043	3.2120593
11.665841	27854.588	70.038086	3.2175922
11.681791	27857.297	70.135742	3.2232904
11.698224	27854.906	70.233398	3.2290206
11.714465	27849.008	70.331055	3.2346439
11.73059	27854.713	70.428711	3.2403524
11.746276	27857.818	70.526367	3.2459884
11.763124	27862.369	70.624023	3.2518885
11.779996	27858.934	70.72168	3.2575288
11.794712	27856.729	70.819336	3.2631969
11.811051	27850.297	70.916992	3.2687964
11.827887	27856.752	71.014648	3.2745245
11.844986	27851.678	71.112305	3.2800715
11.860382	27855.377	71.209961	3.285599
11.876166	27859.695	71.307617	3.291409
11.893762	27860.529	71.405273	3.297214
11.909207	27860.258	71.50293	3.3028586
11.926167	27861.26	71.600586	3.3086631
11.94172	27860.793	71.698242	3.3144169
11.957594	27864.424	71.795898	3.3201227
11.974237	27864.316	71.893555	3.3259687
11.990048	27859.576	71.991211	3.3317354
12.007742	27863.699	72.088867	3.3375781
12.024332	27865.893	72.186523	3.3434494
12.040237	27862.4	72.28418	3.3491538
12.056089	27862.494	72.381836	3.354804
12.072281	27864.209	72.479492	3.360709
12.088799	27867.588	72.577148	3.3665385
12.104937	27868.121	72.674805	3.3723016
12.120248	27868.252	72.772461	3.3781197
12.136471	27870.213	72.870117	3.3840203
12.152591	27867.662	72.967773	3.3896821
12.168777	27871.797	73.06543	3.395685
12.186007	27873.066	73.163086	3.4015961
12.201845	27877.795	73.260742	3.4074025
12.219141	27875.479	73.358398	3.4134662
12.234451	27876.582	73.456055	3.419383
12.252145	27876.621	73.553711	3.4253993
12.268547	27871.381	73.651367	3.4313872
12.284582	27877.482	73.749023	3.4371195
12.300148	27875.074	73.84668	3.4431851
12.315521	27875.117	73.944336	3.4491522
12.333484	27881.477	74.041992	3.4552555
12.34909	27880.391	74.139648	3.4613225
12.36584	27873.045	74.237305	3.467093
12.380905	27871.039	74.334961	3.473078
12.398415	27872.525	74.432617	3.4790134
12.41428	27874.76	74.530273	3.4849281
12.431098	27883.137	74.62793	3.4909291
12.446158	27875.936	74.725586	3.4970496
12.461742	27879.453	74.823242	3.5029764
12.479123	27875.516	74.920898	3.5090685
12.495533	27881.26	75.018555	3.515178
12.511175	27883.113	75.116211	3.5213518
12.528739	27882.377	75.213867	3.5276027
12.545418	27883.393	75.311523	3.5335827
12.561131	27880.453	75.40918	3.5399723
12.57663	27876.934	75.506836	3.5459952
12.593639	27873.098	75.604492	3.5521324
12.609134	27871.305	75.702148	3.558161
12.625124	27874.91	75.799805	3.5642331
12.642152	27878.547	75.897461	3.5702498
12.657495	27879.729	75.995117	3.5764751
12.673663	27878.709	76.092773	3.5825491
12.691558	27882.549	76.19043	3.5888174
12.706901	27878.738	76.288086	3.594943
12.722368	27882.391	76.385742	3.6011143
12.738751	27880.311	76.483398	3.6075013
12.754599	27876.801	76.581055	3.6137874
12.771971	27885.496	76.678711	3.6199698
12.787166	27889.621	76.776367	3.6264231
12.805132	27885.373	76.874023	3.6328681
12.822007	27884.354	76.97168	3.6391966
12.836683	27881.885	77.069336	3.6455173
12.853711	27881.703	77.166992	3.6518874
12.869796	27880.676	77.264648	3.6581633
12.885111	27881.375	77.362305	3.6644409
12.901482	27881.428	77.459961	3.6707983
12.917785	27881.436	77.557617	3.6771507
12.934776	27881.965	77.655273	3.6836069
12.951277	27876.398	77.75293	3.6898444
12.9666	27890.531	77.850586	3.6963603
12.983803	27884.025	77.948242	3.7029834
13.00104	27880.197	78.045898	3.7093821
13.017568	27880.311	78.143555	3.7158549
13.032207	27877.406	78.241211	3.7222154
13.049226	27880.67	78.338867	3.728591
13.063545	27882.719	78.436523	3.7351201
13.080836	27884.463	78.53418	3.7416801
13.096554	27880.641	78.631836	3.7481034
13.113098	27879.047	78.729492	3.7544935
13.12891	27882.006	78.827148	3.7611485
13.1452	27886.092	78.924805	3.7677753
13.162635	27884.445	79.022461	3.7745671
13.17942	27881.262	79.120117	3.7811294
13.193895	27882.119	79.217773	3.7877636
13.211088	27881.883	79.31543	3.794435
13.227097	27883.922	79.413086	3.8009822
13.243092	27881.678	79.510742	3.8077884
13.260504	27887.328	79.608398	3.8145611
13.277106	27879.465	79.706055	3.8214025
13.292087	27875.961	79.803711	3.8278403
13.308672	27876.451	79.901367	3.834532
13.325163	27883.596	79.999023	3.8411958
13.341243	27878.873	80.09668	3.8480086
13.356594	27876.834	80.194336	3.854861
13.374766	27877.42	80.291992	3.8616071
13.391351	27880.252	80.389648	3.8684232
13.407297	27878.027	80.487305	3.8753192
13.423765	27881.551	80.584961	3.8822567
13.440324	27879.453	80.682617	3.8891797
13.4561	27878.641	80.780273	3.8961253
13.472479	27873.059	80.87793	3.9030879
13.488138	27869.521	80.975586	3.909992
13.505023	27874.467	81.073242	3.9168458
13.521505	27869.533	81.170898	3.9236481
13.537742	27871.877	81.268555	3.9306245
13.553021	27873.934	81.366211	3.9376929
13.569217	27868.809	81.463867	3.9446065
13.585874	27871.578	81.561523	3.9515865
13.601632	27867.848	81.65918	3.9587219
13.618655	27868.783	81.756836	3.9658263
13.634707	27871.352	81.854492	3.9729366
13.650649	27872.711	81.952148	3.9801197
13.668593	27871.225	82.049805	3.9872582
13.683413	27869.486	82.147461	3.9943349
13.69943	27865.527	82.245117	4.0014806
13.716434	27866.514	82.342773	4.0087276
13.732908	27865.906	82.44043	4.0159431
13.748241	27868.975	82.538086	4.0231419
13.764942	27867.957	82.635742	4.0303364
13.781389	27862.115	82.733398	4.0377431
13.797424	27864.221	82.831055	4.0449705
13.814058	27867.414	82.928711	4.0523882
13.830013	27865.324	83.026367	4.0598583
13.847564	27863.342	83.124023	4.0671225
13.862432	27866.947	83.22168	4.0744882
13.878879	27866.127	83.319336	4.081995
13.895535	27860.043	83.416992	4.0893946
13.911896	27865.553	83.514648	4.0968585
13.927896	27858.725	83.612305	4.1041512
13.943501	27864.943	83.709961	4.1117468
13.960212	27859.518	83.807617	4.1191878
13.976626	27858.082	83.905273	4.1267805
13.992734	27859.566	84.00293	4.1342573
14.009748	27860.23	84.100586	4.1418786
14.025144	27857.994	84.198242	4.1494613
14.041558	27858.066	84.295898	4.1571341
14.058408	27857.051	84.393555	4.1648688
14.074009	27856.16	84.491211	4.1724076
14.089999	27854.217	84.588867	4.1801338
14.107205	27849.861	84.686523	4.18786
14.1216	27853.227	84.78418	4.1956573
14.13865	27849.295	84.881836	4.2033334
14.155991	27852.387	84.979492	4.2112284
14.172174	27838.498	85.077148	4.218863
14.186939	27855.367	85.174805	4.2270341
14.205254	27856.182	85.272461	4.2352042
14.221432	27849.832	85.370117	4.2432933
14.239148	27844.48	85.467773	4.2514539
14.253382	27841.756	85.56543	4.2594099
14.27104	27833.072	85.663086	4.2672796
14.286471	27835.254	85.760742	4.2751622
14.301764	27834.316	85.858398	4.2831821
14.318274	27831.635	85.956055	4.2911229
14.33438	27832.713	86.053711	4.2990065
14.351425	27829.053	86.151367	4.3070798
14.366763	27830.736	86.249023	4.3150749
14.382856	27831.609	86.34668	4.3231478
14.3989	27832.498	86.444336	4.3313718
14.415436	27832.555	86.541992	4.339633
14.43123	27835.258	86.639648	4.3479624
14.449429	27832.422	86.737305	4.3563042
14.463815	27830.227	86.834961	4.3648534
14.481271	27835.578	86.932617	4.3733969
14.498106	27829.342	87.030273	4.3820424
14.51454	27825.012	87.12793	4.3907318
14.531097	27822.551	87.225586	4.3993258
14.547522	27821.736	87.323242	4.4080386
14.563521	27818.938	87.420898	4.416584
14.579462	27814.52	87.518555	4.4249363
14.594975	27811.133	87.616211	4.4333191
14.61147	27815.043	87.713867	4.44207
14.628171	27814.303	87.811523	4.4507003
14.643875	27812.721	87.90918	4.4591675
14.660125	27815.936	88.006836	4.4678364
14.676594	27814.969	88.104492	4.4767723
14.693094	27807.664	88.202148	4.4855766
14.708105	27804.193	88.299805	4.494287
14.723501	27803.242	88.397461	4.5031905
14.741414	27806.533	88.495117	4.5121264
14.758472	27808.074	88.592773	4.5211544
14.774472	27808.131	88.69043	4.5303888
14.790279	27807.492	88.788086	4.5394664
14.806735	27795.914	88.885742	4.5485826
14.822761	27793.078	88.983398	4.5576367
14.838769	27794.182	89.081055	4.5668073
14.855103	27795.773	89.178711	4.5759726
14.871644	27792.457	89.276367	4.5851216
14.887648	27789.398	89.374023	4.5944376
14.903044	27786.314	89.47168	4.6037107
14.921828	27788.83	89.569336	4.6131606
14.937707	27785.596	89.666992	4.6226168
14.952794	27779.502	89.764648	4.6320858
14.969687	27778.617	89.862305	4.6417131
14.985325	27776.301	89.959961	4.6512089
15.001629	27772.805	90.057617	4.6607394
15.017932	27770.557	90.155273	4.670332
15.033797	27773.361	90.25293	4.6800079
15.049578	27770	90.350586	4.6897449
15.067218	27767.98	90.448242	4.6995931
15.083364	27763.373	90.545898	4.7094364
15.099963	27767.703	90.643555	4.7194071
15.116642	27769.793	90.741211	4.7293453
15.133151	27766.957	90.838867	4.739635
15.149499	27757.678	90.936523	4.7497888
15.165253	27749.85	91.03418	4.7598658
15.180881	27744.752	91.131836	4.769752
15.198749	27748.275	91.229492	4.7797642
15.213631	27746.621	91.327148	4.7898655
15.229343	27747.018	91.424805	4.8000569
15.247037	27741.559	91.522461	4.810246
15.261754	27738.455	91.620117	4.8205862
15.278155	27739.918	91.717773	4.8309817
15.294271	27731.193	91.81543	4.8413372
15.309783	27729.506	91.913086	4.8517861
15.326162	27728.186	92.010742	4.8621039
15.342591	27731.293	92.108398	4.8728547
15.359172	27725.994	92.206055	4.883523
15.375162	27724.328	92.303711	4.8942971
15.392422	27720.252	92.401367	4.9051199
15.408368	27721.701	92.499023	4.9161782
15.4246	27718.738	92.59668	4.9271345
15.441305	27711.9	92.694336	4.9382701
15.457251	27711.184	92.791992	4.9494166
15.474623	27708.793	92.889648	4.9606166
15.491266	27704.6	92.987305	4.9719357
15.506228	27699.77	93.084961	4.983335
15.522232	27700.322	93.182617	4.9946923
15.538379	27695.477	93.280273	5.0061626
15.556479	27686.133	93.37793	5.017683
15.571848	27686.564	93.475586	5.0292287
15.588241	27683.543	93.573242	5.0410242
15.604518	27680.799	93.670898	5.0527058
15.620942	27675.197	93.768555	5.0645618
15.638122	27671.578	93.866211	5.0763669
15.653794	27667.973	93.963867	5.0882406
15.669119	27656.922	94.061523	5.1000519
15.685176	27649.734	94.15918	5.1118531
15.701108	27654.512	94.256836	5.1237388
15.718011	27650.813	94.354492	5.135829
15.734488	27643.09	94.452148	5.1480083
15.750153	27641.748	94.549805	5.1600957
15.766527	27638.143	94.647461	5.1724348
15.782697	27630.834	94.745117	5.1847715
15.800001	27623.217	94.842773	5.1971116
15.814123	27628.188	94.94043	5.2097359
15.831634	27621.359	95.038086	5.2224369
15.846748	27618.248	95.135742	5.2351952
15.864987	27612.023	95.233398	5.2483497
15.882202	27607.879	95.331055	5.261261
15.897803	27603.623	95.428711	5.2744083
15.91379	27593.293	95.526367	5.28755
15.929668	27591.109	95.624023	5.3008537
15.945627	27585.18	95.72168	5.3141828
15.961506	27579.051	95.819336	5.327517
15.978699	27570.236	95.916992	5.3409214
15.995633	27568.094	96.014648	5.3544497
16.010891	27564.518	96.112305	5.3680849
16.028374	27555.697	96.209961	5.3815498
16.043827	27547.699	96.307617	5.3952651
16.059393	27554.191	96.405273	5.4090929
16.077198	27543.611	96.50293	5.4232717
16.093369	27537.803	96.600586	5.4375467
16.108643	27521.047	96.698242	5.4515982
16.124897	27516.449	96.795898	5.4655037
16.141264	27511.803	96.893555	5.47966
16.156946	27505.713	96.991211	5.4940391
16.174103	27503.109	97.088867	5.5085454
16.18965	27496.943	97.186523	5.5233331
16.207621	27485.002	97.28418	5.5379648
16.2232	27475.139	97.381836	5.5527935
16.240644	27463.17	97.479492	5.5674548
16.25489	27456.629	97.577148	5.5822058
16.272339	27447.551	97.674805	5.5970535
16.287663	27437.607	97.772461	5.611939
16.304199	27432.191	97.870117	5.6269479
16.321762	27423.322	97.967773	5.6420708
16.337463	27412.338	98.06543	5.6573792
16.35317	27402.285	98.163086	5.672718
16.369202	27397.182	98.260742	5.6881528
16.385466	27386.607	98.358398	5.7036605
16.401693	27371.775	98.456055	5.7192302
16.417673	27362.328	98.553711	5.734962
16.434872	27354.012	98.651367	5.7508888
16.450861	27340.398	98.749023	5.7666211
16.466454	27325.17	98.84668	5.7823186
16.483213	27317.809	98.944336	5.7981319
16.50038	27309.879	99.041992	5.8140283
16.51531	27291.771	99.139648	5.8300552
16.532835	27280.924	99.237305	5.8459644
16.548838	27269.26	99.334961	5.8620486
16.563707	27257.25	99.432617	5.8781834
16.580275	27245.576	99.530273	5.8942456
16.596752	27232.482	99.62793	5.9106712
16.613735	27222.266	99.725586	5.9269743
16.629232	27202.27	99.823242	5.943469
16.646555	27187.406	99.920898	5.9599104
16.661964	27178.561	100.01855	5.9762225
16.679056	27164.859	100.11621	5.9930911
16.694893	27146.176	100.21387	6.0098572
16.7118	27127.945	100.31152	6.0265026
16.728596	27116.488	100.40918	6.0432172
16.744595	27102.625	100.50684	6.0598478
16.760111	27081.451	100.60449	6.076539
16.776052	27064.084	100.70215	6.0930595
16.792999	27049.557	100.7998	6.1097026
16.808687	27033.928	100.89746	6.1262956
16.824497	27011.291	100.99512	6.1428914
16.841038	26993.795	101.09277	6.1594949
16.856493	26985.963	101.19043	6.176187
16.87495	26961.334	101.28809	6.1931939
16.889721	26941.51	101.38574	6.2100244
16.90601	26925.184	101.4834	6.2271729
16.923382	26909.373	101.58105	6.2442226
16.939011	26886.51	101.67871	6.2614808
16.955542	26865.555	101.77637	6.2786317
16.971367	26842.75	101.87402	6.2958441
16.987644	26819.258	101.97168	6.3125987
17.005041	26802.02	102.06934	6.3294253
17.019804	26781.396	102.16699	6.3461747
17.037031	26762.648	102.26465	6.3632073
17.053148	26739.816	102.3623	6.3804207
17.069088	26718.408	102.45996	6.3975668
17.085642	26696.955	102.55762	6.4149928
17.102039	26672.215	102.65527	6.4322319
17.119368	26646.27	102.75293	6.4493165
17.136211	26622.9	102.85059	6.4663916
17.150833	26603.82	102.94824	6.4834704
17.168818	26579.66	103.0459	6.5006056
17.18399	26556.686	103.14355	6.5177927
17.200432	26529.846	103.24121	6.5349598
17.216547	26509.611	103.33887	6.5523419
17.232235	26480.98	103.43652	6.5695567
17.248909	26450.926	103.53418	6.586524
17.265081	26428.645	103.63184	6.603291
17.280983	26403.6	103.72949	6.6202569
17.29801	26377.156	103.82715	6.6371932
17.314238	26349	103.9248	6.6540489
17.329081	26324.926	104.02246	6.6709867
17.346022	26297.822	104.12012	6.6879587
17.361687	26271.211	104.21777	6.7051473
17.377346	26240.609	104.31543	6.7220826
17.39427	26217.314	104.41309	6.7393298
17.409403	26189.031	104.51074	6.756526
17.427397	26157.752	104.6084	6.7738719
17.442635	26127.74	104.70605	6.7912521
17.460285	26097.969	104.80371	6.8086772
17.476686	26065.916	104.90137	6.8259473
17.492887	26034.852	104.99902	6.8434629
17.509087	26000.871	105.09668	6.8608603
17.52599	25974.5	105.19434	6.8784027
17.542471	25939.477	105.29199	6.8957262
17.557993	25905.881	105.38965	6.9131718
17.57476	25873.549	105.4873	6.9305658
17.591431	25839.559	105.58496	6.9479923
17.60634	25805.957	105.68262	6.9655375
17.623291	25769.361	105.78027	6.9828963
17.641611	25735.463	105.87793	7.0001984
17.65587	25698.543	105.97559	7.0174956
17.672407	25661.328	106.07324	7.0348449
17.688465	25625.387	106.1709	7.0520916
17.705372	25586.936	106.26855	7.0694313
17.722738	25550.77	106.36621	7.0864935
17.738031	25511.344	106.46387	7.1036997
17.752945	25472.883	106.56152	7.1207786
17.769024	25437.07	106.65918	7.1378112
17.785305	25395.133	106.75684	7.1547704
17.801287	25355.332	106.85449	7.1716828
17.816387	25320.934	106.95215	7.1886301
17.832142	25278.889	107.0498	7.2056746
17.848417	25237.338	107.14746	7.2229776
17.866924	25196.686	107.24512	7.2403536
17.881844	25152.1	107.34277	7.2578216
17.898512	25113.295	107.44043	7.2755399
17.915934	25065.314	107.53809	7.2932343
17.931196	25021.076	107.63574	7.3109927
17.948067	24979.268	107.7334	7.3289313
17.96533	24927.232	107.83105	7.3467016
17.981398	24878.512	107.92871	7.3645339
17.998304	24828.816	108.02637	7.3823538
18.014156	24775.469	108.12402	7.4001145
18.029636	24720.686	108.22168	7.4178238
18.046236	24667.221	108.31934	7.4354944
18.063799	24611.242	108.41699	7.4531579
18.078735	24552.387	108.51465	7.4707565
18.095556	24497.672	108.6123	7.488338
18.112942	24437.713	108.70996	7.5057988
18.128593	24378.955	108.80762	7.5234809
18.145844	24310.801	108.90527	7.5411253
18.16086	24236.637	109.00293	7.5587225
18.176783	24149.289	109.10059	7.5766025
18.193033	23998.309	109.19824	7.5953074
18.219095	16.534586	109.2959	7.6662498
18.227655	298.18341	109.39355	7.6631455
18.243954	-89.904175	109.49121	7.6684618
18.260427	-26.763302	109.58887	7.6661482
18.27445	67.724144	109.68652	7.6671047
18.293133	-149.39183	109.78418	7.6705818
18.30814	138.43399	109.88184	7.6696157
18.324028	-144.22031	109.97949	7.6780028
18.338837	74.875664	110.07715	7.6832566
18.353374	-45.826077	110.1748	7.6913242
18.35413	-37.367805	110.27246	7.6886058
18.352938	61.973347	110.37012	7.6831679
18.352236	-114.11949	110.46777	7.6818647
18.35194	89.567856	110.56543	7.6797442
18.35257	-18.484541	110.62402	7.6800318