File: data/Q1.dat
MTS793|MPT|ENU|1|2|.|/|:|1|0|0|A

Data Acquisition						Time:	10.009766	s	2/4/2020 10:16:38 AM
Axial Displacement	Axial Force	Time	Axial Extensometer
mm	N	s	mm
0.0012472272	290.39963	0.018554688	-0.00018542705
0.0011242926	284.88297	0.038085938	-0.000169349
0.00052303076	290.02155	0.057617188	-0.00017188286
0.0022016466	307.8418	0.077148438	-0.00010145304
0.0025302172	384.702	0.096679688	0.00012358633
0.0055342913	542.10205	0.11621094	0.00057483301
0.0094614923	740.61346	0.13574219	0.0012102989
0.013381988	954.85931	0.15527344	0.0018424939
0.017210841	1176.7323	0.17480469	0.0026144586
0.020590425	1386.9308	0.19433594	0.0032153747
0.024229288	1592.6975	0.21386719	0.0039013133
0.028697401	1781.9569	0.23339844	0.0043888125
0.032490492	1969.2399	0.25292969	0.0050275414
0.036084652	2139.804	0.27246094	0.0056202766
0.038476288	2311.4006	0.29199219	0.0061101723
0.042276084	2475.2986	0.31152344	0.0066336319
0.045490265	2643.0471	0.33105469	0.0072180824
0.048087537	2801.323	0.35058594	0.0076868297
0.051672757	2962.7351	0.37011719	0.0080997627
0.053939223	3120.9072	0.38964844	0.0086513711
0.057213753	3270.9229	0.40917969	0.009097293
0.060714036	3423.1265	0.42871094	0.0096155722
0.064525008	3583.627	0.44824219	0.010138427
0.066704303	3738.3052	0.46777344	0.010640484
0.070171058	3891.3574	0.48730469	0.011172778
0.073085725	4050.467	0.50683594	0.011615468
0.076539069	4216.1128	0.52636719	0.012123496
0.07994324	4380.3569	0.54589844	0.012644205
0.084020197	4536.6602	0.56542969	0.013154532
0.085473061	4695.543	0.58496094	0.013648023
0.089659542	4867.5806	0.60449219	0.014122467
0.092697144	5025.5923	0.62402344	0.014672963
0.095319003	5175.8027	0.64355469	0.015189712
0.098651648	5321.4287	0.66308594	0.015727935
0.10150596	5474.9185	0.68261719	0.016131274
0.10429546	5640.6504	0.70214844	0.016602641
0.1080595	5805.7188	0.72167969	0.01714349
0.1123555	5975.5396	0.74121094	0.017804593
0.11615306	6159.0601	0.76074219	0.018349936
0.11894479	6343.6382	0.78027344	0.01892771
0.12380183	6530.5752	0.79980469	0.019495301
0.12593642	6718.4814	0.81933594	0.020164944
0.13036653	6908.0615	0.83886719	0.020738471
0.13428703	7091.335	0.85839844	0.021358006
0.13890043	7273.1372	0.87792969	0.021825546
0.14150888	7452.0054	0.89746094	0.022459291
0.14528632	7625.2139	0.91699219	0.022919519
0.14750361	7785.21	0.93652344	0.023536325
0.15209466	7935.4287	0.95605469	0.023998652
0.15526637	8088.7241	0.97558594	0.024533864
0.15831962	8231.7021	0.99511719	0.024992786
0.16162768	8376.7031	1.0146484	0.025419658
0.16429201	8521.5596	1.0341797	0.02587099
0.16714633	8674.2969	1.0537109	0.02649278
0.16838461	8826.2842	1.0732422	0.02686899
0.1734294	8974.2676	1.0927734	0.02732751
0.17620325	9123.3301	1.1123047	0.027917134
0.17841384	9269.0889	1.1318359	0.028383747
0.18309876	9415.1777	1.1513672	0.028790632
0.18547028	9563.4912	1.1708984	0.02927025
0.1888141	9718.2227	1.1904297	0.029813349
0.19200817	9871.7871	1.2099609	0.03038629
0.19558445	10022.445	1.2294922	0.030782178
0.1979202	10172.028	1.2490234	0.031294495
0.20176694	10320.315	1.2685547	0.031804133
0.20448491	10472.545	1.2880859	0.0323385
0.20822883	10627.458	1.3076172	0.03285335
0.21119937	10783.757	1.3271484	0.033337753
0.21409616	10933.317	1.3466797	0.033812609
0.21801442	11086.073	1.3662109	0.034355763
0.22181645	11236.618	1.3857422	0.034862161
0.22482723	11393.419	1.4052734	0.03545988
0.22724345	11549.522	1.4248047	0.035910681
0.23132935	11703.039	1.4443359	0.036415592
0.23448765	11857.329	1.4638672	0.036942448
0.23934469	12015.664	1.4833984	0.037353255
0.24245381	12176.26	1.5029297	0.037958812
0.24536178	12329.012	1.5224609	0.038354378
0.24807528	12483.948	1.5419922	0.038976561
0.25203153	12638.454	1.5615234	0.039535832
0.25485232	12793.053	1.5810547	0.0399989
0.2593562	12947.47	1.6005859	0.040559724
0.26160479	13095.572	1.6201172	0.041111652
0.26551411	13241.046	1.6396484	0.041507933
0.26812255	13385.637	1.6591797	0.042018063
0.27050078	13535.36	1.6787109	0.042534612
0.27379319	13683.451	1.6982422	0.04296479
0.27815625	13828.966	1.7177734	0.043530758
0.28093234	13978.83	1.7373047	0.04406536
0.28461814	14131.23	1.7568359	0.044577789
0.28788596	14278.761	1.7763672	0.045086373
0.29037818	14426.603	1.7958984	0.045549873
0.29333979	14572.837	1.8154297	0.046088889
0.29755533	14719.028	1.8349609	0.046574231
0.3005214	14865.578	1.8544922	0.047060713
0.30356124	15012.014	1.8740234	0.047549933
0.30651167	15164.298	1.8935547	0.048065361
0.31041428	15315.161	1.9130859	0.04863013
0.31348094	15465.797	1.9326172	0.049128376
0.31684265	15612.637	1.9521484	0.049654622
0.32040775	15762.907	1.9716797	0.050162472
0.32390803	15910.156	1.9912109	0.050709046
0.3272295	16058.766	2.0107422	0.05110712
0.330057	16200.104	2.0302734	0.051711626
0.33266097	16342.695	2.0498047	0.052260358
0.3371492	16491.094	2.0693359	0.052740492
0.34003258	16633.91	2.0888672	0.0532392
0.34334064	16772.406	2.1083984	0.053711407
0.34736171	16914.045	2.1279297	0.054247517
0.35007745	17054.701	2.1474609	0.054687794
0.35346597	17197.293	2.1669922	0.055087306
0.35805926	17335.674	2.1865234	0.055591963
0.35963729	17477.402	2.2060547	0.056150414
0.36315545	17616.436	2.2255859	0.056611344
0.36460161	17759.902	2.2451172	0.057137188
0.36848187	17902.678	2.2646484	0.057621222
0.372646	18044.732	2.2841797	0.058135927
0.375925	18183.912	2.3037109	0.058701593
0.37912801	18322.559	2.3232422	0.059108689
0.38182586	18460.225	2.3427734	0.059643663
0.3855139	18600.029	2.3623047	0.060230281
0.38884208	18736.105	2.3818359	0.06065451
0.39225519	18881.436	2.4013672	0.061107986
0.39643049	19019.596	2.4208984	0.061640736
0.3992267	19157.555	2.4404297	0.062184308
0.40114447	19294.635	2.4599609	0.062680133
0.40611327	19433.434	2.4794922	0.06321945
0.40859208	19572.049	2.4990234	0.063732482
0.41144416	19712.156	2.5185547	0.064353518
0.4157424	19856.635	2.5380859	0.064743854
0.41792616	19994.145	2.5576172	0.065346479
0.42293519	20132.762	2.5771484	0.065864705
0.42583868	20275.193	2.5966797	0.066345565
0.42858124	20419.848	2.6162109	0.06691622
0.43204352	20557.523	2.6357422	0.067358769
0.43548346	20694.668	2.6552734	0.068027735
0.43725371	20835.936	2.6748047	0.06844084
0.44258684	20964.154	2.6943359	0.068974823
0.44530705	21101.129	2.7138672	0.069486693
0.44866875	21231.01	2.7333984	0.069987267
0.45277923	21366.063	2.7529297	0.070596673
0.45572296	21497.391	2.7724609	0.071063787
0.45888126	21624.736	2.7919922	0.071488164
0.46198815	21757.08	2.8115234	0.072068907
0.46574101	21885.172	2.8310547	0.072680391
0.46772808	22010.381	2.8505859	0.073164195
0.47217831	22147.715	2.8701172	0.07368172
0.474751	22274.391	2.8896484	0.074290805
0.47850162	22403.426	2.9091797	0.07476607
0.48123747	22532.758	2.9287109	0.075231038
0.48510656	22657.854	2.9482422	0.075783916
0.48781782	22784.428	2.9677734	0.076204844
0.48963726	22906.797	2.9873047	0.076774888
0.49415454	23035.582	3.0068359	0.077307411
0.49764588	23154.51	3.0263672	0.077870838
0.50146353	23280.146	3.0458984	0.078385927
0.50407875	23403.043	3.0654297	0.078893773
0.50737333	23528.686	3.0849609	0.079269312
0.51008236	23651.334	3.1044922	0.079849787
0.51397383	23772.445	3.1240234	0.080408119
0.51723272	23897.555	3.1435547	0.080925755
0.52100569	24026.85	3.1630859	0.081608318
0.52401197	24152.701	3.1826172	0.082033597
0.52736926	24274.799	3.2021484	0.082616977
0.53002012	24402.037	3.2216797	0.083135501
0.53391826	24529.396	3.2412109	0.083641782
0.53647983	24651.574	3.2607422	0.084246725
0.53991526	24772.492	3.2802734	0.084788822
0.5422734	24893.842	3.2998047	0.085364275
0.54706782	25016.293	3.3193359	0.085890844
0.55122745	25135.018	3.3388672	0.086433843
0.55289042	25252.564	3.3583984	0.086945921
0.55702102	25367.27	3.3779297	0.087479785
0.56020391	25481.895	3.3974609	0.087939702
0.56217086	25598.059	3.4169922	0.088579386
0.56710392	25708.992	3.4365234	0.089158878
0.56970787	25822.91	3.4560547	0.089622729
0.57248843	25934.242	3.4755859	0.0902256
0.57700127	26043.084	3.4951172	0.09070009
0.57927221	26154.502	3.5146484	0.091171712
0.58218467	26266.498	3.5341797	0.091717228
0.58535409	26382.111	3.5537109	0.092276119
0.58871579	26492	3.5732422	0.092806928
0.59216022	26607.553	3.5927734	0.093393348
0.59523582	26717.219	3.6123047	0.094025694
0.59866905	26828.039	3.6318359	0.094476067
0.60219616	26942.314	3.6513672	0.095131189
0.60509741	27051.189	3.6708984	0.095536232
0.60845685	27162.279	3.6904297	0.096172184
0.61138272	27275.641	3.7099609	0.096752517
0.61504173	27386.012	3.7294922	0.097401135
0.617782	27496.619	3.7490234	0.097980738
0.62148345	27608.777	3.7685547	0.09845262
0.62494349	27717.967	3.7880859	0.099084824
0.62710494	27828.525	3.8076172	0.099551834
0.63222122	27934.172	3.8271484	0.10020391
0.63461733	28047.984	3.8466797	0.10071496
0.63745826	28156.494	3.8662109	0.10132059
0.64151955	28262.658	3.8857422	0.10188616
0.64472485	28370.975	3.9052734	0.1024844
0.64851791	28481.4	3.9248047	0.10314413
0.65180135	28586.959	3.9443359	0.10368222
0.65497756	28694.844	3.9638672	0.10421999
0.65902323	28802.885	3.9833984	0.1047459
0.6613456	28907.871	4.0029297	0.10546143
0.6646648	29016.439	4.0224609	0.10600661
0.66889155	29121.404	4.0419922	0.10664894
0.67154241	29225.021	4.0615234	0.10727434
0.67473203	29331.059	4.0810547	0.10770816
0.67895204	29434.234	4.1005859	0.10836111
0.68111122	29534.676	4.1201172	0.10894049
0.68529993	29635.258	4.1396484	0.10955021
0.68832636	29737.396	4.1591797	0.11017716
0.69111139	29834.201	4.1787109	0.11075747
0.69542527	29930.754	4.1982422	0.11127546
0.69870651	30029.117	4.2177734	0.11178932
0.7017687	30128.406	4.2373047	0.11242174
0.70504546	30226.002	4.2568359	0.11298145
0.70812106	30319.008	4.2763672	0.11365181
0.71102679	30414.773	4.2958984	0.1141983
0.71473718	30513.059	4.3154297	0.11478417
0.71740597	30607.674	4.3349609	0.11539969
0.72022676	30702.275	4.3544922	0.11596203
0.72307885	30796.412	4.3740234	0.11644747
0.72784871	30892.385	4.3935547	0.11710172
0.73049068	30986.057	4.4130859	0.11764669
0.7339552	31077.668	4.4326172	0.11818657
0.73701739	31173.984	4.4521484	0.1187771
0.74036568	31268.422	4.4716797	0.11934979
0.74339658	31362.129	4.4912109	0.11994582
0.74644983	31451.793	4.5107422	0.12048931
0.7494539	31540.852	4.5302734	0.12113323
0.75249374	31632.939	4.5498047	0.12174532
0.75603873	31720.625	4.5693359	0.12223952
0.75881481	31808.531	4.5888672	0.12274107
0.76246262	31906.813	4.6083984	0.12337698
0.76462179	31999.621	4.6279297	0.1239608
0.76856464	32093.83	4.6474609	0.12448855
0.77139884	32188.846	4.6669922	0.12508255
0.77442527	32288.242	4.6865234	0.12573302
0.77989697	32389.076	4.7060547	0.12635051
0.78260154	32488.641	4.7255859	0.1269082
0.78665167	32583.869	4.7451172	0.1275558
0.78872591	32682.16	4.7646484	0.12813659
0.79265982	32778.102	4.7841797	0.12867562
0.79495758	32872.332	4.8037109	0.12935302
0.79856515	32964.449	4.8232422	0.12999187
0.80287009	33056.902	4.8427734	0.13059798
0.80545396	33147.844	4.8623047	0.1311202
0.80885589	33242.68	4.8818359	0.13180022
0.81228465	33342.082	4.9013672	0.13245289
0.81640184	33430.816	4.9208984	0.1330395
0.81988871	33523.875	4.9404297	0.13361594
0.82218647	33607.063	4.9599609	0.13430959
0.82556605	33703.305	4.9794922	0.13482709
0.82961619	33787.559	4.9990234	0.13551109
0.83223581	33877.93	5.0185547	0.13611092
0.83482414	33961	5.0380859	0.13666376
0.838539	34044.098	5.0576172	0.13721073
0.84167719	34129.531	5.0771484	0.13788046
0.84509701	34215.184	5.0966797	0.13838437
0.84751099	34297.113	5.1162109	0.13896382
0.85138679	34377.895	5.1357422	0.13955596
0.85361749	34464.492	5.1552734	0.14009956
0.85710883	34550.383	5.1748047	0.14072719
0.86032748	34633.5	5.1943359	0.14120032
0.86351931	34713.938	5.2138672	0.14177908
0.86626858	34798.031	5.2333984	0.14242563
0.87001026	34885.574	5.2529297	0.14297621
0.87353736	34971.5	5.2724609	0.14357413
0.87549537	35060.023	5.2919922	0.14415476
0.87925047	35141.652	5.3115234	0.14477384
0.88311732	35228.063	5.3310547	0.14537206
0.88607222	35308.223	5.3505859	0.14593698
0.89005083	35393.508	5.3701172	0.14645125
0.89381486	35484.273	5.3896484	0.1470544
0.89530796	35579.18	5.4091797	0.14762746
0.89977384	35668.184	5.4287109	0.14828859
0.90237558	35759.137	5.4482422	0.14891258
0.90516061	35847.121	5.4677734	0.14953208
0.90849102	35943.395	5.4873047	0.15007204
0.91355145	36028.965	5.5068359	0.15071504
0.91615766	36119.113	5.5263672	0.15134141
0.91894716	36209.359	5.5458984	0.15197182
0.92254132	36294.207	5.5654297	0.1525819
0.92649758	36384.344	5.5849609	0.15319295
0.92960447	36471.035	5.6044922	0.15381488
0.93268901	36558.523	5.6240234	0.15447652
0.93567073	36639.551	5.6435547	0.15501477
0.9391129	36729.465	5.6630859	0.15561377
0.94191134	36811.082	5.6826172	0.15625329
0.94593018	36893.973	5.7021484	0.15677868
0.94917119	36980.496	5.7216797	0.15744977
0.95180422	37060.867	5.7412109	0.15799065
0.95534027	37144.613	5.7607422	0.15858388
0.95859021	37227.02	5.7802734	0.15906556
0.96222013	37313.094	5.7998047	0.1597119
0.96468329	37396.367	5.8193359	0.1603407
0.96840709	37481.852	5.8388672	0.1608426
0.97194314	37564.527	5.8583984	0.16155641
0.97551495	37649.637	5.8779297	0.16223291
0.97826868	37728.543	5.8974609	0.1627236
0.98165274	37810.242	5.9169922	0.16327351
0.98378509	37893.906	5.9365234	0.16391955
0.98840743	37974.383	5.9560547	0.16455033
0.99139363	38056.195	5.9755859	0.16509393
0.99349469	38138.492	5.9951172	0.16567533
0.99742413	38222.699	6.0146484	0.16632074
1.000978	38300.227	6.0341797	0.1667483
1.0053366	38376.922	6.0537109	0.16740815
1.0076076	38459.715	6.0732422	0.16799673
1.0104775	38546.426	6.0927734	0.16857545
1.0138617	38635.043	6.1123047	0.16926971
1.0169506	38721.664	6.1318359	0.1698513
1.0201424	38804.734	6.1513672	0.17043485
1.0233521	38892.926	6.1708984	0.17110401
1.0277555	38981.891	6.1904297	0.17166865
1.0303795	39060.051	6.2099609	0.17228594
1.0336027	39146.684	6.2294922	0.17282794
1.0367587	39231.801	6.2490234	0.17350644
1.0407329	39311.313	6.2685547	0.17414537
1.043424	39387.949	6.2880859	0.17471752
1.0470539	39472.809	6.3076172	0.17534856
1.0500715	39553.668	6.3271484	0.17581867
1.0534108	39632.199	6.3466797	0.17635109
1.0564551	39710.5	6.3662109	0.17705829
1.0598928	39789.512	6.3857422	0.1775886
1.0627002	39868.898	6.4052734	0.17826447
1.0659144	39948.586	6.4248047	0.17886367
1.0692761	40025.836	6.4443359	0.17940922
1.073487	40102.477	6.4638672	0.17994048
1.0750562	40185.23	6.4833984	0.18053238
1.079397	40259.188	6.5029297	0.18111023
1.0809705	40335.516	6.5224609	0.18167596
1.0841265	40414.133	6.5419922	0.18233281
1.0892138	40491.57	6.5615234	0.18286775
1.0922492	40564.719	6.5810547	0.1833429
1.0938495	40642.602	6.6005859	0.18404052
1.0973141	40720.992	6.6201172	0.18462908
1.1013955	40802.117	6.6396484	0.18522607
1.1041045	40875.445	6.6591797	0.18579572
1.10832	40955.02	6.6787109	0.18629251
1.1112213	41036.465	6.6982422	0.186887
1.1137515	41118.02	6.7177734	0.18739241
1.1166527	41202.887	6.7373047	0.18797763
1.1202872	41292.387	6.7568359	0.18861993
1.12326	41380.328	6.7763672	0.18930292
1.1268363	41467.637	6.7958984	0.18995872
1.1303812	41556.938	6.8154297	0.19049475
1.1351957	41643.125	6.8349609	0.19109739
1.1371672	41730.582	6.8544922	0.19172886
1.1409357	41819.703	6.8740234	0.19235773
1.1454999	41900.289	6.8935547	0.19291562
1.1481196	41985.637	6.9130859	0.19362171
1.1520848	42073.445	6.9326172	0.19420643
1.1555448	42160.367	6.9521484	0.19482671
1.1582583	42237.121	6.9716797	0.19541511
1.1606276	42318.75	6.9912109	0.19596057
1.1643916	42401.586	7.0107422	0.19663747
1.168558	42482.297	7.0302734	0.19728464
1.1723354	42561.75	7.0498047	0.19781381
1.1740699	42639.066	7.0693359	0.19845456
1.1781871	42717.148	7.0888672	0.19902265
1.181437	42790.082	7.1083984	0.19967185
1.1844144	42865.801	7.1279297	0.20023623
1.1891574	42940.078	7.1474609	0.20081307
1.1902839	43017.16	7.1669922	0.20132057
1.1945977	43093.004	7.1865234	0.20196067
1.1973872	43162.641	7.2060547	0.20251699
1.2002394	43242.035	7.2255859	0.20317152
1.2034982	43320.645	7.2451172	0.20367853
1.2080044	43394.137	7.2646484	0.20413071
1.2097075	43468.359	7.2841797	0.20484491
1.2123003	43544.941	7.3037109	0.20541754
1.2166455	43621.973	7.3232422	0.20590189
1.219824	43697.957	7.3427734	0.20654066
1.223655	43775.441	7.3623047	0.20717688
1.2259752	43851.797	7.3818359	0.20773926
1.2290597	43926.016	7.4013672	0.20832999
1.2322917	44000.617	7.4208984	0.20885509
1.2355461	44072.832	7.4404297	0.20936956
1.2393997	44144.891	7.4599609	0.20986691
1.2427881	44213.398	7.4794922	0.21043003
1.2455642	44282.828	7.4990234	0.2110271
1.2478218	44355.504	7.5185547	0.21162383
1.2508795	44434.129	7.5380859	0.21214926
1.2551576	44512.738	7.5576172	0.21267195
1.2581482	44592.23	7.5771484	0.21329241
1.2607143	44673.168	7.5966797	0.21390699
1.2640268	44749.816	7.6162109	0.21445665
1.2678891	44828.316	7.6357422	0.214967
1.2712777	44908.156	7.6552734	0.21553327
1.2747242	44981.129	7.6748047	0.21611755
1.2772501	45059.906	7.6943359	0.21670629
1.2805984	45140.383	7.7138672	0.21724899
1.2840897	45221.066	7.7333984	0.21790215
1.2878537	45294.711	7.7529297	0.2185261
1.2897267	45373.668	7.7724609	0.2191436
1.2930483	45452.43	7.7919922	0.21957481
1.2968659	45531.039	7.8115234	0.22019425
1.2994184	45608.617	7.8310547	0.22088644
1.3046846	45686.855	7.8505859	0.22137742
1.3075501	45768.758	7.8701172	0.22198404
1.3102233	45849.051	7.8896484	0.22256614
1.3142421	45925.063	7.9091797	0.22320071
1.3155073	45998.82	7.9287109	0.22372523
1.3198882	46075.07	7.9482422	0.22436737
1.3228744	46149.492	7.9677734	0.22485685
1.3266653	46221.984	7.9873047	0.22544661
1.330416	46294.02	8.0068359	0.2259399
1.3329238	46374.211	8.0263672	0.2265771
1.3353199	46445.18	8.0458984	0.22710869
1.3381183	46517.691	8.0654297	0.22766362
1.3422623	46588.656	8.0849609	0.22826146
1.3462275	46666.648	8.1044922	0.22879124
1.3491645	46738.055	8.1240234	0.22939007
1.3523028	46810.141	8.1435547	0.23001742
1.3549938	46884.461	8.1630859	0.23052727
1.3576448	46958.84	8.1826172	0.23110373
1.3610735	47036.867	8.2021484	0.23171072
1.3652756	47112.246	8.2216797	0.23235939
1.3681144	47195.875	8.2412109	0.232899
1.371941	47273.09	8.2607422	0.23348041
1.3753921	47352.043	8.2802734	0.23403637
1.3782396	47428.516	8.2998047	0.23457554
1.3820662	47512.789	8.3193359	0.23510608
1.3840377	47598.016	8.3388672	0.23578803
1.3891518	47678.629	8.3583984	0.23639801
1.3918207	47757.125	8.3779297	0.23707701
1.3955131	47836.508	8.3974609	0.23762982
1.3981462	47914.922	8.4169922	0.23822923
1.4019861	47994.141	8.4365234	0.23877461
1.4042526	48064.512	8.4560547	0.2393394
1.4085755	48144.125	8.4755859	0.24000475
1.4117271	48220.496	8.4951172	0.24059457
1.41491	48292.172	8.5146484	0.24122427
1.4186964	48363.609	8.5341797	0.24175851
1.4221654	48436.227	8.5537109	0.2422785
1.4245123	48511.66	8.5732422	0.24287851
1.4283254	48581.039	8.5927734	0.24339619
1.4309452	48656.551	8.6123047	0.24394938
1.434119	48727.07	8.6318359	0.24444112
1.4380708	48803.945	8.6513672	0.24511798
1.4415576	48871.23	8.6708984	0.24567051
1.444298	48939.715	8.6904297	0.24618916
1.4475658	49013.777	8.7099609	0.24676763
1.4496446	49080.438	8.7294922	0.24722129
1.4534757	49148.109	8.7490234	0.24784902
1.4569268	49222.27	8.7685547	0.2484632
1.4590189	49293.984	8.7880859	0.24899815
1.4622599	49367.414	8.8076172	0.24962708
1.465349	49444.227	8.8271484	0.25015405
1.470016	49518.305	8.8466797	0.25073695
1.4729261	49593.641	8.8662109	0.25128421
1.4759257	49671.488	8.8857422	0.2518805
1.4800161	49743.332	8.9052734	0.25236595
1.4827654	49817.34	8.9248047	0.25304759
1.4856889	49890.637	8.9443359	0.25360718
1.4887959	49969.266	8.9638672	0.25411096
1.4935702	50040.488	8.9833984	0.25468394
1.494965	50116.531	9.0029297	0.25529405
1.4993906	50192.082	9.0224609	0.25589538
1.5036061	50267.758	9.0419922	0.25653097
1.5061319	50338.473	9.0615234	0.25706741
1.5093148	50409.121	9.0810547	0.25758767
1.5116796	50487.77	9.1005859	0.25817469
1.5155911	50559.785	9.1201172	0.25873229
1.5190601	50635.727	9.1396484	0.25926721
1.5211926	50709.48	9.1591797	0.25986201
1.5244424	50785.723	9.1787109	0.26043114
1.5281842	50860.352	9.1982422	0.26096463
1.5315145	50932.145	9.2177734	0.26161712
1.5348583	51004.063	9.2373047	0.26218
1.537554	51081.402	9.2568359	0.26285633
1.5409336	51151.461	9.2763672	0.2633042
1.5446351	51223.609	9.2958984	0.2639271
1.5486538	51299.719	9.3154297	0.26457652
1.5512377	51372.961	9.3349609	0.26519182
1.5548096	51446.898	9.3544922	0.26565036
1.5577867	51524.809	9.3740234	0.26627648
1.5614122	51598.836	9.3935547	0.26676324
1.5652746	51672.465	9.4130859	0.26737955
1.5672729	51742.262	9.4326172	0.26797855
1.5706525	51817.699	9.4521484	0.26848504
1.5740142	51887.613	9.4716797	0.26903495
1.5777335	51963.699	9.4912109	0.26961675
1.5811577	52029.09	9.5107422	0.27023906
1.5836567	52098.262	9.5302734	0.27078414
1.5872329	52169.883	9.5498047	0.27135599
1.5906394	52237.82	9.5693359	0.27193886
1.5938759	52310.277	9.5888672	0.27248633
1.5977025	52376.953	9.6083984	0.27308434
1.6004429	52424.824	9.6279297	0.27363542
1.6036123	52479.129	9.6474609	0.27404603
1.6066923	52553.883	9.6669922	0.27466008
1.6091287	52639.891	9.6865234	0.27528375
1.6128033	52734.879	9.7060547	0.27582288
1.6169965	52816.215	9.7255859	0.27633783
1.6202197	52893.672	9.7451172	0.27698976
1.6237736	52973.875	9.7646484	0.2775715
1.6258881	53053.363	9.7841797	0.27824703
1.6301439	53133.887	9.8037109	0.27877867
1.6331658	53217.152	9.8232422	0.27943206
1.6369432	53293.223	9.8427734	0.27998638
1.641114	53373.098	9.8623047	0.28058314
1.6430721	53454.406	9.8818359	0.28120121
1.6479403	53525.91	9.9013672	0.28182152
1.650305	53602.27	9.9208984	0.28241187
1.6536444	53674.246	9.9404297	0.28301498
1.6577528	53747.449	9.9599609	0.28357586
1.6610205	53818.934	9.9794922	0.28414422
1.6638055	53881.543	9.9990234	0.28471822
1.6675115	53947.727	10.018555	0.28527951
1.6712532	54006.953	10.038086	0.28580716
1.6729786	54070.453	10.057617	0.28633153
1.6759068	54127	10.077148	0.28689131
1.6786873	54183.855	10.09668	0.28738824
1.6824335	54236.25	10.116211	0.28794348
1.686126	54307.734	10.135742	0.28848955
1.6885891	54366.785	10.155273	0.28906435
1.6910434	54430.184	10.174805	0.28953326
1.6949997	54507.105	10.194336	0.29016247
1.6987771	54578.234	10.213867	0.29060924
1.7025993	54648.824	10.233398	0.2911174
1.7042444	54720.887	10.25293	0.29175854
1.7079904	54795.656	10.272461	0.29237428
1.709792	54870.426	10.291992	0.29295158
1.7140836	54943.367	10.311523	0.29346856
1.7177627	55019.887	10.331055	0.29408637
1.720892	55094.789	10.350586	0.29461583
1.7243609	55170.816	10.370117	0.29523239
1.7275617	55247.305	10.389648	0.29588184
1.7302215	55320.316	10.40918	0.29643637
1.7351344	55393.883	10.428711	0.29702938
1.7376647	55462.629	10.448242	0.29756075
1.7419696	55532.836	10.467773	0.29807979
1.7451837	55602.055	10.487305	0.29876685
1.7471061	55665.742	10.506836	0.29922384
1.751183	55732.68	10.526367	0.29977944
1.752846	55798.559	10.545898	0.30043918
1.7570748	55865.605	10.56543	0.30093855
1.7596364	55933.047	10.584961	0.30144784
1.7647058	56002.012	10.604492	0.30204317
1.7665207	56069.063	10.624023	0.3026607
1.769887	56136.738	10.643555	0.30315825
1.7736151	56210.453	10.663086	0.30374941
1.7759397	56273.863	10.682617	0.3042565
1.7797798	56346.801	10.702148	0.30488932
1.7832488	56414.453	10.72168	0.30544418
1.786624	56484.93	10.741211	0.30593184
1.7893195	56554.844	10.760742	0.30653751
1.7919884	56623.16	10.780273	0.30714282
1.7946213	56689.242	10.799805	0.30763489
1.799427	56758.41	10.819336	0.30826324
1.8021538	56820.891	10.838867	0.30875921
1.8052876	56888.574	10.858398	0.30930367
1.8086627	56953.652	10.87793	0.30988255
1.8124356	57022.418	10.897461	0.31032634
1.81375	57084.242	10.916992	0.31089661
1.8170893	57149.227	10.936523	0.31142917
1.8205941	57213.262	10.956055	0.31204355
1.8243581	57283.648	10.975586	0.31260714
1.827988	57347.492	10.995117	0.31312215
1.8307552	57423.176	11.014648	0.31374124
1.8345684	57500.953	11.03418	0.31424916
1.8366516	57575.234	11.053711	0.31485659
1.8402368	57647.09	11.073242	0.31545836
1.8439426	57720.977	11.092773	0.31600863
1.8475816	57796.141	11.112305	0.31667262
1.8512115	57872.637	11.131836	0.31719387
1.8538311	57943.961	11.151367	0.31777242
1.857537	58016.094	11.170898	0.31836703
1.8615291	58089.855	11.19043	0.31899399
1.8650248	58161.273	11.209961	0.31956658
1.8672779	58225.168	11.229492	0.32015309
1.8713772	58291.809	11.249023	0.32068464
1.8739655	58359.504	11.268555	0.32127687
1.878257	58430.688	11.288086	0.32186726
1.880756	58496.535	11.307617	0.32240206
1.8857628	58558.25	11.327148	0.32298008
1.8868357	58625.273	11.34668	0.32350081
1.8908858	58692.516	11.366211	0.32409728
1.8943682	58757.684	11.385742	0.3246319
1.8967464	58825.777	11.405273	0.32514104
1.8997639	58891.137	11.424805	0.32571572
1.9030809	58955.004	11.444336	0.32626656
1.9068539	59020.352	11.463867	0.32688046
1.9096837	59085.82	11.483398	0.32747796
1.9129515	59149.109	11.50293	0.32797095
1.915504	59213.609	11.522461	0.3285808
1.9187003	59275.121	11.541992	0.32910469
1.921834	59350.293	11.561523	0.32964826
1.9254684	59419.898	11.581055	0.33014947
1.9287632	59487.371	11.600586	0.33077681
1.9321427	59553.945	11.620117	0.33139488
1.9356519	59618.918	11.639648	0.33187088
1.9393041	59687.527	11.65918	0.33247671
1.9416869	59755.078	11.678711	0.33299127
1.9448608	59819.078	11.698242	0.33350289
1.9492418	59889.738	11.717773	0.33411396
1.9515127	59954.109	11.737305	0.3346673
1.9545257	60018.949	11.756836	0.33522591
1.9581959	60089.141	11.776367	0.33583176
1.9613922	60154.121	11.795898	0.33638746
1.9644365	60219.902	11.81543	0.33692598
1.968415	60284.348	11.834961	0.33752105
1.9720182	60345.953	11.854492	0.33806866
1.9742086	60413.781	11.874023	0.338723
1.9775703	60478.918	11.893555	0.33923936
1.9795239	60545.035	11.913086	0.33970979
1.9839272	60615.164	11.932617	0.34030402
1.9873917	60690.094	11.952148	0.34089184
1.9911335	60761.625	11.97168	0.34146363
1.994285	60831	11.991211	0.34205699
1.9980669	60898.633	12.010742	0.34261978
2.0012407	60965.609	12.030273	0.34319574
2.0040796	61031.242	12.049805	0.34383205
2.007334	61099.203	12.069336	0.34428886
2.0108433	61169.02	12.088867	0.34492821
2.01298	61234.352	12.108398	0.34549427
2.0169318	61299.523	12.12793	0.34606469
2.0207539	61364.801	12.147461	0.34659788
2.023056	61433.191	12.166992	0.34714934
2.0275712	61499.809	12.186523	0.34770355
2.0298333	61563.984	12.206055	0.34828901
2.0341649	61630.188	12.225586	0.34894988
2.0361855	61699.293	12.245117	0.34942874
2.0395293	61762.375	12.264648	0.35007942
2.0441606	61827.598	12.28418	0.35055175
2.0456538	61893.098	12.303711	0.35115761
2.0501823	61957.582	12.323242	0.35173434
2.0531282	62021.313	12.342773	0.35229838
2.0553498	62087.945	12.362305	0.35290906
2.0588324	62153.824	12.381836	0.35348326
2.0627439	62217.875	12.401367	0.35404566
2.0662532	62281.656	12.420898	0.35454214
2.069284	62344.691	12.44043	0.35508057
2.072154	62410.895	12.459961	0.35570771
2.0760207	62474.504	12.479492	0.35619673
2.0791993	62540.367	12.499023	0.35690227
2.0815997	62595.598	12.518555	0.35746229
2.0852387	62659.516	12.538086	0.35793275
2.0887613	62721.34	12.557617	0.35846773
2.0913587	62782.469	12.577148	0.35903767
2.0946889	62854.191	12.59668	0.35959646
2.0987167	62919.348	12.616211	0.36025557
2.1009474	62987.641	12.635742	0.36076978
2.1051183	63052.555	12.655273	0.36128414
2.1070495	63119.41	12.674805	0.36195502
2.110009	63186.934	12.694336	0.36246726
2.1149218	63247.746	12.713867	0.3629975
2.1177382	63312.695	12.733398	0.3635242
2.1213145	63373.395	12.75293	0.3641468
2.1245062	63437.438	12.772461	0.36468324
2.1270812	63501.133	12.791992	0.36536977
2.1307602	63571.773	12.811523	0.36585891
2.1342249	63637.859	12.831055	0.36649626
2.1370144	63701.906	12.850586	0.36705056
2.1410556	63770.055	12.870117	0.36762393
2.1440639	63835.043	12.889648	0.36817253
2.1471887	63901.02	12.90918	0.36881983
2.1509662	63962.141	12.928711	0.36931399
2.1543012	64028.527	12.948242	0.36984733
2.1583109	64091.063	12.967773	0.37048671
2.1612167	64150.199	12.987305	0.3710185
2.1625712	64211.098	13.006836	0.37158707
2.1669388	64272.949	13.026367	0.37212151
2.1684542	64336.723	13.045898	0.37263256
2.1729872	64401.543	13.06543	0.37321943
2.1761165	64468.492	13.084961	0.37373608
2.181016	64530.305	13.104492	0.37441567
2.1825762	64597.113	13.124023	0.37493163
2.1859422	64656.859	13.143555	0.37537992
2.1891251	64721.367	13.163086	0.37607434
2.1930099	64792.367	13.182617	0.3766503
2.1965504	64856.613	13.202148	0.37725973
2.2000597	64914.789	13.22168	0.377819
2.2029831	64981.934	13.241211	0.3783251
2.2051959	65041.777	13.260742	0.37895527
2.2096395	65104.203	13.280273	0.3795031
2.2124557	65168.359	13.299805	0.38006544
2.216135	65231.398	13.319336	0.38068026
2.2181602	65292.055	13.338867	0.38124904
2.2221832	65356.941	13.358398	0.38170573
2.2252588	65415.168	13.37793	0.38236612
2.2286475	65479.125	13.397461	0.38295782
2.2310524	65536.664	13.416992	0.38344982
2.2346423	65597.625	13.436523	0.38404563
2.2388577	65653.898	13.456055	0.38454905
2.2409453	65714.43	13.475586	0.38518903
2.244164	65774.5	13.495117	0.3857016
2.2487373	65836.891	13.514648	0.38621217
2.2507131	65894.516	13.53418	0.38678354
2.254066	65954.164	13.553711	0.38732669
2.2567928	66015.977	13.573242	0.38784593
2.260597	66079.336	13.592773	0.3883791
2.2644594	66136.734	13.612305	0.38903505
2.2663817	66197.906	13.631836	0.38953319
2.2695689	66262.734	13.651367	0.39020869
2.2734671	66332.68	13.670898	0.39075249
2.2767038	66397.836	13.69043	0.39135107
2.2795334	66460.703	13.709961	0.39189845
2.2822514	66528.875	13.729492	0.39248714
2.2868335	66594.344	13.749023	0.39302692
2.2901864	66653.969	13.768555	0.39360598
2.2938206	66717.508	13.788086	0.39423519
2.2961318	66780.773	13.807617	0.39473906
2.3004279	66847.453	13.827148	0.3954196
2.3021221	66906.102	13.84668	0.39586475
2.3067131	66967.406	13.866211	0.39646736
2.3099945	67032.5	13.885742	0.39705533
2.3125782	67088.234	13.905273	0.39754894
2.3155868	67151.266	13.924805	0.39825606
2.3199677	67210.375	13.944336	0.39870068
2.3222117	67276.586	13.963867	0.3992976
2.3271918	67335.047	13.983398	0.39986598
2.328846	67399.75	14.00293	0.40046987
2.3329899	67460.367	14.022461	0.4010652
2.3353145	67524.867	14.041992	0.40156689
2.3391633	67583.859	14.061523	0.40221506
2.3423777	67643.555	14.081055	0.4027406
2.3455873	67702.133	14.100586	0.40324116
2.348949	67763.609	14.120117	0.40389615
2.3524852	67820.227	14.139648	0.40439379
2.3556366	67878.672	14.15918	0.40493941
2.3592889	67940.82	14.178711	0.405534
2.3613362	68000.609	14.198242	0.40614891
2.365829	68067.336	14.217773	0.40667871
2.3686275	68132.016	14.237305	0.40724772
2.3718908	68195.133	14.256836	0.40789798
2.3756952	68258.438	14.276367	0.40845612
2.3780956	68324.203	14.295898	0.40906602
2.3822353	68384.219	14.31543	0.40967545
2.3857579	68447.219	14.334961	0.41029209
2.3893743	68513.117	14.354492	0.41074535
2.3929596	68577.664	14.374023	0.41132057
2.3950472	68634.844	14.393555	0.4119114
2.3993611	68690.672	14.413086	0.41248021
2.4016409	68747.234	14.432617	0.4129644
2.4049356	68809.906	14.452148	0.4135679
2.4090707	68869.211	14.47168	0.41419339
2.4117305	68924.461	14.491211	0.4148052
2.4147213	68986.906	14.510742	0.41530672
2.4183691	69040.258	14.530273	0.41592646
2.4212301	69098.578	14.549805	0.41653201
2.4245963	69157.719	14.569336	0.4170287
2.4287627	69218.648	14.588867	0.41762337
2.4309084	69278.211	14.608398	0.41821414
2.4338498	69337.383	14.62793	0.41884378
2.4372518	69397.414	14.647461	0.41934463
2.440846	69458.75	14.666992	0.41997445
2.4436667	69514.945	14.686523	0.4204908
2.4465725	69573.359	14.706055	0.4210977
2.4499297	69634.219	14.725586	0.42159992
2.4535239	69691.203	14.745117	0.42214689
2.456291	69748.273	14.764648	0.42272624
2.4587498	69804.117	14.78418	0.4233281
2.462487	69861.719	14.803711	0.42389259
2.466327	69919.422	14.823242	0.42440152
2.4695544	69977.977	14.842773	0.42499647
2.4728446	70038.461	14.862305	0.42562085
2.4764791	70098.688	14.881836	0.42621052
2.4789958	70162.813	14.901367	0.4267987
2.4834216	70222.156	14.920898	0.42730638
2.4863853	70280.516	14.94043	0.42792639
2.4888217	70342.023	14.959961	0.42850891
2.4923265	70401.398	14.979492	0.42903683
2.4959877	70461.867	14.999023	0.42972603
2.4984331	70519.172	15.018555	0.43020242
2.5036321	70578.711	15.038086	0.43073708
2.5052905	70637.719	15.057617	0.43136811
2.5086119	70689.938	15.077148	0.43201002
2.5111153	70743.344	15.09668	0.43252605
2.514106	70806.023	15.116211	0.43304646
2.5177493	70861.383	15.135742	0.43363053
2.5212586	70918.766	15.155273	0.43421522
2.5254159	70973.148	15.174805	0.43472838
2.5274277	71034.531	15.194336	0.43534771
2.5313392	71087.43	15.213867	0.43597358
2.5338292	71142.25	15.233398	0.43645206
2.5379152	71199.727	15.25293	0.4370887
2.5409684	71254.047	15.272461	0.43744734
2.5432751	71314.797	15.291992	0.43809593
2.547343	71365.359	15.311523	0.43880525
2.5497794	71426.664	15.331055	0.43932956
2.553329	71483.523	15.350586	0.439877
2.5566995	71542.539	15.370117	0.4404211
2.560307	71596.031	15.389648	0.44098991
2.5631056	71655.07	15.40918	0.4416149
2.5662794	71718.086	15.428711	0.44212353
2.5698647	71778.992	15.448242	0.44277787
2.5720193	71835.563	15.467773	0.44328743
2.5761366	71900.742	15.487305	0.44395876
2.5792434	71963.664	15.506836	0.44457439
2.5830343	72028.789	15.526367	0.44508773
2.5869818	72087.625	15.545898	0.4456794
2.5901153	72146.547	15.56543	0.44622147
2.592525	72210.414	15.584961	0.44689485
2.5978713	72274.781	15.604492	0.44757938
2.5991187	72340.313	15.624023	0.44810763
2.6036649	72402.734	15.643555	0.44880366
2.6079252	72456.594	15.663086	0.44932532
2.6102633	72519.695	15.682617	0.44988894
2.6138439	72576.289	15.702148	0.45050859
2.6177332	72635.578	15.72168	0.45107457
2.6202588	72693.523	15.741211	0.45181429
2.6242509	72752.742	15.760742	0.45236546
2.6268392	72808.258	15.780273	0.45298085
2.8969421	-10372.652	15.799805	0.26333007
2.7362018	-6284.812	15.819336	-0.079220653
2.6628971	-2472.0686	15.838867	-0.38533404
2.6995897	-5682.7236	15.858398	-0.93458158
2.675499	-2916.095	15.87793	-1.0581461
2.6598752	-711.27142	15.897461	-1.0556717
2.6810021	-1856.3915	15.916992	-1.0548785
2.6716278	-585.85895	15.936523	-1.0514992
2.6681767	355.74997	15.956055	-1.0558933
2.6767464	190.91927	15.975586	-1.0539303
2.6766346	604.14886	15.995117	-1.0626949
2.6798263	656.06982	16.014648	-1.0674484
2.6829958	435.78409	16.03418	-1.0643301
2.6851149	246.47382	16.053711	-1.0641164
2.6889994	-66.301437	16.073242	-1.0726537
2.6932015	-289.14679	16.092773	-1.0730196
2.6959598	-407.88297	16.112305	-1.0724273
2.6986375	-404.67419	16.131836	-1.0694582
2.7014315	-266.63953	16.151367	-1.0722252
2.7042656	-56.319984	16.170898	-1.0707852
2.7068272	168.18906	16.19043	-1.0765154
2.7109265	360.6373	16.209961	-1.0734254
2.7139485	469.97156	16.229492	-1.0746861
2.7160182	460.63434	16.249023	-1.0746789
2.7185261	351.61862	16.268555	-1.0741395
2.7207792	161.40205	16.288086	-1.0775226
2.7252092	-42.596947	16.307617	-1.073719
2.728209	-233.18781	16.327148	-1.074438
2.7310655	-330.37445	16.34668	-1.0736134
2.7360811	-326.1701	16.366211	-1.0773456
2.7381108	-228.6716	16.385742	-1.0741625
2.7411327	-54.433125	16.405273	-1.0743651
2.7440474	127.50435	16.424805	-1.0748039
2.7476952	296.16907	16.444336	-1.0759002
2.7508557	396.36636	16.463867	-1.0751816
2.7533009	411.56415	16.483398	-1.0772984
2.7566984	318.5618	16.50293	-1.0772681
2.7596354	162.36095	16.522461	-1.0778612
2.7619734	-19.144152	16.541992	-1.079423
2.7651877	-178.659	16.561523	-1.0781711
2.7685716	-270.53918	16.581055	-1.0792216
2.7719512	-270.09659	16.600586	-1.0780909
2.7757869	-181.03607	16.620117	-1.0789115
2.7790279	-45.632713	16.639648	-1.0766555
2.7820005	119.46412	16.65918	-1.0785408
2.7855098	265.02484	16.678711	-1.0762501
2.7877808	354.89594	16.698242	-1.07862
2.7910261	354.95557	16.717773	-1.075992
2.7940214	279.07489	16.737305	-1.0788596
2.7980134	146.87469	16.756836	-1.0769024
2.8015494	-5.0453238	16.776367	-1.0794857
2.8037577	-139.59676	16.795898	-1.0785003
2.8074815	-210.62489	16.81543	-1.0808691
2.8096809	-215.09488	16.834961	-1.0804861
2.8136909	-140.14961	16.854492	-1.0817471
2.8162212	-30.307798	16.874023	-1.0816163
2.8192117	102.14653	16.893555	-1.0801836
2.8228059	227.81279	16.913086	-1.0809311
2.8249428	297.6019	16.932617	-1.0781702
2.8286622	297.01392	16.952148	-1.0807214
2.831903	230.64914	16.97168	-1.0768553
2.8355732	120.98241	16.991211	-1.0804631
2.8384924	-7.1729302	17.010742	-1.0778147
2.8411343	-119.04491	17.030273	-1.0815319
2.844666	-184.38721	17.049805	-1.0801946
2.8481886	-177.76492	17.069336	-1.0818578
2.8504505	-115.30111	17.088867	-1.0812863
2.8542638	-12.029894	17.108398	-1.0810423
2.8567984	106.63213	17.12793	-1.0810027
2.8615997	212.14224	17.147461	-1.0796614
2.8644383	270.80557	17.166992	-1.0813949
2.8675675	267.13031	17.186523	-1.0790291
2.8718412	209.75223	17.206055	-1.0807749
2.874948	108.10571	17.225586	-1.0794128
2.8782516	-0.48906076	17.245117	-1.0805498
2.880764	-96.224014	17.264648	-1.0795486
2.884747	-143.81496	17.28418	-1.0812715
2.8869197	-136.27205	17.303711	-1.0800755
2.8897538	-81.783859	17.323242	-1.081759
2.8932273	9.9741154	17.342773	-1.0808227
2.8959765	110.24915	17.362305	-1.0817349
2.9002056	194.35399	17.381836	-1.0814531
2.9023826	240.32243	17.401367	-1.0806826
2.9065266	231.69536	17.420898	-1.0813731
2.9089003	176.29646	17.44043	-1.0798997
2.9127226	88.035011	17.459961	-1.0808972
2.9158564	-9.1664257	17.479492	-1.0800776
2.9185965	-88.953415	17.499023	-1.080821
2.9215245	-128.87398	17.518555	-1.0797937
2.9252038	-119.1675	17.538086	-1.0809886
2.9277472	-61.747734	17.557617	-1.0798013
2.9310777	19.288738	17.577148	-1.081704
2.9338315	106.64645	17.59668	-1.0801339
2.9367461	185.14937	17.616211	-1.0815345
2.9409752	214.75798	17.635742	-1.0812389
2.9434249	205.2019	17.655273	-1.081378
2.9462636	152.18126	17.674805	-1.0809913
2.9511542	74.091019	17.694336	-1.0805984
2.9536395	-10.960735	17.713867	-1.0809505
2.9571757	-79.059273	17.733398	-1.0810055
2.9595628	-104.01511	17.75293	-1.0812399
2.9628932	-86.490181	17.772461	-1.0801522
2.9660449	-35.979321	17.791992	-1.0812714
2.9700055	35.057076	17.811523	-1.0802534
2.9736891	110.12459	17.831055	-1.0813696
2.9769659	174.28386	17.850586	-1.0802424
2.9796615	202.40701	17.870117	-1.0812017
2.9825583	183.50233	17.889648	-1.0806482
2.9870062	132.29007	17.90918	-1.081566
2.990006	64.267197	17.928711	-1.0805155
2.9939935	-10.424643	17.948242	-1.0814483
2.9955983	-69.081665	17.967773	-1.0809969
2.9985666	-88.920815	17.987305	-1.0814095
3.0029922	-70.574814	18.006836	-1.0814633
3.0045345	-23.457804	18.026367	-1.0805421
3.0090451	44.971703	18.045898	-1.0814424
3.0126617	111.8501	18.06543	-1.0805681
3.0161798	165.44002	18.084961	-1.081306
3.0178382	180.55202	18.104492	-1.0806
3.0216515	160.86142	18.124023	-1.0810721
3.0246198	110.84753	18.143555	-1.0803627
3.0287549	51.002369	18.163086	-1.0812891
3.0305834	-16.079168	18.182617	-1.0804294
3.0341461	-60.410469	18.202148	-1.0816791
3.0384734	-75.712677	18.22168	-1.0807471
3.0406952	-51.307026	18.241211	-1.0815926
3.0448482	-2.4535694	18.260742	-1.0813987
3.0470788	57.298805	18.280273	-1.0813864
3.0509501	115.06583	18.299805	-1.08143
3.0539722	155.15404	18.319336	-1.0809529
3.0582457	159.19911	18.338867	-1.0815192
3.0610576	139.22586	18.358398	-1.0809222
3.0636594	94.657417	18.37793	-1.0811828
3.0643969	38.724506	18.397461	-1.0805399
3.0649378	-16.521894	18.416992	-1.0811844
3.0633955	-50.197823	18.436523	-1.080506
3.0640259	-56.913937	18.456055	-1.0813502
3.0622289	-30.810129	18.475586	-1.0806499
3.0611963	15.394529	18.495117	-1.0816309
3.0622065	68.589111	18.514648	-1.0807015
3.0606866	117.9782	18.53418	-1.0817224
3.0614643	145.57887	18.553711	-1.0808793
3.0614688	146.0428	18.573242	-1.0814899
3.0614197	124.77918	18.592773	-1.0811441
3.0606105	83.264893	18.612305	-1.0813307
3.0608609	28.411625	18.631836	-1.0811108
3.0606732	-16.767181	18.651367	-1.081287
3.0606554	-44.123734	18.670898	-1.0814061
3.0609102	-38.628002	18.69043	-1.0810922
3.0598283	-14.086952	18.709961	-1.081495
3.0600519	29.080431	18.729492	-1.0810035
3.0608609	75.989632	18.749023	-1.0816199
3.0603065	122.25716	18.768555	-1.0810777
3.0606375	139.01956	18.788086	-1.0814689
3.0609236	134.72792	18.807617	-1.0811467
3.06108	106.65925	18.827148	-1.0811051
3.0599222	89.24247	18.836914	-1.0811772