File: data/Q2.dat
MTS793|MPT|ENU|1|2|.|/|:|1|0|0|A

Data Acquisition						Time:	10.009766	s	2/4/2020 10:21:33 AM
Axial Displacement	Axial Force	Time	Axial Extensometer
mm	N	s	mm
-0.0013612211	256.54211	0.018554688	-0.0004166337
-0.00054091215	257.57333	0.038085938	-0.00042827087
-0.00025480986	261.42935	0.057617188	-0.00045354464
-0.00093430281	268.67575	0.077148438	-0.00039697625
-0.00051409006	292.74704	0.096679688	-0.00036448182
0.0031225383	420.77411	0.11621094	9.0212416e-05
0.0065200031	639.50031	0.13574219	0.0008037088
0.011553615	882.45813	0.15527344	0.0016084213
0.01418218	1111.4164	0.17480469	0.0022403786
0.02015233	1328.7427	0.19433594	0.0028626672
0.022722781	1535.4113	0.21386719	0.0035449518
0.026670098	1719.9176	0.23339844	0.0040568844
0.028366596	1899.2842	0.25292969	0.0046523032
0.032363087	2078.1389	0.27246094	0.0051773647
0.035758317	2252.2063	0.29199219	0.0057698754
0.038534403	2422.6047	0.31152344	0.0062925485
0.042394549	2586.0024	0.33105469	0.0067479732
0.044732541	2750.9885	0.35058594	0.0072568939
0.048467517	2911.957	0.37011719	0.0077984231
0.052790344	3072.9839	0.38964844	0.0082595358
0.054457784	3227.7375	0.40917969	0.0087529216
0.057041645	3380.4392	0.42871094	0.0092054801
0.061547756	3536.0361	0.44824219	0.0098132007
0.063626468	3694.3569	0.46777344	0.010242792
0.066532195	3854.3823	0.48730469	0.010734599
0.068946183	4002.5891	0.50683594	0.011149947
0.072922558	4165.7222	0.52636719	0.011719312
0.075562298	4318.7314	0.54589844	0.012105672
0.079543144	4477.1001	0.56542969	0.012704059
0.081344694	4634.501	0.58496094	0.013215249
0.084983557	4792.1724	0.60449219	0.013683111
0.088117272	4951.229	0.62402344	0.014159445
0.091601908	5114.7603	0.64355469	0.014683419
0.094724447	5278.1353	0.66308594	0.015090955
0.09804368	5444.4736	0.68261719	0.015743887
0.10187477	5610.2832	0.70214844	0.016290141
0.10495707	5793.7344	0.72167969	0.016835386
0.10904074	5977.6572	0.74121094	0.017382173
0.11209846	6157.8599	0.76074219	0.017871726
0.11624023	6346.5342	0.78027344	0.018502561
0.12059435	6544.0552	0.79980469	0.019146457
0.12414157	6723.2881	0.81933594	0.019741736
0.12735575	6900.6787	0.83886719	0.02024075
0.13169646	7083.8105	0.85839844	0.020782309
0.13561472	7247.6709	0.87792969	0.021293992
0.13881996	7402.1309	0.89746094	0.021852875
0.1412183	7554.4541	0.91699219	0.022339651
0.14370605	7710.2607	0.93652344	0.022805406
0.14651343	7859.7964	0.95605469	0.023440776
0.15038699	8012.1602	0.97558594	0.023774695
0.15416443	8176.3647	0.99511719	0.02428939
0.15647337	8330.2695	1.0146484	0.024752486
0.16025528	8483.3457	1.0341797	0.025213948
0.16417578	8639.625	1.0537109	0.025694804
0.16577169	8791.5986	1.0732422	0.026262015
0.1694195	8934.0371	1.0927734	0.026646625
0.17342046	9087.8076	1.1123047	0.027210377
0.17643124	9235.1396	1.1318359	0.027585575
0.17770082	9384.9453	1.1513672	0.028079448
0.18173531	9540.7324	1.1708984	0.028595084
0.18613636	9693.2109	1.1904297	0.029121287
0.18899515	9849.1309	1.2099609	0.029672282
0.19213781	10002.895	1.2294922	0.030230459
0.19607618	10162.888	1.2490234	0.030682446
0.19799173	10317.569	1.2685547	0.031239765
0.20163506	10471.743	1.2880859	0.031619187
0.20460784	10631.065	1.3076172	0.032191891
0.20795614	10788.514	1.3271484	0.032641936
0.21256059	10940.188	1.3466797	0.033123046
0.21456778	11100.55	1.3662109	0.033716846
0.2179876	11257.688	1.3857422	0.034246691
0.22186339	11418.878	1.4052734	0.034736954
0.22551343	11579.042	1.4248047	0.035254229
0.22820681	11732.24	1.4443359	0.035686836
0.23213848	11884.439	1.4638672	0.036214363
0.23518056	12046.618	1.4833984	0.036762699
0.23856908	12194.804	1.5029297	0.037309039
0.24104789	12342.456	1.5224609	0.037755318
0.24496168	12496.278	1.5419922	0.038338289
0.24831891	12649.43	1.5615234	0.038786974
0.25103241	12803.402	1.5810547	0.039243162
0.25492385	12955.53	1.6005859	0.039805356
0.25801063	13103.247	1.6201172	0.040300764
0.26237369	13261.325	1.6396484	0.040802233
0.26433393	13416.506	1.6591797	0.041367978
0.26720837	13570.75	1.6787109	0.041784428
0.27286112	13727.049	1.6982422	0.042388555
0.27457774	13880.449	1.7177734	0.042711746
0.27860999	14033.204	1.7373047	0.043317012
0.28293505	14191.076	1.7568359	0.043929886
0.28550997	14347.09	1.7763672	0.044534538
0.28791726	14498.323	1.7958984	0.044842131
0.29285476	14642.943	1.8154297	0.045382842
0.29460043	14789.332	1.8349609	0.045924768
0.29863268	14939.437	1.8544922	0.046433356
0.30170828	15089.838	1.8740234	0.046897564
0.3045246	15233.314	1.8935547	0.047404222
0.30781925	15376.616	1.9130859	0.047837764
0.3113687	15527.949	1.9326172	0.048479326
0.3150031	15672.725	1.9521484	0.048923414
0.31746626	15817.686	1.9716797	0.049382813
0.32081455	15957.855	1.9912109	0.049900349
0.32409802	16105.943	2.0107422	0.050345983
0.32864213	16251.271	2.0302734	0.05080324
0.33080131	16395.516	2.0498047	0.051358696
0.33423901	16538.783	2.0693359	0.051901963
0.33708662	16678.008	2.0888672	0.052358877
0.34026504	16812.607	2.1083984	0.052834038
0.34354851	16949.289	2.1279297	0.05331048
0.34617037	17089.381	2.1474609	0.05380246
0.34990758	17231.93	2.1669922	0.054251943
0.35349056	17375.295	2.1865234	0.054824039
0.35619959	17519.482	2.2060547	0.055242263
0.35929754	17658.689	2.2255859	0.05574831
0.36255419	17804.51	2.2451172	0.056264043
0.36671609	17948.07	2.2646484	0.056735069
0.36908984	18090.285	2.2841797	0.057258725
0.37224367	18234.742	2.3037109	0.057701021
0.3765285	18378.719	2.3232422	0.058286667
0.37930235	18526.436	2.3427734	0.058820032
0.38288757	18671.432	2.3623047	0.059262555
0.38710535	18823.861	2.3818359	0.059801519
0.38840398	18979.459	2.4013672	0.060383014
0.39347336	19132.145	2.4208984	0.060836975
0.39621592	19281.068	2.4404297	0.061406083
0.40067732	19427.057	2.4599609	0.061937779
0.40381998	19572.539	2.4794922	0.06248574
0.40776953	19713.854	2.4990234	0.062984951
0.40988177	19850.486	2.5185547	0.063506983
0.41363016	19989.389	2.5380859	0.064055488
0.41552782	20128.756	2.5576172	0.064514577
0.42078719	20266.078	2.5771484	0.065115049
0.42356774	20398.641	2.5966797	0.065524839
0.42634383	20532.162	2.6162109	0.06601578
0.4295446	20664.637	2.6357422	0.066565156
0.43295547	20795.713	2.6552734	0.067067638
0.43641329	20923.719	2.6748047	0.067469418
0.43922067	21053.514	2.6943359	0.068022907
0.44192299	21181.039	2.7138672	0.068523958
0.4454568	21309.691	2.7333984	0.069038071
0.44933707	21430.996	2.7529297	0.069379225
0.45147166	21560.912	2.7724609	0.069983624
0.45454949	21687.256	2.7919922	0.070373103
0.45837834	21821.256	2.8115234	0.070911929
0.46168193	21942.82	2.8310547	0.07147266
0.46381652	22068.645	2.8505859	0.071965829
0.46737716	22198.852	2.8701172	0.072388925
0.46910271	22325.17	2.8896484	0.072939277
0.47340319	22454.262	2.9091797	0.073471256
0.47742203	22582.963	2.9287109	0.073898159
0.48029646	22716.191	2.9482422	0.07449723
0.48419237	22848.24	2.9677734	0.07497713
0.486774	22979.986	2.9873047	0.075608917
0.48972666	23116.273	3.0068359	0.076106749
0.49415901	23250.563	3.0263672	0.076691389
0.4972592	23387.914	3.0458984	0.077177674
0.50127804	23525.879	3.0654297	0.077699251
0.50403404	23670.135	3.0849609	0.078306362
0.5068928	23791.756	3.1044922	0.078807756
0.51133859	23934.742	3.1240234	0.079391189
0.51464665	24051.094	3.1435547	0.079906181
0.5178988	24193.52	3.1630859	0.080443457
0.52129626	24306.018	3.1826172	0.080993421
0.52448583	24435.641	3.2021484	0.081590086
0.52834153	24550.896	3.2216797	0.082116529
0.53044927	24678.334	3.2412109	0.08259882
0.5341351	24795.186	3.2607422	0.083153777
0.53784102	24918.348	3.2802734	0.08369039
0.54064167	25031.496	3.2998047	0.084325515
0.54426044	25160.293	3.3193359	0.084773391
0.5470857	25271.869	3.3388672	0.085312836
0.55060387	25391.09	3.3583984	0.085746646
0.55252612	25509.063	3.3779297	0.08637742
0.55653155	25629.803	3.3974609	0.086802006
0.56019276	25748.051	3.4169922	0.08734034
0.56292415	25868.869	3.4365234	0.087966412
0.5666703	25981.996	3.4560547	0.088476636
0.56970567	26101.271	3.4755859	0.089033321
0.57331771	26212.145	3.4951172	0.089446574
0.57662129	26327.316	3.5146484	0.090049051
0.57940185	26435.281	3.5341797	0.090595379
0.58218241	26548.324	3.5537109	0.091103435
0.58609396	26659.379	3.5732422	0.091653921
0.58814585	26770.678	3.5927734	0.09224578
0.59183389	26875.34	3.6123047	0.092725083
0.59610754	26988.197	3.6318359	0.09320689
0.59868693	27094.572	3.6513672	0.093796618
0.6022051	27207.479	3.6708984	0.094334431
0.60517341	27324.322	3.6904297	0.094872154
0.60833395	27441.322	3.7099609	0.095479801
0.61180741	27557.162	3.7294922	0.095859498
0.61556697	27671.641	3.7490234	0.0966224
0.61956793	27789.355	3.7685547	0.097234368
0.62187463	27899.707	3.7880859	0.097714484
0.62506646	28014.148	3.8076172	0.09834107
0.62847286	28120.324	3.8271484	0.098875418
0.63285828	28230.678	3.8466797	0.09944015
0.63514709	28344.086	3.8662109	0.099850357
0.63854456	28452.383	3.8857422	0.10060176
0.64119995	28560.436	3.9052734	0.10119942
0.64528584	28667.178	3.9248047	0.10167628
0.64812452	28778.514	3.9443359	0.10230861
0.65104365	28884.494	3.9638672	0.10280735
0.65517873	28988.311	3.9833984	0.10341036
0.65882653	29093.75	4.0029297	0.10399456
0.662072	29201.285	4.0224609	0.10462028
0.6651029	29297.809	4.0419922	0.10516141
0.66652447	29397.072	4.0615234	0.1057095
0.67208558	29498.918	4.0810547	0.10628003
0.67367256	29600.83	4.1005859	0.10679723
0.67689568	29700.631	4.1201172	0.10733459
0.68139732	29801.623	4.1396484	0.1080127
0.68498701	29895.191	4.1591797	0.10853936
0.68854094	29993.848	4.1787109	0.10900521
0.69055259	30092.992	4.1982422	0.10966614
0.69455802	30190.646	4.2177734	0.11024015
0.69702119	30293.219	4.2373047	0.1107334
0.70013702	30393.586	4.2568359	0.11130457
0.70344955	30485.965	4.2763672	0.11179504
0.70717335	30580.719	4.2958984	0.11238832
0.70989579	30673.977	4.3154297	0.11297301
0.71373135	30773.477	4.3349609	0.11360431
0.71573853	30870.984	4.3544922	0.11407356
0.71982443	30965.445	4.3740234	0.11469109
0.72262287	31064.283	4.3935547	0.11532918
0.72643161	31163.771	4.4130859	0.11585484
0.72910935	31264.34	4.4326172	0.11649656
0.73224306	31361.365	4.4521484	0.11703841
0.73601604	31463.098	4.4716797	0.11771786
0.73819309	31563.703	4.4912109	0.11828022
0.74246675	31659.275	4.5107422	0.11879219
0.74651241	31756.174	4.5302734	0.11941234
0.74885935	31853.297	4.5498047	0.11996903
0.75217634	31946.701	4.5693359	0.12055626
0.75553805	32040.176	4.5888672	0.1211578
0.75881034	32136.01	4.6083984	0.12170123
0.76091141	32233.771	4.6279297	0.12234866
0.766249	32332.084	4.6474609	0.12283023
0.76821595	32430.992	4.6669922	0.12350787
0.77127367	32526.543	4.6865234	0.1241833
0.77654421	32622.604	4.7060547	0.12482959
0.77869892	32713.6	4.7255859	0.12536038
0.78135878	32806.266	4.7451172	0.12592004
0.78485012	32894.957	4.7646484	0.12643954
0.78836828	32981.242	4.7841797	0.12698874
0.79092532	33067.742	4.8037109	0.12755626
0.79395622	33155.238	4.8232422	0.12813447
0.79819411	33246.242	4.8427734	0.12880892
0.80174804	33333.781	4.8623047	0.12927784
0.8032769	33423.094	4.8818359	0.12985194
0.80753714	33517.41	4.9013672	0.13057771
0.81082731	33602.879	4.9208984	0.13106047
0.81337988	33696.234	4.9404297	0.13169435
0.81847161	33791.66	4.9599609	0.13218434
0.82149357	33882.703	4.9794922	0.13288228
0.82426518	33977.188	4.9990234	0.13338253
0.827609	34074.875	5.0185547	0.13408093
0.83066672	34165.332	5.0380859	0.13466029
0.83391666	34256.668	5.0576172	0.13523491
0.8374393	34348.273	5.0771484	0.13591062
0.84065795	34443.234	5.0966797	0.13641092
0.84394813	34534.715	5.1162109	0.13704713
0.84815919	34620.777	5.1357422	0.13768893
0.85028261	34707.914	5.1552734	0.13828449
0.8542031	34802.461	5.1748047	0.13894783
0.85724741	34889.301	5.1943359	0.13949113
0.8606717	34976.563	5.2138672	0.14015801
0.86424798	35066.813	5.2333984	0.14072779
0.86708665	35149.656	5.2529297	0.14127874
0.87005496	35234.395	5.2724609	0.14186509
0.87329596	35319.035	5.2919922	0.14242961
0.87658167	35406.945	5.3115234	0.14301793
0.87930858	35493.676	5.3310547	0.14361486
0.88255405	35581.992	5.3505859	0.14420767
0.8847177	35667.133	5.3701172	0.14483431
0.88947415	35751.863	5.3896484	0.14536846
0.89320242	35836.227	5.4091797	0.14597856
0.89542866	35919.668	5.4287109	0.14651763
0.8999303	36009.711	5.4482422	0.14718056
0.90239793	36100.836	5.4677734	0.14779386
0.90682358	36189.066	5.4873047	0.14838657
0.90869665	36277.973	5.5068359	0.14895822
0.91347098	36364.348	5.5263672	0.14957498
0.91647953	36458.883	5.5458984	0.15017316
0.91855377	36548.578	5.5654297	0.15081087
0.92314035	36634.18	5.5849609	0.15149014
0.92639476	36716.137	5.6044922	0.15188329
0.93096346	36806.672	5.6240234	0.15249026
0.93306005	36895.453	5.6435547	0.15312999
0.93670785	36983.656	5.6630859	0.15379691
0.9391129	37068.219	5.6826172	0.15443163
0.94240308	37152.047	5.7021484	0.15495159
0.94594806	37239.387	5.7216797	0.15549919
0.94966292	37321.742	5.7412109	0.15615077
0.95262676	37404.965	5.7607422	0.15675552
0.95622092	37490.504	5.7802734	0.15740298
0.95823705	37573.391	5.7998047	0.15790348
0.96210837	37657.992	5.8193359	0.15862131
0.96519291	37736.574	5.8388672	0.15921752
0.96861273	37817.457	5.8583984	0.15973768
0.97226501	37898.289	5.8779297	0.16030532
0.97511709	37982.867	5.8974609	0.16094333
0.9777233	38059.516	5.9169922	0.16151635
0.98079443	38137.598	5.9365234	0.16200472
0.98392367	38219.809	5.9560547	0.16262773
0.98706633	38295.758	5.9755859	0.16322081
0.99100471	38381.438	5.9951172	0.16377342
0.99415183	38461.398	6.0146484	0.16440837
0.9971112	38545.262	6.0341797	0.16495135
1.0006919	38625.914	6.0537109	0.16552296
1.0033965	38708.742	6.0732422	0.1661626
1.0071248	38790.949	6.0927734	0.16669178
1.0106697	38873.02	6.1123047	0.16720773
1.0127888	38953.25	6.1318359	0.1678554
1.0160118	39045.117	6.1513672	0.16837239
1.0199368	39127.457	6.1708984	0.1690495
1.0237858	39218.5	6.1904297	0.16962937
1.0261863	39306.332	6.2099609	0.17026801
1.0295033	39392.223	6.2294922	0.1708784
1.0344162	39480.316	6.2490234	0.17149308
1.0363386	39563.738	6.2685547	0.17217727
1.0395348	39648.43	6.2880859	0.17262746
1.0429547	39737.113	6.3076172	0.17338708
1.0466158	39818.645	6.3271484	0.17393138
1.0494902	39905.242	6.3466797	0.17458072
1.0527537	39986.602	6.3662109	0.17510852
1.0562181	40068.039	6.3857422	0.17575239
1.0591596	40149.367	6.4052734	0.17638081
1.0626912	40229.082	6.4248047	0.17687516
1.0660887	40307.965	6.4443359	0.17746899
1.0693207	40383.375	6.4638672	0.1781165
1.071985	40463.566	6.4833984	0.17857346
1.0765002	40540.766	6.5029297	0.1791984
1.0788739	40617.871	6.5224609	0.17973284
1.0822803	40692.398	6.5419922	0.18040285
1.0852888	40775.371	6.5615234	0.18092111
1.0883913	40854.164	6.5810547	0.18151686
1.0909929	40926.902	6.6005859	0.18214273
1.0948195	41008.703	6.6201172	0.18262926
1.0981991	41088.672	6.6396484	0.18330604
1.100868	41162.418	6.6591797	0.18387772
1.103434	41240.863	6.6787109	0.18444249
1.1068449	41321.199	6.6982422	0.1849141
1.1103898	41397.684	6.7177734	0.18562627
1.1148021	41474.609	6.7373047	0.18613715
1.1166573	41553.965	6.7568359	0.18668295
1.1199877	41631.328	6.7763672	0.18725498
1.1230409	41716.254	6.7958984	0.18793991
1.1276319	41800.566	6.8154297	0.1885522
1.130332	41885.273	6.8349609	0.18917824
1.1334747	41970.797	6.8544922	0.18973012
1.1364117	42060.051	6.8740234	0.19024858
1.14052	42144.91	6.8935547	0.19087319
1.1438503	42226.223	6.9130859	0.19158258
1.1471763	42310.34	6.9326172	0.19212797
1.1504397	42394.672	6.9521484	0.19271511
1.1534482	42473.117	6.9716797	0.19336572
1.1577353	42557.453	6.9912109	0.19385995
1.159966	42636.953	7.0107422	0.19447729
1.1631534	42720.234	7.0302734	0.19505824
1.1667385	42803.484	7.0498047	0.19576344
1.1699259	42878.574	7.0693359	0.19619159
1.1747092	42960.051	7.0888672	0.19689992
1.176399	43040.254	7.1083984	0.19740805
1.1795282	43115.301	7.1279297	0.19802807
1.1839449	43194.164	7.1474609	0.19861098
1.1870652	43275.691	7.1669922	0.19920991
1.1905923	43354.367	7.1865234	0.19981535
1.1930869	43436.438	7.2060547	0.2003849
1.1956081	43511.148	7.2255859	0.20097832
1.1997924	43589.586	7.2451172	0.20162551
1.2022152	43672.398	7.2646484	0.20217675
1.2062118	43757.434	7.2841797	0.20274727
1.2102618	43838.918	7.3037109	0.20342219
1.2137085	43922.434	7.3232422	0.20393319
1.2159973	44004.531	7.3427734	0.20457856
1.2191623	44083.863	7.3623047	0.20522851
1.2232572	44165.793	7.3818359	0.20579964
1.2273207	44246.074	7.4013672	0.20645441
1.2290329	44326.359	7.4208984	0.20701137
1.2337849	44404.727	7.4404297	0.20760967
1.2362123	44480.672	7.4599609	0.20818114
1.2401551	44559.547	7.4794922	0.20869082
1.2421042	44638.84	7.4990234	0.20933335
1.2463778	44714.395	7.5185547	0.20994401
1.2494534	44786.512	7.5380859	0.21049483
1.2518317	44862.543	7.5576172	0.21107946
1.254885	44932.379	7.5771484	0.21153523
1.2586892	45006.883	7.5966797	0.21224523
1.2619078	45078.66	7.6162109	0.21277003
1.2657657	45150.434	7.6357422	0.21328162
1.2683942	45223.492	7.6552734	0.21384241
1.2710363	45301.07	7.6748047	0.21437283
1.2743711	45370.523	7.6943359	0.21492761
1.2777016	45448.629	7.7138672	0.21549451
1.2806654	45523.527	7.7333984	0.21610789
1.2836204	45596.465	7.7529297	0.21661295
1.2871742	45671.32	7.7724609	0.21711032
1.2911394	45742.039	7.7919922	0.21786496
1.2925878	45818.941	7.8115234	0.21830396
1.2972504	45892.336	7.8310547	0.21888453
1.3000757	45968.496	7.8505859	0.21942922
1.3021097	46041.938	7.8701172	0.21992356
1.3069286	46120.344	7.8896484	0.22056635
1.3096064	46194.465	7.9091797	0.221056
1.3123155	46275.703	7.9287109	0.22163707
1.3158381	46352.945	7.9482422	0.22227773
1.3184488	46441.32	7.9677734	0.22291617
1.3229325	46523.992	7.9873047	0.22347371
1.3252348	46603.445	8.0068359	0.22411004
1.328896	46688.719	8.0263672	0.22475955
1.332499	46774.984	8.0458984	0.22531524
1.3360977	46858.547	8.0654297	0.22581175
1.3400629	46938.586	8.0849609	0.22643341
1.3430804	47027.336	8.1044922	0.22709297
1.3452218	47107.859	8.1240234	0.22765565
1.3498843	47186.57	8.1435547	0.22826108
1.3519943	47266.699	8.1630859	0.22889306
1.3566122	47347.121	8.1826172	0.22949515
1.3608589	47425.41	8.2021484	0.23004287
1.3635232	47500.305	8.2216797	0.2306425
1.3665543	47575.473	8.2412109	0.23113878
1.3692141	47648.055	8.2607422	0.23183811
1.3727858	47729.828	8.2802734	0.23236819
1.3757676	47800.008	8.2998047	0.23294757
1.3800234	47875.727	8.3193359	0.23351187
1.3825581	47950.547	8.3388672	0.23417109
1.3860583	48022.918	8.3583984	0.23480201
1.3884141	48095.883	8.3779297	0.23539186
1.3922721	48172.805	8.3974609	0.23594646
1.3962195	48250.008	8.4169922	0.23647588
1.3991072	48319.016	8.4365234	0.2369861
1.4014989	48393.402	8.4560547	0.23759875
1.4055312	48463.195	8.4755859	0.23815992
1.4088259	48539.957	8.4951172	0.23870175
1.4114678	48606.07	8.5146484	0.2392133
1.4144673	48676.371	8.5341797	0.23982848
1.417829	48746.16	8.5537109	0.24043491
1.4215217	48820.531	8.5732422	0.24095647
1.4236138	48893.137	8.5927734	0.24147744
1.4268146	48964.367	8.6123047	0.24201849
1.4302522	49036.363	8.6318359	0.24257658
1.4343649	49114.645	8.6513672	0.24319939
1.4371455	49196.902	8.6708984	0.24384522
1.4408112	49273.254	8.6904297	0.24434003
1.4442577	49348.859	8.7099609	0.24494381
1.4463633	49430.152	8.7294922	0.24545033
1.4490724	49504.949	8.7490234	0.246113
1.4532611	49587	8.7685547	0.24669015
1.4565601	49659.75	8.7880859	0.24722862
1.4605343	49739.293	8.8076172	0.24780725
1.4640346	49815.297	8.8271484	0.24837089
1.467432	49890.895	8.8466797	0.24903791
1.4695778	49969.758	8.8662109	0.24953045
1.4737844	50051.254	8.8857422	0.25012365
1.4769405	50123.531	8.9052734	0.25065681
1.479578	50200.008	8.9248047	0.25133842
1.4830112	50269.016	8.9443359	0.25194117
1.4862969	50347.422	8.9638672	0.25244302
1.4898688	50415.973	8.9833984	0.25297567
1.4933691	50494.609	9.0029297	0.25359926
1.4965072	50560.168	9.0224609	0.2542662
1.4994174	50640.324	9.0419922	0.25475749
1.5024259	50719.238	9.0615234	0.25534719
1.5057296	50794.852	9.0810547	0.25594175
1.5096813	50869.824	9.1005859	0.25649345
1.5125871	50943.809	9.1201172	0.25709304
1.5164495	51018.914	9.1396484	0.25766289
1.5196502	51085.574	9.1591797	0.25827268
1.5225425	51157.313	9.1787109	0.25884604
1.5248313	51234.668	9.1982422	0.25937733
1.5290916	51305.887	9.2177734	0.25999221
1.5306473	51380.828	9.2373047	0.260539
1.5355378	51455.578	9.2568359	0.26107991
1.5383317	51525.109	9.2763672	0.26168394
1.5437589	51588.348	9.2958984	0.26209211
1.5451803	51653.418	9.3154297	0.26268461
1.5481442	51727.277	9.3349609	0.26330438
1.5518457	51799.227	9.3544922	0.26385579
1.554595	51865.375	9.3740234	0.26441595
1.5578359	51930.996	9.3935547	0.26491323
1.5594139	52000.672	9.4130859	0.26556063
1.5636518	52071.246	9.4326172	0.26600975
1.5669689	52140.773	9.4521484	0.2666114
1.5704066	52204.836	9.4716797	0.26717147
1.5724585	52282.934	9.4912109	0.26774395
1.5762359	52352.508	9.5107422	0.26831472
1.580286	52429.281	9.5302734	0.26881227
1.5832498	52501.297	9.5498047	0.26940179
1.585713	52588.234	9.5693359	0.27001968
1.589182	52667.668	9.5888672	0.2705943
1.5930444	52747.598	9.6083984	0.27113801
1.5962586	52825.109	9.6279297	0.27191553
1.6004875	52905.488	9.6474609	0.27239907
1.6029418	52987.266	9.6669922	0.27299556
1.6071393	53066.465	9.6865234	0.27365392
1.610738	53143.242	9.7060547	0.27422401
1.6135678	53222.742	9.7255859	0.27476043
1.6172111	53295.84	9.7451172	0.27543169
1.6205639	53369.879	9.7646484	0.27600545
1.6238809	53441.961	9.7841797	0.27655298
1.6276807	53515.953	9.8037109	0.27719265
1.6298532	53582.113	9.8232422	0.27765211
1.6331122	53647.422	9.8427734	0.27824932
1.6365319	53713.48	9.8623047	0.27873001
1.6391516	53783.305	9.8818359	0.27936164
1.6427503	53847.602	9.9013672	0.27985898
1.6447709	53915.344	9.9208984	0.28040439
1.6496971	53984.215	9.9404297	0.28104764
1.6517043	54048.871	9.9599609	0.28144678
1.6558573	54117.41	9.9794922	0.28202048
1.658839	54184.906	9.9990234	0.28254646
1.6618476	54256.055	10.018555	0.28317043
1.6651108	54324.727	10.038086	0.28374627
1.6691387	54397.918	10.057617	0.28422707
1.672098	54470.543	10.077148	0.28484288
1.675272	54547.145	10.09668	0.28541109
1.6789913	54619.906	10.116211	0.28598213
1.6815708	54697.094	10.135742	0.28651538
1.6856521	54768.375	10.155273	0.28711915
1.6888216	54842.402	10.174805	0.2877368
1.691781	54917.434	10.194336	0.28832132
1.6952366	54984.559	10.213867	0.28878143
1.6979009	55057.754	10.233398	0.28946888
1.7011821	55127.117	10.25293	0.29002997
1.7061129	55203.332	10.272461	0.2905423
1.7076597	55274.18	10.291992	0.29111972
1.7112718	55343.891	10.311523	0.29171088
1.7137885	55412.355	10.331055	0.29226771
1.7177582	55479.355	10.350586	0.29277098
1.7202526	55549.98	10.370117	0.29347974
1.723753	55619.895	10.389648	0.29393363
1.726614	55689.676	10.40918	0.29450202
1.7303735	55759.75	10.428711	0.29510251
1.7334223	55831.746	10.448242	0.2956669
1.7367035	55899.27	10.467773	0.29621565
1.7405391	55969.629	10.487305	0.29673675
1.743932	56040.703	10.506836	0.29730007
1.747097	56112.723	10.526367	0.29787737
1.7498956	56175.938	10.545898	0.29847345
1.7539546	56244.211	10.56543	0.29903269
1.7563329	56316.316	10.584961	0.2996116
1.7599895	56383.719	10.604492	0.30011126
1.7628998	56455.254	10.624023	0.30071208
1.7663195	56519.07	10.643555	0.30125841
1.7683625	56586.082	10.663086	0.30181417
1.7720908	56655.82	10.682617	0.30234554
1.7757251	56723.977	10.702148	0.30287394
1.7787695	56794.777	10.72168	0.30342954
1.7830878	56865.016	10.741211	0.30406293
1.7853453	56933.09	10.760742	0.30455112
1.788707	56999.98	10.780273	0.30508217
1.7918676	57068.293	10.799805	0.30570966
1.7963245	57139.949	10.819336	0.30625123
1.7986715	57212.539	10.838867	0.30688903
1.8017739	57278.602	10.858398	0.30744675
1.8045857	57352.297	10.87793	0.30803856
1.8087834	57425.352	10.897461	0.30851197
1.8112376	57495.945	10.916992	0.30905706
1.8144965	57563.332	10.936523	0.3096585
1.8183186	57635.012	10.956055	0.31030387
1.8213584	57708.445	10.975586	0.31082505
1.8246756	57775.961	10.995117	0.31141779
1.8284619	57856.566	11.014648	0.3119604
1.8318594	57930.547	11.03418	0.31254226
1.8351227	57999.027	11.053711	0.31306341
1.8382609	58078.605	11.073242	0.31367055
1.8417611	58144.43	11.092773	0.31424767
1.8435448	58217.793	11.112305	0.31490591
1.8482254	58287.82	11.131836	0.31540561
1.8516362	58354.684	11.151367	0.31606138
1.8550068	58424.887	11.170898	0.31659609
1.8583328	58495.566	11.19043	0.31719631
1.8615603	58563.098	11.209961	0.31770918
1.8647879	58629.516	11.229492	0.31822139
1.8684044	58698.184	11.249023	0.31887203
1.870662	58765.32	11.268555	0.31950474
1.8752307	58830.871	11.288086	0.3200548
1.8778771	58897.258	11.307617	0.32061347
1.8806398	58963.281	11.327148	0.32118288
1.8836484	59027.07	11.34668	0.3216446
1.8872112	59094.301	11.366211	0.3222076
1.8907428	59154.379	11.385742	0.32276735
1.8939569	59218.77	11.405273	0.32333833
1.8975109	59286.824	11.424805	0.32386911
1.899992	59351.586	11.444336	0.32438517
1.9029067	59418.859	11.463867	0.3249284
1.9064202	59487.559	11.483398	0.32553825
1.9091517	59555.578	11.50293	0.32608053
1.9128933	59625.16	11.522461	0.32671845
1.9172742	59687.109	11.541992	0.32721484
1.9200057	59756.781	11.561523	0.3277944
1.9227326	59822.641	11.581055	0.32830596
1.9262731	59890.602	11.600586	0.32893336
1.929161	59949.043	11.620117	0.32940137
1.9324198	60013.68	11.639648	0.33001384
1.9354596	60086.281	11.65918	0.33062124
1.9390001	60149.984	11.678711	0.33104941
1.9421294	60219.094	11.698242	0.3316285
1.9453973	60283.336	11.717773	0.33221614
1.9488797	60349.84	11.737305	0.3327361
1.9520044	60418.113	11.756836	0.33336523
1.9547492	60484.98	11.776367	0.33389089
1.9597828	60554.164	11.795898	0.33451274
1.9614637	60624.891	11.81543	0.3350189
1.964736	60695.531	11.834961	0.33560666
1.9676194	60761.203	11.854492	0.33622125
1.9709229	60817.273	11.874023	0.33674642
1.9745708	60865.02	11.893555	0.33717915
1.9772172	60928.48	11.913086	0.33773997
1.9797339	61013.68	11.932617	0.33833614
1.9835875	61087.063	11.952148	0.33900347
1.9875214	61175.82	11.97168	0.3396405
1.9925058	61253.746	11.991211	0.34014365
1.9945934	61328.148	12.010742	0.3408283
1.9978523	61404.316	12.030273	0.34138104
2.0006106	61482.504	12.049805	0.34199065
2.0057292	61552.668	12.069336	0.34261435
2.0079017	61624.266	12.088867	0.34318954
2.0123496	61694.273	12.108398	0.34384036
2.0144553	61764.5	12.12793	0.34428293
2.018863	61830.883	12.147461	0.34496719
2.0218043	61892.66	12.166992	0.34550205
2.025023	61949.117	12.186523	0.34610796
2.0281031	62009.039	12.206055	0.3465721
2.0310223	62064.91	12.225586	0.34719831
2.0346701	62125.754	12.245117	0.34767079
2.0367444	62179.629	12.264648	0.34818774
2.0399451	62237.711	12.28418	0.3486551
2.043946	62295.613	12.303711	0.34920111
2.0463064	62353.965	12.323242	0.34972522
2.0495563	62412.734	12.342773	0.35031542
2.0524487	62470.695	12.362305	0.35082632
2.056396	62530.91	12.381836	0.35132095
2.0593419	62596.652	12.401367	0.35196474
2.0620778	62660.625	12.420898	0.35243303
2.0657749	62729.637	12.44043	0.35301229
2.0688682	62795.816	12.459961	0.35368955
2.0718231	62858.273	12.479492	0.35416076
2.0748005	62925.051	12.499023	0.35472846
2.0779967	62996.477	12.518555	0.35533905
2.0817966	63066.441	12.538086	0.35584348
2.0857797	63133.922	12.557617	0.35642317
2.0882874	63205.84	12.577148	0.3569667
2.092731	63273.551	12.59668	0.357568
2.0947874	63342.059	12.616211	0.35825157
2.0984173	63406.816	12.635742	0.35880533
2.1014035	63475.926	12.655273	0.3594166
2.1051719	63541.363	12.674805	0.35991442
2.1083102	63602.125	12.694336	0.36040354
2.1109746	63667.223	12.713867	0.36098772
2.1138086	63732.465	12.733398	0.36158228
2.1189675	63799.332	12.75293	0.36212772
2.1213188	63871.934	12.772461	0.36284623
2.1242962	63938.543	12.791992	0.36333096
2.128078	64004.875	12.811523	0.36397514
2.1316364	64073.898	12.831055	0.36444271
2.1344528	64133.719	12.850586	0.36503407
2.1376982	64198.227	12.870117	0.36563781
2.141185	64261.461	12.889648	0.36611396
2.1439209	64328.422	12.90918	0.36677045
2.146688	64387.43	12.928711	0.3672761
2.1503851	64451.59	12.948242	0.36791241
2.1538317	64517.859	12.967773	0.3684811
2.1576853	64584.879	12.987305	0.36900321
2.1608324	64646.219	13.006836	0.36962309
2.1639705	64713.426	13.026367	0.37019217
2.1672339	64775.809	13.045898	0.37071511
2.1699653	64839.363	13.06543	0.37129241
2.1741226	64905.426	13.084961	0.37186021
2.1777346	64965.996	13.104492	0.37242839
2.1799297	65030.41	13.124023	0.37299043
2.1841049	65090.742	13.143555	0.37351924
2.1862731	65153.711	13.163086	0.37410009
2.1892099	65211.441	13.182617	0.374643
2.1933987	65276.125	13.202148	0.37524247
2.1962106	65343.605	13.22168	0.37582883
2.2008016	65409.539	13.241211	0.37637952
2.2030501	65478.578	13.260742	0.37699392
2.2064879	65547.164	13.280273	0.37755916
2.2093668	65607.047	13.299805	0.37811685
2.2130146	65663.313	13.319336	0.37871659
2.2155538	65724.531	13.338867	0.37921035
2.2172883	65781.336	13.358398	0.37981421
2.2227869	65843.648	13.37793	0.38032186
2.22563	65898.188	13.397461	0.38084349
2.2278428	65962.547	13.416992	0.38140398
2.2319064	66019.563	13.436523	0.38193628
2.2349463	66081.031	13.456055	0.38252041
2.2380934	66133.969	13.475586	0.3830471
2.2411153	66200.008	13.495117	0.38358575
2.2439003	66258.289	13.514648	0.38416561
2.2477806	66322.891	13.53418	0.38475072
2.2509456	66378.961	13.553711	0.38523844
2.2543206	66442.914	13.573242	0.3857438
2.2570119	66510.211	13.592773	0.38643101
2.2609949	66574.031	13.612305	0.38702181
2.263458	66646.711	13.631836	0.38754714
2.2671595	66718.781	13.651367	0.38821593
2.2698686	66795.242	13.670898	0.38879627
2.2739947	66864.438	13.69043	0.38936153
2.2777228	66934.414	13.709961	0.38994727
2.2818446	67002.438	13.729492	0.39050382
2.2845759	67076.258	13.749023	0.39117706
2.2886844	67138.695	13.768555	0.39174986
2.2910535	67199.828	13.788086	0.39239687
2.2939458	67266.156	13.807617	0.39290264
2.2978797	67330.609	13.827148	0.39359796
2.300951	67385.266	13.84668	0.39411005
2.3042009	67448.328	13.866211	0.39477903
2.307795	67513.805	13.885742	0.39527103
2.3118405	67571.297	13.905273	0.39588436
2.3136511	67627.242	13.924805	0.39641187
2.3184881	67687.43	13.944336	0.39700621
2.3198068	67739.016	13.963867	0.3974022
2.3245006	67797.289	13.983398	0.39812744
2.3272455	67852.055	14.00293	0.39858907
2.3291678	67905.453	14.022461	0.39919886
2.3326232	67964.531	14.041992	0.39976838
2.3353503	68022.898	14.061523	0.40022224
2.3384838	68076.93	14.081055	0.40084231
2.3421764	68131.734	14.100586	0.4013539
2.3449347	68187.766	14.120117	0.40190613
2.347894	68245.328	14.139648	0.40238976
2.3512735	68302.172	14.15918	0.40299645
2.3544521	68366.531	14.178711	0.40347672
2.3581445	68429.227	14.198242	0.40413371
2.3611486	68493.789	14.217773	0.40468198
2.3646533	68551.398	14.237305	0.4052425
2.3677959	68616.766	14.256836	0.40582815
2.370563	68679.859	14.276367	0.40641478
2.3750782	68743.891	14.295898	0.40702397
2.3771346	68810.742	14.31543	0.40766805
2.3802326	68879.094	14.334961	0.40815809
2.3835137	68956.219	14.354492	0.40878844
2.3882656	69029.883	14.374023	0.40939581
2.3913682	69099.602	14.393555	0.40999115
2.3952036	69174.68	14.413086	0.4107016
2.398248	69241.867	14.432617	0.41128704
2.4028435	69302.938	14.452148	0.41190305
2.4057851	69370.102	14.47168	0.41252038
2.4098709	69437.477	14.491211	0.41312465
2.4115829	69501.266	14.510742	0.41368556
2.4157584	69562.031	14.530273	0.41428024
2.4193883	69621.922	14.549805	0.41496438
2.4229646	69670.68	14.569336	0.41540581
2.4245203	69726.32	14.588867	0.41590932
2.4288788	69778.813	14.608398	0.41654956
2.4312749	69825.18	14.62793	0.4170894
2.4342299	69875.461	14.647461	0.41764784
2.4372249	69930.336	14.666992	0.41819429
2.4415388	69981.25	14.686523	0.41875097
2.4437473	70032.508	14.706055	0.41936064
2.4469211	70084.703	14.725586	0.41981539
2.4501443	70143.391	14.745117	0.42033935
2.4534078	70198.133	14.764648	0.42090073
2.455683	70250.344	14.78418	0.42147011
2.4582491	70312.789	14.803711	0.42206994
2.4632468	70371.289	14.823242	0.42265064
2.4653659	70424.578	14.842773	0.42316046
2.4690673	70482.961	14.862305	0.42370322
2.4713562	70539.523	14.881836	0.42421502
2.4752722	70598.18	14.901367	0.42486882
2.479197	70660.734	14.920898	0.42537662
2.4818568	70724.289	14.94043	0.42608824
2.4852767	70782.578	14.959961	0.42659858
2.4881825	70850.438	14.979492	0.42727041
2.4911776	70914.609	14.999023	0.42777202
2.4948478	70975.07	15.018555	0.42841715
2.4985538	71038.102	15.038086	0.42896965
2.5014281	71101.211	15.057617	0.42953572
2.5047407	71163.289	15.077148	0.43016639
2.5079012	71226.063	15.09668	0.4307977
2.5117769	71287.867	15.116211	0.43137011
2.5146871	71354.445	15.135742	0.43190074
2.5176957	71413.492	15.155273	0.43253899
2.5217323	71474.445	15.174805	0.43310869
2.5249197	71532.5	15.194336	0.4337557
2.5287554	71600.688	15.213867	0.43432716
2.5312946	71667.805	15.233398	0.43499106
2.5355725	71729.969	15.25293	0.43562761
2.5387466	71792.617	15.272461	0.43623194
2.54125	71859.328	15.291992	0.43676385
2.5458276	71916.586	15.311523	0.43735543
2.548568	71976.922	15.331055	0.43795162
2.552846	72038.727	15.350586	0.4386065
2.5555372	72093.258	15.370117	0.43912873
2.5593772	72148.477	15.389648	0.43973392
2.5621624	72203.391	15.40918	0.44030651
2.5641694	72259.695	15.428711	0.44082171
2.5685191	72314.156	15.448242	0.44147962
2.572547	72362.313	15.467773	0.44211414
2.5750279	72408.469	15.487305	0.44267246
2.5780544	72457.688	15.506836	0.44318223
2.5811167	72506.734	15.526367	0.44375908
2.5839062	72556.828	15.545898	0.4442583
2.5875359	72606.836	15.56543	0.44481274
2.5901377	72658.5	15.584961	0.44537973
2.5935934	72707.328	15.604492	0.44594413
2.596879	72758.469	15.624023	0.44650781
2.5996149	72808.484	15.643555	0.44707727
2.6018052	72864.766	15.663086	0.44762272
2.6053324	72915.555	15.682617	0.44815037
2.6082828	72967.297	15.702148	0.44872513
2.6114569	73018.969	15.72168	0.44913086
2.6149704	73074.203	15.741211	0.44971305
2.6172235	73129.289	15.760742	0.4503684
2.6217699	73189.492	15.780273	0.45092773
2.6247561	73257.141	15.799805	0.45154235
2.6284442	73328.813	15.819336	0.45224565
2.6321187	73400.938	15.838867	0.45279005
2.6358426	73467.805	15.858398	0.45342141
2.6385114	73534.648	15.87793	0.45406118
2.853848	-13324.631	15.897461	0.62386334
2.7396665	-5134.2559	15.916992	-0.11179551
2.6692808	-1684.0585	15.936523	-0.24203154
2.7007654	-3803.7053	15.956055	-0.76174122
2.6905999	-2403.0508	15.975586	-0.77686155
2.6719093	-913.47473	15.995117	-0.77618885
2.6909397	-1948.8118	16.014648	-0.78561568
2.687314	-1315.3876	16.03418	-0.79943073
2.6823833	-523.69281	16.053711	-0.79833215
2.6896968	-573.79926	16.073242	-0.80511123
2.6886463	-81.192123	16.092773	-0.81915343
2.6896298	290.44574	16.112305	-0.82425904
2.6926563	432.63333	16.131836	-0.82610565
2.6958213	585.70947	16.151367	-0.84280366
2.6988029	450.9357	16.170898	-0.84857494
2.7018161	295.27908	16.19043	-0.85273129
2.7049809	43.668083	16.209961	-0.8558771
2.7082756	-203.01295	16.229492	-0.85933685
2.7119412	-379.27365	16.249023	-0.86105466
2.716738	-457.71127	16.268555	-0.86281639
2.7189641	-405.78647	16.288086	-0.86766732
2.7223036	-242.30605	16.307617	-0.86640531
2.7262421	-36.833225	16.327148	-0.8736766
2.7287052	179.17552	16.34668	-0.87225944
2.7321293	357.56711	16.366211	-0.87875468
2.7356653	436.8555	16.385742	-0.87896466
2.7378917	401.69501	16.405273	-0.88638765
2.7415798	252.51495	16.424805	-0.88635451
2.7438819	62.344711	16.444336	-0.89361453
2.7469084	-149.95364	16.463867	-0.89391285
2.7492061	-311.48062	16.483398	-0.89905673
2.7531176	-387.13193	16.50293	-0.89981157
2.756247	-344.26538	16.522461	-0.90133578
2.7609096	-216.30525	16.541992	-0.90365428
2.7618885	-48.276268	16.561523	-0.90299577
2.7648971	134.20255	16.581055	-0.90677953
2.7680173	278.09268	16.600586	-0.90256381
2.7706637	350.78754	16.620117	-0.90696877
2.7729795	317.21918	16.639648	-0.90269893
2.7734756	211.95761	16.65918	-0.90591991
2.7724788	51.018551	16.678711	-0.90330142
2.7712181	-117.29752	16.698242	-0.90730256
2.7710974	-250.17769	16.717773	-0.90428883
2.7715178	-314.47888	16.737305	-0.91032022
2.7708113	-285.2605	16.756836	-0.90889484
2.7698324	-186.94856	16.776367	-0.91464651
2.7705028	-44.50779	16.795898	-0.91466558
2.7696981	108.69408	16.81543	-0.92045212
2.7696357	243.94725	16.834961	-0.91960323
2.7687237	307.44077	16.854492	-0.91991848
2.7683125	285.16959	16.874023	-0.91992378
2.7686656	187.65881	16.893555	-0.91996455
2.7689383	55.256882	16.913086	-0.91967642
2.7691975	-91.247139	16.932617	-0.91966206
2.7682006	-206.90926	16.952148	-0.91981483
2.7680576	-264.45172	16.97168	-0.91989285
2.7678876	-243.79825	16.991211	-0.91985995
2.7673869	-162.17551	17.010742	-0.91978967
2.7673693	-38.237778	17.030273	-0.9197877
2.7674451	96.197708	17.049805	-0.91987085
2.7674227	200.81679	17.069336	-0.92012018
2.7663856	250.02473	17.088867	-0.91993755