File: data/Q3.dat
MTS793|MPT|ENU|1|2|.|/|:|1|0|0|A

Data Acquisition						Time:	10.009766	s	2/4/2020 10:25:12 AM
Axial Displacement	Axial Force	Time	Axial Extensometer
mm	N	s	mm
-0.00062808394	305.81723	0.018554688	-1.8230639e-05
-0.0002771616	304.32733	0.038085938	6.0837192e-05
-0.00042468309	304.04514	0.057617188	2.4790643e-05
-0.00076442957	313.38425	0.077148438	2.9505463e-05
0.00029280782	320.69742	0.096679688	0.00010118238
0.00076889992	383.6362	0.11621094	0.00025427871
0.0033169985	552.34906	0.13574219	0.00084093626
0.0075146556	783.35565	0.15527344	0.0014600998
0.012436509	1030.8494	0.17480469	0.0022782916
0.016893446	1268.4081	0.19433594	0.0030600058
0.021399558	1501.8861	0.21386719	0.0037925174
0.024792552	1713.658	0.23339844	0.0043364484
0.030324608	1912.8035	0.25292969	0.0050628297
0.032372028	2096.0339	0.27246094	0.0055898391
0.035912544	2281.8845	0.29199219	0.0062165959
0.038827211	2459.707	0.31152344	0.0067339912
0.043243915	2624.3928	0.33105469	0.0073083001
0.044886768	2792.6636	0.35058594	0.0078779021
0.048141181	2949.6987	0.37011719	0.0082988506
0.051299483	3107.5918	0.38964844	0.0087859873
0.053753704	3264.2065	0.40917969	0.0092313411
0.057274103	3411.5747	0.42871094	0.0098741204
0.060251355	3565.5925	0.44824219	0.010286829
0.063356012	3722.3264	0.46777344	0.010812331
0.067057461	3882.3013	0.48730469	0.011283771
0.068718195	4040.2888	0.50683594	0.011811991
0.073231012	4201.9219	0.52636719	0.012281227
0.076018274	4363.5068	0.54589844	0.012776293
0.078394264	4523.874	0.56542969	0.013335333
0.081393868	4678.0054	0.58496094	0.013831483
0.084393471	4837.8604	0.60449219	0.014374787
0.087676942	4984.377	0.62402344	0.014772651
0.091914833	5142.8789	0.64355469	0.015340727
0.094138831	5300.4219	0.66308594	0.015830142
0.097154081	5465.0688	0.68261719	0.016310129
0.10151491	5639.5532	0.70214844	0.016917037
0.10497048	5817.1699	0.72167969	0.017408608
0.10771528	5996.2217	0.74121094	0.018080298
0.11138543	6195.5283	0.76074219	0.018816859
0.1153551	6396.873	0.78027344	0.019327912
0.11834577	6586.2788	0.79980469	0.019947834
0.12308657	6771.9492	0.81933594	0.020615082
0.12673885	6946.2026	0.83886719	0.021084612
0.1301989	7115.4648	0.85839844	0.021649307
0.13414398	7280.2969	0.87792969	0.022275729
0.13573989	7439.4414	0.89746094	0.02279184
0.14000908	7596.7729	0.91699219	0.023301622
0.1440078	7752.0127	0.93652344	0.023796473
0.14652461	7899.7002	0.95605469	0.024228889
0.14927834	8048.4429	0.97558594	0.024652386
0.1519762	8198.5156	0.99511719	0.025177175
0.15606433	8343.5322	1.0146484	0.025617244
0.15972555	8490.0713	1.0341797	0.026280513
0.16220659	8635.5605	1.0537109	0.02672893
0.16503632	8783.7939	1.0732422	0.027157139
0.16811192	8928.9385	1.0927734	0.027600719
0.1711987	9076.1484	1.1123047	0.028156843
0.17389655	9227.7021	1.1318359	0.028526947
0.17709285	9376.8379	1.1513672	0.029113429
0.18102005	9530.4795	1.1708984	0.029642396
0.18401518	9686.8418	1.1904297	0.030098805
0.18643141	9838.2471	1.2099609	0.030607268
0.19104257	9999.2334	1.2294922	0.031135606
0.19396842	10155.376	1.2490234	0.031578209
0.19696802	10311.376	1.2685547	0.03216137
0.19936189	10470.651	1.2880859	0.032671802
0.20354167	10628.916	1.3076172	0.033239365
0.20785108	10797.791	1.3271484	0.033764478
0.21099597	10969.496	1.3466797	0.034363266
0.21473765	11137.327	1.3662109	0.034864016
0.21796972	11304.637	1.3857422	0.035460345
0.22143424	11470.123	1.4052734	0.036072735
0.22558719	11632.684	1.4248047	0.036683567
0.2288796	11795.106	1.4443359	0.037067752
0.23216531	11953.927	1.4638672	0.037662324
0.23657531	12110.673	1.4833984	0.038128193
0.23849979	12261.677	1.5029297	0.038669515
0.24115518	12413.462	1.5224609	0.039159849
0.24546459	12555.518	1.5419922	0.039660104
0.24792328	12702.5	1.5615234	0.040297173
0.25185272	12842.866	1.5810547	0.040667601
0.25529489	12986.515	1.6005859	0.041180808
0.25728419	13127.343	1.6201172	0.041621558
0.26092306	13268.505	1.6396484	0.042098653
0.26490837	13411.395	1.6591797	0.042627975
0.26759505	13554.78	1.6787109	0.043096986
0.26999786	13696.838	1.6982422	0.043638378
0.27406588	13842.628	1.7177734	0.044092536
0.27834177	13997.925	1.7373047	0.044672374
0.28078705	14149.96	1.7568359	0.045161687
0.28366148	14303.753	1.7763672	0.045662541
0.28698295	14451.246	1.7958984	0.046207756
0.29074475	14603.516	1.8154297	0.046676099
0.29506758	14750.321	1.8349609	0.047261134
0.29667467	14890.967	1.8544922	0.047798321
0.29980391	15033.848	1.8740234	0.0481865
0.30356124	15173.418	1.8935547	0.048720621
0.30647591	15314.923	1.9130859	0.049258135
0.30914694	15456.448	1.9326172	0.049680676
0.31367093	15601.933	1.9521484	0.050191782
0.31595975	15751.992	1.9716797	0.050710559
0.3198579	15904.139	1.9912109	0.05128457
0.3229402	16051.226	2.0107422	0.051751371
0.32699928	16201.252	2.0302734	0.05231325
0.32952726	16353.251	2.0498047	0.052973833
0.33346117	16506.48	2.0693359	0.053362228
0.33699498	16662.979	2.0888672	0.05397727
0.34060702	16814.182	2.1083984	0.054474264
0.34467056	16965.912	2.1279297	0.055036325
0.34654811	17105.973	2.1474609	0.055606917
0.35043508	17248.512	2.1669922	0.056018468
0.35409182	17376.1	2.1865234	0.056504164
0.35716742	17514.92	2.2060547	0.057045627
0.35976022	17648.174	2.2255859	0.057476826
0.3626816	17784.418	2.2451172	0.058020703
0.36599636	17922.178	2.2646484	0.058491539
0.36926642	18061.17	2.2841797	0.059009135
0.3725253	18197.795	2.3037109	0.059477068
0.37598982	18338.367	2.3232422	0.060005989
0.37906542	18470.842	2.3427734	0.060559362
0.38155317	18602.66	2.3623047	0.061084509
0.38562343	18737.08	2.3818359	0.061584659
0.38844198	18872.643	2.4013672	0.061982188
0.39192885	19008.764	2.4208984	0.06247377
0.39497539	19148.293	2.4404297	0.062985405
0.39800182	19286.84	2.4599609	0.063547149
0.40204078	19425.783	2.4794922	0.064087905
0.40499792	19562.969	2.4990234	0.06460277
0.40787235	19697.123	2.5185547	0.065086804
0.4109703	19833.986	2.5380859	0.065590777
0.41505173	19967.965	2.5576172	0.066129446
0.41809157	20107.025	2.5771484	0.066662885
0.42204335	20246.107	2.5966797	0.067192703
0.42561516	20385.555	2.6162109	0.067656226
0.42822137	20517.439	2.6357422	0.068102695
0.43144897	20649.475	2.6552734	0.068690814
0.43419823	20782.211	2.6748047	0.069251344
0.43762699	20913.611	2.6943359	0.069744818
0.43985769	21049.652	2.7138672	0.070247874
0.44390336	21186.715	2.7333984	0.070875801
0.44720694	21316.203	2.7529297	0.071390063
0.45141354	21452.516	2.7724609	0.07186237
0.4543148	21587.621	2.7919922	0.072365358
0.45797601	21723.26	2.8115234	0.072943613
0.46207979	21856.748	2.8310547	0.073510684
0.46472177	21994.514	2.8505859	0.073981158
0.4682444	22120.775	2.8701172	0.074558482
0.47064498	22244.773	2.8896484	0.075166978
0.47399327	22374.004	2.9091797	0.075687818
0.47709569	22497.715	2.9287109	0.076202415
0.48118159	22621.439	2.9482422	0.076675124
0.48370287	22746.443	2.9677734	0.077118821
0.48709586	22868.383	2.9873047	0.077703573
0.48992112	22993.199	3.0068359	0.078216977
0.49383268	23113.893	3.0263672	0.078821808
0.4969351	23237.266	3.0458984	0.079306453
0.50005984	23363.041	3.0654297	0.079798535
0.50258565	23481.512	3.0849609	0.080380462
0.50610375	23601.912	3.1044922	0.080827892
0.50908554	23727.018	3.1240234	0.081457928
0.5131669	23850.506	3.1435547	0.081969462
0.51598322	23969.66	3.1630859	0.082495965
0.51938963	24094.91	3.1826172	0.083060421
0.52272451	24215.664	3.2021484	0.083672129
0.52549171	24335.582	3.2216797	0.084102005
0.52934515	24449.277	3.2412109	0.084720634
0.53343105	24570.873	3.2607422	0.085278578
0.53692687	24686.506	3.2802734	0.085881956
0.53872836	24808.373	3.2998047	0.086329482
0.54197383	24923.543	3.3193359	0.086770765
0.54481697	25038.783	3.3388672	0.087348454
0.54880452	25152.07	3.3583984	0.088027894
0.55217516	25269.359	3.3779297	0.088441625
0.55583644	25386.371	3.3974609	0.089007311
0.5576067	25499.191	3.4169922	0.089582533
0.56172383	25618.764	3.4365234	0.090105489
0.5662657	25739.406	3.4560547	0.090630911
0.56821477	25855.432	3.4755859	0.091299348
0.57275224	25974.385	3.4951172	0.091941923
0.5755372	26090.926	3.5146484	0.092454486
0.57870221	26207.996	3.5341797	0.093106151
0.5821712	26321.297	3.5537109	0.093588844
0.58487582	26434.539	3.5732422	0.094202444
0.5887605	26547.861	3.5927734	0.094721295
0.5914427	26660.127	3.6123047	0.0953082
0.59417415	26768.762	3.6318359	0.095915876
0.59824216	26874.355	3.6513672	0.096477151
0.60133564	26984.09	3.6708984	0.097040713
0.60476887	27096.277	3.6904297	0.097503006
0.60856414	27202.992	3.7099609	0.098155662
0.61213148	27309.791	3.7294922	0.098648794
0.61510432	27418.957	3.7490234	0.099210799
0.61833632	27521.908	3.7685547	0.099831626
0.62110794	27626.443	3.7880859	0.10043063
0.62422383	27730.598	3.8076172	0.10104981
0.62730837	27837.783	3.8271484	0.10162671
0.63096058	27945.33	3.8466797	0.10217114
0.63392448	28045.707	3.8662109	0.10267431
0.63714314	28150.275	3.8857422	0.10329353
0.64004433	28259.6	3.9052734	0.1038525
0.64396036	28366.256	3.9248047	0.10449918
0.64747405	28468.438	3.9443359	0.10509124
0.65022779	28570.563	3.9638672	0.10557699
0.65353584	28673.545	3.9833984	0.10612626
0.65669191	28776.498	4.0029297	0.10673748
0.66029501	28879.059	4.0224609	0.10732688
0.66380429	28980.438	4.0419922	0.10789054
0.66688883	29076.064	4.0615234	0.10858795
0.67092109	29181.818	4.0810547	0.10910235
0.67340207	29279.285	4.1005859	0.10972384
0.67641509	29380.498	4.1201172	0.11029695
0.68076026	29484.537	4.1396484	0.11086961
0.68366599	29581.662	4.1591797	0.1114499
0.68655837	29683.07	4.1787109	0.11208116
0.68972778	29779.447	4.1982422	0.11272772
0.69273186	29877.594	4.2177734	0.11324716
0.6962322	29971.971	4.2373047	0.11381617
0.69973695	30068.883	4.2568359	0.11438724
0.70148933	30166.826	4.2763672	0.11501041
0.7061832	30265.629	4.2958984	0.11556754
0.70891011	30359.039	4.3154297	0.11617091
0.71290207	30450.357	4.3349609	0.11677933
0.71588826	30550.01	4.3544922	0.11747152
0.7187314	30645.016	4.3740234	0.11796626
0.72179806	30743.178	4.3935547	0.11856809
0.72559345	30837.971	4.4130859	0.11913768
0.72768557	30934.244	4.4326172	0.11973648
0.73195469	31030.285	4.4521484	0.1203402
0.73550868	31128.57	4.4716797	0.12095
0.73921907	31221.527	4.4912109	0.12159422
0.74095798	31310.691	4.5107422	0.12220361
0.74392188	31408.654	4.5302734	0.12271532
0.74870515	31496.369	4.5498047	0.12324651
0.75119066	31587.375	4.5693359	0.12388735
0.75461495	31678.697	4.5888672	0.12462838
0.75822699	31771.215	4.6083984	0.12508133
0.76098967	31863.197	4.6279297	0.12573279
0.76448989	31957.354	4.6474609	0.12636904
0.76771307	32043.689	4.6669922	0.1269618
0.77098978	32135.133	4.6865234	0.12754431
0.77503991	32219.182	4.7060547	0.12811539
0.77744949	32311.703	4.7255859	0.12860358
0.78126717	32402.645	4.7451172	0.12925102
0.78477633	32492.676	4.7646484	0.12978774
0.78672993	32584.113	4.7841797	0.13043104
0.79015863	32677.646	4.8037109	0.13099881
0.79447258	32766.17	4.8232422	0.1316006
0.79638588	32858.047	4.8427734	0.13222256
0.80007386	32951.684	4.8623047	0.13288073
0.80415976	33039.645	4.8818359	0.13347925
0.8069135	33132.07	4.9013672	0.13411856
0.809551	33229.105	4.9208984	0.13468966
0.81364143	33319.016	4.9404297	0.13534161
0.81730711	33412.316	4.9599609	0.13590685
0.82017708	33504.523	4.9794922	0.13650279
0.82320344	33596.84	4.9990234	0.13717735
0.82822812	33686.914	5.0185547	0.13777861
0.83095062	33781.125	5.0380859	0.13839884
0.83315003	33873.672	5.0576172	0.1390503
0.83624792	33958.582	5.0771484	0.13957231
0.84013712	34041.77	5.0966797	0.14024621
0.84284616	34124.414	5.1162109	0.14085567
0.84675777	34209.504	5.1357422	0.14139985
0.85033405	34294.82	5.1552734	0.14198223
0.85234118	34378.809	5.1748047	0.14262736
0.85550177	34464.805	5.1943359	0.14316301
0.85883212	34551.508	5.2138672	0.14382124
0.86364675	34637.492	5.2333984	0.14447272
0.86535442	34726.063	5.2529297	0.1449479
0.86956096	34814.699	5.2724609	0.14560065
0.87228787	34907.59	5.2919922	0.14624555
0.87637377	34996.922	5.3115234	0.1468146
0.87914097	35080.191	5.3310547	0.14747788
0.88336992	35166.367	5.3505859	0.14813933
0.8861773	35258.238	5.3701172	0.14871271
0.88915455	35342.191	5.3896484	0.14935242
0.89240003	35425.031	5.4091797	0.14992492
0.89653063	35515.328	5.4287109	0.15053986
0.89854228	35602.258	5.4482422	0.15112242
0.90177429	35687.02	5.4677734	0.15169746
0.90519416	35764.105	5.4873047	0.15226813
0.90821612	35845.789	5.5068359	0.15288931
0.91247189	35931.375	5.5263672	0.15353255
0.91574419	36013.367	5.5458984	0.15404819
0.91725063	36091.125	5.5654297	0.15469527
0.92112648	36177.824	5.5849609	0.15527432
0.92357624	36261.691	5.6044922	0.15584062
0.92772019	36346.035	5.6240234	0.15651408
0.93170333	36426.887	5.6435547	0.15718119
0.93497109	36508.996	5.6630859	0.15770832
0.93808699	36594.492	5.6826172	0.15825102
0.94006729	36671.137	5.7021484	0.15887888
0.94348717	36752.805	5.7216797	0.15948306
0.94690692	36837.574	5.7412109	0.16002887
0.95001829	36920.355	5.7607422	0.16064124
0.95332634	37000.91	5.7802734	0.16113317
0.95677745	37080.395	5.7998047	0.16181667
0.95951331	37160.883	5.8193359	0.16224341
0.96180212	37244.09	5.8388672	0.16279458
0.96709502	37329.219	5.8583984	0.16353062
0.96931231	37414.57	5.8779297	0.16419037
0.97353232	37501.359	5.8974609	0.16478112
0.97494054	37585.066	5.9169922	0.16539843
0.97981763	37670.504	5.9365234	0.16595672
0.9831481	37755.582	5.9560547	0.16658524
0.9859376	37838.785	5.9755859	0.1672288
0.99025142	37923.344	5.9951172	0.16784039
0.9930588	38007.125	6.0146484	0.1683943
0.99648762	38093.141	6.0341797	0.16902435
0.9994514	38176.781	6.0537109	0.16964854
1.0028713	38266.32	6.0732422	0.1702241
1.0051466	38352.906	6.0927734	0.17078331
1.0109268	38444.348	6.1123047	0.17147556
1.0139756	38530.68	6.1318359	0.17208214
1.0156966	38614.727	6.1513672	0.17277738
1.0198675	38698.805	6.1708984	0.17335109
1.0227643	38787.516	6.1904297	0.17394072
1.0255851	38869.973	6.2099609	0.17459805
1.0293849	38949.891	6.2294922	0.17519666
1.0330461	39031.383	6.2490234	0.17584044
1.0365509	39108.555	6.2685547	0.17638847
1.0403507	39191.203	6.2880859	0.17702213
1.043015	39272.262	6.3076172	0.17772225
1.0452591	39347.438	6.3271484	0.17824221
1.0491349	39426.586	6.3466797	0.17883146
1.0527693	39506.492	6.3662109	0.17935386
1.0556973	39585.016	6.3857422	0.17999746
1.0585941	39659.195	6.4052734	0.1806341
1.0618217	39738.348	6.4248047	0.1811296
1.0652863	39816.223	6.4443359	0.18186279
1.0676957	39895.809	6.4638672	0.1822959
1.0718621	39970.883	6.4833984	0.18295301
1.0745846	40047.352	6.5029297	0.18352284
1.0776378	40131.598	6.5224609	0.18410103
1.0811381	40214.238	6.5419922	0.18473369
1.0845847	40290.551	6.5615234	0.18534321
1.0873877	40366.539	6.5810547	0.18593149
1.0908432	40446.383	6.6005859	0.18644281
1.0939412	40519.164	6.6201172	0.18706544
1.0979779	40599.297	6.6396484	0.18763509
1.1002041	40680.027	6.6591797	0.18815069
1.104138	40758.586	6.6787109	0.18875085
1.106932	40836.422	6.6982422	0.18941399
1.1095785	40913.707	6.7177734	0.18997444
1.1131727	40996.938	6.7373047	0.19062653
1.1167221	41073.055	6.7568359	0.19111323
1.119668	41149.68	6.7763672	0.19168715
1.122529	41228.348	6.7958984	0.19228694
1.1260248	41307.762	6.8154297	0.19291481
1.1292391	41389.133	6.8349609	0.19348715
1.132422	41472.906	6.8544922	0.19409524
1.1359535	41547.445	6.8740234	0.1947054
1.1401289	41633.762	6.8935547	0.19523832
1.142127	41714.969	6.9130859	0.19587967
1.1452831	41798.648	6.9326172	0.1964833
1.1492975	41872.414	6.9521484	0.19707666
1.152087	41957.738	6.9716797	0.19766384
1.1555426	42040.227	6.9912109	0.19836006
1.1586763	42119.516	7.0107422	0.19893983
1.1626594	42202.012	7.0302734	0.1995343
1.1652522	42287.754	7.0498047	0.20003614
1.168672	42369.625	7.0693359	0.20067941
1.1727982	42450.469	7.0888672	0.20131561
1.1753596	42526.145	7.1083984	0.20194684
1.1794991	42607.844	7.1279297	0.20252293
1.1825882	42688.008	7.1474609	0.2030666
1.1858069	42767.172	7.1669922	0.20365168
1.1892759	42842.742	7.1865234	0.20431708
1.1920072	42923.664	7.2060547	0.20490922
1.1953198	43000.285	7.2255859	0.20545869
1.1988335	43075.559	7.2451172	0.2060699
1.2017347	43154.539	7.2646484	0.20675012
1.2045867	43233.445	7.2841797	0.20725335
1.2088515	43311.688	7.3037109	0.20789301
1.2115561	43387.867	7.3232422	0.20839332
1.2152665	43461.688	7.3427734	0.20905863
1.2175732	43537.293	7.3623047	0.20962933
1.2205772	43615.539	7.3818359	0.21016937
1.2246675	43691.297	7.4013672	0.21075007
1.2271844	43775.129	7.4208984	0.21135443
1.2311943	43862.273	7.4404297	0.21198785
1.2342029	43941.199	7.4599609	0.21259829
1.2375556	44023.996	7.4794922	0.21322525
1.2411721	44104.887	7.4990234	0.21384479
1.2443684	44184.141	7.5185547	0.21454106
1.2481951	44265.957	7.5380859	0.21504889
1.2511767	44340.66	7.5576172	0.21566261
1.2541585	44417.5	7.5771484	0.2163078
1.2584769	44495.488	7.5966797	0.21679857
1.2601935	44565.82	7.6162109	0.21741906
1.2639798	44638.602	7.6357422	0.21794707
1.26689	44715.293	7.6552734	0.21860906
1.271262	44791.926	7.6748047	0.21915683
1.2737877	44859.949	7.6943359	0.21980762
1.2765772	44931.477	7.7138672	0.22033069
1.2804933	45006.895	7.7333984	0.22085665
1.2831397	45083.02	7.7529297	0.22147192
1.2869172	45165.703	7.7724609	0.22206503
1.2890495	45243.922	7.7919922	0.22272919
1.2938685	45325.898	7.8115234	0.22327016
1.2963004	45399.828	7.8310547	0.22386563
1.2995548	45480.277	7.8505859	0.22442457
1.3036184	45551.863	7.8701172	0.22501734
1.3059341	45629.867	7.8896484	0.22569582
1.3096087	45705.129	7.9091797	0.22620983
1.3130374	45778.727	7.9287109	0.22678585
1.3152503	45849.176	7.9482422	0.22742106
1.3184063	45922.836	7.9677734	0.2279018
1.3221748	46001.449	7.9873047	0.2284804
1.325702	46071.926	8.0068359	0.22912329
1.3285584	46144.805	8.0263672	0.22964124
1.3310708	46216.742	8.0458984	0.23022601
1.3352103	46293.098	8.0654297	0.23072551
1.3371192	46356.629	8.0849609	0.23124741
1.3401144	46407.172	8.1044922	0.23180576
1.343999	46479.18	8.1240234	0.2323591
1.3479017	46573.086	8.1435547	0.23299137
1.3515897	46671.527	8.1630859	0.23365392
1.3538204	46758.785	8.1826172	0.23435231
1.3578885	46842.875	8.2021484	0.23491982
1.3610356	46927.238	8.2216797	0.2355116
1.3645447	47015.855	8.2412109	0.23621248
1.3684027	47102.578	8.2607422	0.23681088
1.3708479	47186.203	8.2802734	0.23731107
1.3752199	47266	8.2998047	0.23801011
1.3785146	47348.648	8.3193359	0.23869273
1.3822294	47424.723	8.3388672	0.23927638
1.3855822	47505.906	8.3583984	0.23991555
1.3886578	47580.199	8.3779297	0.24045706
1.3914429	47653.238	8.3974609	0.24101618
1.395417	47719.324	8.4169922	0.24168989
1.3986312	47784.871	8.4365234	0.24219893
1.4012463	47849.621	8.4560547	0.242676
1.4045768	47912.672	8.4755859	0.24328008
1.4075361	47973.906	8.4951172	0.24380621
1.4105089	48039.336	8.5146484	0.24450462
1.4133208	48106.84	8.5341797	0.24497074
1.4172949	48172.668	8.5537109	0.24557361
1.4201916	48239.801	8.5732422	0.24600983
1.4226102	48308.98	8.5927734	0.24661323
1.4255561	48376.035	8.6123047	0.24720381
1.4296867	48445.66	8.6318359	0.24771515
1.4317073	48522.16	8.6513672	0.24827546
1.4342107	48595.063	8.6708984	0.24886853
1.4378541	48668.23	8.6904297	0.24948685
1.4418103	48745.766	8.7099609	0.24994686
1.4455653	48822.293	8.7294922	0.25054643
1.4476173	48903.035	8.7490234	0.25111559
1.4512919	48983.16	8.7685547	0.25175908
1.4552884	49065.621	8.7880859	0.25243774
1.4583863	49148.52	8.8076172	0.25306657
1.4619761	49231.953	8.8271484	0.25355014
1.4662005	49311.063	8.8466797	0.25422883
1.4684491	49391.672	8.8662109	0.25488362
1.4726781	49471.109	8.8857422	0.25538146
1.4755793	49548.816	8.9052734	0.25609747
1.4788426	49623.523	8.9248047	0.25658041
1.4824234	49705.973	8.9443359	0.25733647
1.4858968	49780.551	8.9638672	0.25790825
1.4891379	49857.707	8.9833984	0.25838083
1.4918334	49933.645	9.0029297	0.25900173
1.4954902	50003.48	9.0224609	0.25958687
1.4987804	50082.789	9.0419922	0.26018715
1.5027546	50154.504	9.0615234	0.2609053
1.5053607	50225.098	9.0810547	0.2613965
1.51098	50298.742	9.1005859	0.26201323
1.5121557	50366.277	9.1201172	0.26250714
1.5145518	50438.535	9.1396484	0.26313421
1.5192233	50508.871	9.1591797	0.26369029
1.5209354	50578.715	9.1787109	0.26432797
1.5259736	50650.414	9.1982422	0.26486036
1.5285306	50718.629	9.2177734	0.2654275
1.5312307	50785.301	9.2373047	0.26597086
1.5341319	50853.934	9.2568359	0.26653507
1.5373774	50924.668	9.2763672	0.26715729
1.5401982	50994.629	9.2958984	0.26775658
1.5444316	51061.066	9.3154297	0.26821291
1.5474312	51131.828	9.3349609	0.26884732
1.5490897	51199.137	9.3544922	0.26942936
1.5534259	51272.379	9.3740234	0.26991567
1.5569978	51337.984	9.3935547	0.27050918
1.5598141	51405.434	9.4130859	0.2711114
1.5623085	51471.996	9.4326172	0.27164307
1.5651561	51542.609	9.4521484	0.27211344
1.5686833	51609.688	9.4716797	0.27275014
1.5724562	51683.406	9.4912109	0.27340162
1.5753709	51754.703	9.5107422	0.27394906
1.5781738	51826.52	9.5302734	0.27447551
1.5822105	51903.438	9.5498047	0.27501994
1.585903	51980.492	9.5693359	0.27563402
1.5894525	52055.434	9.5888672	0.27628738
1.5907578	52131.074	9.6083984	0.27681428
1.5958048	52201.398	9.6279297	0.27744088
1.5984155	52279.156	9.6474609	0.27799252
1.6013391	52352.234	9.6669922	0.2785823
1.6047187	52428.168	9.6865234	0.27920234
1.6081877	52498.422	9.7060547	0.27975985
1.6112231	52573.016	9.7255859	0.28031617
1.6151034	52647.129	9.7451172	0.28091133
1.6188406	52722.504	9.7646484	0.28152478
1.6221755	52788.863	9.7841797	0.28207195
1.6241021	52860.551	9.8037109	0.28268158
1.6276873	52938.215	9.8232422	0.28326738
1.6317285	53008.496	9.8427734	0.28379053
1.6343974	53079.473	9.8623047	0.28449342
1.6378127	53153.48	9.8818359	0.28502503
1.6409867	53225.977	9.9013672	0.28570944
1.6450144	53296.766	9.9208984	0.28619167
1.6472809	53366.449	9.9404297	0.2868191
1.6511075	53440.418	9.9599609	0.28743181
1.6530342	53515.352	9.9794922	0.28799939
1.6573704	53584.676	9.9990234	0.28847936
1.6613044	53655.43	10.018555	0.28913182
1.6641341	53735.445	10.038086	0.28960106
1.6675092	53808.992	10.057617	0.29022762
1.6711526	53885.316	10.077148	0.29085648
1.6739376	53959.156	10.09668	0.29146051
1.6775585	54030.785	10.116211	0.29208797
1.6809918	54098.43	10.135742	0.2925975
1.6837455	54168.012	10.155273	0.29315963
1.6870044	54240.789	10.174805	0.29381937
1.6903795	54306.742	10.194336	0.29435414
1.6941391	54374.914	10.213867	0.29492348
1.6975366	54443.273	10.233398	0.29548949
1.7013274	54512.746	10.25293	0.29612014
1.7036028	54576.816	10.272461	0.29664418
1.7073714	54639.445	10.291992	0.29713055
1.7094814	54705.91	10.311523	0.29772604
1.7123289	54771.184	10.331055	0.29832602
1.7168529	54836.852	10.350586	0.29889491
1.7189943	54904.004	10.370117	0.29939649
1.7227985	54966.141	10.389648	0.29999784
1.7254673	55033.168	10.40918	0.30056125
1.7282836	55104.59	10.428711	0.30112761
1.7310418	55172.648	10.448242	0.30174556
1.7350875	55242.109	10.467773	0.30225855
1.7389275	55313.109	10.487305	0.30284482
1.7412878	55385.391	10.506836	0.30343798
1.7445825	55459.84	10.526367	0.30400008
1.747895	55534.02	10.545898	0.30459413
1.7518692	55601.668	10.56543	0.30519152
1.7541312	55672.414	10.584961	0.30573854
1.7577969	55741.68	10.604492	0.30625266
1.7609261	55809	10.624023	0.30682656
1.7643012	55878.418	10.643555	0.30750105
1.7672248	55949.965	10.663086	0.30792433
1.770658	56019.973	10.682617	0.3085593
1.7747216	56090.215	10.702148	0.30904949
1.7769836	56160.285	10.72168	0.30966336
1.7808371	56234.426	10.741211	0.31012729
1.7834611	56303.93	10.760742	0.31082088
1.788003	56373.418	10.780273	0.31130749
1.7895453	56443.715	10.799805	0.311939
1.794865	56514.242	10.819336	0.3124994
1.7964698	56579.508	10.838867	0.3130717
1.800739	56648.398	10.858398	0.31361392
1.8038236	56719.852	10.87793	0.31416491
1.8069304	56782.594	10.897461	0.31475452
1.8098586	56850.293	10.916992	0.31531689
1.813712	56916.504	10.936523	0.31583288
1.8160276	56987.266	10.956055	0.31643912
1.8197961	57060.609	10.975586	0.31703803
1.8239849	57134.656	10.995117	0.31763574
1.8262602	57206.227	11.014648	0.31824523
1.8308245	57281.566	11.03418	0.3189595
1.8329836	57356.688	11.053711	0.31946436
1.8363677	57422.434	11.073242	0.32011402
1.8400871	57494.215	11.092773	0.32052827
1.8442981	57568.992	11.112305	0.32121912
1.8466092	57636.582	11.131836	0.32173213
1.8501676	57698.938	11.151367	0.32232413
1.8536054	57772.215	11.170898	0.32292858
1.8570923	57839.973	11.19043	0.3234714
1.860065	57901.184	11.209961	0.32410347
1.8626041	57971.934	11.229492	0.32473099
1.8675439	58034.02	11.249023	0.32523012
1.8693991	58099.5	11.268555	0.32574126
1.8718086	58166.113	11.288086	0.32630259
1.8759258	58232.207	11.307617	0.32692385
1.8789477	58294.895	11.327148	0.32746118
1.8825955	58356.871	11.34668	0.32802498
1.8855863	58422.934	11.366211	0.32856232
1.8885814	58489.641	11.385742	0.32917836
1.8918581	58552.828	11.405273	0.32971427
1.8948399	58617.699	11.424805	0.33029985
1.8979423	58677.977	11.444336	0.3307763
1.9027121	58744.25	11.463867	0.33137387
1.9056313	58808.922	11.483398	0.33186126
1.9078754	58874.418	11.50293	0.33249089
1.9112371	58937.008	11.522461	0.33301443
1.9143753	58999.469	11.541992	0.33360842
1.9170128	59067.375	11.561523	0.33410206
1.9216799	59128.777	11.581055	0.33471411
1.9225829	59194.254	11.600586	0.33520287
1.926852	59255.387	11.620117	0.33579195
1.9304596	59324.641	11.639648	0.33629981
1.9333519	59393.617	11.65918	0.33691776
1.9368522	59462.578	11.678711	0.33749163
1.9407816	59532.219	11.698242	0.3380968
1.9433789	59597.484	11.717773	0.33866003
1.947505	59670.422	11.737305	0.33922029
1.9494765	59734.66	11.756836	0.33986694
1.9539691	59806.375	11.776367	0.34037033
1.9556545	59870.578	11.795898	0.3409462
1.9589044	59943.645	11.81543	0.34155926
1.9629635	60013.809	11.834961	0.34201083
1.96523	60074.41	11.854492	0.34268427
1.969821	60142.32	11.874023	0.34315896
1.9741886	60211.754	11.893555	0.34384453
1.9760214	60274.121	11.913086	0.34430814
1.9799374	60339.117	11.932617	0.34488574
1.9825213	60402.371	11.952148	0.34545526
1.9852661	60473.883	11.97168	0.34611782
1.9894414	60541.965	11.991211	0.34668133
1.9941353	60610.926	12.010742	0.34725133
1.9971795	60676.547	12.030273	0.34775007
1.9997053	60746.352	12.049805	0.3483558
2.0031252	60813.227	12.069336	0.34889507
2.0057895	60882.094	12.088867	0.34952632
2.0101526	60947.832	12.108398	0.35017872
2.0140283	61016.316	12.12793	0.35068136
2.0165272	61084.094	12.147461	0.35131228
2.0187936	61148.5	12.166992	0.35190508
2.0226114	61214.555	12.186523	0.3524316
2.0259104	61278.543	12.206055	0.35292351
2.0303271	61336.656	12.225586	0.35355112
2.0329692	61400.918	12.245117	0.35410425
2.0357409	61468.324	12.264648	0.35464975
2.0385079	61531.332	12.28418	0.35524097
2.0422094	61593.035	12.303711	0.35591188
2.044364	61656.637	12.323242	0.3564117
2.0486333	61714.848	12.342773	0.35695347
2.0512753	61776.164	12.362305	0.35740954
2.0546279	61839.398	12.381836	0.35801557
2.059	61898.02	12.401367	0.3586441
2.0608821	61963.133	12.420898	0.35913372
2.0649276	62026.414	12.44043	0.35961065
2.0676322	62085.227	12.459961	0.36027405
2.0709136	62147.668	12.479492	0.36079463
2.0743065	62212.328	12.499023	0.36138365
2.0784013	62277.445	12.518555	0.36191669
2.0801134	62336.395	12.538086	0.36253276
2.084101	62401.633	12.557617	0.36303091
2.0873599	62461.848	12.577148	0.36369267
2.0903149	62526.957	12.59668	0.36422926
2.0943515	62592.219	12.616211	0.36476403
2.0976372	62665.602	12.635742	0.3653658
2.1003106	62735.797	12.655273	0.36605605
2.1043069	62805.602	12.674805	0.36657208
2.10677	62878.91	12.694336	0.36711755
2.1104672	62944.117	12.713867	0.36773509
2.1140211	63014.293	12.733398	0.36839437
2.1176152	63085.367	12.75293	0.36899072
2.1210215	63150.262	12.772461	0.36953831
2.1246872	63213.875	12.791992	0.37004727
2.1273739	63279.141	12.811523	0.37070727
2.1316388	63341.746	12.831055	0.37133679
2.1345177	63406.105	12.850586	0.37194765
2.1374903	63464.652	12.870117	0.37254089
2.1409192	63530.293	12.889648	0.37311956
2.1442764	63590.141	12.90918	0.3736414
2.1462255	63652.184	12.928711	0.37421015
2.1497838	63715.371	12.948242	0.37479371
2.1540663	63772.691	12.967773	0.37531993
2.1570482	63840.809	12.987305	0.37580484
2.1603293	63895.75	13.006836	0.37644795
2.1631501	63961.063	13.026367	0.37704322
2.1678486	64023.102	13.045898	0.37752491
2.1695652	64071.891	13.06543	0.37812161
2.173043	64131.652	13.084961	0.37872806
2.1762929	64186.441	13.104492	0.37923998
2.1791272	64244.941	13.124023	0.3797605
2.1825156	64303.215	13.143555	0.3803106
2.1851978	64361.711	13.163086	0.38094944
2.1885731	64420.113	13.182617	0.38144857
2.1910272	64482.23	13.202148	0.38204932
2.1948495	64543.578	13.22168	0.38258311
2.1985331	64602.98	13.241211	0.38314691
2.2011034	64669.523	13.260742	0.38366452
2.2045233	64725.809	13.280273	0.3842904
2.2077687	64788.895	13.299805	0.38478684
2.2103481	64849.258	13.319336	0.38538373
2.213835	64910.156	13.338867	0.38584298
2.2174337	64974.578	13.358398	0.38648453
2.2205181	65038.254	13.37793	0.38703936
2.2245235	65096.777	13.397461	0.38758522
2.2262759	65157.395	13.416992	0.38821459
2.2302232	65222.398	13.436523	0.3887248
2.2321858	65286.867	13.456055	0.38937858
2.2358603	65348.832	13.475586	0.3898994
2.238708	65416.008	13.495117	0.39045879
2.242311	65477.234	13.514648	0.39099222
2.2464552	65547.594	13.53418	0.39163888
2.2491686	65617.273	13.553711	0.39224744
2.2525749	65683.438	13.573242	0.39281535
2.2549622	65750.969	13.592773	0.39337319
2.2610106	65818.266	13.612305	0.3940995
2.2634246	65887.727	13.631836	0.39464086
2.2664824	65955.664	13.651367	0.39523974
2.2694461	66013.211	13.670898	0.39576924
2.2737198	66066.383	13.69043	0.39641434
2.2760353	66134.281	13.709961	0.39704379
2.2805951	66207.773	13.729492	0.39762563
2.2833579	66271.602	13.749023	0.39821663
2.2872157	66334.992	13.768555	0.39876524
2.290859	66395.953	13.788086	0.39927757
2.2927144	66458.258	13.807617	0.39989692
2.2958121	66523.008	13.827148	0.40058413
2.2989056	66583.422	13.84668	0.40116116
2.3036399	66651.469	13.866211	0.40179977
2.3064919	66718.266	13.885742	0.40247625
2.3094335	66780.414	13.905273	0.4030056
2.3141541	66836.75	13.924805	0.4035995
2.3164651	66892.977	13.944336	0.40419635
2.3192816	66952.273	13.963867	0.40474626
2.3240559	67010.477	13.983398	0.405292
2.3247354	67065.266	14.00293	0.405817
2.3287318	67120.617	14.022461	0.40638813
2.3320892	67168.781	14.041992	0.40703452
2.3351111	67224.391	14.061523	0.4074727
2.3377976	67275.594	14.081055	0.40807191
2.3409717	67326.242	14.100586	0.40861073
2.3452096	67383.922	14.120117	0.40921852
2.3471675	67435.273	14.139648	0.40973791
2.3499973	67488.781	14.15918	0.41030243
2.3529835	67541.617	14.178711	0.41076073
2.3557239	67602.852	14.198242	0.41144922
2.3595862	67663.641	14.217773	0.41182527
2.3620851	67722.836	14.237305	0.41251487
2.3664839	67786.188	14.256836	0.41306302
2.3695104	67855.391	14.276367	0.41370207
2.3726127	67924.906	14.295898	0.41433322
2.3760774	67986.336	14.31543	0.41487303
2.3801587	68053.93	14.334961	0.41543126
2.3841329	68123.016	14.354492	0.4161391
2.3866854	68185.016	14.374023	0.41668496
2.3898282	68247.563	14.393555	0.41721904
2.3925371	68311.859	14.413086	0.41783547
2.3964486	68380.797	14.432617	0.41847199
2.3999848	68445.477	14.452148	0.41920084
2.4031944	68512.031	14.47168	0.41970047
2.4070032	68581.047	14.491211	0.42039928
2.4101906	68647.047	14.510742	0.42099211
2.4140842	68707.555	14.530273	0.42163089
2.4172404	68773.055	14.549805	0.42221189
2.4210176	68840.664	14.569336	0.42279488
2.4237313	68899.695	14.588867	0.42337468
2.4278305	68959.797	14.608398	0.42401314
2.4300165	69020.758	14.62793	0.42453817
2.434639	69082.594	14.647461	0.42516893
2.4370618	69139.25	14.666992	0.42579007
2.440428	69194.102	14.686523	0.42646518
2.4438701	69248.461	14.706055	0.42705664
2.4474957	69306.344	14.725586	0.42763624
2.4497309	69360.063	14.745117	0.42821005
2.4535217	69414.141	14.764648	0.42885354
2.4565883	69469.422	14.78418	0.42935884
2.4608531	69527.539	14.803711	0.42986146
2.4631062	69583.18	14.823242	0.43039197
2.4672098	69633.281	14.842773	0.4310807
2.468837	69686.883	14.862305	0.43158275
2.4725385	69738.773	14.881836	0.43208247
2.4759717	69789.773	14.901367	0.43274546
2.4775765	69835.125	14.920898	0.43327174
2.4814703	69884.125	14.94043	0.43375981
2.4853907	69934.188	14.959961	0.43440771
2.4886587	69983.891	14.979492	0.4349626
2.4904914	70030.078	14.999023	0.43549711
2.4935133	70082.648	15.018555	0.43606165
2.4960167	70136.5	15.038086	0.43660563
2.4992666	70187.477	15.057617	0.43713412
2.5029056	70242.969	15.077148	0.43767712
2.5058918	70300.07	15.09668	0.43817839
2.5090747	70358.055	15.116211	0.43880346
2.512423	70411.383	15.135742	0.43932149
2.5157444	70470.703	15.155273	0.43990859
2.5189764	70538.578	15.174805	0.44052958
2.5224545	70605.633	15.194336	0.44109231
2.5245824	70671.859	15.213867	0.44180796
2.5294998	70739.531	15.233398	0.44233459
2.5322132	70810.539	15.25293	0.44298106
2.5358431	70876.523	15.272461	0.44359294
2.5398753	70944.977	15.291992	0.44431761
2.5431969	71012.133	15.311523	0.44499481
2.5456645	71081.219	15.331055	0.44553939
2.5499828	71145.508	15.350586	0.44619003
2.5529423	71206.547	15.370117	0.44675499
2.5573902	71270.539	15.389648	0.44734496
2.55967	71334.664	15.40918	0.44806132
2.5627367	71394.492	15.428711	0.44864216
2.5672607	71452.734	15.448242	0.44925413
2.5698223	71509.359	15.467773	0.44994345
2.574914	71570.922	15.487305	0.45050764
2.6763372	12301.054	15.506836	0.32944405
2.6052275	5251.3833	15.526367	0.23934723
2.6149101	3808.9136	15.545898	0.28902793
2.5806763	4010.4026	15.56543	0.29870555
2.5936134	2305.8157	15.584961	0.35105026
2.6127777	1277.1245	15.604492	0.35739246
2.6035957	1478.5537	15.624023	0.36212665
2.6104577	615.40442	15.643555	0.35962534
2.6187816	-54.358971	15.663086	0.39795092
2.6163943	-182.01244	15.682617	0.3887772
2.6213653	-510.43744	15.702148	0.39999139
2.6248791	-561.89423	15.72168	0.40037504
2.6282318	-482.87573	15.741211	0.40150005
2.630172	-301.84293	15.760742	0.41549045
2.633708	18.613878	15.780273	0.40180096
2.6351295	213.9738	15.799805	0.41140413
2.6393943	426.1192	15.819336	0.40883717
2.6433907	479.02133	15.838867	0.41773042
2.6474812	417.18176	15.858398	0.41367623
2.6497743	245.36659	15.87793	0.42159536
2.6524165	25.746298	15.897461	0.42932615
2.6559749	-199.34843	15.916992	0.43275958
2.659569	-367.561	15.936523	0.44003093
2.6625462	-430.33249	15.956055	0.44180578
2.6659927	-376.99683	15.975586	0.4498769
2.6676335	-230.08836	15.995117	0.45079488
2.6704988	-35.987465	16.014648	0.45336729
2.6735477	163.76794	16.03418	0.45599094
2.6763597	326.61948	16.053711	0.45983469
2.6795068	396.2894	16.073242	0.46224663
2.6831455	354.65881	16.092773	0.46863529
2.6861587	227.86343	16.112305	0.47262162
2.6902087	40.248154	16.131836	0.47992438
2.6919835	-151.50755	16.151367	0.48516381
2.694469	-298.28436	16.170898	0.49041501
2.6981659	-348.60043	16.19043	0.49630183
2.7015321	-313.33478	16.209961	0.49876013
2.7044423	-192.72197	16.229492	0.50318193
2.7072496	-27.479137	16.249023	0.50488251
2.710674	148.16866	16.268555	0.50882339
2.7144871	280.83264	16.288086	0.51100624
2.7174287	334.48196	16.307617	0.51519597
2.7211525	302.01254	16.327148	0.5198009
2.723629	191.67841	16.34668	0.52455723
2.7265749	41.091698	16.366211	0.52946413
2.7307146	-123.67068	16.385742	0.53557271
2.733942	-243.89172	16.405273	0.53990269
2.7370534	-296.46011	16.424805	0.54405206
2.7399547	-262.57849	16.444336	0.54801077
2.7427039	-169.99269	16.463867	0.54934436
2.7459898	-33.621326	16.483398	0.55282998
2.7489803	107.35157	16.50293	0.55335766
2.7522035	227.63805	16.522461	0.55726969
2.7556858	275.27417	16.541992	0.55860043
2.758234	258.80594	16.561523	0.563748
2.7611933	167.04666	16.581055	0.56768125
2.7653553	37.013668	16.600586	0.5720219
2.7681582	-97.078499	16.620117	0.5768922
2.7701476	-203.72588	16.639648	0.57984209
2.7712829	-241.82874	16.65918	0.58090937
2.770237	-228.30466	16.678711	0.58050722
2.7699463	-148.2357	16.698242	0.57921678
2.7697585	-21.028913	16.717773	0.57669234
2.768471	107.08569	16.737305	0.57546645
2.7678676	197.76682	16.756836	0.5725596
2.7665534	244.51572	16.776367	0.57337946
2.7662985	217.15205	16.795898	0.57135469
2.7673044	139.33028	16.81543	0.57371706
2.7664058	29.226997	16.834961	0.57297343
2.7663252	-89.451088	16.854492	0.57509375
2.7663879	-176.12695	16.874023	0.57561922
2.7665355	-215.92296	16.893555	0.57594264
2.7670004	-194.21709	16.913086	0.57622337
2.7659633	-120.24655	16.932617	0.57549244
2.7667098	-13.497309	16.952148	0.57486308
2.7670898	94.453453	16.97168	0.57357687
2.7671793	173.91402	16.991211	0.57315725
2.7672238	202.87418	17.010742	0.57184941
2.7676485	189.81577	17.030273	0.57290804
2.7666471	118.82081	17.049805	0.5718317
2.7667589	20.301085	17.069336	0.57395804
2.7662404	-84.527298	17.088867	0.57248652
2.7662761	-122.41583	17.098633	0.57452524