File: data/T1.dat
MTS793|MPT|ENU|1|2|.|/|:|1|0|0|A

Data Acquisition						Time:	10.008789	s	2/4/2020 10:33:12 AM
Axial Displacement	Axial Force	Time	Axial Extensometer
mm	N	s	mm
0.00035315752	211.66843	0.017578125	-0.0002487115
-0.0012874603	211.0569	0.046875	-0.00024063229
-8.046627e-05	215.31026	0.076171875	-9.5855648e-05
0.00092983246	245.37381	0.10546875	-8.620591e-05
0.0038959086	436.71579	0.13476563	0.00043412182
0.0099599361	804.96143	0.1640625	0.0015951664
0.016792864	1171.0325	0.19335938	0.0026336808
0.022787601	1517.0504	0.22265625	0.0037322731
0.028565526	1811.9871	0.25195313	0.0046013789
0.033140928	2068.76	0.28125	0.0053941538
0.037010014	2313.4812	0.31054688	0.0061246785
0.042238086	2567.7432	0.33984375	0.0069066328
0.047470629	2829.7534	0.36914063	0.0077980356
0.052052736	3087.5496	0.3984375	0.0085441303
0.056791306	3334.4695	0.42773438	0.0092357332
0.060251355	3577.9824	0.45703125	0.010025702
0.065369904	3827.2852	0.48632813	0.010806041
0.069004297	4085.8159	0.515625	0.011582656
0.073778629	4344.5625	0.54492188	0.012372551
0.078977644	4620.811	0.57421875	0.013248349
0.085280836	4894.4805	0.60351563	0.014112148
0.089196861	5168.1621	0.6328125	0.014877957
0.0939399	5430.7983	0.66210938	0.01565
0.098834932	5691.2603	0.69140625	0.016478848
0.10448545	5957.2705	0.72070313	0.017361965
0.10913014	6215.5571	0.75	0.018114896
0.11373013	6474.27	0.77929688	0.019008733
0.1190722	6747.4644	0.80859375	0.019787785
0.12412369	7038.2183	0.83789063	0.020742528
0.13086498	7334.895	0.8671875	0.021624377
0.13625622	7623.3135	0.89648438	0.022428824
0.14141053	7905.3589	0.92578125	0.023304116
0.14608651	8170.1421	0.95507813	0.024135858
0.15140176	8421.0293	0.984375	0.024869373
0.15620291	8671.1016	1.0136719	0.025730388
0.16101301	8918.8799	1.0429688	0.02650225
0.16584098	9147.3711	1.0722656	0.027190762
0.16977489	9381.6123	1.1015625	0.027844574
0.17446429	9614.0322	1.1308594	0.028627463
0.17921627	9860.4355	1.1601563	0.029436804
0.18389225	10096.636	1.1894531	0.030148491
0.18838048	10351.896	1.21875	0.030871483
0.19431263	10599.989	1.2480469	0.031656295
0.1985997	10859.132	1.2773438	0.032545496
0.20411611	11108.183	1.3066406	0.033264779
0.20851046	11363.428	1.3359375	0.034107905
0.21403134	11616.061	1.3652344	0.034953512
0.21968186	11873.597	1.3945313	0.035671495
0.22362024	12126.344	1.4238281	0.03648242
0.22911876	12383.038	1.453125	0.037361406
0.23324937	12631.977	1.4824219	0.038131643
0.239034	12892.894	1.5117188	0.038920395
0.24456829	13143.823	1.5410156	0.039773621
0.25004447	13397.005	1.5703125	0.040569376
0.25483668	13639.422	1.5996094	0.041349869
0.25860518	13889.75	1.6289063	0.042095393
0.26340634	14130.665	1.6582031	0.042981517
0.2685383	14376.754	1.6875	0.043596134
0.27331263	14615.575	1.7167969	0.044402707
0.27865469	14866.235	1.7460938	0.04524342
0.28382242	15107.663	1.7753906	0.045986596
0.28899908	15355.534	1.8046875	0.046756845
0.29360801	15600.551	1.8339844	0.047584586
0.29838234	15846.971	1.8632813	0.048415024
0.30384064	16085.335	1.8925781	0.049116373
0.3082931	16325.176	1.921875	0.049852964
0.31294674	16553.996	1.9511719	0.050654877
0.3184095	16786.473	1.9804688	0.051348034
0.32258034	17016.977	2.0097656	0.052216265
0.3271535	17254.791	2.0390625	0.052826554
0.33248663	17476.615	2.0683594	0.053495377
0.33752471	17715.971	2.0976563	0.054286379
0.3424108	17942.111	2.1269531	0.055121198
0.3466174	18180.262	2.15625	0.05578135
0.35173595	18406.01	2.1855469	0.056540374
0.35575032	18634.656	2.2148438	0.057258315
0.36018491	18874.17	2.2441406	0.058060654
0.36633164	19127.506	2.2734375	0.058839966
0.37120879	19376.889	2.3027344	0.059619527
0.3766045	19631.094	2.3320313	0.06037949
0.38221925	19874.535	2.3613281	0.061209377
0.38618892	20120.252	2.390625	0.062060524
0.39088726	20354.422	2.4199219	0.062834196
0.39649308	20593.168	2.4492188	0.063538194
0.40171891	20819.307	2.4785156	0.064409226
0.40632337	21052.709	2.5078125	0.065154098
0.41150451	21274.99	2.5371094	0.065896533
0.41633248	21508.947	2.5664063	0.066634178
0.42160749	21731.078	2.5957031	0.067375623
0.42539835	21956.885	2.625	0.068105832
0.43170154	22177.461	2.6542969	0.068796925
0.43606907	22401.201	2.6835938	0.069552541
0.44049919	22625.93	2.7128906	0.070325397
0.44569373	22852.176	2.7421875	0.071129084
0.45138001	23078.959	2.7714844	0.071871921
0.45526922	23303.268	2.8007813	0.072553299
0.45986027	23520.262	2.8300781	0.073288359
0.46495199	23746.332	2.859375	0.074115634
0.46996325	23966.559	2.8886719	0.074884094
0.47505498	24194.322	2.9179688	0.075534873
0.47953874	24408.656	2.9472656	0.076274917
0.4849121	24658.828	2.9765625	0.077140942
0.48993677	24905.219	3.0058594	0.077942215
0.49551576	25151.314	3.0351563	0.078793868
0.50053596	25384.496	3.0644531	0.079587042
0.50678998	25620.686	3.09375	0.080333695
0.5117476	25855.414	3.1230469	0.08127249
0.51600337	26093.121	3.1523438	0.081979036
0.52091181	26303.201	3.1816406	0.082822822
0.52633882	26533.297	3.2109375	0.083542533
0.53127855	26742.635	3.2402344	0.084346518
0.53506941	26950.436	3.2695313	0.084947802
0.54050535	27151.857	3.2988281	0.085708842
0.54467618	27352.492	3.328125	0.086412288
0.54933429	27548.439	3.3574219	0.087103479
0.55334866	27753.865	3.3867188	0.087872535
0.55820346	27953.297	3.4160156	0.08850576
0.56385845	28175.063	3.4453125	0.089253165
0.56847632	28384.979	3.4746094	0.090067819
0.57415366	28604.27	3.5039063	0.090899736
0.57902634	28814.564	3.5332031	0.091493048
0.58336705	29023.912	3.5625	0.092196465
0.58808774	29234.406	3.5917969	0.093025953
0.59220046	29447.225	3.6210938	0.093778618
0.59731007	29652.223	3.6503906	0.094620444
0.60391277	29864.398	3.6796875	0.095258281
0.60715377	30077.242	3.7089844	0.095981099
0.61196387	30295.73	3.7382813	0.096848771
0.61790943	30503.291	3.7675781	0.097615577
0.6220758	30707.197	3.796875	0.098412223
0.62735975	30914.641	3.8261719	0.099218637
0.63160211	31122.992	3.8554688	0.099877886
0.63596517	31335.799	3.8847656	0.10071664
0.64282268	31550.855	3.9140625	0.10145373
0.64741373	31763.074	3.9433594	0.10230666
0.65217465	31976.08	3.9726563	0.10308073
0.65835267	32182.057	4.0019531	0.10390778
0.66226423	32392.598	4.03125	0.10453077
0.66698045	32591.832	4.0605469	0.10535643
0.67196935	32785.301	4.0898438	0.10608602
0.67750812	32971.578	4.1191406	0.10677508
0.68079829	33166.855	4.1484375	0.10756826
0.68584979	33355.578	4.1777344	0.10828748
0.69113821	33543.238	4.2070313	0.10895614
0.69525987	33735.461	4.2363281	0.10979969
0.70011467	33931.551	4.265625	0.11052749
0.70516169	34132.793	4.2949219	0.11128456
0.71029365	34336.715	4.3242188	0.11213072
0.71526468	34542.891	4.3535156	0.11283991
0.72080791	34773.797	4.3828125	0.11380369
0.72518438	34968.203	4.4121094	0.11466492
0.73024035	35179.727	4.4414063	0.11548477
0.73547065	35383.203	4.4707031	0.11621489
0.74010193	35582.051	4.5	0.11697553
0.74558258	35781.809	4.5292969	0.11769754
0.75030774	35971.566	4.5585938	0.11854319
0.75578839	36165.715	4.5878906	0.11938272
0.76026767	36355.914	4.6171875	0.12009859
0.76478273	36539.313	4.6464844	0.12084793
0.77003986	36727.797	4.6757813	0.12172578
0.77467114	36916.359	4.7050781	0.12245186
0.77893585	37101.281	4.734375	0.12323842
0.78476518	37288.18	4.7636719	0.12396529
0.78920871	37469.969	4.7929688	0.12467007
0.7946983	37658.543	4.8222656	0.12553898
0.79920441	37843.453	4.8515625	0.12627797
0.80459118	38030.91	4.8808594	0.12715439
0.80877095	38205.688	4.9101563	0.12792584
0.81299096	38386.184	4.9394531	0.12866351
0.81823468	38564.188	4.96875	0.12938979
0.82243234	38744.629	4.9980469	0.1302046
0.82746595	38925.215	5.0273438	0.13093719
0.83199441	39100.57	5.0566406	0.13173215
0.83730072	39283.238	5.0859375	0.13250855
0.84186047	39461.758	5.1152344	0.13325736
0.84751993	39637.707	5.1445313	0.13405263
0.85203052	39826.078	5.1738281	0.1348832
0.8560583	40014.824	5.203125	0.13558848
0.862737	40205.637	5.2324219	0.13666503
0.86794496	40389.828	5.2617188	0.13737787
0.87150335	40573	5.2910156	0.13825436
0.87695271	40750.508	5.3203125	0.13907687
0.88218749	40931.102	5.3496094	0.13992485
0.88672489	41094.496	5.3789063	0.14059271
0.89186579	41268.094	5.4082031	0.14135739
0.89630038	41432.285	5.4375	0.14223421
0.90102106	41611.664	5.4667969	0.14298169
0.90556294	41775.813	5.4960938	0.14377819
0.9119153	41947.504	5.5253906	0.14460719
0.91552734	42108.906	5.5546875	0.14542262
0.92163831	42276.938	5.5839844	0.14619495
0.92483908	42443.395	5.6132813	0.14698918
0.92926919	42614.922	5.6425781	0.14778537
0.93561709	42781.977	5.671875	0.14864129
0.93871057	42965.316	5.7011719	0.14946383
0.94503611	43133.484	5.7304688	0.1502579
0.95033348	43306.598	5.7597656	0.15113144
0.95490217	43471.785	5.7890625	0.15188064
0.96049011	43643.559	5.8183594	0.15275446
0.96475482	43805.734	5.8476563	0.15361932
0.96956491	43974.766	5.8769531	0.15443459
0.9754613	44136.797	5.90625	0.15529323
0.97854584	44303.863	5.9355469	0.15610331
0.98400861	44453.234	5.9648438	0.15689488
0.98871142	44618.602	5.9941406	0.15777919
0.99450946	44778.266	6.0234375	0.15846178
0.99861324	44950.625	6.0527344	0.15946518
1.0035664	45104.883	6.0820313	0.16014208
1.0081977	45269.898	6.1113281	0.16112326
1.0138526	45424.574	6.140625	0.16198887
1.0191097	45581.742	6.1699219	0.16271277
1.023437	45735.613	6.1992188	0.16361502
1.0283947	45891.18	6.2285156	0.16447508
1.0329276	46041.148	6.2578125	0.16513927
1.0372951	46202.008	6.2871094	0.16612034
1.0431066	46350.238	6.3164063	0.16695085
1.0481805	46506.215	6.3457031	0.16769235
1.0521815	46658.961	6.375	0.16855825
1.0569334	46820.488	6.4042969	0.1695282
1.0631114	46967.973	6.4335938	0.17036098
1.066795	47130.926	6.4628906	0.17122751
1.0715157	47286.371	6.4921875	0.17213181
1.0767549	47450.082	6.5214844	0.17304179
1.0816143	47610.051	6.5507813	0.17388949
1.0890663	47770.422	6.5800781	0.17481799
1.0923252	47918.023	6.609375	0.17562489
1.0987089	48072.828	6.6386719	0.17654736
1.1025935	48205.273	6.6679688	0.17730789
1.108463	48346.711	6.6972656	0.17821701
1.1128575	48478	6.7265625	0.17904004
1.116693	48615.188	6.7558594	0.17989583
1.1221379	48746.777	6.7851563	0.18068811
1.1254907	48884.684	6.8144531	0.18145825
1.1309042	49013.949	6.84375	0.18233992
1.1362106	49153.426	6.8730469	0.18315117
1.1403635	49284.918	6.9023438	0.18398596
1.1454463	49426.719	6.9316406	0.18482397
1.1493534	49561.387	6.9609375	0.18569551
1.1542664	49712.922	6.9902344	0.18655413
1.1595726	49852.57	7.0195313	0.18746039
1.1627779	50001.598	7.0488281	0.18827634
1.1686251	50139.43	7.078125	0.18915169
1.174745	50294.691	7.1074219	0.19018571
1.1792779	50429.898	7.1367188	0.1909849
1.1842802	50581.277	7.1660156	0.19195661
1.1899664	50724.855	7.1953125	0.19285864
1.1945039	50870.582	7.2246094	0.19382441
1.2001858	51006.223	7.2539063	0.19468114
1.205416	51147.07	7.2832031	0.19561456
1.2100071	51278.668	7.3125	0.19646244
1.2153	51413.246	7.3417969	0.19745061
1.2197793	51543.359	7.3710938	0.19828415
1.224102	51678.727	7.4003906	0.19926243
1.2295514	51803.301	7.4296875	0.20004635
1.2340128	51932.809	7.4589844	0.20096454
1.23927	52041.008	7.4882813	0.20182489
1.2444109	52155.688	7.5175781	0.2026249
1.2485683	52296.027	7.546875	0.20351137
1.2532353	52444.02	7.5761719	0.20449004
1.2589306	52578.637	7.6054688	0.20542336
1.2650549	52714.922	7.6347656	0.20634751
1.2691722	52845.207	7.6640625	0.20729382
1.2742414	52982.664	7.6933594	0.20825306
1.2787879	53111.391	7.7226563	0.2092181
1.2838349	53241.035	7.7519531	0.21014944
1.2892306	53365.977	7.78125	0.21100096
1.2938261	53488.523	7.8105469	0.21193732
1.2979031	53606.969	7.8398438	0.21282361
1.3034552	53728.355	7.8691406	0.21371703
1.308006	53842.25	7.8984375	0.21455082
1.312378	53964.332	7.9277344	0.21545808
1.3179436	54078.32	7.9570313	0.2163935
1.3226599	54200.313	7.9863281	0.2172929
1.3273716	54313.68	8.015625	0.21826203
1.3324366	54442.141	8.0449219	0.21906903
1.3376043	54561.094	8.0742188	0.22004184
1.3426334	54680.809	8.1035156	0.22095913
1.3480201	54795.742	8.1328125	0.22187997
1.35165	54912.504	8.1621094	0.22275889
1.357457	55022.262	8.1914063	0.22375739
1.3619721	55134.398	8.2207031	0.2246189
1.3664827	55240.93	8.25	0.22548148
1.3713107	55352.602	8.2792969	0.22626884
1.3758526	55461.832	8.3085938	0.22717093
1.3809979	55572.527	8.3378906	0.22808631
1.3849497	55684.512	8.3671875	0.22895718
1.3895319	55803.426	8.3964844	0.23001252
1.3950214	55916.043	8.4257813	0.23088323
1.3995945	56032.145	8.4550781	0.23180021
1.4044895	56141.242	8.484375	0.2326958
1.4097691	56254.488	8.5136719	0.23369293
1.4156789	56367.371	8.5429688	0.23460516
1.4193132	56473.887	8.5722656	0.23546436
1.4239311	56580.789	8.6015625	0.23644042
1.4285088	56686.137	8.6308594	0.23732869
1.4336586	56790.313	8.6601563	0.23825498
1.4382496	56902.758	8.6894531	0.23922718
1.4424294	57008.824	8.71875	0.24008018
1.448071	57127.832	8.7480469	0.24102867
1.4535382	57245.109	8.7773438	0.24213701
1.4583037	57360.016	8.8066406	0.24303094
1.4626131	57477.332	8.8359375	0.24402356
1.4681518	57589.27	8.8652344	0.24505912
1.4741733	57700.211	8.8945313	0.24603646
1.4793724	57809.273	8.9238281	0.24703737
1.482743	57915.82	8.953125	0.24801457
1.4889882	58023.383	8.9824219	0.24908714
1.4933958	58124.574	9.0117188	0.2500073
1.4988631	58230.156	9.0410156	0.25091022
1.5035927	58330.059	9.0703125	0.25189924
1.5081391	58430.879	9.0996094	0.2528047
1.5125916	58525.668	9.1289063	0.25385725
1.5177548	58616.832	9.1582031	0.25481027
1.5225738	58717.215	9.1875	0.25564229
1.5273974	58814.688	9.2167969	0.25660089
1.532355	58913.438	9.2460938	0.25769085
1.5375584	59010.891	9.2753906	0.25858706
1.5422299	59111.164	9.3046875	0.25947112
1.5459627	59207.324	9.3339844	0.26043716
1.5515417	59303.418	9.3632813	0.26146579
1.5560791	59402.398	9.3925781	0.26235667
1.5610769	59505.188	9.421875	0.26339528
1.5654892	59603.152	9.4511719	0.26437652
1.5710056	59703.711	9.4804688	0.26538786
1.5755608	59800.672	9.5097656	0.26631325
1.5816718	59901.961	9.5390625	0.26732951
1.5854627	60000.57	9.5683594	0.26832452
1.5911088	60099.398	9.5976563	0.26918414
1.5947878	60188.535	9.6269531	0.27029887
1.6010509	60280.375	9.65625	0.27125105
1.6054541	60371.152	9.6855469	0.27228606
1.6095221	60468.559	9.7148438	0.27328047
1.6168177	60555.336	9.7441406	0.27421337
1.6198218	60652.777	9.7734375	0.27525926
1.625432	60749.266	9.8027344	0.27617261
1.630336	60844.363	9.8320313	0.27716643
1.6355977	60934.488	9.8613281	0.27822492
1.6393751	61029.684	9.890625	0.27914804
1.6444445	61111.605	9.9199219	0.28016123
1.6485081	61202.691	9.9492188	0.2811482
1.653774	61293	9.9785156	0.28221625
1.6593665	61379.664	10.007813	0.28315586
1.6639709	61468.059	10.037109	0.28412339
1.6688838	61557.652	10.066406	0.28510898
1.6734884	61641.207	10.095703	0.28608704
1.6783118	61734.254	10.125	0.28714478
1.6843826	61816.664	10.154297	0.28816897
1.6882181	61909.566	10.183594	0.28913784
1.6928806	61993.012	10.212891	0.29006332
1.6983614	62089.832	10.242188	0.29114547
1.7030015	62176.336	10.271484	0.29221115
1.7091169	62273.141	10.300781	0.29323974
1.7138511	62356.531	10.330078	0.29430947
1.7182901	62446.074	10.359375	0.29528284
1.723726	62527.293	10.388672	0.29637724
1.7279193	62613.617	10.417969	0.29740211
1.7337754	62692.266	10.447266	0.29844424
1.7382503	62780.613	10.476563	0.29941675
1.7426624	62855.203	10.505859	0.30033058
1.7478929	62937.523	10.535156	0.3013669
1.7529666	63004.992	10.564453	0.30234319
1.7574415	63084.531	10.59375	0.30333868
1.7615273	63152.918	10.623047	0.3043687
1.7670572	63231.363	10.652344	0.30534235
1.770942	63304.227	10.681641	0.30633444
1.7750412	63383.133	10.710938	0.30720741
1.7807543	63457.793	10.740234	0.30823475
1.784867	63540.941	10.769531	0.30922949
1.7908931	63615.352	10.798828	0.31023321
1.7957256	63696.336	10.828125	0.31118768
1.8001244	63780.25	10.857422	0.31217009
1.8057168	63871.504	10.886719	0.31335989
1.8104777	63958.438	10.916016	0.31434906
1.815632	64046.66	10.945313	0.31539842
1.8205851	64134.398	10.974609	0.31659049
1.8268347	64227.875	11.003906	0.31770548
1.8310235	64300.82	11.033203	0.31876221
1.8359721	64386.277	11.0625	0.31985149
1.8418505	64457.758	11.091797	0.32098544
1.8456995	64536.309	11.121094	0.32201713
1.8507109	64604.836	11.150391	0.32301053
1.8563569	64671.098	11.179688	0.32402414
1.8597767	64737.969	11.208984	0.3250533
1.8645599	64801.645	11.238281	0.32615921
1.8699735	64871.926	11.267578	0.32706723
1.8738315	64951.012	11.296875	0.32803243
1.8788517	65004.723	11.326172	0.32911211
1.8836305	65084.938	11.355469	0.33010903
1.8890798	65149.301	11.384766	0.3310461
1.8923432	65218.652	11.414063	0.33212563
1.8993437	65296.465	11.443359	0.33322972
1.903908	65377.699	11.472656	0.3342025
1.9087493	65446.648	11.501953	0.33524033
1.9133761	65519.012	11.53125	0.33642542
1.9183159	65585.273	11.560547	0.33739784
1.9225717	65665.422	11.589844	0.33851269
1.9292772	65729.211	11.619141	0.33952424
1.933913	65811.031	11.648438	0.34064376
1.9383028	65875.922	11.677734	0.34162116
1.9438996	65941.641	11.707031	0.34267715
1.9460902	66020.078	11.736328	0.34368208
1.9533545	66081.82	11.765625	0.34478948
1.9568727	66152.164	11.794922	0.34580776
1.9623488	66220.289	11.824219	0.34689856
1.9663677	66289.211	11.853516	0.34791896
1.972501	66357	11.882813	0.34904623
1.9769177	66426.344	11.912109	0.35023096
1.9820362	66494.469	11.941406	0.35118508
1.9863234	66556.578	11.970703	0.35225061
1.9917414	66627	12	0.35331267
1.9963413	66691.094	12.029297	0.35449931
2.0014107	66749.727	12.058594	0.35544994
2.0053089	66813.93	12.087891	0.35656959
2.011174	66871.055	12.117188	0.35751519
2.0156219	66936.922	12.146484	0.35864258
2.0212188	66995.617	12.175781	0.35960364
2.0257607	67059.094	12.205078	0.36070672
2.0300076	67120.477	12.234375	0.36169204
2.0351796	67180.203	12.263672	0.36277345
2.0399048	67248.5	12.292969	0.36384499
2.045542	67319.25	12.322266	0.36498895
2.050437	67389.734	12.351563	0.36612371
2.0544336	67462.555	12.380859	0.36717221
2.0599456	67531.852	12.410156	0.36840212
2.0646124	67598.625	12.439453	0.3695513
2.069901	67664.625	12.46875	0.37061173
2.0752833	67729.617	12.498047	0.3717393
2.0802453	67788.289	12.527344	0.37277141
2.0846395	67842.75	12.556641	0.37397185
2.0898476	67894.102	12.585938	0.37498334
2.0942867	67952.969	12.615234	0.37608516
2.0995929	68011.031	12.644531	0.37713143
2.1050513	68065.016	12.673828	0.37822372
2.1079257	68120.844	12.703125	0.37924507
2.113317	68179.102	12.732422	0.38024628
2.117367	68234.906	12.761719	0.38139266
2.1228745	68296.484	12.791016	0.38241109
2.1295533	68355.398	12.820313	0.38350165
2.1316006	68413.477	12.849609	0.38462669
2.13781	68470.133	12.878906	0.38571808
2.1421239	68532.289	12.908203	0.38683128
2.14819	68585.781	12.9375	0.38784638
2.1523073	68646.93	12.966797	0.38897336
2.1569252	68704.07	12.996094	0.39007768
2.1617799	68765.344	13.025391	0.3912527
2.167377	68820.852	13.054688	0.39238009
2.1723344	68877.164	13.083984	0.39341992
2.1769791	68931.664	13.113281	0.39456245
2.1825047	68993.016	13.142578	0.39564228
2.1864519	69050.086	13.171875	0.39680535
2.1914229	69108.063	13.201172	0.39791754
2.1973372	69157.031	13.230469	0.39892733
2.2010298	69213.164	13.259766	0.40011981
2.2058711	69261.664	13.289063	0.40117529
2.2118835	69317.313	13.318359	0.40229875
2.2161438	69366.781	13.347656	0.40338224
2.2203236	69423.477	13.376953	0.40444392
2.2264838	69475.531	13.40625	0.40557769
2.2305608	69531.297	13.435547	0.40668643
2.2354603	69580.906	13.464844	0.40788269
2.2398636	69640.32	13.494141	0.4089129
2.244638	69690.539	13.523438	0.40993753
2.2495017	69748.5	13.552734	0.41110638
2.2544906	69798.914	13.582031	0.4123252
2.259171	69858.813	13.611328	0.41333252
2.2640347	69912.219	13.640625	0.41439569
2.2699044	69969.773	13.669922	0.41566196
2.2753134	70016.578	13.699219	0.4168424
2.2785544	70073.648	13.728516	0.41798919
2.2849739	70123.891	13.757813	0.41918144
2.2894711	70178.773	13.787109	0.42035538
2.295202	70226.156	13.816406	0.42147982
2.2994802	70281.953	13.845703	0.42264292
2.304858	70329.609	13.875	0.42380086
2.309154	70386.32	13.904297	0.42499292
2.3137183	70432.039	13.933594	0.42612436
2.3195431	70483.016	13.962891	0.42726293
2.3252873	70530.789	13.992188	0.42837012
2.3284078	70583.523	14.021484	0.42962748
2.3338795	70625.734	14.050781	0.43066153
2.3388729	70674.469	14.080078	0.43185145
2.3438528	70719.469	14.109375	0.43299019
2.3483052	70773.07	14.138672	0.43411294
2.3531065	70815.117	14.167969	0.43525311
2.3582027	70865.039	14.197266	0.43628711
2.3635759	70908.086	14.226563	0.4375385
2.3688645	70957.109	14.255859	0.43854946
2.3721547	70993.328	14.285156	0.43972307
2.3780823	71048.148	14.314453	0.44092143
2.3824856	71092.281	14.34375	0.44207937
2.3872824	71143.922	14.373047	0.44322163
2.3920207	71186.359	14.402344	0.44426101
2.3971171	71232.875	14.431641	0.44558114
2.4014621	71276.43	14.460938	0.4465377
2.4060755	71323.078	14.490234	0.4476606
2.4121284	71366.086	14.519531	0.44890255
2.4159641	71414.797	14.548828	0.4500829
2.4209394	71456.156	14.578125	0.45123473
2.4269924	71508.578	14.607422	0.45231789
2.4311945	71551.547	14.636719	0.45353884
2.4364963	71600.859	14.666016	0.45460352
2.4410605	71641.797	14.695313	0.45579064
2.4456248	71686.586	14.724609	0.45705575
2.4514184	71732.055	14.753906	0.45811933
2.4555221	71777.109	14.783203	0.459362
2.4596663	71818.492	14.8125	0.46052408
2.46609	71863.703	14.841797	0.46164128
2.469568	71906.93	14.871094	0.46280977
2.4747849	71952.047	14.900391	0.4639163
2.4807796	71995.492	14.929688	0.46520898
2.4854689	72040.578	14.958984	0.46631971
2.490078	72083.172	14.988281	0.46750617
2.4941862	72125.523	15.017578	0.46861136
2.4996758	72169.734	15.046875	0.46985674
2.5044277	72214.336	15.076172	0.4709889
2.5098815	72257.367	15.105469	0.47217801
2.5146961	72300.375	15.134766	0.47341302
2.5193586	72341.055	15.164063	0.47459146
2.5246561	72377.008	15.193359	0.47567883
2.5296404	72420	15.222656	0.47700223
2.5339544	72458.703	15.251953	0.47812673
2.539578	72505.633	15.28125	0.47934681
2.5436952	72537.594	15.310547	0.48045075
2.5480537	72580.445	15.339844	0.48166651
2.5534139	72618.688	15.369141	0.48275697
2.5587468	72659.516	15.398438	0.48385623
2.5628552	72695.992	15.427734	0.48507133
2.5677772	72736.734	15.457031	0.48619395
2.5730119	72776.313	15.486328	0.48738545
2.5783315	72820.313	15.515625	0.48868915
2.5831461	72856.172	15.544922	0.48979101
2.5878892	72898.523	15.574219	0.49098781
2.5922923	72936.414	15.603516	0.49222785
2.5978222	72983.648	15.632813	0.49333978
2.6013494	73017.344	15.662109	0.49451691
2.6080995	73060.594	15.691406	0.49578676
2.6127086	73095.836	15.720703	0.4970209
2.6175723	73136.633	15.75	0.49818206
2.622901	73173.828	15.779297	0.49927393
2.6274517	73217.18	15.808594	0.50047487
2.6324451	73249.797	15.837891	0.50171041
2.6373134	73293.43	15.867188	0.50294632
2.6419356	73326.352	15.896484	0.50411403
2.6478589	73370.281	15.925781	0.50543749
2.6518912	73398.031	15.955078	0.50647181
2.6573718	73440.758	15.984375	0.50776863
2.6624277	73475.508	16.013672	0.50899076
2.6664422	73512.258	16.042969	0.5101707
2.6716278	73543.211	16.072266	0.51136154
2.6758478	73583.695	16.101563	0.5125879
2.6804969	73610.883	16.130859	0.51367152
2.686563	73650.641	16.160156	0.51483393
2.6895986	73681.406	16.189453	0.51613486
2.6958795	73719.422	16.21875	0.51735538
2.7001529	73751.289	16.248047	0.51848221
2.7049944	73791.234	16.277344	0.51960808
2.7096524	73824.648	16.306641	0.52091604
2.7156115	73863.695	16.335938	0.52205497
2.7196259	73893.766	16.365234	0.52310675
2.7247622	73926.563	16.394531	0.52429157
2.7289243	73959.188	16.423828	0.52561063
2.733685	73994.352	16.453125	0.52678758
2.7384102	74026.047	16.482422	0.52806705
2.744405	74062.133	16.511719	0.52913767
2.7478561	74095.094	16.541016	0.53027421
2.7537658	74130.984	16.570313	0.53142869
2.758558	74159.992	16.599609	0.53267568
2.7639136	74196.344	16.628906	0.5338105
2.7677269	74228.25	16.658203	0.53498715
2.7713566	74264.617	16.6875	0.5363363
2.7778699	74295.531	16.716797	0.53743654
2.7818396	74330.852	16.746094	0.53866369
2.7869985	74360.273	16.775391	0.53987443
2.793458	74401.898	16.804688	0.54090536
2.7958541	74430.977	16.833984	0.54220009
2.8027387	74470.563	16.863281	0.54342705
2.8075933	74501.555	16.892578	0.54468721
2.811867	74544.352	16.921875	0.54586148
2.8174505	74573.789	16.951172	0.54721874
2.8221936	74612.461	16.980469	0.54843611
2.8272583	74646.344	17.009766	0.54964876
2.8316526	74683.813	17.039063	0.55091351
2.8366327	74721.391	17.068359	0.55232733
2.842556	74765.234	17.097656	0.55355996
2.847424	74796.258	17.126953	0.55488563
2.8528957	74825.398	17.15625	0.55616778
2.8574243	74856.656	17.185547	0.55736351
2.8626056	74889.398	17.214844	0.5587678
2.868037	74915.422	17.244141	0.56001419
2.873446	74948.758	17.273438	0.56119496
2.8781176	74971.195	17.302734	0.56245196
2.8830216	74997.867	17.332031	0.56364185
2.8874471	75022.227	17.361328	0.56484842
2.8930397	75051.391	17.390625	0.56606734
2.8977065	75072.102	17.419922	0.56730735
2.9038131	75102.523	17.449219	0.56845593
2.9065177	75126.531	17.478516	0.56966931
2.9110999	75157.82	17.507813	0.57084799
2.9162498	75187.383	17.537109	0.57197022
2.9216275	75212.703	17.566406	0.57326216
2.9260306	75239.258	17.595703	0.57445258
2.930063	75265.688	17.625	0.5756619
2.9357984	75295.703	17.654297	0.57685477
2.9397056	75323.352	17.683594	0.57799888
2.9446006	75355.164	17.712891	0.57919043
2.949661	75383.633	17.742188	0.58051175
2.9536934	75412.641	17.771484	0.58163548
2.9602914	75440.477	17.800781	0.58282471
2.9627905	75469.953	17.830078	0.58415788
2.9688835	75501.906	17.859375	0.58528513
2.9739842	75535.422	17.888672	0.58653879
2.9782712	75558.984	17.917969	0.58770984
2.9839978	75590.797	17.947266	0.58892202
2.9892592	75620.359	17.976563	0.59024853
2.9928579	75650.305	18.005859	0.59157532
2.9987679	75681.438	18.035156	0.59268057
3.0033321	75709.875	18.064453	0.59394574
3.0083344	75736.094	18.09375	0.59512633
3.0131712	75768.375	18.123047	0.59654611
3.018415	75799.359	18.152344	0.59772402
3.023149	75831.781	18.181641	0.59906948
3.02812	75864.18	18.210938	0.60032725
3.0327513	75897.352	18.240234	0.6016311
3.0380621	75915.367	18.269531	0.60286081
3.0421348	75946.891	18.298828	0.6041376
3.048192	75975.188	18.328125	0.60540134
3.053154	76002.109	18.357422	0.60665739
3.0582905	76021.633	18.386719	0.60791218
3.063056	76050.75	18.416016	0.60926467
3.0678794	76069.203	18.445313	0.61049962
3.0718982	76094.164	18.474609	0.61172712
3.0778527	76109.789	18.503906	0.61285186
3.0825825	76136.703	18.533203	0.61413938
3.0881076	76158.367	18.5625	0.61540937
3.0918002	76184.008	18.591797	0.61663985
3.097084	76201	18.621094	0.61773837
3.1009779	76227.188	18.650391	0.61891019
3.1057744	76247.344	18.679688	0.62027091
3.1102986	76276.031	18.708984	0.62136966
3.1153858	76299.75	18.738281	0.62258804
3.1208129	76330.5	18.767578	0.62388045
3.1247869	76349.25	18.796875	0.62509137
3.1310811	76377.313	18.826172	0.6263001
3.1352208	76397.57	18.855469	0.62755024
3.1398251	76426.875	18.884766	0.62877178
3.1438663	76449.641	18.914063	0.6299777
3.1492352	76481.133	18.943359	0.63127708
3.1534598	76502.938	18.972656	0.63245559
3.1586633	76538.094	19.001953	0.63375539
3.1633348	76559.477	19.03125	0.63497943
3.1694279	76593.734	19.060547	0.63647962
3.1735182	76612.797	19.089844	0.63767028
3.1790972	76644.18	19.119141	0.63884521
3.1841352	76663.289	19.148438	0.64017189
3.1893835	76691.711	19.177734	0.6414265
3.194113	76710.953	19.207031	0.6426394
3.1972556	76734.008	19.236328	0.6440329
3.2030807	76754.078	19.265625	0.64524049
3.207077	76775.609	19.294922	0.64646626
3.2128839	76798.563	19.324219	0.64785314
3.2182262	76824.516	19.353516	0.64905065
3.2226114	76843.852	19.382813	0.65028399
3.2271311	76872.313	19.412109	0.6516149
3.2316594	76887.43	19.441406	0.65277487
3.2377303	76917.461	19.470703	0.65396851
3.2426252	76935.578	19.5	0.65528184
3.2475069	76963.008	19.529297	0.65660852
3.2522991	76982.844	19.558594	0.6577872
3.2564521	77006.305	19.587891	0.65910119
3.2614052	77025.094	19.617188	0.66036934
3.2674403	77056.648	19.646484	0.66159195
3.270556	77072.75	19.675781	0.66287643
3.2755449	77098.898	19.705078	0.66409093
3.2826617	77115.805	19.734375	0.66545415
3.2852321	77143.859	19.763672	0.66668862
3.2895327	77163.039	19.792969	0.66793001
3.294383	77186.242	19.822266	0.66917825
3.3016071	77209.375	19.851563	0.67052895
3.3059478	77236.633	19.880859	0.67176664
3.3114686	77254.883	19.910156	0.6731087
3.3159838	77278.359	19.939453	0.674254
3.3210173	77302.922	19.96875	0.67574072
3.325577	77326.695	19.998047	0.67695636
3.330034	77348.828	20.027344	0.67828035
3.3355057	77371.344	20.056641	0.67964286
3.3410401	77390.469	20.085938	0.68081945
3.3451974	77415.555	20.115234	0.68217617
3.3495874	77432.961	20.144531	0.6834864
3.3551528	77455.977	20.173828	0.68482
3.3602266	77477.102	20.203125	0.68599707
3.3652828	77498.359	20.232422	0.6873039
3.3705935	77515.164	20.261719	0.68866891
3.3752785	77539.023	20.291016	0.6899606
3.3806114	77558.406	20.320313	0.69132024
3.3846169	77577.367	20.349609	0.69251722
3.3903389	77593.68	20.378906	0.69383639
3.3947377	77611.203	20.408203	0.69517273
3.3998117	77626.352	20.4375	0.696401
3.404139	77646.484	20.466797	0.6976074
3.4091413	77666.352	20.496094	0.69897741
3.4146712	77684.938	20.525391	0.70021451
3.4188643	77702.727	20.554688	0.70147675
3.4231067	77719.148	20.583984	0.70263457
3.4287663	77737.359	20.613281	0.70402706
3.432946	77755.305	20.642578	0.70525563
3.4381316	77776.172	20.671875	0.70646513
3.442745	77794.484	20.701172	0.70783073
3.4477963	77818.281	20.730469	0.70907187
3.4528165	77836.773	20.759766	0.71035999
3.4576983	77854.234	20.789063	0.71169335
3.4622402	77874.188	20.818359	0.71284771
3.4675195	77897.344	20.847656	0.71429265
3.4727991	77919.461	20.876953	0.71547639
3.4765811	77938.359	20.90625	0.71684659
3.4825177	77959.063	20.935547	0.71808976
3.4871533	77979.039	20.964844	0.71943039
3.4919949	77998.281	20.994141	0.72056037
3.4968138	78020.25	21.023438	0.72184485
3.5007386	78035.734	21.052734	0.72325176
3.5063088	78055.82	21.082031	0.72457182
3.5115972	78076.055	21.111328	0.7258324
3.5157948	78096.188	21.140625	0.72716856
3.521481	78114.336	21.169922	0.72839236
3.5266891	78131.141	21.199219	0.72975409
3.5303144	78144.156	21.228516	0.73106676
3.5351918	78166.734	21.257813	0.7324549
3.5407929	78183.578	21.287109	0.73364633
3.5457864	78205.414	21.316406	0.73499227
3.550878	78219.945	21.345703	0.73614973
3.554754	78240.234	21.375	0.73749864
3.5605564	78251.359	21.404297	0.73875284
3.5652504	78275.633	21.433594	0.74004596
3.57095	78288.797	21.462891	0.74139738
3.5760374	78304.711	21.492188	0.74274987
3.580369	78315.961	21.521484	0.74397498
3.5846472	78332.188	21.550781	0.74519825
3.5899401	78328.234	21.580078	0.74638426
3.5947056	78341.445	21.609375	0.74761748
3.5983219	78367.164	21.638672	0.74881589
3.6036685	78388.703	21.667969	0.75011516
3.6073878	78415.141	21.697266	0.7514832
3.6130965	78451.602	21.726563	0.75278652
3.6192746	78470.414	21.755859	0.75414234
3.6236153	78498.5	21.785156	0.75548661
3.6288991	78516.625	21.814453	0.75690639
3.6332712	78540.852	21.84375	0.75836927
3.6389217	78546.766	21.873047	0.75964504
3.644769	78570.609	21.902344	0.76099724
3.649056	78581.406	21.931641	0.76223904
3.6548495	78598.281	21.960938	0.76370466
3.659512	78604.32	21.990234	0.76492661
3.6644742	78623.039	22.019531	0.76624411
3.6688149	78632.813	22.048828	0.76759237
3.6737635	78649.797	22.078125	0.76882428
3.6788554	78663.578	22.107422	0.77012593
3.6826775	78680.5	22.136719	0.77152747
3.6878719	78692.813	22.166016	0.77283013
3.6928878	78712.281	22.195313	0.77415383
3.6990569	78724.57	22.224609	0.77546293
3.7032232	78740.102	22.253906	0.77670968
3.7072687	78747.453	22.283203	0.77794415
3.7122397	78769.883	22.3125	0.77923781
3.7171171	78778.086	22.341797	0.78055549
3.7217035	78798.508	22.371094	0.78183156
3.7265136	78808.32	22.400391	0.78320789
3.7312613	78827.984	22.429688	0.78451496
3.7362547	78841.773	22.458984	0.78575927
3.7407608	78856.758	22.488281	0.78704524
3.7455707	78871.109	22.517578	0.78829557
3.7501483	78890.75	22.546875	0.78950834
3.7548423	78905.438	22.576172	0.79094976
3.7610202	78920.219	22.605469	0.79220122
3.76596	78932.961	22.634766	0.79349267
3.7697287	78947.789	22.664063	0.79473555
3.775008	78961.094	22.693359	0.79600304
3.7792416	78973.727	22.722656	0.79729003
3.7843823	78985.469	22.751953	0.79861635
3.7892551	79004.188	22.78125	0.79993814
3.7936897	79015.227	22.810547	0.80126047
3.7981689	79032.148	22.839844	0.80245006
3.8038821	79049.594	22.869141	0.80374426
3.8079991	79062.727	22.898438	0.80509698
3.8130462	79076.266	22.927734	0.80639988
3.8189425	79094.664	22.957031	0.80769432
3.8223042	79107.984	22.986328	0.80899841
3.8277671	79130.219	23.015625	0.81027108
3.8320944	79146.75	23.044922	0.81161904
3.8366051	79162.242	23.074219	0.81297261
3.8420901	79180.969	23.103516	0.81423688
3.8468509	79195.328	23.132813	0.81572068
3.851907	79206.797	23.162109	0.81699336
3.8576915	79224.75	23.191406	0.81837946
3.8631141	79235.93	23.220703	0.81970739
3.8671956	79250.508	23.25	0.82099557
3.8725824	79264.969	23.279297	0.82233918
3.8758144	79283.453	23.308594	0.82370925
3.8823366	79294.477	23.337891	0.82509118
3.887634	79306.406	23.367188	0.82638007
3.8907542	79316.461	23.396484	0.82770264
3.8966908	79325.719	23.425781	0.82889551
3.9011791	79339.398	23.455078	0.83021259
3.9059803	79350.938	23.484375	0.83158755
3.9107232	79370.266	23.513672	0.83292037
3.9161592	79379.789	23.542969	0.83420187
3.9203434	79395.406	23.572266	0.83561605
3.9255559	79407.102	23.601563	0.83694011
3.930366	79424.766	23.630859	0.83831012
3.9353862	79436.297	23.660156	0.83950347
3.9395838	79452.18	23.689453	0.84087849
3.9442644	79462.125	23.71875	0.84218353
3.9489894	79478.086	23.748047	0.84356153
3.9551497	79490.539	23.777344	0.84495443
3.9590299	79505.047	23.806641	0.84626353
3.9655254	79519.695	23.835938	0.84760422
3.9692402	79532.188	23.865234	0.84896851
3.9754496	79545.32	23.894531	0.85034615
3.9795308	79559.938	23.923828	0.85163188
3.9842873	79574.773	23.953125	0.85304892
3.9898798	79590.625	23.982422	0.8544687
3.9948688	79607.461	24.011719	0.85575342
3.9998622	79622.477	24.041016	0.85714847
4.0049582	79628.555	24.070313	0.85843432
4.0098801	79645.242	24.099609	0.85987192
4.0152936	79652.438	24.128906	0.86115479
4.0199118	79671.797	24.158203	0.86261857
4.0248961	79680.023	24.1875	0.86395484
4.0292902	79701.609	24.216797	0.86538839
4.0343242	79709.164	24.246094	0.86682451
4.0394158	79725.797	24.275391	0.86808985
4.0432782	79732.031	24.304688	0.86948496
4.0496931	79749.508	24.333984	0.87091601
4.0550842	79757.344	24.363281	0.87217051
4.060431	79770.773	24.392578	0.87363583
4.064034	79777.438	24.421875	0.87505233
4.0693045	79792.93	24.451172	0.87633896
4.0750222	79798.969	24.480469	0.87773967
4.0794029	79810.016	24.509766	0.87916118
4.0839539	79817.258	24.539063	0.88039118
4.0890722	79830.82	24.568359	0.8817237
4.0925012	79832.039	24.597656	0.88311958
4.09694	79843.281	24.626953	0.88435328
4.102376	79845.078	24.65625	0.88562405
4.1080756	79858.07	24.685547	0.88698506
4.1129665	79862.109	24.714844	0.88829243
4.1173472	79878.195	24.744141	0.88948417
4.1228862	79885.672	24.773438	0.89081144
4.1258545	79902.805	24.802734	0.89206052
4.1315851	79909.484	24.832031	0.89342892
4.1367664	79924.094	24.861328	0.89475077
4.1399941	79932.484	24.890625	0.8961513
4.1454611	79945.617	24.919922	0.89734197
4.1505308	79951.375	24.949219	0.898682
4.154974	79967.633	24.978516	0.90016121
4.1600304	79979.703	25.007813	0.90136397
4.164094	79992.813	25.037109	0.90270674
4.1682825	80007.453	25.066406	0.90404898
4.1733699	80021.023	25.095703	0.90541029
4.1788998	80030.68	25.125	0.90668386
4.1833029	80045.906	25.154297	0.90805125
4.1887121	80055.609	25.183594	0.90944779
4.1936069	80073.703	25.212891	0.91086781
4.1992083	80087.563	25.242188	0.91214567
4.202847	80097.523	25.271484	0.91353095
4.2083635	80112.727	25.300781	0.91493362
4.2139111	80125.539	25.330078	0.91631728
4.2192802	80137.578	25.359375	0.9177866
4.2222619	80145.047	25.388672	0.91908592
4.2288022	80157.719	25.417969	0.92051536
4.2335944	80168.664	25.447266	0.92186183
4.23806	80178.891	25.476563	0.92328691
4.244627	80190.727	25.505859	0.92452568
4.2472067	80204.711	25.535156	0.92604482
4.2527857	80211.445	25.564453	0.92737627
4.2584939	80223.625	25.59375	0.92885953
4.2645068	80230.93	25.623047	0.93015015
4.2679625	80242.391	25.652344	0.93154556
4.270555	80253.625	25.681641	0.93294311
4.2776494	80262.344	25.710938	0.93441164
4.2813244	80273.773	25.740234	0.9357307
4.2888746	80284.547	25.769531	0.93714541
4.2929382	80294.555	25.798828	0.93850571
4.2974262	80307.727	25.828125	0.93997371
4.3027639	80312.148	25.857422	0.94132626
4.3086824	80327.578	25.886719	0.9427318
4.3123035	80329.922	25.916016	0.94407958
4.3187947	80347.305	25.945313	0.94556451
4.3230281	80348.883	25.974609	0.94690937
4.3282495	80361.367	26.003906	0.94832325
4.3326931	80366.313	26.033203	0.94971651
4.3376818	80381.094	26.0625	0.95106888
4.3423533	80383.313	26.091797	0.95239758
4.3472886	80393.25	26.121094	0.95377523
4.3518662	80398.406	26.150391	0.95515478
4.3558135	80408.352	26.179688	0.95656508
4.3620768	80415.148	26.208984	0.95791948
4.3663683	80429.844	26.238281	0.95929724
4.3703556	80434.016	26.267578	0.96071291
4.377079	80448.211	26.296875	0.96200794
4.3809013	80454.695	26.326172	0.96338612
4.3855233	80463.617	26.355469	0.9648518
4.391058	80471.547	26.384766	0.9661476
4.3962522	80480.039	26.414063	0.96750236
4.4006467	80483.813	26.443359	0.9688068
4.4044242	80501.133	26.472656	0.97027159
4.4104948	80506.133	26.501953	0.9717176
4.4159575	80523.07	26.53125	0.97303128
4.4193373	80526.266	26.560547	0.97433954
4.4238386	80539.789	26.589844	0.97568977
4.4293418	80542.242	26.619141	0.97709811
4.4345455	80557.109	26.648438	0.97853303
4.4397712	80563.523	26.677734	0.97987986
4.444778	80576.836	26.707031	0.98128927
4.4493914	80583.055	26.736328	0.98260826
4.453084	80596.195	26.765625	0.98406619
4.458426	80599.242	26.794922	0.9853844
4.4643359	80612.844	26.824219	0.98680151
4.4687614	80617.539	26.853516	0.98823845
4.4735537	80625.945	26.882813	0.98956811
4.4789805	80633.102	26.912109	0.99092811
4.4833884	80643.156	26.941406	0.99226928
4.4881401	80646.656	26.970703	0.99360687
4.4926109	80659.625	27	0.99505568
4.4980912	80664.734	27.029297	0.99637127
4.5022578	80674.641	27.058594	0.99782449
4.5075998	80678.695	27.087891	0.99913889
4.5122442	80688.578	27.117188	1.0004785
4.5166969	80695.727	27.146484	1.0019656
4.5218916	80708.727	27.175781	1.0032097
4.5264244	80713.352	27.205078	1.004728
4.5314713	80726.727	27.234375	1.0061023
4.5368581	80730.828	27.263672	1.0075294
4.5419545	80748.25	27.292969	1.0089414
4.5459776	80750.375	27.322266	1.0101584
4.5521064	80757.992	27.351563	1.0116398
4.5560942	80767.555	27.380859	1.0131173
4.5616956	80774.531	27.410156	1.0144167
4.5660362	80782.25	27.439453	1.0158458
4.5718474	80791.633	27.46875	1.017195
4.5753121	80798.766	27.498047	1.0186713
4.5805917	80806.297	27.527344	1.0199826
4.5854554	80814.922	27.556641	1.021399
4.589282	80824.266	27.585938	1.0228524
4.5953617	80830.078	27.615234	1.0241603
4.6004577	80839.258	27.644531	1.0255821
4.6046109	80843.828	27.673828	1.0269701
4.6097474	80853.563	27.703125	1.0283221
4.6141682	80865.43	27.732422	1.0299391
4.6195016	80874.25	27.761719	1.0312674
4.6250091	80884.398	27.791016	1.032645
4.6301322	80890.594	27.820313	1.0340512
4.6340437	80895.328	27.849609	1.0355328
4.6396537	80904.211	27.878906	1.0368744
4.6444731	80916.922	27.908203	1.038386
4.6493993	80925.93	27.9375	1.0398579
4.6544776	80934.297	27.966797	1.0411739
4.6598687	80947.82	27.996094	1.0425695
4.6653895	80956.867	28.025391	1.0441188
4.6697526	80964.25	28.054688	1.0455319
4.675108	80972.828	28.083984	1.0470629
4.6800165	80977.891	28.113281	1.0484929
4.6844645	80981.523	28.142578	1.0498658
4.6902447	80986.898	28.171875	1.0512722
4.694572	80995.352	28.201172	1.052652
4.6993732	80996.969	28.230469	1.0541612
4.7046437	80981.477	28.259766	1.055463
4.7104912	80992.992	28.289063	1.056766
4.7143221	81005.195	28.318359	1.0583204
4.7189445	81017.789	28.347656	1.0597006
4.7229233	81026.766	28.376953	1.0611241
4.7286496	81030.836	28.40625	1.0625486
4.7339201	81045.406	28.435547	1.0640404
4.7370448	81045.633	28.464844	1.0653609
4.7431245	81053.477	28.494141	1.066819
4.7471657	81058.617	28.523438	1.0682237
4.7526999	81062.227	28.552734	1.0696449
4.7579126	81062.344	28.582031	1.0709934
4.7612071	81072.234	28.611328	1.0723621
4.7666698	81068.797	28.640625	1.0737603
4.7715425	81079.656	28.669922	1.0751084
4.7757177	81082.5	28.699219	1.076558
4.7814398	81089.031	28.728516	1.0780069
4.7863975	81092.438	28.757813	1.079294
4.7903404	81106.641	28.787109	1.0806336
4.7953696	81111.664	28.816406	1.0820841
4.8000994	81124.828	28.845703	1.0836003
4.8058391	81131.93	28.875	1.0849621
4.8111453	81148.141	28.904297	1.0865021
4.8158793	81153.445	28.933594	1.0878545
4.8207164	81160.359	28.962891	1.0891621
4.8249006	81162.367	28.992188	1.0906968
4.8306718	81168.406	29.021484	1.0920165
4.8347754	81167.445	29.050781	1.0935286
4.8392415	81179.82	29.080078	1.0949904
4.8444538	81179.742	29.109375	1.096247
4.8499079	81189.633	29.138672	1.0976924
4.8543959	81192.078	29.167969	1.0992266
4.8593402	81203.883	29.197266	1.1005299
4.8651605	81205.875	29.226563	1.1019969
4.8693271	81214.633	29.255859	1.1033638
4.8735647	81217.719	29.285156	1.1046853
4.8774185	81227.367	29.314453	1.1061398
4.8833551	81228.109	29.34375	1.1075959
4.8890772	81241.258	29.373047	1.1090864
4.8936634	81246.172	29.402344	1.1104392
4.897356	81256.602	29.431641	1.1118348
4.9032121	81257.211	29.460938	1.1132914
4.907146	81266.477	29.490234	1.114742
4.9125152	81270.984	29.519531	1.1161704
4.9156399	81277.555	29.548828	1.1176422
4.9229307	81274.586	29.578125	1.1189615
4.9274101	81286.023	29.607422	1.1204017
4.932332	81289.406	29.636719	1.1218467
4.9367266	81300.617	29.666016	1.1233019
4.9415679	81301.789	29.695313	1.1246998
4.9469857	81313.969	29.724609	1.1261286
4.9518719	81317.172	29.753906	1.1275485
4.9572048	81321.469	29.783203	1.129065
4.960844	81328.656	29.8125	1.13046
4.9663558	81333.57	29.841797	1.1318057
4.9715147	81341.844	29.871094	1.1332549
4.9756498	81345.063	29.900391	1.1347955
4.9807816	81350.406	29.929688	1.136158
4.9856229	81362.453	29.958984	1.1375663
4.9909472	81362.586	29.988281	1.1391454
4.9965038	81374.82	30.017578	1.1405635
5.00105	81378.922	30.046875	1.1420017
5.0055652	81387.953	30.076172	1.1433742
5.0103621	81389.227	30.105469	1.1449112
5.0168262	81397.898	30.134766	1.1463884
5.0211802	81399.211	30.164063	1.1477562
5.0257893	81405.844	30.193359	1.1493682
5.0296516	81407.07	30.222656	1.1507401
5.0354047	81414.656	30.251953	1.152225
5.0402284	81418.594	30.28125	1.1536552
5.045186	81419.031	30.310547	1.1550076
5.0494013	81424.094	30.339844	1.1566033
5.0554142	81426.891	30.369141	1.1579099
5.0592585	81433.266	30.398438	1.1593894
5.064064	81433.664	30.427734	1.1607659
5.0702825	81438.016	30.457031	1.1623263
5.0742207	81441.906	30.486328	1.163653
5.0782666	81444.898	30.515625	1.1650993
5.0832911	81450.766	30.544922	1.1665711
5.0890131	81456.406	30.574219	1.1679572
5.0928888	81460.078	30.603516	1.1693871
5.0975785	81471.961	30.632813	1.1708503
5.1018658	81478.906	30.662109	1.172183
5.1089602	81489	30.691406	1.1737682
5.1133409	81493.914	30.720703	1.1752275
5.1182179	81502.93	30.75	1.1766924
5.1235514	81504.273	30.779297	1.1781704
5.1276326	81511.117	30.808594	1.1796395
5.1334085	81514.711	30.837891	1.1812274
5.1379638	81522.211	30.867188	1.1826673
5.1435246	81525.266	30.896484	1.1839793
5.1481113	81531.922	30.925781	1.1856198
5.1515088	81526.594	30.955078	1.1869037
5.1571326	81533.063	30.984375	1.188457
5.1624522	81533.5	31.013672	1.1899278
5.1684246	81538	31.042969	1.1913793
5.1718178	81539.922	31.072266	1.1928308
5.1769228	81545.555	31.101563	1.1942379
5.181746	81548.539	31.130859	1.1957257
5.1867127	81556.852	31.160156	1.197197
5.1907806	81552.844	31.189453	1.1986421
5.1953049	81559.852	31.21875	1.2001224
5.2001147	81560.703	31.248047	1.2015382
5.2049694	81565.297	31.277344	1.2030202
5.2113042	81567.508	31.306641	1.2044179
5.2158775	81573.594	31.335938	1.2058302
5.2195921	81576.656	31.365234	1.2072637
5.2246571	81588.109	31.394531	1.208704
5.2307186	81587.289	31.423828	1.210171
5.2349658	81593.586	31.453125	1.211598
5.240397	81596.508	31.482422	1.2130624
5.2444654	81610.492	31.511719	1.2145462
5.2507105	81609.492	31.541016	1.2159892
5.2552476	81617.898	31.570313	1.217486
5.2587481	81619.523	31.599609	1.2189305
5.2659049	81627.414	31.628906	1.2204609
5.2684755	81630.484	31.658203	1.2219144
5.2741928	81637.859	31.6875	1.2233493
5.2783546	81630.563	31.716797	1.2248511
5.2837191	81640.859	31.746094	1.2262392
5.2876263	81639.813	31.775391	1.2277359
5.2932634	81647.203	31.804688	1.2292618
5.298409	81648.047	31.833984	1.2307478
5.3026466	81654.352	31.863281	1.2320884
5.3074794	81652.422	31.892578	1.2336242
5.3129869	81661.664	31.921875	1.2350922
5.3181543	81663.844	31.951172	1.2364519
5.3230362	81666.141	31.980469	1.2379017
5.327198	81670.422	32.009766	1.239445
5.3325624	81678.055	32.039063	1.2408849
5.3370371	81674.484	32.068359	1.2424374
5.341445	81685.383	32.097656	1.2438387
5.3465724	81683.07	32.126953	1.2452229
5.350913	81692.703	32.15625	1.2467791
5.3562684	81692.313	32.185547	1.24822
5.3607521	81696.766	32.214844	1.2497329
5.3663044	81699.164	32.244141	1.2512374
5.3709893	81703.898	32.273438	1.2527137
5.3753524	81706.609	32.302734	1.2541829
5.3822546	81714.938	32.332031	1.2556115
5.3848252	81712.992	32.361328	1.2571754
5.3904533	81725.859	32.390625	1.2586199
5.3953304	81723.586	32.419922	1.2600756
5.4009228	81731	32.449219	1.2614964
5.4052725	81729.977	32.478516	1.2630976
5.4110661	81736.859	32.507813	1.2644705
5.4139986	81737.898	32.537109	1.2660266
5.4198461	81746.305	32.566406	1.2674539
5.424799	81751.148	32.595703	1.2690471
5.5544434	2071.0342	32.625	1.8076445
5.4894805	560.80518	32.654297	2.0802813
5.4478884	2383.2271	32.683594	1.8114815
5.4592161	1439.1381	32.712891	1.9141592
5.4678621	-684.67334	32.742188	1.892321
5.4669366	251.61496	32.771484	1.9078046
5.4766102	-916.16064	32.800781	1.9171267
5.4781346	98.6614	32.830078	1.9072281
5.482945	246.8602	32.859375	1.917613
5.487165	474.0311	32.888672	1.8950719
5.4923506	435.98679	32.917969	1.9013398
5.4974599	62.729931	32.947266	1.9117217
5.5020599	-272.06552	32.976563	1.9025478
5.5063157	-498.49158	33.005859	1.9340197
5.5105405	-412.09753	33.035156	1.9324222
5.5151315	-125.03366	33.064453	1.9323014
5.5192351	228.47345	33.09375	1.9348251
5.5242019	428.06216	33.123047	1.9323746
5.5291505	375.64246	33.152344	1.9467483
5.5336924	116.93803	33.181641	1.9523844
5.5397229	-226.01498	33.210938	1.9579145
5.5443363	-406.62021	33.240234	1.966252
5.5484133	-364.02432	33.269531	1.9691998
5.5491371	-122.05367	33.298828	1.9722199
5.5491419	164.37575	33.328125	1.9692711
5.5474253	358.33871	33.357422	1.9639815
5.546196	319.62805	33.386719	1.9614528
5.5463076	103.1257	33.416016	1.9637507
5.5439205	-162.94502	33.445313	1.9717844
5.5444794	-339.21585	33.474609	1.9732345
5.5448589	-313.50284	33.503906	1.9747794
5.5459142	-117.77773	33.533203	1.9738079
5.5451541	128.86536	33.5625	1.9716456
5.5445104	294.08627	33.591797	1.9702216
5.5436611	272.81326	33.621094	1.9707255
5.5447073	92.960541	33.650391	1.9729348
5.5439472	-143.11191	33.679688	1.9731504
5.5448904	-285.06665	33.708984	1.9743545
5.544837	-267.25909	33.738281	1.9762602