File: data/T2.dat
MTS793|MPT|ENU|1|2|.|/|:|1|0|0|A

Data Acquisition						Time:	10.008789	s	2/4/2020 10:38:57 AM
Axial Displacement	Axial Force	Time	Axial Extensometer
mm	N	s	mm
-0.00048726797	279.57092	0.017578125	-0.00047142748
0.00066608191	281.19797	0.046875	-0.00038454455
0.00058561563	285.21777	0.076171875	-0.00038186699
0.00083148479	324.40152	0.10546875	-0.00021998785
0.0042960048	586.14441	0.13476563	0.00050133024
0.011184812	948.78979	0.1640625	0.0016511738
0.017671287	1297.7261	0.19335938	0.0027803043
0.023531914	1611.5315	0.22265625	0.0037268903
0.028963387	1881.6516	0.25195313	0.00455881
0.033581257	2135.8252	0.28125	0.0053373259
0.03734082	2375.7288	0.31054688	0.0060956143
0.043219328	2602.1855	0.33984375	0.0068583684
0.046889484	2836.7773	0.36914063	0.0076277158
0.050295889	3077.4148	0.3984375	0.0082801757
0.055919588	3317.127	0.42773438	0.0089276386
0.061096251	3563.1648	0.45703125	0.0097861988
0.065866113	3816.8293	0.48632813	0.010587159
0.070989132	4072.4763	0.515625	0.01139078
0.075271726	4318.9028	0.54492188	0.012186785
0.080434978	4569.0181	0.57421875	0.012895554
0.085119903	4819.3237	0.60351563	0.013693828
0.090274215	5075.0903	0.6328125	0.014441643
0.09393096	5332.1191	0.66210938	0.015269214
0.10043979	5589.8906	0.69140625	0.016087534
0.10550916	5846.9971	0.72070313	0.016863499
0.11115521	6128.3472	0.75	0.017720636
0.11505783	6404.7598	0.77929688	0.018628849
0.12166947	6688.9966	0.80859375	0.019511374
0.12782067	6951.8652	0.83789063	0.020265881
0.13188422	7214.3223	0.8671875	0.021055728
0.13729334	7464.8315	0.89648438	0.021856317
0.14294386	7700.1851	0.92578125	0.022636993
0.14682859	7921.1245	0.95507813	0.023268003
0.15193373	8149.3853	0.984375	0.02408048
0.15679747	8362.2402	1.0136719	0.024723575
0.16017258	8575.4639	1.0429688	0.025325095
0.16523302	8790.1758	1.0722656	0.026011247
0.16953796	9021.6563	1.1015625	0.02674412
0.17400384	9245.3018	1.1308594	0.027569436
0.17890781	9490.8809	1.1601563	0.028161135
0.18430352	9733.4668	1.1894531	0.029017122
0.18964112	9990.7119	1.21875	0.029781971
0.19393265	10246.696	1.2480469	0.030495802
0.19927472	10503.91	1.2773438	0.031197019
0.20421445	10760.374	1.3066406	0.032061305
0.2105087	11019.922	1.3359375	0.03286168
0.21478683	11263.877	1.3652344	0.033642016
0.22095144	11518.824	1.3945313	0.034560569
0.22449195	11765.521	1.4238281	0.035258666
0.23069233	12018.84	1.453125	0.036051977
0.23559183	12258.905	1.4824219	0.036819119
0.24031699	12501.065	1.5117188	0.037535045
0.24573058	12731.976	1.5410156	0.038268596
0.25019646	12965.088	1.5703125	0.039016619
0.25512725	13193.071	1.5996094	0.039751623
0.25982559	13420.555	1.6289063	0.040394753
0.2654314	13646.736	1.6582031	0.041155383
0.2691105	13879.334	1.6875	0.04189305
0.27393848	14098.699	1.7167969	0.042614162
0.28075129	14334.688	1.7460938	0.043253273
0.28363019	14556.957	1.7753906	0.044060264
0.28881133	14788.027	1.8046875	0.044679157
0.29341131	15016.688	1.8339844	0.045476906
0.29783249	15242.151	1.8632813	0.046175916
0.30370206	15472.583	1.8925781	0.046984646
0.30804276	15703.464	1.921875	0.047644455
0.31277686	15932.11	1.9511719	0.048363544
0.31726956	16164.063	1.9804688	0.049110394
0.3224194	16386.123	2.0097656	0.049858764
0.32610744	16620.408	2.0390625	0.050596062
0.33255816	16852.041	2.0683594	0.051230486
0.33712238	17087.445	2.0976563	0.051999394
0.34201741	17323.01	2.1269531	0.052779559
0.34730583	17571.338	2.15625	0.053570803
0.35263896	17815.111	2.1855469	0.054430619
0.3576681	18066.063	2.2148438	0.055115119
0.36273748	18313.137	2.2441406	0.055987615
0.36780238	18545.816	2.2734375	0.056543823
0.37332326	18782.914	2.3027344	0.057404872
0.37778467	19011.916	2.3320313	0.058149993
0.38369447	19237.986	2.3613281	0.058947627
0.38776249	19465.252	2.390625	0.059539862
0.39325655	19694.865	2.4199219	0.060338922
0.39771795	19914.109	2.4492188	0.061031956
0.40203184	20139.721	2.4785156	0.061702374
0.40749907	20358.447	2.5078125	0.062464897
0.4111737	20590.471	2.5371094	0.063177504
0.41576028	20809.475	2.5664063	0.063792862
0.422059	21033.441	2.5957031	0.064551532
0.42604655	21247.162	2.625	0.065296292
0.43121874	21467.592	2.6542969	0.066021763
0.4365027	21681.607	2.6835938	0.066649213
0.4414469	21898.037	2.7128906	0.067335472
0.44580996	22108.547	2.7421875	0.068027996
0.45105815	22333.186	2.7714844	0.068780296
0.45542568	22546.516	2.8007813	0.069484264
0.46055317	22769.879	2.8300781	0.070135981
0.46518892	22988.773	2.859375	0.070979059
0.470303	23214.266	2.8886719	0.071682274
0.47543049	23434.783	2.9179688	0.072354443
0.48034787	23663.451	2.9472656	0.073223591
0.48529208	23879.543	2.9765625	0.073919043
0.49055368	24106.963	3.0058594	0.074624144
0.49543083	24317.68	3.0351563	0.075318769
0.49933791	24541.545	3.0644531	0.076015308
0.50480515	24758.416	3.09375	0.076800056
0.50988346	24974.125	3.1230469	0.077520646
0.51483214	25168.461	3.1523438	0.078216426
0.52111745	25397.439	3.1816406	0.078828573
0.52473396	25638.479	3.2109375	0.07977026
0.53039789	25869.324	3.2402344	0.080443472
0.53527951	26103.316	3.2695313	0.081258297
0.54099262	26333.158	3.2988281	0.082063094
0.54584295	26553.086	3.328125	0.082820423
0.55085868	26774.316	3.3574219	0.083537392
0.55538714	26991.912	3.3867188	0.084285714
0.56085438	27207.814	3.4160156	0.084949233
0.56574494	27415.973	3.4453125	0.085717022
0.56984872	27623.682	3.4746094	0.086385868
0.57483315	27829.711	3.5039063	0.08716616
0.58016181	28034.91	3.5332031	0.08772067
0.58431029	28234.082	3.5625	0.088589713
0.5884096	28438.865	3.5917969	0.089190878
0.59457868	28642.48	3.6210938	0.090023614
0.59968829	28850.213	3.6503906	0.090655319
0.60330927	29055.109	3.6796875	0.091323078
0.60874522	29257	3.7089844	0.092183717
0.61353296	29463.791	3.7382813	0.092792913
0.6177932	29666.949	3.7675781	0.09346579
0.62223673	29868.193	3.796875	0.094258733
0.62766373	30072.107	3.8261719	0.09499681
0.63169152	30275.814	3.8554688	0.095634803
0.63711405	30480.471	3.8847656	0.096312776
0.64090937	30678.447	3.9140625	0.097072497
0.64719915	30882.086	3.9433594	0.097825363
0.651218	31086.947	3.9726563	0.098565929
0.65634549	31292.367	4.0019531	0.099208258
0.66018999	31497.244	4.03125	0.09986487
0.66646188	31695.566	4.0605469	0.10072386
0.67130327	31898.148	4.0898438	0.1013542
0.67609102	32098.133	4.1191406	0.10221834
0.68087876	32302.029	4.1484375	0.10281266
0.68593919	32503.258	4.1777344	0.10355504
0.69033802	32711.467	4.2070313	0.10429475
0.69621652	32914.172	4.2363281	0.10507225
0.70080757	33128.645	4.265625	0.10589243
0.70640445	33331.547	4.2949219	0.1066066
0.71035177	33535.137	4.3242188	0.10742398
0.7162258	33729.227	4.3535156	0.10809978
0.72250217	33929.848	4.3828125	0.10881118
0.72503239	34119.086	4.4121094	0.1096032
0.73182732	34317.637	4.4414063	0.11032958
0.73590875	34504.965	4.4707031	0.1109636
0.7399857	34699.863	4.5	0.11170854
0.74564517	34891.164	4.5292969	0.11250571
0.74976683	35078.547	4.5585938	0.1131354
0.75439811	35266.828	4.5878906	0.11398234
0.75989664	35460.305	4.6171875	0.1147469
0.76395571	35641.332	4.6464844	0.11537147
0.76864064	35843.645	4.6757813	0.11612821
0.77349097	36042.906	4.7050781	0.11691705
0.77964664	36252.715	4.734375	0.11766431
0.78429133	36450.184	4.7636719	0.11854295
0.79003572	36651.195	4.7929688	0.11924468
0.79436749	36839.496	4.8222656	0.12004951
0.79973638	37037.637	4.8515625	0.12077803
0.8039251	37221.027	4.8808594	0.12148399
0.80972761	37413.176	4.9101563	0.12232747
0.81513226	37605.59	4.9394531	0.12304107
0.81951767	37796.164	4.96875	0.1237687
0.82368404	37972.449	4.9980469	0.12449694
0.82912892	38155.793	5.0273438	0.12512076
0.83439946	38331.887	5.0566406	0.12593596
0.83793998	38518.656	5.0859375	0.12673274
0.84268302	38688.277	5.1152344	0.12745506
0.84805638	38865.016	5.1445313	0.12816833
0.85262954	39033.734	5.1738281	0.12883991
0.85623264	39205.75	5.203125	0.12959929
0.8621648	39377.926	5.2324219	0.13027944
0.86634457	39549.254	5.2617188	0.13109659
0.87213367	39723.48	5.2910156	0.13169263
0.87671131	39906.398	5.3203125	0.13246012
0.88169575	40089.922	5.3496094	0.13315032
0.88668913	40276.492	5.3789063	0.13404302
0.89255869	40466.684	5.4082031	0.13479944
0.89595169	40661.68	5.4375	0.13568959
0.90204477	40847.289	5.4667969	0.13649389
0.90772212	41028.93	5.4960938	0.13724832
0.9123534	41205.469	5.5253906	0.13798754
0.91654658	41377.414	5.5546875	0.13876785
0.9216696	41552.699	5.5839844	0.13954449
0.92711002	41729.547	5.6132813	0.14033844
0.93099028	41905.188	5.6425781	0.14107099
0.93647093	42077.996	5.671875	0.14190842
0.94061941	42247.957	5.7011719	0.14257081
0.94682425	42415.484	5.7304688	0.14341429
0.95160753	42582.504	5.7597656	0.14414541
0.95528662	42744.84	5.7890625	0.14487585
0.96013695	42915.824	5.8183594	0.14570476
0.96421391	43074.785	5.8476563	0.14635801
0.97086579	43243.398	5.8769531	0.14723116
0.97639114	43406.512	5.90625	0.14793275
0.98076761	43576.016	5.9355469	0.14870918
0.98475516	43740.258	5.9648438	0.14947627
0.98947138	43908.406	5.9941406	0.15027007
0.99522918	44075.18	6.0234375	0.15101613
0.99911839	44241.887	6.0527344	0.15175238
1.0044515	44401.047	6.0820313	0.15259965
1.0097041	44567.512	6.1113281	0.15343527
1.0146797	44722.066	6.140625	0.15418291
1.0197089	44886.02	6.1699219	0.15488891
1.023066	45044.129	6.1992188	0.15565348
1.0286405	45208.324	6.2285156	0.15647626
1.0327488	45371.762	6.2578125	0.15724547
1.0396332	45548.293	6.2871094	0.15814015
1.0447249	45709.82	6.3164063	0.15890211
1.0475099	45883.035	6.3457031	0.15971857
1.0541215	46043.035	6.375	0.16054779
1.0590568	46208.488	6.4042969	0.16141514
1.0631337	46360.34	6.4335938	0.16216253
1.0690123	46519.453	6.4628906	0.16287717
1.0730937	46663.926	6.4921875	0.16380799
1.0783911	46821.113	6.5214844	0.16458894
1.0829911	46970.383	6.5507813	0.16533311
1.088141	47126.234	6.5800781	0.16613522
1.0927365	47269.195	6.609375	0.16693147
1.0978281	47422.762	6.6386719	0.16768746
1.1029422	47567.203	6.6679688	0.168456
1.1068001	47709.805	6.6972656	0.16919421
1.1114806	47855.438	6.7265625	0.17006928
1.1166841	48008.039	6.7558594	0.17087871
1.1217043	48150.496	6.7851563	0.17167996
1.1273191	48302.074	6.8144531	0.17238718
1.1312574	48446.52	6.84375	0.17319821
1.1369035	48599.805	6.8730469	0.17404635
1.1407703	48741.191	6.9023438	0.17484173
1.1461749	48890.422	6.9316406	0.1756537
1.1504486	49038.715	6.9609375	0.17639327
1.1561483	49187.969	6.9902344	0.1773127
1.1609852	49333.984	7.0195313	0.17812231
1.1649996	49488.559	7.0488281	0.17895696
1.1708691	49639.262	7.078125	0.17981897
1.1762872	49785.91	7.1074219	0.18072626
1.1810973	49934.863	7.1367188	0.1814912
1.1860058	50081.215	7.1660156	0.18236764
1.189971	50226.965	7.1953125	0.18323445
1.1956215	50365.469	7.2246094	0.18402946
1.2012944	50506.43	7.2539063	0.18475792
1.2065337	50642.277	7.2832031	0.18563399
1.2105435	50779.301	7.3125	0.18657495
1.2145088	50912.82	7.3417969	0.18731822
1.2206688	51047.078	7.3710938	0.18818544
1.2259796	51181.367	7.4003906	0.18893917
1.230432	51315.633	7.4296875	0.18978493
1.2344732	51454.254	7.4589844	0.19071326
1.2397975	51595.523	7.4882813	0.19146214
1.2448937	51725.5	7.5175781	0.19234967
1.2496322	51846.125	7.546875	0.19318809
1.2548401	51965.266	7.5761719	0.1939761
1.2587562	52090.23	7.6054688	0.19466862
1.2638569	52208.855	7.6347656	0.19554949
1.268573	52339.797	7.6640625	0.19623516
1.2728781	52462.484	7.6933594	0.19693153
1.2777507	52591.18	7.7226563	0.19786669
1.2828603	52713.156	7.7519531	0.19867191
1.2870536	52839.824	7.78125	0.19954178
1.2925565	52967.82	7.8105469	0.20040262
1.2965173	53106.148	7.8398438	0.20120536
1.3018057	53233.121	7.8691406	0.20211791
1.3062134	53368.715	7.8984375	0.20287944
1.3120294	53490.191	7.9277344	0.2037852
1.3163879	53631.688	7.9570313	0.20470516
1.3225973	53766.898	7.9863281	0.20555803
1.3280914	53903.852	8.015625	0.20646739
1.3320789	54028.484	8.0449219	0.20726168
1.3368398	54152.344	8.0742188	0.20819525
1.3421907	54274.5	8.1035156	0.209077
1.3481498	54401.762	8.1328125	0.21005215
1.3528258	54517.98	8.1621094	0.2108942
1.3564467	54640.328	8.1914063	0.21168566
1.3619989	54757.348	8.2207031	0.21251518
1.3689146	54875.074	8.25	0.21338168
1.3723612	54993.043	8.2792969	0.21422537
1.3774529	55114.227	8.3085938	0.21510033
1.381825	55224.34	8.3378906	0.21598217
1.3870955	55344.598	8.3671875	0.21690714
1.3910562	55455.109	8.3964844	0.21766721
1.3964965	55571.195	8.4257813	0.21850498
1.4002964	55680.172	8.4550781	0.21932907
1.4057233	55794.688	8.484375	0.22014339
1.4101714	55905.047	8.5136719	0.2209997
1.4154017	56019.211	8.5429688	0.22188628
1.4205918	56132.121	8.5722656	0.22279882
1.4250666	56246.176	8.6015625	0.22365411
1.4290899	56354.766	8.6308594	0.22449629
1.4343247	56470.172	8.6601563	0.22541645
1.4394253	56579.531	8.6894531	0.22631092
1.4443249	56691.629	8.71875	0.22710328
1.4489248	56800.129	8.7480469	0.22795522
1.4537528	56917.938	8.7773438	0.22883353
1.4595062	57030.164	8.8066406	0.22976534
1.4633507	57144.711	8.8359375	0.2306553
1.4684558	57252.871	8.8652344	0.23156258
1.4744327	57367.348	8.8945313	0.23245622
1.4796271	57477.668	8.9238281	0.23330671
1.4833868	57591.07	8.953125	0.23421052
1.4896319	57699.277	8.9824219	0.23507009
1.4939234	57800.359	9.0117188	0.23603155
1.4988631	57905.605	9.0410156	0.23696168
1.5028507	58003.672	9.0703125	0.23780049
1.5090913	58113.422	9.0996094	0.23866051
1.5132308	58215.688	9.1289063	0.23955491
1.5180767	58327.645	9.1582031	0.24042825
1.5237272	58431.93	9.1875	0.24142812
1.5276923	58535.176	9.2167969	0.24222304
1.5332311	58636.602	9.2460938	0.24311461
1.538077	58743.445	9.2753906	0.24403541
1.5431509	58840.488	9.3046875	0.2448508
1.5474155	58944.414	9.3339844	0.24594477
1.5522971	59044.727	9.3632813	0.24679516
1.557456	59145.355	9.3925781	0.24764794
1.5627756	59238.379	9.421875	0.24861294
1.5669286	59343.18	9.4511719	0.24942073
1.5722305	59442.438	9.4804688	0.25050974
1.5769064	59541.926	9.5097656	0.25134647
1.5811086	59635.453	9.5390625	0.25212571
1.5860662	59732.742	9.5683594	0.25310513
1.5908182	59827.59	9.5976563	0.25396645
1.596348	59926.543	9.6269531	0.25490445
1.6010151	60018.473	9.65625	0.25583553
1.6065941	60117.777	9.6855469	0.25662777
1.6103671	60201.605	9.7148438	0.25763965
1.6157269	60300.598	9.7441406	0.25853944
1.6205146	60386.84	9.7734375	0.25932902
1.6257181	60487.07	9.8027344	0.26030591
1.6298175	60573.941	9.8320313	0.26110145
1.6341851	60674.516	9.8613281	0.26204541
1.6400278	60766.613	9.890625	0.26302424
1.6442835	60859.871	9.9199219	0.26385531
1.6488612	60953.918	9.9492188	0.26485974
1.6554952	61053.391	9.9785156	0.26580396
1.6587629	61148.18	10.007813	0.26676169
1.663962	61249.602	10.037109	0.26771471
1.6696751	61340.852	10.066406	0.26862204
1.6748697	61445.227	10.095703	0.26970658
1.6802833	61533.848	10.125	0.27062619
1.6847446	61634.723	10.154297	0.27159268
1.6899168	61722.43	10.183594	0.27256644
1.6957283	61815.313	10.212891	0.27353412
1.6990364	61896.066	10.242188	0.27452236
1.7031938	61991.594	10.271484	0.27549124
1.7089874	62076.09	10.300781	0.27641875
1.7137796	62163.656	10.330078	0.27726415
1.7180532	62247.93	10.359375	0.27829123
1.7240077	62342.172	10.388672	0.27934575
1.7289519	62419.941	10.417969	0.28029624
1.7337441	62508.84	10.447266	0.28117561
1.7369225	62590.5	10.476563	0.2820926
1.7434269	62676.543	10.505859	0.28302324
1.7484516	62756.051	10.535156	0.28403503
1.7523005	62839.898	10.564453	0.2849538
1.7574682	62916.676	10.59375	0.2858685
1.7620013	63004.922	10.623047	0.28680807
1.7665162	63083.563	10.652344	0.287754
1.7718047	63167.328	10.681641	0.28859708
1.7763287	63243.895	10.710938	0.28951779
1.7812014	63326.707	10.740234	0.29054222
1.7870173	63410.566	10.769531	0.29149672
1.7914385	63500.027	10.798828	0.292483
1.7956227	63590.313	10.828125	0.29351729
1.8013225	63673.805	10.857422	0.2945545
1.8064946	63758.785	10.886719	0.29542282
1.81147	63837.375	10.916016	0.29644513
1.816745	63916.563	10.945313	0.29739267
1.8218949	63997.781	10.974609	0.29842865
1.824595	64075.789	11.003906	0.29941568
1.8321767	64158.492	11.033203	0.30038404
1.8359945	64236.953	11.0625	0.30140883
1.8420115	64315.789	11.091797	0.30241099
1.8477693	64397.02	11.121094	0.30339184
1.8511488	64474.656	11.150391	0.30436122
1.8554046	64550.566	11.179688	0.30537513
1.8611894	64626.953	11.208984	0.30629995
1.8655747	64706.465	11.238281	0.30729651
1.8709705	64778.656	11.267578	0.3082734
1.8755124	64855.742	11.296875	0.30931044
1.8805951	64929.543	11.326172	0.31030774
1.8857763	65002.328	11.355469	0.31134737
1.8895447	65073.082	11.384766	0.31226197
1.8951192	65141.242	11.414063	0.31315768
1.9006	65205.637	11.443359	0.31411067
1.9038856	65282.121	11.472656	0.31513962
1.9092276	65347.383	11.501953	0.31604576
1.9142702	65422.738	11.53125	0.3170802
1.9183338	65494.117	11.560547	0.31807849
1.9241049	65568.766	11.589844	0.31900835
1.9279271	65631.828	11.619141	0.31998733
1.9336536	65710.523	11.648438	0.32088548
1.9388884	65780.492	11.677734	0.32191676
1.9433409	65859.469	11.707031	0.32297698
1.9480705	65923.703	11.736328	0.32399154
1.9524962	66001.648	11.765625	0.32507086
1.9580796	66068.484	11.794922	0.32602233
1.9635603	66144.953	11.824219	0.32703722
1.9679501	66211.82	11.853516	0.32795945
1.9721836	66276.805	11.882813	0.32894257
1.9774497	66320.141	11.912109	0.32992443
1.9822464	66413.43	11.941406	0.33102712
1.9871995	66477.797	11.970703	0.33196789
1.9911959	66562.273	12	0.33305055
1.9965603	66637.102	12.029297	0.33415449
2.0020053	66716.648	12.058594	0.33519408
2.0077853	66785.664	12.087891	0.33628538
2.0123587	66858.414	12.117188	0.33732414
2.0174236	66922.039	12.146484	0.33831349
2.0229311	66991.773	12.175781	0.33942416
2.0271645	67054.852	12.205078	0.34046558
2.0325646	67119.258	12.234375	0.34153658
2.036865	67177.133	12.263672	0.34250423
2.0411253	67238.727	12.292969	0.34352893
2.0457253	67299.844	12.322266	0.34454396
2.0509152	67361.633	12.351563	0.34558254
2.0564854	67421.078	12.380859	0.34646872
2.060549	67490.078	12.410156	0.34761989
2.0653903	67550.664	12.439453	0.34865558
2.0717337	67617.016	12.46875	0.34958515
2.0755961	67683.898	12.498047	0.35065237
2.0814033	67744.242	12.527344	0.35163426
2.0855024	67802.617	12.556641	0.3526935
2.0898118	67868.563	12.585938	0.35368219
2.0947247	67923.93	12.615234	0.3546606
2.1003485	67986.156	12.644531	0.35572088
2.1045551	68043.578	12.673828	0.35667771
2.1101117	68104.125	12.703125	0.35778832
2.114439	68163.297	12.732422	0.35884219
2.1193118	68230.398	12.761719	0.35981372
2.1248193	68284.094	12.791016	0.36093649
2.1293612	68349.203	12.820313	0.36198142
2.1350608	68405.734	12.849609	0.36295205
2.1388426	68464.367	12.878906	0.3639923
2.1442428	68524.977	12.908203	0.36505792
2.1491199	68588.125	12.9375	0.36610666
2.1540508	68651.82	12.966797	0.36721429
2.157475	68707.516	12.996094	0.36827043
2.1630316	68767.781	13.025391	0.36940905
2.1698356	68827.188	13.054688	0.37033588
2.1732063	68883.063	13.083984	0.37144196
2.1781371	68942.453	13.113281	0.37242791
2.1830544	68996.383	13.142578	0.37349966
2.1877303	69050.336	13.171875	0.37459207
2.1921382	69108.047	13.201172	0.37566459
2.1978691	69164.711	13.230469	0.37661767
2.2024333	69220.742	13.259766	0.37783051
2.207221	69274.492	13.289063	0.37888184
2.2118523	69328.055	13.318359	0.37980545
2.2163405	69382.266	13.347656	0.38077259
2.2214994	69436.875	13.376953	0.3818379
2.2258983	69488.656	13.40625	0.3829549
2.2315712	69539.688	13.435547	0.3839756
2.2366495	69592.727	13.464844	0.38505214
2.2404716	69645.141	13.494141	0.38611537
2.2448926	69699.523	13.523438	0.38722822
2.2500963	69755.086	13.552734	0.38809943
2.2543654	69808.422	13.582031	0.38926539
2.2600069	69862.758	13.611328	0.39029247
2.2647276	69918.063	13.640625	0.39147398
2.2699535	69976.414	13.669922	0.39248118
2.2748618	70027.844	13.699219	0.39361838
2.2799582	70083.789	13.728516	0.39468536
2.2846653	70135.102	13.757813	0.39580581
2.290678	70189.539	13.787109	0.39691406
2.2957072	70241.648	13.816406	0.39799163
2.3015857	70294.406	13.845703	0.39904475
2.3036509	70341.547	13.875	0.40019178
2.3098111	70396.453	13.904297	0.40124092
2.3149476	70442.133	13.933594	0.40224716
2.319087	70494.953	13.962891	0.40345642
2.3236423	70541.047	13.992188	0.4045113
2.329941	70597.367	14.021484	0.40564635
2.3330033	70647.234	14.050781	0.40667161
2.339673	70700.328	14.080078	0.40767065
2.3448586	70744.086	14.109375	0.40888837
2.348855	70799.094	14.138672	0.40994662
2.3539515	70843.68	14.167969	0.411134
2.3583636	70897.336	14.197266	0.41211769
2.363728	70943.953	14.226563	0.41319987
2.3697138	70994.281	14.255859	0.41430795
2.3739963	71039.195	14.285156	0.41537923
2.3783281	71089.234	14.314453	0.41653636
2.3839786	71132.102	14.34375	0.41768628
2.3890793	71182.398	14.373047	0.41863808
2.392745	71219.336	14.402344	0.41979793
2.398324	71268.867	14.431641	0.42078868
2.4030714	71316.203	14.460938	0.42204878
2.407372	71372.523	14.490234	0.42309919
2.4130538	71417.109	14.519531	0.42424619
2.4170325	71467.781	14.548828	0.42537212
2.4225667	71507.688	14.578125	0.42632982
2.4279892	71557	14.607422	0.42752612
2.4322941	71597.094	14.636719	0.42866454
2.4364829	71641.195	14.666016	0.42970514
2.4419055	71687.891	14.695313	0.43083778
2.4470196	71730.367	14.724609	0.43201554
2.4514899	71770.445	14.753906	0.43310735
2.4568989	71818.664	14.783203	0.43411681
2.4612844	71859.195	14.8125	0.43526193
2.4659066	71908.211	14.841797	0.43634272
2.4705515	71944.711	14.871094	0.43753541
2.4764209	71991.563	14.900391	0.43856412
2.4799123	72024.125	14.929688	0.43960303
2.4853528	72074.039	14.958984	0.44082198
2.4900289	72119.727	14.988281	0.44191727
2.4953663	72165.086	15.017578	0.44304305
2.5004313	72206.344	15.046875	0.44401285
2.5049641	72253.242	15.076172	0.44519457
2.5101855	72294.195	15.105469	0.44629759
2.5153847	72335.922	15.134766	0.44749701
2.5195107	72379.352	15.164063	0.44872445
2.5239766	72421.109	15.193359	0.44976869
2.529511	72459.469	15.222656	0.45085651
2.535358	72504.781	15.251953	0.45195836
2.5400071	72543.313	15.28125	0.45310113
2.5437534	72586.117	15.310547	0.45411885
2.5496409	72623.875	15.339844	0.45527431
2.5535436	72665.07	15.369141	0.45652565
2.5588498	72704.477	15.398438	0.45752072
2.5640578	72745.875	15.427734	0.4587841
2.5688589	72785.758	15.457031	0.45990512
2.5743709	72828.602	15.486328	0.46094427
2.5788994	72868.781	15.515625	0.46211892
2.5845006	72904.844	15.544922	0.4632237
2.588135	72945.125	15.574219	0.46435657
2.5921226	72982.781	15.603516	0.46547693
2.5983632	73022.328	15.632813	0.4666259
2.6030838	73058.641	15.662109	0.46772009
2.6074915	73098.695	15.691406	0.46884313
2.6122079	73135.156	15.720703	0.46998563
2.6186182	73172.859	15.75	0.47114965
2.6212513	73208.344	15.779297	0.47218579
2.6287212	73244.93	15.808594	0.47332337
2.6319444	73278.742	15.837891	0.47445452
2.6378677	73317.5	15.867188	0.47555843
2.6413367	73356.859	15.896484	0.47667873
2.6472197	73395.406	15.925781	0.47786444
2.6513233	73428.266	15.955078	0.47882321
2.6564956	73467.625	15.984375	0.48003048
2.6603937	73502.5	16.013672	0.48114008
2.6661515	73536.219	16.042969	0.48228592
2.6704834	73567.672	16.072266	0.48341566
2.676791	73613.266	16.101563	0.48451269
2.6814535	73646.805	16.130859	0.48566765
2.684927	73685.289	16.160156	0.48678082
2.6902735	73718.305	16.189453	0.4879393
2.6947036	73757.773	16.21875	0.48907191
2.700439	73796.141	16.248047	0.49023777
2.7054012	73834.117	16.277344	0.49130559
2.7098358	73871.969	16.306641	0.49255943
2.7154014	73909.211	16.335938	0.49367794
2.7202964	73947.461	16.365234	0.49487454
2.7255268	73986.867	16.394531	0.49610102
2.7303233	74024.023	16.423828	0.49719587
2.7351871	74066.578	16.453125	0.49848762
2.7397468	74094.008	16.482422	0.49968323
2.7454019	74129.898	16.511719	0.50071621
2.7505383	74161.211	16.541016	0.50203782
2.7549505	74196.578	16.570313	0.50312608
2.7600691	74221.547	16.599609	0.50425786
2.7650132	74257.133	16.628906	0.5054602
2.7701676	74284.68	16.658203	0.50658154
2.774781	74323.156	16.6875	0.50776017
2.7788177	74352.094	16.716797	0.50880444
2.7846961	74392.008	16.746094	0.51006901
2.7888088	74422.359	16.775391	0.51117253
2.793798	74459.281	16.804688	0.51239252
2.7990952	74486.344	16.833984	0.51346326
2.8038473	74525.234	16.863281	0.51472121
2.8091133	74554.867	16.892578	0.5158788
2.8149202	74591.875	16.921875	0.51714116
2.8196588	74616.758	16.951172	0.51824033
2.8245091	74652.102	16.980469	0.51937807
2.8287382	74680.742	17.009766	0.52051556
2.8343081	74715.984	17.039063	0.52169627
2.8384387	74740.766	17.068359	0.52281177
2.8431058	74771.758	17.097656	0.52399898
2.8480902	74794.047	17.126953	0.52509981
2.852659	74830.961	17.15625	0.52639782
2.8580725	74854.844	17.185547	0.52752066
2.8623328	74885.906	17.214844	0.52865207
2.8671875	74912.102	17.244141	0.52978051
2.8720379	74946.188	17.273438	0.53085887
2.8764992	74971.18	17.302734	0.53197855
2.8812022	74999.25	17.332031	0.53308564
2.8858781	75025.883	17.361328	0.53435218
2.8911755	75057.68	17.390625	0.5354358
2.8958693	75088.898	17.419922	0.53659683
2.8999777	75118.555	17.449219	0.53770095
2.90557	75144.727	17.478516	0.53876394
2.9098167	75179.047	17.507813	0.53995162
2.9143901	75208.344	17.537109	0.54124087
2.9194281	75244.234	17.566406	0.54224384
2.9239476	75273.391	17.595703	0.54345602
2.9283643	75309.484	17.625	0.5446173
2.9347703	75343.516	17.654297	0.54590851
2.9383645	75374.328	17.683594	0.54698706
2.9442832	75403.445	17.712891	0.54823542
2.9485254	75438.836	17.742188	0.5495044
2.9548421	75462.148	17.771484	0.55070341
2.9598892	75493.672	17.800781	0.55186945
2.9641762	75522.656	17.830078	0.55314201
2.9698	75551.695	17.859375	0.55427241
2.9739485	75576.836	17.888672	0.55549872
2.9792144	75609.828	17.917969	0.55664808
2.984199	75634.859	17.947266	0.55789065
2.988884	75662.305	17.976563	0.55905867
2.9939532	75691.625	18.005859	0.56026632
2.9994116	75716.836	18.035156	0.56142485
3.0051291	75740.914	18.064453	0.56268805
3.0092239	75769.117	18.09375	0.56384772
3.0139134	75795.375	18.123047	0.56500691
3.018491	75821.266	18.152344	0.56620467
3.0238106	75846.039	18.181641	0.56739944
3.0281334	75874.938	18.210938	0.56864178
3.0334129	75898.344	18.240234	0.56973732
3.0376196	75923.836	18.269531	0.5709908
3.0413792	75952.398	18.298828	0.57211083
3.0481071	75983.281	18.328125	0.57337356
3.0524611	76012.727	18.357422	0.57455128
3.0581429	76037.594	18.386719	0.57577121
3.062515	76064.617	18.416016	0.57695919
3.0670433	76092.141	18.445313	0.57817334
3.072238	76118.93	18.474609	0.57937431
3.0771465	76141.211	18.503906	0.58062184
3.0816972	76168.039	18.533203	0.58176726
3.0872674	76197.945	18.5625	0.58310717
3.0917196	76225.75	18.591797	0.58428305
3.0970976	76250.453	18.621094	0.58550733
3.1024218	76277.648	18.650391	0.58676189
3.1070619	76298.195	18.679688	0.58798659
3.1122029	76317.32	18.708984	0.58916706
3.1171157	76343.07	18.738281	0.59038186
3.1215324	76365.633	18.767578	0.59156382
3.1270356	76385.547	18.796875	0.59265959
3.1315506	76411.875	18.826172	0.59387356
3.1347737	76431.852	18.855469	0.59507984
3.1412735	76461.75	18.884766	0.59631687
3.1455472	76464.742	18.914063	0.59737164
3.1507821	76478.914	18.943359	0.59847081
3.1548812	76523.109	18.972656	0.59980381
3.159915	76560.086	19.001953	0.60095519
3.164716	76585.719	19.03125	0.60217309
3.1697319	76621.414	19.060547	0.60346246
3.1751857	76649.438	19.089844	0.60469568
3.1796827	76685.742	19.119141	0.6060307
3.1848238	76708.586	19.148438	0.60719079
3.1909437	76739.695	19.177734	0.60863793
3.1948419	76757.453	19.207031	0.60977614
3.2007561	76782.227	19.236328	0.61099893
3.2055213	76796.063	19.265625	0.61225349
3.2097683	76815.305	19.294922	0.61353087
3.2155797	76827.234	19.324219	0.61476076
3.21946	76845.883	19.353516	0.61593181
3.2239392	76864.953	19.382813	0.61712736
3.2281146	76889.789	19.412109	0.61831743
3.2340825	76909.477	19.441406	0.61954165
3.2381549	76932.305	19.470703	0.62074965
3.2433987	76953.25	19.5	0.62190634
3.2492101	76982.742	19.529297	0.62318778
3.2535508	77000.758	19.558594	0.62438816
3.25858	77025.789	19.587891	0.62559658
3.2638371	77044.367	19.617188	0.62675697
3.2671227	77070.211	19.646484	0.62808287
3.2717853	77089.352	19.675781	0.62922662
3.277494	77115.781	19.705078	0.63044661
3.2832787	77128.648	19.734375	0.63166934
3.2887325	77153.789	19.763672	0.63300794
3.2928898	77172.852	19.792969	0.63412642
3.2970116	77199.766	19.822266	0.63527793
3.3009365	77218.227	19.851563	0.63654816
3.3059969	77240.875	19.880859	0.63766587
3.3116386	77267.352	19.910156	0.63894916
3.3162966	77290.938	19.939453	0.64027464
3.3207088	77305.711	19.96875	0.6414662
3.3260956	77333.383	19.998047	0.64265788
3.3306553	77351.953	20.027344	0.64391589
3.3367708	77376.195	20.056641	0.64521945
3.3407898	77392.203	20.085938	0.64638865
3.3462121	77421.836	20.115234	0.64772671
3.3507407	77436.477	20.144531	0.64891255
3.3562436	77459.766	20.173828	0.65015113
3.3605084	77477.383	20.203125	0.65129811
3.3648224	77494.953	20.232422	0.65258348
3.3704236	77512.164	20.261719	0.65384984
3.3756046	77535.789	20.291016	0.65511972
3.3810139	77554.516	20.320313	0.65633488
3.38573	77575.313	20.349609	0.65760016
3.3893824	77597.469	20.378906	0.65870583
3.3945189	77615.539	20.408203	0.65995061
3.3992262	77636.484	20.4375	0.66130817
3.4047291	77658.617	20.466797	0.66248411
3.4099057	77671.656	20.496094	0.66362363
3.4148321	77694.453	20.525391	0.66494882
3.4189894	77714.992	20.554688	0.66626084
3.424859	77736.516	20.583984	0.66738135
3.4292936	77754.383	20.613281	0.6686604
3.4333036	77776.727	20.642578	0.66990036
3.4392669	77795.969	20.671875	0.67120022
3.4431384	77808.414	20.701172	0.67230731
3.4484892	77829.602	20.730469	0.67353338
3.4527898	77846.031	20.759766	0.6749016
3.4564555	77868.164	20.789063	0.67606336
3.4616992	77888.328	20.818359	0.67730039
3.4679756	77907.648	20.847656	0.67851424
3.4719274	77926.281	20.876953	0.67993599
3.4765587	77946.125	20.90625	0.6810953
3.4817309	77961.148	20.935547	0.68232125
3.4861386	77984.789	20.964844	0.68362927
3.4912481	78000.414	20.994141	0.68487841
3.4972339	78027.266	21.023438	0.68611509
3.5020709	78043.445	21.052734	0.68736303
3.5065188	78063.477	21.082031	0.68858796
3.5113559	78080.813	21.111328	0.68994081
3.5165727	78098.797	21.140625	0.69124055
3.5209446	78118.094	21.169922	0.69247687
3.5265417	78140.555	21.199219	0.69372249
3.5315394	78153.156	21.228516	0.69498783
3.5362198	78173.313	21.257813	0.69625562
3.5406723	78187.063	21.287109	0.69754112
3.546104	78205.297	21.316406	0.6987415
3.5493984	78223.805	21.345703	0.70001882
3.5551519	78248.047	21.375	0.701334
3.5606458	78261.656	21.404297	0.70265698
3.5645127	78283.391	21.433594	0.70385593
3.5692558	78293.273	21.462891	0.70518237
3.5757647	78317.008	21.492188	0.70635259
3.5791979	78328.5	21.521484	0.70775849
3.5854652	78353.789	21.550781	0.70902914
3.5895019	78366.766	21.580078	0.71023989
3.5940261	78390.516	21.609375	0.711555
3.5996451	78399.055	21.638672	0.71296763
3.605917	78422.477	21.667969	0.71417022
3.6099002	78433.859	21.697266	0.71545506
3.6148713	78449.18	21.726563	0.71665597
3.6196723	78465.406	21.755859	0.71792775
3.6237583	78486.797	21.785156	0.71929592
3.6291494	78500.469	21.814453	0.72053456
3.6338031	78521.703	21.84375	0.72181481
3.639266	78532.609	21.873047	0.72310102
3.6436648	78554.094	21.902344	0.72434342
3.6483362	78561.953	21.931641	0.72567689
3.6540003	78578.516	21.960938	0.72693193
3.6587701	78589.805	21.990234	0.72820503
3.6640182	78609.531	22.019531	0.72941953
3.6683724	78617.906	22.048828	0.73061073
3.6729546	78640.406	22.078125	0.73194689
3.6776259	78651.313	22.107422	0.73316538
3.6826239	78670.344	22.136719	0.73439628
3.6867187	78684.367	22.166016	0.73575079
3.6915512	78699.617	22.195313	0.73702806
3.6971211	78713.594	22.224609	0.73825514
3.7027268	78734.766	22.253906	0.73945534
3.7070007	78750.078	22.283203	0.74078029
3.711328	78764.5	22.3125	0.74204367
3.7165091	78776.484	22.341797	0.74329984
3.721498	78796.898	22.371094	0.74462259
3.7261872	78805.992	22.400391	0.74578202
3.7309661	78824.609	22.429688	0.74714214
3.7363081	78835.883	22.458984	0.74838644
3.7402689	78855.594	22.488281	0.74971098
3.74524	78871.023	22.517578	0.75104064
3.7503898	78886.234	22.546875	0.75220937
3.754811	78902.43	22.576172	0.75356179
3.7587001	78922.258	22.605469	0.75484824
3.7650704	78933.914	22.634766	0.75612009
3.7691832	78949.539	22.664063	0.75739592
3.7731977	78960.695	22.693359	0.75866348
3.7789912	78981.266	22.722656	0.75992817
3.7838593	78995.211	22.751953	0.76121348
3.7887857	79015.242	22.78125	0.7625832
3.7935958	79036.375	22.810547	0.76389563
3.7989781	79055.828	22.839844	0.76526803
3.805089	79070.266	22.869141	0.76655149
3.8095906	79086.836	22.898438	0.76786923
3.8140163	79103.352	22.927734	0.76921088
3.8200603	79115.234	22.957031	0.77051073
3.82424	79134.516	22.986328	0.77193266
3.8294883	79150.688	23.015625	0.77330226
3.8351119	79166.609	23.044922	0.77473074
3.8394303	79179.461	23.074219	0.77606732
3.8442984	79194.758	23.103516	0.77728957
3.8493276	79205.867	23.132813	0.77862734
3.8546696	79219.906	23.162109	0.78000081
3.8599625	79228.469	23.191406	0.7814135
3.8643658	79246.141	23.220703	0.78276181
3.8697257	79257.328	23.25	0.78405493
3.8744106	79266.508	23.279297	0.78532916
3.8798735	79279.594	23.308594	0.78662205
3.8851709	79290.789	23.337891	0.7879529
3.8893149	79298.555	23.367188	0.78924823
3.8941965	79313.102	23.396484	0.79064083
3.9001465	79318.297	23.425781	0.79182082
3.9038749	79334.32	23.455078	0.79321569
3.9088459	79347.211	23.484375	0.79438597
3.914103	79357.477	23.513672	0.79578984
3.9188995	79368.305	23.542969	0.79702818
3.9235399	79383.289	23.572266	0.7981953
3.9287925	79391.242	23.601563	0.799519
3.9334462	79408.32	23.630859	0.8008585
3.9389133	79415.547	23.660156	0.80217433
3.9427042	79432.844	23.689453	0.80346704
3.948225	79442.125	23.71875	0.80477232
3.9516807	79456.18	23.748047	0.80599707
3.9581404	79465.43	23.777344	0.80737734
3.9610863	79483.109	23.806641	0.80854231
3.9667993	79491	23.835938	0.80986995
3.9708183	79506.648	23.865234	0.81111008
3.9754763	79514.492	23.894531	0.81235719
3.9810107	79529.305	23.923828	0.81367725
3.9851456	79540.227	23.953125	0.8149299
3.9905815	79559.461	23.982422	0.81635273
3.9946988	79569.758	24.011719	0.81755787
3.9996653	79586.977	24.041016	0.81898546
4.0059061	79593.813	24.070313	0.82015753
4.0100098	79606.773	24.099609	0.82149029
4.014431	79618.078	24.128906	0.82279152
4.0192857	79633.945	24.158203	0.82407665
4.0243106	79638.492	24.1875	0.82535851
4.0281816	79654.031	24.216797	0.82666576
4.0332241	79662.406	24.246094	0.82791317
4.0386157	79677.211	24.275391	0.82918143
4.0429296	79688.273	24.304688	0.83049774
4.0487275	79705.828	24.333984	0.83172405
4.0521874	79713.742	24.363281	0.83315998
4.0587277	79731.203	24.392578	0.8344816
4.0629253	79742.477	24.421875	0.83578354
4.06601	79755.125	24.451172	0.83698457
4.0732203	79761.422	24.480469	0.83830768
4.0777845	79779.781	24.509766	0.83974361
4.0806456	79791.336	24.539063	0.84105873
4.0863991	79807.695	24.568359	0.84237921
4.0926175	79819.43	24.597656	0.84374714
4.0967169	79836.289	24.626953	0.84512717
4.1012764	79850.094	24.65625	0.84648055
4.1066227	79865.352	24.685547	0.84781682
4.112886	79874.914	24.714844	0.84912533
4.1166186	79892.508	24.744141	0.85047185
4.121943	79899.563	24.773438	0.85194063
4.1264849	79914.516	24.802734	0.85326546
4.1317148	79922.586	24.832031	0.85464311
4.1378932	79936.664	24.861328	0.85597807
4.1432843	79949.414	24.890625	0.8573674
4.1473746	79959.516	24.919922	0.85873812
4.152082	79971.32	24.949219	0.86003441
4.1567621	79985.891	24.978516	0.86145377
4.1626096	79994.492	25.007813	0.86283684
4.1676879	80003.555	25.037109	0.86421961
4.1717248	80012.102	25.066406	0.86550856
4.1770487	80027.492	25.095703	0.86698699
4.1827216	80034.727	25.125	0.86828852
4.1863828	80044.859	25.154297	0.86965078
4.1923776	80050.508	25.183594	0.8710261
4.1965218	80061.781	25.212891	0.87244332
4.2004423	80067.836	25.242188	0.87366664
4.2071075	80075.438	25.271484	0.87499624
4.2114391	80078.594	25.300781	0.87638891
4.2168169	80082.906	25.330078	0.87768215
4.2208138	80086.492	25.359375	0.87894905
4.2242556	80094.453	25.388672	0.88025075
4.2294593	80098.453	25.417969	0.88141733
4.234725	80109.266	25.447266	0.88276958
4.2394457	80119.289	25.476563	0.88405025
4.2442827	80128.766	25.505859	0.88536257
4.2478142	80137.992	25.535156	0.88667274
4.2540731	80144.234	25.564453	0.88799769
4.2585521	80156.578	25.59375	0.88924152
4.2622404	80170.156	25.623047	0.89058751
4.2665095	80178.273	25.652344	0.89184248
4.2716146	80190.234	25.681641	0.89310014
4.2772069	80205.414	25.710938	0.89447409
4.2815881	80209.875	25.740234	0.89571077
4.2857184	80223.758	25.769531	0.89705753
4.2910872	80231.742	25.798828	0.89841938
4.2954192	80245.586	25.828125	0.89971566
4.301414	80256.125	25.857422	0.90102166
4.3064923	80276.164	25.886719	0.90240669
4.3107748	80293.234	25.916016	0.90376776
4.3170109	80310.055	25.945313	0.90518403
4.3218346	80322.672	25.974609	0.90658259
4.3258934	80341.445	26.003906	0.9080075
4.3315353	80345.039	26.033203	0.90944445
4.3360767	80360.461	26.0625	0.91085505
4.3420358	80366.094	26.091797	0.91223007
4.3462248	80377.414	26.121094	0.91353911
4.3519778	80380.367	26.150391	0.91501403
4.3564215	80393.68	26.179688	0.91642672
4.360302	80403.391	26.208984	0.91781777
4.3657379	80414.75	26.238281	0.91921514
4.3711467	80418.266	26.267578	0.92062193
4.3755054	80427.633	26.296875	0.92191058
4.3805304	80434.367	26.326172	0.92337376
4.3871684	80447.547	26.355469	0.92466396
4.3920012	80451.891	26.384766	0.9260487
4.3949785	80463.141	26.414063	0.92749095
4.4003782	80467.844	26.443359	0.92885244
4.4058142	80475	26.472656	0.93019134
4.4115453	80477.078	26.501953	0.93145299
4.4154077	80487.781	26.53125	0.93276978
4.4210763	80487.227	26.560547	0.93425095
4.4240623	80501.75	26.589844	0.93561661
4.4312057	80504.922	26.619141	0.93693173
4.4343128	80513.313	26.648438	0.93831664
4.4389486	80520.211	26.677734	0.93960601
4.4446526	80530.273	26.707031	0.94099849
4.4490871	80534.594	26.736328	0.94237018
4.4530573	80545.781	26.765625	0.9435969
4.4579477	80550.266	26.794922	0.9450146
4.4639511	80561.352	26.824219	0.94640756
4.4687347	80567.07	26.853516	0.9476772
4.4734058	80577.32	26.882813	0.94910181
4.4786854	80586.383	26.912109	0.95038515
4.4826956	80601.453	26.941406	0.95173258
4.4876618	80608.195	26.970703	0.95311588
4.4924316	80620.25	27	0.95449096
4.4978724	80630.07	27.029297	0.95592862
4.5022531	80642.891	27.058594	0.9574284
4.5076313	80648.672	27.087891	0.95884317
4.5116053	80659.594	27.117188	0.96005207
4.5164423	80668.922	27.146484	0.9614495
4.5222359	80683.328	27.175781	0.96295547
4.5266299	80690.188	27.205078	0.96442753
4.5321956	80702.375	27.234375	0.96574646
4.5376987	80704.961	27.263672	0.96720862
4.5414896	80716.117	27.292969	0.96861333
4.5466928	80719.508	27.322266	0.97004074
4.5516863	80730.633	27.351563	0.97148311
4.5569792	80736.188	27.380859	0.97279644
4.5618114	80744.125	27.410156	0.97420788
4.5672297	80749.18	27.439453	0.97568727
4.5710788	80757.844	27.46875	0.97711587
4.5770645	80764.273	27.498047	0.97843456
4.5826077	80770.391	27.527344	0.9797731
4.5866756	80770.688	27.556641	0.98122102
4.5916739	80777.125	27.585938	0.98252708
4.5964212	80779.555	27.615234	0.98387122
4.6010165	80785.422	27.644531	0.98527461
4.6061621	80790.047	27.673828	0.98666394
4.6106997	80800.484	27.703125	0.98793614
4.6160593	80807.68	27.732422	0.98934066
4.6197562	80818.117	27.761719	0.99076331
4.6247902	80825.383	27.791016	0.99216926
4.6298995	80836.344	27.820313	0.99345636
4.6344995	80840.656	27.849609	0.99481708
4.6388493	80846.906	27.878906	0.99632424
4.6446204	80855.117	27.908203	0.99762726
4.6486573	80864.836	27.9375	0.99906093
4.6537218	80871.258	27.966797	1.0004239
4.6593056	80881.297	27.996094	1.0018754
4.6645894	80888.906	28.025391	1.0032794
4.6679468	80893.883	28.054688	1.0045965
4.6739326	80903.867	28.083984	1.0060805
4.6783981	80907.25	28.113281	1.0074278
4.6825962	80919.453	28.142578	1.0088707
4.6880679	80923.383	28.171875	1.010299
4.6931686	80934.5	28.201172	1.0116937
4.6982245	80935.047	28.230469	1.0130372
4.7035398	80943.25	28.259766	1.0145197
4.7072501	80944.766	28.289063	1.01587
4.7123194	80953.133	28.318359	1.0172021
4.717742	80963.008	28.347656	1.0185537
4.7211213	80967.453	28.376953	1.0200071
4.7269821	80974.992	28.40625	1.0214417
4.7316494	80983.961	28.435547	1.0227329
4.7369599	80987.148	28.464844	1.02416
4.7422037	80995.711	28.494141	1.0256523
4.7460928	80997.531	28.523438	1.0269586
4.7504334	81007.32	28.552734	1.028468
4.7567816	81014.992	28.582031	1.0298866
4.7605591	81024.984	28.611328	1.0312461
4.7672286	81031.102	28.640625	1.0326015
4.770215	81042.359	28.669922	1.0340955
4.7753153	81046.086	28.699219	1.0355527
4.7808943	81057.789	28.728516	1.0369599
4.7863932	81064.398	28.757813	1.0384201
4.7911496	81075	28.787109	1.0398215
4.7957363	81080.391	28.816406	1.0413524
4.8018022	81091.57	28.845703	1.0427004
4.8057675	81096.75	28.875	1.0442607
4.8111095	81107.055	28.904297	1.0458091
4.8156424	81111.094	28.933594	1.0472082
4.8207479	81123.078	28.962891	1.0486288
4.8256917	81123.492	28.992188	1.0500969
4.8319368	81133.242	29.021484	1.0515491
4.8354955	81135.375	29.050781	1.0529708
4.840663	81143.719	29.080078	1.0544935
4.8452454	81141.078	29.109375	1.0559
4.8504753	81148.836	29.138672	1.0573813
4.8555584	81146	29.167969	1.0587494
4.861155	81156.523	29.197266	1.0602098
4.865366	81160.406	29.226563	1.0616654
4.8707843	81171.055	29.255859	1.0630641
4.876265	81166.023	29.285156	1.0644692
4.8793449	81178.094	29.314453	1.0658805
4.8848839	81174.023	29.34375	1.0674204
4.8902974	81184.344	29.373047	1.0687344
4.8956618	81183.641	29.402344	1.0701395
4.8981471	81187.641	29.431641	1.0716013
4.9050317	81189.789	29.460938	1.07311
4.9101367	81200.313	29.490234	1.0744203
4.9123988	81202.352	29.519531	1.0758332
4.9187465	81210.773	29.548828	1.0773466
4.9242048	81213.953	29.578125	1.0787429
4.9276071	81219.133	29.607422	1.0802243
4.933074	81224.742	29.636719	1.0815296
4.9381657	81229	29.666016	1.0829265
4.9430294	81232.758	29.695313	1.08441
4.9464898	81243.883	29.724609	1.0858297
4.952167	81250.234	29.753906	1.0872478
4.9577103	81257.93	29.783203	1.0887042
4.9616933	81262.055	29.8125	1.0901707
4.9674511	81272.875	29.841797	1.0915911
4.9722748	81274.57	29.871094	1.0930151
4.9774513	81280.914	29.900391	1.0944718
4.9818459	81286.961	29.929688	1.0958735
4.985878	81292.734	29.958984	1.0973023
4.9913988	81294.227	29.988281	1.0988326
4.995914	81297.531	30.017578	1.1001755
5.0004959	81301.469	30.046875	1.1015971
5.0051765	81304.172	30.076172	1.1030846
5.0113811	81310.719	30.105469	1.1044863
5.0151405	81314.641	30.134766	1.1059206
5.0196557	81322.164	30.164063	1.1074163
5.0251365	81326.594	30.193359	1.1088375
5.030179	81334.305	30.222656	1.1102898
5.0353737	81338.578	30.251953	1.111626
5.0398932	81346.875	30.28125	1.1130928
5.0453916	81352.461	30.310547	1.1146188
5.0497098	81358.078	30.339844	1.1159488
5.0534515	81364.609	30.369141	1.1175188
5.060318	81366.969	30.398438	1.1189202
5.0646095	81371.258	30.427734	1.1203722
5.0691872	81372.68	30.457031	1.1217325
5.0738277	81372.594	30.486328	1.1232568
5.0783916	81379.406	30.515625	1.1246598
5.0828753	81386.641	30.544922	1.1261061
5.0871892	81393.711	30.574219	1.1275983
5.093998	81401.586	30.603516	1.1290243
5.0975337	81404.984	30.632813	1.1304842
5.1039176	81412	30.662109	1.1319768
5.1083879	81417.352	30.691406	1.1334819
5.1121964	81422.977	30.720703	1.1349616
5.1183701	81430.625	30.75	1.1364268
5.1230907	81432.938	30.779297	1.1379191
5.1280351	81429.477	30.808594	1.1392925
5.1325278	81430.109	30.837891	1.1408305
5.1375208	81446.664	30.867188	1.1423672
5.1421971	81456.516	30.896484	1.1439024
5.1475344	81464.75	30.925781	1.1452949
5.1533995	81470.078	30.955078	1.1468999
5.1566453	81482.18	30.984375	1.1484382
5.1626177	81485.844	31.013672	1.1499246
5.1673694	81500.281	31.042969	1.1514879
5.1728683	81504.188	31.072266	1.1530811
5.178277	81511.352	31.101563	1.154614
5.1829395	81510.734	31.130859	1.156106
5.1878839	81517.281	31.160156	1.1577959
5.1942005	81515.922	31.189453	1.1592017
5.1983356	81517.531	31.21875	1.1607462
5.2033916	81509.266	31.248047	1.1622031
5.2083359	81515.727	31.277344	1.1637582
5.2110806	81515.891	31.306641	1.1652774
5.2189169	81522.695	31.335938	1.1668495
5.2228913	81522.922	31.365234	1.168251
5.2288504	81520.453	31.394531	1.1698457
5.2319927	81521.547	31.423828	1.1712023
5.2373571	81524.383	31.453125	1.1727083
5.2421942	81521.414	31.482422	1.1742394
5.2475944	81530.297	31.511719	1.1757646
5.2518682	81530.984	31.541016	1.1771853
5.2570448	81535.172	31.570313	1.1786093
5.2607417	81530.344	31.599609	1.1799984
5.2656903	81532.688	31.628906	1.1815252
5.2708807	81528.883	31.658203	1.1830523
5.2754717	81538.031	31.6875	1.1844262
5.2800403	81535.32	31.716797	1.1858469
5.2849755	81545.484	31.746094	1.1873262
5.2892179	81541.289	31.775391	1.1888012
5.2930713	81551.797	31.804688	1.1902537
5.2973404	81551.914	31.833984	1.1916307
5.303617	81561.688	31.863281	1.1931654
5.3076849	81565.156	31.892578	1.1946404
5.312799	81572.281	31.921875	1.1961348
5.3171487	81569.234	31.951172	1.1975962
5.3234024	81578.977	31.980469	1.1991303
5.3278551	81584.484	32.009766	1.2006029
5.3322763	81592.391	32.039063	1.2020699
5.3370595	81595.547	32.068359	1.2036598
5.3422494	81607.164	32.097656	1.2051733
5.3482399	81612.734	32.126953	1.2066633
5.3522272	81624.43	32.15625	1.2082514
5.3568139	81629.148	32.185547	1.2096927
5.3616195	81633.328	32.214844	1.2112719
5.3667202	81636.555	32.244141	1.2129073
5.3718476	81647.297	32.273438	1.2144269
5.3771586	81646.711	32.302734	1.2160542
5.3819237	81653.023	32.332031	1.2175512
5.3867073	81647.789	32.361328	1.2190325
5.3920584	81656.055	32.390625	1.2207135
5.3976593	81654.875	32.419922	1.2222216
5.4030061	81660.43	32.449219	1.2238275
5.4079814	81664.047	32.478516	1.2253581
5.4122238	81672.875	32.507813	1.2269043
5.4164977	81672.094	32.537109	1.2285298
5.4235964	81674.711	32.566406	1.2300891
5.4275885	81678.742	32.595703	1.2316551
5.4331989	81680.57	32.625	1.2332236
5.4369984	81674.109	32.654297	1.234642
5.4397163	81678.063	32.683594	1.2362982
5.446507	81680.422	32.712891	1.2379249
5.4507179	81684.531	32.742188	1.2393707
5.4563684	81682.781	32.771484	1.2408094
5.4603338	81683.727	32.800781	1.2424088
5.4652872	81687.484	32.830078	1.2438989
5.4706736	81690.82	32.859375	1.2455375
5.4760022	81692.117	32.888672	1.2470306
5.4802895	81699.82	32.917969	1.2485002
5.4852738	81696.656	32.947266	1.2502161
5.4890337	81700.719	32.976563	1.2517226
5.4946885	81702.641	33.005859	1.2532378
5.499579	81703.789	33.035156	1.2547199
5.5034904	81705.227	33.064453	1.2562546
5.5085602	81707.664	33.09375	1.2578245
5.5137053	81708.094	33.123047	1.2593215
5.5191545	81711.43	33.152344	1.2609124
5.5231423	81712.57	33.181641	1.2625234
5.5282564	81716.719	33.210938	1.2640013
5.5331154	81725.398	33.240234	1.2655673
5.5380955	81723.148	33.269531	1.2671669
5.5430665	81726.586	33.298828	1.268744
5.5481806	81724.836	33.328125	1.270261
5.5526466	81729.672	33.357422	1.2717685
5.5586233	81733.633	33.386719	1.2732615
5.5636973	81744.125	33.416016	1.274877
5.567318	81750.281	33.445313	1.2765179
5.5725126	81758.133	33.474609	1.2781385
5.5771036	81758.766	33.503906	1.2797238
5.5827184	81765.789	33.533203	1.2813447
5.5881367	81762.609	33.5625	1.2829545
5.5934963	81766.063	33.591797	1.2844076
5.596693	81767.281	33.621094	1.2861017
5.6019053	81772.883	33.650391	1.2877165
5.606492	81769.859	33.679688	1.2893436
5.612536	81777.383	33.708984	1.2909007
5.6173682	81774.961	33.738281	1.2925282
5.6217937	81780.039	33.767578	1.2940749
5.6262107	81780.063	33.796875	1.2957301
5.6311903	81785.656	33.826172	1.2972509
5.63592	81777.953	33.855469	1.2988057
5.6407256	81785.836	33.884766	1.3005021
5.6467252	81778.352	33.914063	1.3020755
5.651772	81787.336	33.943359	1.3037162
5.6566267	81784.289	33.972656	1.3053737
5.6610389	81791.211	34.001953	1.3068334
5.6651564	81784.805	34.03125	1.3084441
5.670373	81794.188	34.060547	1.3100295
5.6752501	81792.883	34.089844	1.3117143
5.6805477	81799.008	34.119141	1.3132099
5.6848302	81797.547	34.148438	1.3147652
5.6905074	81799.953	34.177734	1.316443
5.6943297	81801.672	34.207031	1.318079
5.6992159	81800.938	34.236328	1.3196398
5.7735443	2873.7651	34.265625	-0.5397867
5.7246118	-1704.8373	34.294922	-1.8918339
5.7303472	2373.9993	34.324219	-2.9396293
5.7398067	-673.73682	34.353516	-3.0507195
5.7393775	1593.2976	34.382813	-3.1182737
5.7485013	28.657377	34.412109	-3.1097236
5.7496505	186.78198	34.441406	-3.1092052
5.754724	-323.01166	34.470703	-3.1092973
5.7589173	-617.47083	34.5	-3.1094542
5.7642817	-466.87585	34.529297	-3.1095519
5.7685823	-152.21036	34.558594	-3.109724
5.7727709	206.48364	34.587891	-3.1094949
5.7780952	463.19678	34.617188	-3.1095245
5.782248	422.80133	34.646484	-3.1097324
5.7883143	157.09398	34.675781	-3.1096773
5.7923288	-220.35849	34.705078	-3.1097546
5.7964058	-439.21454	34.734375	-3.1099308
5.8008089	-421.83966	34.763672	-3.1098039
5.8042107	-175.03032	34.792969	-3.1098711
5.809289	163.06503	34.822266	-3.1098299
5.8135853	366.2377	34.851563	-3.1099479
5.8187127	365.81467	34.880859	-3.1098919
5.8232322	142.4373	34.910156	-3.1099741
5.8260798	-158.12648	34.939453	-3.1099572
5.8268666	-366.75192	34.96875	-3.1100843
5.8249669	-355.09399	34.998047	-3.1100256
5.8251457	-155.46184	35.027344	-3.1099939
5.8227181	102.53082	35.056641	-3.1099703
5.8214664	306.17719	35.085938	-3.110105
5.8222442	315.79776	35.115234	-3.1100066
5.821918	133.18239	35.144531	-3.1100287
5.8221998	-123.95962	35.173828	-3.1101387
5.8219271	-304.37787	35.203125	-3.1101961
5.8216095	-313.8273	35.232422	-3.1102152
5.8227987	-146.95595	35.261719	-3.110254
5.8222575	87.78833	35.291016	-3.1101656
5.8215199	249.1012	35.320313	-3.1101041
5.8212428	264.61435	35.349609	-3.1102765
5.8210907	114.04289	35.378906	-3.1101913