File: data/T3.dat
MTS793|MPT|ENU|1|2|.|/|:|1|0|0|A

Data Acquisition						Time:	10.008789	s	2/4/2020 10:44:20 AM
Axial Displacement	Axial Force	Time	Axial Extensometer
mm	N	s	mm
-0.0013455749	173.10178	0.017578125	-0.00035076155
-0.0016853213	176.49365	0.046875	-0.00032326241
-0.00084936619	229.42888	0.076171875	-0.00014768702
0.0034600496	479.94034	0.10546875	0.0006913353
0.010165572	840.89905	0.13476563	0.0018365008
0.016464293	1194.1639	0.1640625	0.0028405949
0.022150576	1514.6068	0.19335938	0.0037153508
0.027483702	1803.1337	0.22265625	0.0047185146
0.032959878	2072.0186	0.25195313	0.0055484874
0.037993491	2319.1335	0.28125	0.0062806536
0.041569769	2567.9983	0.31054688	0.007093566
0.047193468	2805.6082	0.33984375	0.0078960154
0.051163137	3045.0901	0.36914063	0.0086071119
0.05504787	3276.3455	0.3984375	0.0093698688
0.059473515	3514.9771	0.42773438	0.0099867554
0.063626468	3759.5481	0.45703125	0.010799134
0.068369508	3998.7585	0.48632813	0.011598735
0.073814392	4241.7227	0.515625	0.012339863
0.078329444	4509.1851	0.54492188	0.013136541
0.084225833	4769.8496	0.57421875	0.013970499
0.089804828	5026.6484	0.60351563	0.014804419
0.094239414	5275.6885	0.6328125	0.015583577
0.098365545	5520.0742	0.66210938	0.016299829
0.10483414	5802.9624	0.69140625	0.017185237
0.11000633	6094.2061	0.72070313	0.018079696
0.11483878	6379.3462	0.75	0.018978143
0.12118667	6651.1299	0.77929688	0.019870743
0.12561232	6906.8315	0.80859375	0.020661537
0.131464	7154.1069	0.83789063	0.021465952
0.13533086	7394.3809	0.8671875	0.022170123
0.14087409	7628.7212	0.89648438	0.022868602
0.14448166	7861.0103	0.92578125	0.023592934
0.14912188	8087.6367	0.95507813	0.024343206
0.15437454	8315.4824	0.984375	0.024974827
0.15833974	8535.7227	1.0136719	0.025682289
0.16347617	8766.4092	1.0429688	0.026312675
0.16761571	8984.0625	1.0722656	0.027090108
0.17238557	9224.7979	1.1015625	0.027769903
0.17745495	9482.168	1.1308594	0.028632278
0.18359721	9741.1504	1.1601563	0.029441101
0.18846542	9999.6836	1.1894531	0.030258566
0.1944378	10261.659	1.21875	0.031027997
0.1987651	10517.643	1.2480469	0.031859558
0.20440221	10783.265	1.2773438	0.032689124
0.20890832	11031.003	1.3066406	0.033462003
0.2140224	11276.389	1.3359375	0.034283396
0.21938235	11508.668	1.3652344	0.03501137
0.22407621	11750.71	1.3945313	0.035853736
0.22825599	11992.519	1.4238281	0.03664086
0.2337411	12232.376	1.453125	0.037468538
0.23863167	12468.458	1.4824219	0.038062692
0.24400055	12709.315	1.5117188	0.038802411
0.24857819	12938.762	1.5410156	0.039597113
0.25388896	13189.758	1.5703125	0.040419146
0.25917739	13428.361	1.5996094	0.041163221
0.26470274	13670.816	1.6289063	0.041890591
0.26860535	13902.989	1.6582031	0.042635404
0.27410835	14141.871	1.6875	0.043293081
0.27800649	14364.438	1.7167969	0.044059753
0.28308928	14596.498	1.7460938	0.044841204
0.28741211	14823.037	1.7753906	0.045544975
0.29245466	15057.357	1.8046875	0.046326939
0.29707253	15277.469	1.8339844	0.047011003
0.30239224	15513.46	1.8632813	0.047740679
0.30682683	15744.587	1.8925781	0.048444785
0.31207502	15978.529	1.921875	0.049244527
0.31677783	16206.139	1.9511719	0.049891815
0.32141805	16438.391	1.9804688	0.050705064
0.32685846	16672.23	2.0097656	0.051414765
0.33105165	16915.203	2.0390625	0.052314047
0.33680052	17150.535	2.0683594	0.052984867
0.34194142	17383.908	2.0976563	0.053739447
0.34583509	17615.146	2.1269531	0.054396965
0.35197288	17850.895	2.15625	0.055327613
0.35709143	18083.129	2.1855469	0.055932138
0.36207587	18316.244	2.2148438	0.056639846
0.36685914	18540.541	2.2441406	0.057404861
0.37194639	18774.033	2.2734375	0.058060039
0.37724376	19001.371	2.3027344	0.058822107
0.38128495	19229.193	2.3320313	0.059390042
0.38619787	19461.73	2.3613281	0.060274027
0.39149523	19691.221	2.390625	0.061054125
0.39579123	19914.584	2.4199219	0.061831757
0.40032417	20140.746	2.4492188	0.062506974
0.40667206	20366.229	2.4785156	0.063229114
0.41044056	20588.012	2.5078125	0.063918419
0.41707456	20812.406	2.5371094	0.064691313
0.4204765	21030.693	2.5664063	0.065450318
0.42500943	21255.818	2.5957031	0.066148452
0.4301995	21479.439	2.625	0.066873141
0.43566674	21706.303	2.6542969	0.067602023
0.44018179	21928.506	2.6835938	0.068429552
0.44485331	22154.381	2.7128906	0.06910909
0.44950694	22375.709	2.7421875	0.069827184
0.45481324	22601.084	2.7714844	0.070543654
0.46043694	22829.646	2.8007813	0.071330644
0.4653275	23061.721	2.8300781	0.072109498
0.47049522	23293.139	2.859375	0.072834574
0.47453195	23523.916	2.8886719	0.073609784
0.47950298	23746.949	2.9179688	0.074363612
0.48500597	23970.08	2.9472656	0.075146951
0.48971325	24186.805	2.9765625	0.075864948
0.49452782	24396.875	3.0058594	0.076486349
0.49949884	24607.102	3.0351563	0.077226512
0.50418824	24823.361	3.0644531	0.077907659
0.50792992	25029.604	3.09375	0.078617036
0.51384866	25250.246	3.1230469	0.079391576
0.51820278	25463.168	3.1523438	0.080045037
0.52319169	25687.785	3.1816406	0.080808647
0.52907914	25896.715	3.2109375	0.08154577
0.53353161	26109.426	3.2402344	0.082233645
0.53884685	26319.428	3.2695313	0.08309067
0.5428344	26539.533	3.2988281	0.083704717
0.54795742	26749.74	3.328125	0.084402598
0.55317879	26965.713	3.3574219	0.085215576
0.55816323	27181.232	3.3867188	0.085901871
0.56267381	27401.264	3.4160156	0.086655132
0.56682229	27611.037	3.4453125	0.087435864
0.57261586	27825.162	3.4746094	0.088084161
0.57677776	28030.908	3.5039063	0.088768698
0.58170855	28237.102	3.5332031	0.089552619
0.58637559	28436.764	3.5625	0.090237878
0.59130192	28642.404	3.5917969	0.090974562
0.59543252	28849.752	3.6210938	0.091777392
0.60209781	29073.932	3.6503906	0.092404045
0.60545951	29286.107	3.6796875	0.093264684
0.6113559	29503.766	3.7089844	0.09397658
0.61583519	29713.291	3.7382813	0.094726659
0.62141418	29927.18	3.7675781	0.095422558
0.62651038	30131.066	3.796875	0.09616024
0.6319508	30345.584	3.8261719	0.096905239
0.63520521	30545.301	3.8554688	0.097592689
0.64047128	30753.93	3.8847656	0.098370068
0.64561665	30957.703	3.9140625	0.099107251
0.65040886	31166.801	3.9433594	0.099927925
0.65553635	31366.994	3.9726563	0.10068222
0.66066831	31572.051	4.0019531	0.10142028
0.66521466	31767.986	4.03125	0.10214113
0.66993535	31971.381	4.0605469	0.10271669
0.67500472	32176.342	4.0898438	0.10352908
0.68051219	32378.01	4.1191406	0.104421
0.68422258	32580.57	4.1484375	0.10512874
0.69049448	32794.484	4.1777344	0.10587934
0.69458485	32996.16	4.2070313	0.10657911
0.69964975	33204.383	4.2363281	0.10745399
0.70512593	33413.715	4.265625	0.10821031
0.71011037	33621.219	4.2949219	0.108914
0.7145226	33820.598	4.3242188	0.10977139
0.72080791	34028.711	4.3535156	0.11038799
0.72433054	34230.859	4.3828125	0.11123157
0.72957873	34430.648	4.4121094	0.11199983
0.7342726	34625.73	4.4414063	0.11277127
0.74045509	34826.234	4.4707031	0.11349785
0.74416548	35028.129	4.5	0.11433566
0.74877441	35199.043	4.5292969	0.11491106
0.75261891	35368.559	4.5585938	0.11568423
0.75889081	35576.18	4.5878906	0.11642332
0.76413006	35770.605	4.6171875	0.11722089
0.76769292	35967.375	4.6464844	0.11798514
0.77248067	36166.742	4.6757813	0.11869702
0.77837259	36371.199	4.7050781	0.11954571
0.78423768	36567.383	4.734375	0.12039876
0.78872144	36763.914	4.7636719	0.12111808
0.7929951	36962.781	4.7929688	0.12193682
0.79915076	37146.242	4.8222656	0.12262283
0.80337524	37346.566	4.8515625	0.1234349
0.80802441	37531.684	4.8808594	0.12422431
0.81361234	37717.473	4.9101563	0.12491519
0.81747025	37895.297	4.9394531	0.12566188
0.82377344	38080.082	4.96875	0.12638661
0.82805157	38251.559	4.9980469	0.12711236
0.832133	38431.051	5.0273438	0.12795386
0.83783716	38606.195	5.0566406	0.12873596
0.84156543	38777.707	5.0859375	0.12931505
0.84652752	38956.395	5.1152344	0.13010524
0.85263848	39134.402	5.1445313	0.1308527
0.85651875	39313.887	5.1738281	0.13167357
0.86212903	39499.66	5.203125	0.13248876
0.86630434	39679.168	5.2324219	0.13314573
0.87142289	39858.777	5.2617188	0.13393745
0.87619722	40050.23	5.2910156	0.13484685
0.88076144	40237.012	5.3203125	0.13563307
0.88677406	40416.605	5.3496094	0.13630421
0.89103878	40595.148	5.3789063	0.1371693
0.89652836	40770.664	5.4082031	0.1378763
0.90004206	40953.695	5.4375	0.13868877
0.90542436	41122.895	5.4667969	0.139469
0.91140121	41294.484	5.4960938	0.14024954
0.91482997	41457.766	5.5253906	0.14103347
0.92038214	41633.234	5.5546875	0.14177175
0.92493296	41797.156	5.5839844	0.1424918
0.9298414	41971.223	5.6132813	0.14331967
0.93497336	42143.535	5.6425781	0.14409032
0.94010085	42318.527	5.671875	0.14482656
0.94496459	42483.371	5.7011719	0.14568439
0.94886273	42653.555	5.7304688	0.14639385
0.95421374	42815.703	5.7597656	0.14726759
0.95832646	42983.785	5.7890625	0.14798599
0.96391886	43143.418	5.8183594	0.14883187
0.96869767	43313.641	5.8476563	0.14942913
0.97362846	43473.086	5.8769531	0.15036862
0.97758919	43644.523	5.90625	0.1511358
0.9827435	43810.148	5.9355469	0.15191182
0.98817497	43986.496	5.9648438	0.15268332
0.99285543	44155.879	5.9941406	0.15354089
0.99808574	44329.344	6.0234375	0.15434119
1.0026143	44499.145	6.0527344	0.15524229
1.0078714	44667.699	6.0820313	0.15600029
1.0129406	44825.238	6.1113281	0.1567547
1.0176748	44984.367	6.140625	0.15755369
1.023133	45139.801	6.1699219	0.15849072
1.0276392	45300.684	6.1992188	0.15927644
1.0326102	45456.09	6.2285156	0.16001289
1.0387077	45612.496	6.2578125	0.16078852
1.042311	45766.66	6.2871094	0.16155837
1.0460079	45926.852	6.3164063	0.16233715
1.0514259	46080.32	6.3457031	0.16324688
1.0562673	46242.496	6.375	0.16406126
1.062186	46402.023	6.4042969	0.16492039
1.0672599	46563.34	6.4335938	0.1657788
1.0708585	46717.84	6.4628906	0.1664826
1.0774567	46871.574	6.4921875	0.1673457
1.0809481	47028.199	6.5214844	0.16819344
1.0857761	47182.133	6.5507813	0.16903329
1.091136	47330.844	6.5800781	0.16986407
1.0953381	47484.223	6.609375	0.17065513
1.1008813	47641.891	6.6386719	0.17151035
1.1057496	47796.133	6.6679688	0.1723821
1.1101887	47946.684	6.6972656	0.17318535
1.1154101	48084.121	6.7265625	0.17398731
1.1220664	48239.313	6.7558594	0.17487825
1.1257186	48384.988	6.7851563	0.17565538
1.1301711	48539.98	6.8144531	0.17653415
1.1349857	48685.457	6.84375	0.17737025
1.1402831	48828.234	6.8730469	0.1782576
1.1454418	48965.887	6.9023438	0.1790646
1.1503682	49110.758	6.9316406	0.17991906
1.1553035	49245.914	6.9609375	0.18069156
1.1597469	49386.387	6.9902344	0.18149997
1.1644855	49526.645	7.0195313	0.182298
1.170069	49666.375	7.0488281	0.18315089
1.1746645	49800.738	7.078125	0.18397209
1.1782497	49950.383	7.1074219	0.18486647
1.1836007	50093.398	7.1367188	0.18574499
1.1893585	50243.547	7.1660156	0.18655118
1.1931539	50378.73	7.1953125	0.18746115
1.1989474	50519.676	7.2246094	0.18831056
1.2047321	50659.684	7.2539063	0.18914765
1.2084827	50803.906	7.2832031	0.19002385
1.2143924	50947.555	7.3125	0.19078898
1.2186348	51091.969	7.3417969	0.1918049
1.2246027	51231.043	7.3710938	0.19271508
1.2287333	51370.359	7.4003906	0.19357443
1.2338474	51503.066	7.4296875	0.1944571
1.2386844	51644.004	7.4589844	0.19535241
1.2435033	51773.691	7.4882813	0.19619648
1.2479424	51908.348	7.5175781	0.19708626
1.2526989	52027.832	7.546875	0.19794942
1.2582555	52162.711	7.5761719	0.19881183
1.2625337	52283.664	7.6054688	0.19966185
1.2671739	52415.023	7.6347656	0.20051469
1.2723863	52536.207	7.6640625	0.20128177
1.2761459	52666.602	7.6933594	0.20207672
1.2815192	52789.281	7.7226563	0.20309593
1.2865796	52921.57	7.7519531	0.20396698
1.291667	53048.426	7.78125	0.20485127
1.2966424	53177.469	7.8105469	0.20566937
1.3020203	53297.918	7.8398438	0.20650959
1.3064682	53433.641	7.8691406	0.20738891
1.3107374	53558.434	7.8984375	0.20840044
1.316455	53687.707	7.9277344	0.20925662
1.3211265	53804.16	7.9570313	0.21019588
1.3260484	53926.98	7.9863281	0.21093889
1.331301	54047.332	8.015625	0.21179038
1.3361961	54161.957	8.0449219	0.2126721
1.3406307	54282.238	8.0742188	0.21349025
1.3455302	54402.668	8.1035156	0.21436143
1.3505504	54522.668	8.1328125	0.21527196
1.3556197	54642.496	8.1621094	0.21616314
1.3602644	54756.75	8.1914063	0.21700871
1.3639972	54879.68	8.2207031	0.21803761
1.3697102	55004.418	8.25	0.21879768
1.375942	55125.215	8.2792969	0.21959946
1.3796031	55247.563	8.3085938	0.22069672
1.3849676	55370.305	8.3378906	0.22155376
1.3892591	55493.504	8.3671875	0.22249985
1.3937652	55609.258	8.3964844	0.22335981
1.3995721	55725.012	8.4257813	0.2242886
1.404807	55841.559	8.4550781	0.22515202
1.4093087	55960.266	8.484375	0.22624296
1.4141634	56074.617	8.5136719	0.22711325
1.4200866	56188.539	8.5429688	0.22793375
1.4240966	56299.93	8.5722656	0.2287963
1.4292731	56407.461	8.6015625	0.22969005
1.4338017	56517.605	8.6308594	0.23065092
1.4382541	56629.391	8.6601563	0.23153783
1.443243	56742.52	8.6894531	0.2325107
1.4486253	56853.008	8.71875	0.2334305
1.4533863	56966.004	8.7480469	0.23440325
1.4590814	57074.098	8.7773438	0.23527201
1.4634579	57182.93	8.8066406	0.23613393
1.4674678	57292.141	8.8359375	0.23702492
1.4733241	57397.219	8.8652344	0.23797481
1.4782101	57503.508	8.8945313	0.23889293
1.4826045	57609.418	8.9238281	0.23989792
1.4867976	57715.254	8.953125	0.24083
1.4921844	57820.063	8.9824219	0.24165362
1.4973118	57934.555	9.0117188	0.24262936
1.5021354	58033.105	9.0410156	0.24349597
1.5065879	58142.098	9.0703125	0.2445066
1.5115633	58243.25	9.0996094	0.24541259
1.5164137	58348.227	9.1289063	0.24627294
1.5218093	58449.434	9.1582031	0.24721608
1.5250325	58550.438	9.1875	0.24810459
1.5310228	58641.5	9.2167969	0.24896456
1.5358911	58741.313	9.2460938	0.24993843
1.540035	58836.504	9.2753906	0.2508688
1.5458107	58941.719	9.3046875	0.25181925
1.5509472	59042.285	9.3339844	0.25271851
1.5551939	59141.676	9.3632813	0.25360447
1.5605941	59241.91	9.3925781	0.25450835
1.5653908	59347.547	9.421875	0.25548849
1.5695081	59440.672	9.4511719	0.25651187
1.574774	59546.824	9.4804688	0.25750178
1.57924	59653.262	9.5097656	0.25838271
1.5849755	59764.484	9.5390625	0.25941053
1.5905366	59866.543	9.5683594	0.26036555
1.5952349	59970.238	9.5976563	0.26137796
1.6004517	60062.48	9.6269531	0.26236418
1.6057894	60161.965	9.65625	0.26336232
1.6098573	60254.715	9.6855469	0.26434067
1.6157269	60353.387	9.7148438	0.26531035
1.6203135	60439.883	9.7441406	0.26623103
1.6251013	60537.559	9.7734375	0.26724541
1.6300321	60629.582	9.8027344	0.26816306
1.635535	60721.926	9.8320313	0.26911032
1.6395181	60812.508	9.8613281	0.27002156
1.6442657	60909.152	9.890625	0.27097967
1.6502604	60991.5	9.9199219	0.27195907
1.6535594	61083.145	9.9492188	0.27296516
1.6583025	61174.07	9.9785156	0.27393657
1.6633987	61264.672	10.007813	0.27487612
1.6687632	61352.512	10.037109	0.27577424
1.6734078	61445.949	10.066406	0.27677655
1.6777307	61532.57	10.095703	0.27770692
1.6822948	61622.172	10.125	0.27865312
1.6877532	61714.395	10.154297	0.27970675
1.6938374	61805.762	10.183594	0.28061759
1.6984954	61900.973	10.212891	0.28153649
1.7028675	61999.984	10.242188	0.28263497
1.708071	62096.313	10.271484	0.2837036
1.7120852	62187.398	10.300781	0.28471604
1.7182007	62270.43	10.330078	0.28570408
1.7234311	62351.754	10.359375	0.28668693
1.7272935	62436.254	10.388672	0.28770876
1.7327204	62515.699	10.417969	0.28871378
1.7376111	62596	10.447266	0.28961116
1.7423898	62678.523	10.476563	0.29053542
1.7466769	62757.508	10.505859	0.2915923
1.7519832	62834.555	10.535156	0.2924518
1.755774	62918.551	10.564453	0.29347643
1.7611251	63000.961	10.59375	0.29435229
1.7663419	63077.184	10.623047	0.29534221
1.7702267	63157.676	10.652344	0.29627317
1.7756894	63234.613	10.681641	0.29722351
1.7805398	63314.094	10.710938	0.29831666
1.7838969	63403.488	10.740234	0.29931262
1.7888904	63484.898	10.769531	0.30022651
1.7942145	63573.434	10.798828	0.30131161
1.7996595	63654.602	10.828125	0.3022345
1.8043846	63740.27	10.857422	0.30333373
1.8094808	63820.621	10.886719	0.30430871
1.8148587	63903.645	10.916016	0.30530688
1.8193915	63980.297	10.945313	0.30624467
1.8247247	64066.383	10.974609	0.3074021
1.8301115	64146.059	11.003906	0.30844608
1.8334776	64229.066	11.033203	0.30937538
1.8381983	64309.105	11.0625	0.31047907
1.8444121	64391.168	11.091797	0.31152269
1.8485472	64469.148	11.121094	0.31252038
1.85422	64546.305	11.150391	0.31349322
1.8583014	64616.547	11.179688	0.31451538
1.8638716	64700.477	11.208984	0.31559572
1.8689901	64775.727	11.238281	0.31653562
1.8740191	64851.34	11.267578	0.3176091
1.8790975	64919.699	11.296875	0.31864956
1.8842115	64994.383	11.326172	0.31966972
1.8887713	65065.598	11.355469	0.3206619
1.8930271	65140.832	11.384766	0.32178029
1.8981769	65213.957	11.414063	0.32267115
1.903823	65284.941	11.443359	0.32377177
1.9071891	65354.813	11.472656	0.32479069
1.9130363	65435.234	11.501953	0.32581979
1.9177884	65498.934	11.53125	0.32692125
1.9223034	65574.07	11.560547	0.32779536
1.9268498	65643.5	11.589844	0.32897714
1.9316822	65716.188	11.619141	0.32988057
1.9363135	65787.172	11.648438	0.33091611
1.9425855	65860.055	11.677734	0.33185187
1.9465953	65925.406	11.707031	0.33292753
1.9520313	66005.734	11.736328	0.3339251
1.9557416	66076.141	11.765625	0.33508915
1.96082	66148.617	11.794922	0.33605862
1.9664347	66219.586	11.824219	0.33714852
1.9719555	66290.797	11.853516	0.33827764
1.9758179	66356.195	11.882813	0.33927771
1.9801319	66434.25	11.912109	0.34029546
1.9864798	66506.477	11.941406	0.34143376
1.9913971	66582.266	11.970703	0.3425898
1.9966096	66648.602	12	0.34360665
2.0025327	66722.82	12.029297	0.34466487
2.0064487	66793.844	12.058594	0.34582654
2.0122023	66858.844	12.087891	0.3468267
2.0161762	66923.258	12.117188	0.34791666
2.0215049	66991.875	12.146484	0.34892061
2.0270302	67056.703	12.175781	0.35000673
2.0305753	67123.836	12.205078	0.35105476
2.0363019	67188.109	12.234375	0.35213494
2.0411119	67249.094	12.263672	0.35318553
2.0474286	67312.258	12.292969	0.35429588
2.0515368	67371.391	12.322266	0.35532916
2.0558147	67435.789	12.351563	0.35639244
2.0610764	67498.133	12.380859	0.35746816
2.0652831	67555.906	12.410156	0.35853758
2.0705447	67613.977	12.439453	0.35952261
2.0745993	67675.586	12.46875	0.360596
2.0804241	67733.563	12.498047	0.36164239
2.084224	67801.641	12.527344	0.36259949
2.0880194	67859.852	12.556641	0.36359361
2.0933657	67910.367	12.585938	0.36470214
2.0988152	67957.188	12.615234	0.3656725
2.1031425	68029.945	12.644531	0.36675674
2.1082163	68102.797	12.673828	0.36788166
2.1135092	68168.141	12.703125	0.36901015
2.1178007	68235.914	12.732422	0.3700738
2.1224632	68307.461	12.761719	0.37117577
2.1286011	68370.422	12.791016	0.37223583
2.1327674	68434.656	12.820313	0.37331918
2.1389275	68487.953	12.849609	0.37452394
2.1427631	68551.016	12.878906	0.37556446
2.1472826	68605.883	12.908203	0.37661773
2.1530986	68668.289	12.9375	0.37778288
2.1573992	68724.102	12.966797	0.37887651
2.1630764	68786.945	12.996094	0.37990585
2.1675334	68838.898	13.025391	0.38109046
2.1729693	68893.102	13.054688	0.38205937
2.1773458	68952.391	13.083984	0.38313082
2.1822543	69012.867	13.113281	0.38428545
2.1872611	69063.313	13.142578	0.38535321
2.1916599	69126.313	13.171875	0.3865
2.1958933	69173.992	13.201172	0.38753423
2.2012801	69235.852	13.230469	0.38859189
2.2065327	69295.195	13.259766	0.38975561
2.211441	69353.984	13.289063	0.3908734
2.2165327	69407.305	13.318359	0.39195386
2.2220626	69463.617	13.347656	0.39296898
2.2263141	69513.648	13.376953	0.39417782
2.2305341	69573.352	13.40625	0.39521787
2.2359476	69627.531	13.435547	0.39640501
2.2404671	69683.438	13.464844	0.39740989
2.2455142	69736.18	13.494141	0.39855269
2.2506773	69793.195	13.523438	0.39968646
2.2556663	69843.57	13.552734	0.40084851
2.2606463	69901.07	13.582031	0.40172189
2.265358	69944.992	13.611328	0.40293169
2.2695155	69999.516	13.640625	0.40398857
2.2744596	70051.109	13.669922	0.40508541
2.2800655	70104.367	13.699219	0.40624294
2.2840171	70153.172	13.728516	0.40733126
2.2887201	70204.336	13.757813	0.40827873
2.2944868	70254.328	13.787109	0.40944028
2.2996857	70307.43	13.816406	0.41054982
2.302681	70350.555	13.845703	0.41168949
2.3075314	70403.789	13.875	0.41265339
2.3143663	70452.82	13.904297	0.41375691
2.3173258	70504.203	13.933594	0.41484603
2.3238211	70565.32	13.962891	0.41603041
2.3274331	70619.563	13.992188	0.41708764
2.3316889	70673.898	14.021484	0.41838092
2.3378849	70728.008	14.050781	0.41944456
2.3424759	70784.227	14.080078	0.42062205
2.3468347	70838.32	14.109375	0.42174271
2.352427	70887.156	14.138672	0.42294946
2.3576796	70940.336	14.167969	0.42409858
2.3630843	70992.25	14.197266	0.42527172
2.3680329	71039.82	14.226563	0.42650589
2.3737774	71091.609	14.255859	0.42760479
2.3783774	71138.352	14.285156	0.42883614
2.3829639	71183.469	14.314453	0.42983109
2.388221	71228.867	14.34375	0.43107656
2.3928075	71272.344	14.373047	0.43218794
2.3979082	71316.188	14.402344	0.43327191
2.4026692	71357.93	14.431641	0.43427697
2.407238	71398.203	14.460938	0.43548954
2.4116769	71446.836	14.490234	0.4365772
2.4168804	71491.188	14.519531	0.43773267
2.4223118	71538.125	14.548828	0.43887797
2.4266481	71583.008	14.578125	0.43987408
2.4308681	71626.477	14.607422	0.44096148
2.4363353	71667.125	14.636719	0.44222057
2.4408638	71715.992	14.666016	0.44325957
2.4453521	71767.336	14.695313	0.44448119
2.4506316	71817.672	14.724609	0.44548047
2.4565325	71863.219	14.753906	0.44680107
2.4593041	71913.094	14.783203	0.44788647
2.4659157	71953.555	14.8125	0.44907558
2.4699302	72004.008	14.841797	0.45016959
2.4750173	72042.094	14.871094	0.45136935
2.481164	72093.289	14.900391	0.45253378
2.4848433	72132.969	14.929688	0.45363817
2.4899259	72185.25	14.958984	0.45496988
2.4952636	72224.984	14.988281	0.45606253
2.4997921	72272	15.017578	0.45720035
2.5047317	72308.352	15.046875	0.45832893
2.5107667	72350.219	15.076172	0.45952573
2.5143921	72388.195	15.105469	0.46068928
2.5201633	72434.898	15.134766	0.46170032
2.5240972	72472.016	15.164063	0.46296263
2.5286615	72511.797	15.193359	0.46410275
2.5334806	72550.523	15.222656	0.46520144
2.5389924	72595.594	15.251953	0.46625885
2.5433466	72630.117	15.28125	0.4674468
2.5482907	72670.57	15.310547	0.46853
2.5525823	72708.844	15.339844	0.46970633
2.5581121	72753.719	15.369141	0.47079948
2.5625734	72788.703	15.398438	0.472002
2.5672362	72831.602	15.427734	0.47307807
2.5718138	72866.664	15.457031	0.4742268
2.5759041	72912.023	15.486328	0.47541663
2.5813982	72948.617	15.515625	0.47648382
2.5868564	72990.484	15.544922	0.47758621
2.5911973	73027.734	15.574219	0.47881603
2.5957837	73068.773	15.603516	0.4798997
2.6009514	73108.82	15.632813	0.48104277
2.606535	73146.672	15.662109	0.48222554
2.6102006	73189.25	15.691406	0.48334828
2.6152701	73231.352	15.720703	0.48456985
2.6206791	73273.172	15.75	0.4857024
2.6249304	73319.93	15.779297	0.48694766
2.6301293	73361.414	15.808594	0.48811325
2.6350691	73405.898	15.837891	0.48931375
2.6403799	73444.023	15.867188	0.49054438
2.6454449	73480.633	15.896484	0.49169934
2.6502638	73525.906	15.925781	0.49294385
2.655056	73563.25	15.955078	0.49423808
2.6604428	73604.117	15.984375	0.4953157
2.6656911	73639.141	16.013672	0.4965499
2.6705594	73676.914	16.042969	0.49779099
2.6750386	73717.547	16.072266	0.49894041
2.6805236	73755.219	16.101563	0.50020474
2.6861832	73794.828	16.130859	0.50141549
2.6905239	73829.633	16.160156	0.50269276
2.6953652	73869.273	16.189453	0.50383687
2.7002289	73904.242	16.21875	0.50507849
2.7052627	73936.125	16.248047	0.50627536
2.7106941	73971.242	16.277344	0.50730979
2.7155666	74006.281	16.306641	0.50855607
2.7199566	74038.016	16.335938	0.50970513
2.7246685	74065.109	16.365234	0.51095027
2.7292237	74104.328	16.394531	0.51213562
2.7343915	74131.758	16.423828	0.51334286
2.7392774	74170.945	16.453125	0.51442772
2.7431533	74197.703	16.482422	0.51563251
2.7490542	74236.102	16.511719	0.51675302
2.752912	74269.07	16.541016	0.51790917
2.7579725	74311.031	16.570313	0.51914459
2.7637124	74338.063	16.599609	0.52034372
2.7679415	74373.453	16.628906	0.52146459
2.7718976	74405.438	16.658203	0.52271074
2.7787328	74444.047	16.6875	0.52386647
2.782233	74474.672	16.716797	0.52501285
2.7887509	74509.664	16.746094	0.52617252
2.7920947	74539.945	16.775391	0.52744603
2.7975395	74578.453	16.804688	0.52863884
2.8024435	74605.93	16.833984	0.52980143
2.8068781	74643.047	16.863281	0.53099525
2.8116612	74668.953	16.892578	0.53211778
2.8169007	74707.383	16.921875	0.53327382
2.8216169	74734.602	16.951172	0.5344947
2.8262882	74771.43	16.980469	0.53564966
2.8309598	74803.539	17.009766	0.53683412
2.8351531	74838.664	17.039063	0.53802818
2.8400705	74870.289	17.068359	0.53926021
2.8459847	74910.133	17.097656	0.54047781
2.8514431	74941.297	17.126953	0.54174155
2.8562889	74978.852	17.15625	0.54293436
2.8609469	75007.641	17.185547	0.54421866
2.8655336	75042.398	17.214844	0.54538429
2.8699055	75069.555	17.244141	0.54666752
2.8754175	75103.031	17.273438	0.54778194
2.8806434	75128.617	17.302734	0.54907972
2.8849974	75160.156	17.332031	0.55026788
2.8897941	75183.992	17.361328	0.55137116
2.8955474	75220.25	17.390625	0.55255061
2.8992758	75245.867	17.419922	0.55383182
2.9053152	75280.016	17.449219	0.555031
2.90941	75308.805	17.478516	0.55624074
2.914618	75340.625	17.507813	0.5574531
2.918838	75368.906	17.537109	0.55860424
2.9240324	75397.531	17.566406	0.55975795
2.9292808	75426.734	17.595703	0.56096864
2.9331207	75454	17.625	0.56224281
2.9395714	75481.703	17.654297	0.56347024
2.9439077	75517.125	17.683594	0.56457812
2.9492588	75542.078	17.712891	0.56573439
2.9530361	75572.32	17.742188	0.56703311
2.9586105	75605.57	17.771484	0.56813377
2.9637113	75633.539	17.800781	0.56942225
2.9685841	75659.445	17.830078	0.57064456
2.9732153	75691.977	17.859375	0.57190114
2.978164	75726.875	17.888672	0.57308358
2.9820979	75752.719	17.917969	0.57432395
2.9877529	75782.406	17.947266	0.57553327
2.9921784	75806.203	17.976563	0.57669812
2.9977798	75837.516	18.005859	0.57798547
3.0029073	75866.391	18.035156	0.57911557
3.0069351	75896.406	18.064453	0.5805164
3.0115752	75922.781	18.09375	0.58169907
3.0173197	75952.992	18.123047	0.58288002
3.0218616	75974.594	18.152344	0.58416373
3.0262604	76007.859	18.181641	0.58542764
3.030941	76033.133	18.210938	0.5865413
3.0367255	76062.531	18.240234	0.58770686
3.040731	76083.969	18.269531	0.58898491
3.0466228	76113.656	18.298828	0.59029496
3.0504136	76136.438	18.328125	0.59142882
3.0565336	76167.258	18.357422	0.59264421
3.0603468	76189.57	18.386719	0.59403676
3.0659616	76224.023	18.416016	0.59512925
3.0713036	76243.914	18.445313	0.59624499
3.0756221	76271.141	18.474609	0.5975377
3.0815899	76296.133	18.503906	0.59881097
3.0854211	76324.617	18.533203	0.60001719
3.0911162	76343.93	18.5625	0.60121351
3.0950904	76374	18.591797	0.60243797
3.1002893	76395.703	18.621094	0.60369587
3.104353	76418.875	18.650391	0.60486484
3.10864	76445.977	18.679688	0.60609215
3.1142502	76472.563	18.708984	0.60724592
3.119029	76496.484	18.738281	0.60849589
3.124635	76523.406	18.767578	0.6097759
3.1283989	76546.406	18.796875	0.61096328
3.1340673	76578.953	18.826172	0.61221099
3.1386449	76601.969	18.855469	0.61335009
3.1441793	76633	18.884766	0.61468399
3.1491055	76657.461	18.914063	0.61587936
3.1538889	76694.688	18.943359	0.61721176
3.1594322	76715.211	18.972656	0.61841094
3.163013	76743.594	19.001953	0.6196565
3.1684265	76763.188	19.03125	0.62095082
3.1742425	76789.508	19.060547	0.62223113
3.1782479	76810.445	19.089844	0.62355882
3.1829329	76839.594	19.119141	0.62467796
3.1884222	76860.086	19.148438	0.62595397
3.1938224	76890.5	19.177734	0.62730438
3.1987176	76908.797	19.207031	0.6285634
3.20262	76937.367	19.236328	0.62973279
3.2082705	76958.391	19.265625	0.6310752
3.2129154	76982.805	19.294922	0.63229382
3.2183692	76998.922	19.324219	0.63354111
3.2227099	77021.672	19.353516	0.63470858
3.2284141	77040.336	19.382813	0.63588822
3.2323928	77060.461	19.412109	0.63711888
3.2368944	77086.617	19.441406	0.63852561
3.2412484	77114.664	19.470703	0.63973719
3.2474132	77137.445	19.5	0.64095509
3.2530456	77163.117	19.529297	0.64217502
3.2573774	77185.469	19.558594	0.64339238
3.2614543	77210.094	19.587891	0.64466608
3.266439	77236.625	19.617188	0.64597696
3.2723174	77259.461	19.646484	0.64735252
3.276752	77283.023	19.675781	0.64848703
3.2824249	77304.047	19.705078	0.64977092
3.2863946	77321.992	19.734375	0.65103859
3.290905	77340.172	19.763672	0.65234667
3.2965019	77361.063	19.792969	0.65355295
3.3009634	77379.164	19.822266	0.65478981
3.3059211	77399.789	19.851563	0.65600479
3.3108206	77414.547	19.880859	0.65712339
3.3149691	77415.211	19.910156	0.65829098
3.319627	77449.117	19.939453	0.65948552
3.3248663	77489.813	19.96875	0.66083771
3.3301189	77524.609	19.998047	0.66204959
3.33547	77559.398	20.027344	0.66345048
3.3396766	77593.203	20.056641	0.66485375
3.3457651	77622.781	20.085938	0.6662398
3.3504992	77648.039	20.115234	0.66756308
3.3568292	77677.07	20.144531	0.66896886
3.3614919	77693.289	20.173828	0.67027754
3.3668966	77711.07	20.203125	0.6717239
3.372015	77720.617	20.232422	0.67303288
3.376843	77736.727	20.261719	0.67428041
3.3819749	77746.422	20.291016	0.67547661
3.3867762	77760.07	20.320313	0.67685175
3.3903613	77765.266	20.349609	0.67796856
3.3953547	77786.531	20.378906	0.67921567
3.3993199	77800.086	20.408203	0.68036342
3.4050152	77819.859	20.4375	0.68155318
3.4097581	77834.422	20.466797	0.68281901
3.413862	77857.406	20.496094	0.6840378
3.4170046	77872.203	20.525391	0.68528211
3.423661	77893.914	20.554688	0.6865083
3.4278274	77910.328	20.583984	0.68773353
3.4333527	77936.469	20.613281	0.68894827
3.4370093	77951.016	20.642578	0.69019711
3.4422576	77980.656	20.671875	0.69146699
3.4464107	77990.539	20.701172	0.69268775
3.4515963	78013.43	20.730469	0.69393325
3.4564688	78027.984	20.759766	0.69510257
3.4627185	78054.672	20.789063	0.69641829
3.4660711	78071.094	20.818359	0.69773012
3.471458	78095.891	20.847656	0.6988169
3.476438	78113.578	20.876953	0.70011181
3.4811854	78139.602	20.90625	0.70136887
3.4851863	78156.617	20.935547	0.70273477
3.4895539	78178.508	20.964844	0.70390093
3.4956336	78194.75	20.994141	0.70520824
3.5007789	78217.102	21.023438	0.70653278
3.5053432	78241.43	21.052734	0.70775247
3.5098047	78264.813	21.082031	0.70911378
3.5146549	78289.141	21.111328	0.71040356
3.5204887	78306.289	21.140625	0.71178752
3.5245433	78324.055	21.169922	0.71305853
3.5296037	78344.75	21.199219	0.71433312
3.5357819	78356.586	21.228516	0.71556079
3.5384417	78379.586	21.257813	0.71686399
3.5443335	78395.852	21.287109	0.71822643
3.5492687	78417.414	21.316406	0.71946895
3.5541191	78430.703	21.345703	0.72068852
3.5606236	78452.492	21.375	0.72207284
3.5653665	78471.469	21.404297	0.72332877
3.5695062	78492.047	21.433594	0.72463775
3.5738065	78509.43	21.462891	0.72607005
3.5790906	78529.484	21.492188	0.72735578
3.5845623	78543.859	21.521484	0.72856724
3.5891712	78561.891	21.550781	0.72991192
3.5937712	78577.773	21.580078	0.73113501
3.598465	78595.703	21.609375	0.7325297
3.6035881	78608.859	21.638672	0.73376602
3.6088495	78626.836	21.667969	0.73513007
3.613709	78644.516	21.697266	0.73642063
3.6180809	78659.836	21.726563	0.73766744
3.6225603	78678.633	21.755859	0.73894995
3.6281438	78693.766	21.785156	0.74034488
3.6335974	78710.516	21.814453	0.74149668
3.6375136	78723.242	21.84375	0.74278146
3.6426454	78747.539	21.873047	0.74417949
3.6481752	78759.641	21.902344	0.74542952
3.6529765	78777.516	21.931641	0.7467252
3.6573977	78791.141	21.960938	0.74797046
3.6618857	78811.773	21.990234	0.74928755
3.6658378	78823.117	22.019531	0.75060052
3.6726103	78841.797	22.048828	0.75193882
3.6768391	78856.164	22.078125	0.75329858
3.6816268	78880.023	22.107422	0.75446993
3.6860883	78896.297	22.136719	0.75575018
3.6904426	78914.055	22.166016	0.75700247
3.6959543	78925.555	22.195313	0.75835323
3.7024186	78949.648	22.224609	0.75967759
3.7070184	78962.609	22.253906	0.76101661
3.7114441	78981.68	22.283203	0.76234418
3.7151546	78995.289	22.3125	0.76359421
3.7206933	79018.516	22.341797	0.76494354
3.7258968	79031.063	22.371094	0.76636583
3.73085	79053.969	22.400391	0.76763201
3.735611	79062.719	22.429688	0.76896095
3.7402689	79078.672	22.458984	0.77030671
3.7455842	79087.984	22.488281	0.77155364
3.750278	79106.773	22.517578	0.77292162
3.7547753	79119.305	22.546875	0.7741468
3.7599339	79138.195	22.576172	0.77560383
3.7650838	79143.719	22.605469	0.77688825
3.7693129	79165.891	22.634766	0.77817047
3.7745342	79177.109	22.664063	0.77937484
3.7793889	79199.133	22.693359	0.78076142
3.7841053	79209.75	22.722656	0.78215635
3.7901044	79226.555	22.751953	0.78345251
3.7937255	79238.125	22.78125	0.78474438
3.7990899	79254.359	22.810547	0.78602117
3.8034172	79265.992	22.839844	0.78727496
3.8085043	79288.047	22.869141	0.78868741
3.8141906	79297.133	22.898438	0.7900334
3.8179994	79317.016	22.927734	0.79127878
3.8223848	79329.531	22.957031	0.7925902
3.8282542	79344.414	22.986328	0.79392391
3.8323269	79354.914	23.015625	0.79519492
3.8371727	79372.578	23.044922	0.79656672
3.842689	79387.125	23.074219	0.79785949
3.8459525	79401.727	23.103516	0.79920393
3.8521037	79415.805	23.132813	0.80047953
3.8570032	79428.539	23.162109	0.80187345
3.8622692	79442.852	23.191406	0.80321634
3.8649871	79457.297	23.220703	0.80446881
3.8701415	79473.656	23.25	0.805794
3.8772628	79483.563	23.279297	0.80711079
3.8804321	79500.648	23.308594	0.80849242
3.8869545	79512.195	23.337891	0.80978727
3.8913221	79531.125	23.367188	0.8110069
3.8958817	79543.242	23.396484	0.81247783
3.9010942	79558.82	23.425781	0.81375146
3.9058194	79570.313	23.455078	0.81504983
3.9107947	79585.805	23.484375	0.81650758
3.9150999	79597.766	23.513672	0.8177802
3.9203525	79616.578	23.542969	0.81913519
3.9254174	79632.117	23.572266	0.82057089
3.9294496	79651.266	23.601563	0.82190961
3.9351225	79660.484	23.630859	0.82315314
3.9396107	79675.781	23.660156	0.82449579
3.9453104	79687.438	23.689453	0.82584572
3.949146	79703.445	23.71875	0.82715863
3.9544389	79715.828	23.748047	0.82851756
3.9593742	79732.695	23.777344	0.83000612
3.9649174	79742.359	23.806641	0.83127898
3.9700985	79758.664	23.835938	0.83263844
3.9747655	79766.57	23.865234	0.83390969
3.9795489	79783.039	23.894531	0.83529967
3.9836974	79791.039	23.923828	0.8367247
3.9893613	79808.047	23.953125	0.83809769
3.993988	79819.5	23.982422	0.83947676
3.9998844	79836.625	24.011719	0.84081924
4.0037155	79848.469	24.041016	0.84208316
4.009871	79864.258	24.070313	0.84352571
4.0142479	79872.5	24.099609	0.84495312
4.0195627	79889.695	24.128906	0.84611195
4.0232778	79896.359	24.158203	0.84760135
4.0282087	79906.656	24.1875	0.84888411
4.0336266	79913.57	24.216797	0.8502543
4.0378866	79924.711	24.246094	0.85159838
4.0426435	79930.992	24.275391	0.85293561
4.0471716	79950.242	24.304688	0.85425526
4.0524778	79959.086	24.333984	0.8555724
4.0571985	79973.344	24.363281	0.85687089
4.062675	79985.93	24.392578	0.85824728
4.0676861	80002.531	24.421875	0.85952896
4.0716739	80010.398	24.451172	0.86087477
4.0767474	80027.883	24.480469	0.86226726
4.0821209	80034.094	24.509766	0.86366832
4.0867882	80047.07	24.539063	0.86497653
4.0922284	80057.484	24.568359	0.8663395
4.0965066	80075.922	24.597656	0.86765045
4.1025863	80083.383	24.626953	0.86908084
4.1063862	80099.109	24.65625	0.87039089
4.1110172	80110.383	24.685547	0.8717944
4.1163011	80117.383	24.714844	0.87308764
4.1214781	80130.75	24.744141	0.8744356
4.1258321	80144.078	24.773438	0.87583071
4.1311517	80154.086	24.802734	0.87718439
4.1362748	80167.016	24.832031	0.87855679
4.1407986	80176.016	24.861328	0.87989992
4.145524	80191.578	24.890625	0.88130361
4.1506872	80204.141	24.919922	0.88266325
4.154983	80214.711	24.949219	0.88393354
4.1599455	80223.07	24.978516	0.8853575
4.1647687	80227.148	25.007813	0.88666123
4.169981	80242.859	25.037109	0.88800639
4.1743798	80251.727	25.066406	0.88926119
4.1790514	80262.539	25.095703	0.8906365
4.1846352	80272.984	25.125	0.8920241
4.1890473	80283.023	25.154297	0.89334381
4.1929455	80290.367	25.183594	0.89463568
4.1988015	80304.898	25.212891	0.89607453
4.2033882	80315.391	25.242188	0.89740878
4.2079029	80326.656	25.271484	0.89868373
4.2140141	80339.43	25.300781	0.9000864
4.2183728	80351.789	25.330078	0.90143567
4.2237148	80361.891	25.359375	0.90283686
4.2280064	80381.938	25.388672	0.90420723
4.2324767	80388.547	25.417969	0.90550309
4.2375236	80407.578	25.447266	0.90696943
4.2430892	80414.602	25.476563	0.90828401
4.2470007	80429.656	25.505859	0.90969515
4.252142	80439.297	25.535156	0.9111656
4.2577562	80451.781	25.564453	0.9125241
4.2628617	80459.484	25.59375	0.91393483
4.2667775	80475.859	25.623047	0.91533583
4.2724819	80481.406	25.652344	0.91667455
4.2779264	80493.125	25.681641	0.91797173
4.2822943	80498.539	25.710938	0.91940117
4.287158	80510.82	25.740234	0.92075342
4.2919145	80518.063	25.769531	0.92224365
4.2973099	80535.328	25.798828	0.92355651
4.3027506	80545.57	25.828125	0.92486256
4.3078198	80563.055	25.857422	0.92637306
4.3122768	80563.969	25.886719	0.927737
4.3168411	80579.523	25.916016	0.92913485
4.3232694	80581.641	25.945313	0.93046635
4.3277307	80595.32	25.974609	0.93196863
4.3325005	80601.281	26.003906	0.93328446
4.3355136	80613.422	26.033203	0.93470687
4.341732	80620.938	26.0625	0.93612462
4.346837	80631.25	26.091797	0.93742591
4.3507977	80636.992	26.121094	0.938851
4.3563633	80651.414	26.150391	0.94030857
4.3613119	80661.461	26.179688	0.94167846
4.3665023	80668.461	26.208984	0.94303715
4.3709726	80668.992	26.238281	0.94440216
4.3760552	80681.531	26.267578	0.94576579
4.3811336	80686.422	26.296875	0.94700724
4.3855591	80692.922	26.326172	0.9484446
4.3900785	80700.883	26.355469	0.94982529
4.3958187	80708.305	26.384766	0.95117843
4.4001327	80712.766	26.414063	0.95244527
4.4044108	80720.578	26.443359	0.95384574
4.4085903	80732.406	26.472656	0.95528483
4.41366	80739.5	26.501953	0.95663875
4.4184833	80748.352	26.53125	0.95782977
4.4228735	80761.18	26.560547	0.95929956
4.4285417	80772.828	26.589844	0.96067911
4.4332175	80778.32	26.619141	0.96195108
4.4376926	80791.258	26.648438	0.96342272
4.4434729	80797.859	26.677734	0.96471083
4.4482112	80807.188	26.707031	0.96611828
4.4528871	80814.531	26.736328	0.96745431
4.4567809	80827.586	26.765625	0.96882278
4.4628115	80832.297	26.794922	0.97025639
4.4673042	80849.211	26.824219	0.97158921
4.4720383	80853.469	26.853516	0.97306067
4.4769244	80867.492	26.882813	0.97433585
4.4817209	80874.234	26.912109	0.97572434
4.4855566	80883.289	26.941406	0.97709358
4.4901428	80887.039	26.970703	0.97845817
4.4962673	80904.102	27	0.9798888
4.5003085	80908	27.029297	0.98122793
4.5054765	80921.766	27.058594	0.98261577
4.5110598	80926.828	27.087891	0.98408329
4.515624	80945.188	27.117188	0.98543787
4.5202198	80950.055	27.146484	0.9868173
4.5248327	80959.773	27.175781	0.98826927
4.5298934	80967.219	27.205078	0.98968905
4.5359058	80980.195	27.234375	0.99102056
4.5402603	80984.039	27.263672	0.99245095
4.5458837	80995.609	27.292969	0.99390888
4.5503631	81002.758	27.322266	0.9952392
4.5551462	81013.977	27.351563	0.99676579
4.5598536	81019.664	27.380859	0.99810982
4.5647979	81031.766	27.410156	0.99951404
4.5699744	81034.266	27.439453	1.0009248
4.5739799	81048.688	27.46875	1.0023177
4.57934	81050.32	27.498047	1.0038041
4.5850978	81063.75	27.527344	1.0051448
4.5888529	81068.766	27.556641	1.0065582
4.5939445	81079.031	27.585938	1.0080067
4.5991569	81080.664	27.615234	1.0093983
4.6044631	81092.43	27.644531	1.0109118
4.609488	81098.078	27.673828	1.0122083
4.6142311	81111.25	27.703125	1.0136498
4.6189876	81116.211	27.732422	1.0150813
4.6249957	81125.367	27.761719	1.0165504
4.6287909	81128.031	27.791016	1.0179279
4.6347408	81136.836	27.820313	1.0193205
4.6380534	81142.547	27.849609	1.020811
4.6435833	81150.648	27.878906	1.0221606
4.6488538	81154.461	27.908203	1.0236341
4.6526713	81162.438	27.9375	1.0250106
4.6580181	81171.484	27.966797	1.0264189
4.6626673	81178.547	27.996094	1.0277636
4.6671643	81181.602	28.025391	1.0292257
4.6726942	81194.266	28.054688	1.0306365
4.6778665	81205.992	28.083984	1.0321355
4.6838121	81210.555	28.113281	1.0335411
4.6866641	81219.125	28.142578	1.0349156
4.6920867	81227.563	28.171875	1.0363868
4.6967087	81235.484	28.201172	1.0378646
4.7017293	81243.82	28.230469	1.0392542
4.7071161	81255.047	28.259766	1.0408183
4.7120152	81261.375	28.289063	1.0421687
4.7167497	81272.43	28.318359	1.0436455
4.7219396	81277.75	28.347656	1.0450165
4.7274294	81287.039	28.376953	1.0464536
4.7319889	81291.375	28.40625	1.0479112
4.7368169	81300.391	28.435547	1.0494249
4.7415643	81300.477	28.464844	1.0507972
4.7469335	81306.711	28.494141	1.0522096
4.7524633	81310.508	28.523438	1.0536952
4.7564058	81316.016	28.552734	1.0551723
4.7614617	81323	28.582031	1.0566096
4.7664909	81335.031	28.611328	1.0579954
4.7711625	81337.266	28.640625	1.0594866
4.7757668	81346.133	28.669922	1.0608395
4.7813997	81349.32	28.699219	1.0623629
4.7858744	81357.188	28.728516	1.0637765
4.7902641	81352.836	28.757813	1.0651394
4.795763	81364.438	28.787109	1.0665547
4.8001304	81370.602	28.816406	1.0679555
4.8046408	81378.219	28.845703	1.0693878
4.8097906	81378.531	28.875	1.070768
4.8141584	81390.023	28.904297	1.0721823
4.8190489	81396.086	28.933594	1.0736681
4.8244624	81402.797	28.962891	1.0751127
4.8289061	81406.156	28.992188	1.0764532
4.8341808	81418.867	29.021484	1.0779622
4.8398004	81417.195	29.050781	1.0793673
4.8428268	81431.984	29.080078	1.0807267
4.8486471	81433.063	29.109375	1.082243
4.8530192	81445.859	29.138672	1.0836887
4.8576145	81448.883	29.167969	1.0852073
4.8621922	81461.102	29.197266	1.0865711
4.8686876	81463.703	29.226563	1.0880224
4.8731937	81474.609	29.255859	1.0894535
4.8775616	81477.992	29.285156	1.0908999
4.8831182	81487.898	29.314453	1.0923057
4.8881383	81491.164	29.34375	1.093817
4.8930287	81503.906	29.373047	1.0953732
4.8974457	81501.641	29.402344	1.0968406
4.9025326	81509.078	29.431641	1.0982111
4.907021	81512.125	29.460938	1.0998024
4.9120321	81520.391	29.490234	1.1012007
4.9166636	81531.336	29.519531	1.1026859
4.9227161	81538.164	29.548828	1.1041826
4.928483	81544.406	29.578125	1.1056418
4.9315095	81549.398	29.607422	1.1070725
4.9380898	81554.93	29.636719	1.1085058
4.9420776	81558.328	29.666016	1.109933
4.9467311	81562.68	29.695313	1.111403
4.9515681	81569.297	29.724609	1.1129462
4.9570889	81577.656	29.753906	1.1142781
4.9622073	81578.523	29.783203	1.1158105
4.9666824	81583.492	29.8125	1.117244
4.9712062	81591.203	29.841797	1.1187569
4.9768791	81595.492	29.871094	1.1203082
4.981555	81600.336	29.900391	1.121675
4.9866424	81602.258	29.929688	1.1231507
4.9915018	81609.219	29.958984	1.1246744
4.9963293	81615.281	29.988281	1.1260833
5.0011353	81623.313	30.017578	1.1276559
5.0048056	81634.367	30.046875	1.1289918
5.0107913	81635.828	30.076172	1.1305919
5.0160484	81649.398	30.105469	1.1320127
5.0205321	81655.406	30.134766	1.1335728
5.0260887	81659.195	30.164063	1.1351075
5.0306888	81662.117	30.193359	1.1365113
5.0352349	81669.836	30.222656	1.1380532
5.0401478	81672.07	30.251953	1.1395624
5.0449357	81680.383	30.28125	1.1410388
5.0504298	81682.719	30.310547	1.1425381
5.0554008	81687.469	30.339844	1.1440456
5.0603361	81688.242	30.369141	1.145528
5.0650253	81693.57	30.398438	1.1470217
5.0700502	81692.461	30.427734	1.1483865
5.0746589	81700.984	30.457031	1.1498306
5.0796881	81698.047	30.486328	1.151412
5.0847979	81707.789	30.515625	1.1528558
5.0892191	81705.711	30.544922	1.1542476
5.0941544	81717.18	30.574219	1.155791
5.1009359	81719.289	30.603516	1.1572167
5.1026926	81724.234	30.632813	1.1587166
5.1078825	81722.047	30.662109	1.1600677
5.1145926	81733.445	30.691406	1.161617
5.1175609	81734.273	30.720703	1.163057
5.1232471	81737.297	30.75	1.1645738
5.1280708	81743.563	30.779297	1.1660035
5.1319866	81747.781	30.808594	1.1674329
5.1366358	81743.531	30.837891	1.1689082
5.1424923	81752.258	30.867188	1.1701871
5.14677	81750.867	30.896484	1.1716745
5.152081	81757.016	30.925781	1.1730825
5.1567836	81758.617	30.955078	1.1746199
5.1612182	81765.391	30.984375	1.1760368
5.165966	81768.93	31.013672	1.1775248
5.1701145	81776.219	31.042969	1.1789325
5.1749334	81776.711	31.072266	1.180335
5.1798286	81785.57	31.101563	1.1817784
5.1849203	81788.688	31.130859	1.1833457
5.1890998	81794.094	31.160156	1.1847636
5.1937623	81797.656	31.189453	1.1862572
5.1986752	81804.281	31.21875	1.1876614
5.2044959	81808.188	31.248047	1.1890785
5.2086711	81820.836	31.277344	1.1905463
5.2129941	81829.141	31.306641	1.1920935
5.2191095	81837.727	31.335938	1.1936272
5.2235885	81841.461	31.365234	1.1950645
5.2286091	81848.273	31.394531	1.1965394
5.233839	81852.984	31.423828	1.1981045
5.2391634	81853.781	31.453125	1.1996181
5.243504	81861.109	31.482422	1.2011803
5.2493019	81866.563	31.511719	1.2026738
5.253531	81872.555	31.541016	1.204154
5.2576571	81881.766	31.570313	1.2056642
5.2638845	81884.281	31.599609	1.207213
5.2681265	81884.555	31.628906	1.2087787
5.2718863	81891.617	31.658203	1.2101988
5.2777023	81898.906	31.6875	1.2117493
5.2827849	81906.68	31.716797	1.213352
5.2874746	81913.023	31.746094	1.2149827
5.2929597	81923.258	31.775391	1.216475
5.2977071	81922.992	31.804688	1.2180305
5.3025441	81932.461	31.833984	1.2195936
5.3075867	81931.93	31.863281	1.2211496
5.3127584	81938.922	31.892578	1.2227885
5.3183646	81936.969	31.921875	1.2243394
5.3229065	81944.969	31.951172	1.2258044
5.3271847	81938.469	31.980469	1.2273104
5.3332195	81946.406	32.009766	1.2289189
5.3380699	81943.516	32.039063	1.2305744
5.3435593	81953.133	32.068359	1.2320181
5.3476095	81951.023	32.097656	1.2335255
5.3525715	81955.93	32.126953	1.2351278
5.3583651	81957.141	32.15625	1.2365761
5.3621335	81963.422	32.185547	1.2381463
5.3676009	81962.297	32.214844	1.2396418
5.3712754	81971.828	32.244141	1.2412232
5.3769751	81971.742	32.273438	1.2427311
5.3819327	81974.438	32.302734	1.2442698
5.3873286	81975.484	32.332031	1.2458733
5.3911686	81975.063	32.361328	1.2473234
5.3968682	81975.617	32.390625	1.2488517
5.401504	81979.984	32.419922	1.2504785
5.407074	81978.141	32.449219	1.2520192
5.4115624	81986.047	32.478516	1.2534562
5.41576	81987.289	32.507813	1.2550257
5.4208026	81991.523	32.537109	1.2565228
5.4258137	81990.156	32.566406	1.2579566
5.4310308	81997.383	32.595703	1.2595133
5.435452	81998.664	32.625	1.2609879
5.440311	82004.188	32.654297	1.2625909
5.4451079	82004.188	32.683594	1.2641907
5.450016	82007.992	32.712891	1.2656668
5.4543076	82008.766	32.742188	1.2671366
5.5604248	4500.6382	32.771484	1.5234925
5.5263386	-176.90018	32.800781	2.0969672
5.4701462	3747.5576	32.830078	1.4540775
5.4941564	1039.3171	32.859375	1.3439667
5.4944696	-64.808525	32.888672	1.3346043
5.5003748	163.08203	32.917969	1.3281977
5.5067225	-876.85754	32.947266	1.3104401
5.5090246	39.189472	32.976563	1.3162215
5.5141253	121.33969	33.005859	1.3117936
5.516933	474.14169	33.035156	1.3042552
5.5229096	484.07446	33.064453	1.3047023
5.527957	151.39568	33.09375	1.3064872
5.5324407	-183.1433	33.123047	1.3100997
5.5353599	-467.4819	33.152344	1.3119823
5.5410013	-453.8967	33.181641	1.3141179
5.5446582	-197.2334	33.210938	1.3160545
5.5515738	153.18301	33.240234	1.3189877
5.5540681	393.67984	33.269531	1.3209572
5.5606351	413.43271	33.298828	1.3238069
5.5648327	191.34535	33.328125	1.3246437
5.5705948	-151.67905	33.357422	1.3277845
5.5740504	-372.30167	33.386719	1.329623
5.5788698	-395.62119	33.416016	1.3328923
5.5832329	-182.32468	33.445313	1.3347318
5.5867329	92.720383	33.474609	1.3367186
5.5906086	328.09192	33.503906	1.3393871
5.5951862	347.33466	33.533203	1.3416882
5.6006536	171.83054	33.5625	1.3443623
5.6054726	-100.72556	33.591797	1.3467058
5.6108861	-308.71378	33.621094	1.349106
5.6152716	-337.90176	33.650391	1.3510725
5.6203232	-169.68324	33.679688	1.3531506
5.6251736	69.97155	33.708984	1.3556528
5.6302967	266.42972	33.738281	1.3577651
5.6349812	296.33145	33.767578	1.3591624
5.6392951	153.51631	33.796875	1.3617876
5.6432204	-88.305565	33.826172	1.363269
5.6485891	-255.47716	33.855469	1.3658208
5.6524291	-280.7587	33.884766	1.367184
5.6577802	-155.96603	33.914063	1.3686572
5.6614952	56.492516	33.943359	1.3706411
5.6652322	222.96259	33.972656	1.3725203
5.6711421	249.41284	34.001953	1.3744117
5.676609	126.84567	34.03125	1.3753545
5.67977	-65.636589	34.060547	1.3776593
5.6801319	-223.89182	34.089844	1.3780737
5.6785541	-246.47183	34.119141	1.3768367
5.6790633	-131.2982	34.148438	1.3766546
5.6778655	46.286846	34.177734	1.3765546
5.6778431	189.12181	34.207031	1.3765047
5.6766047	211.47472	34.236328	1.3765494
5.6774049	105.31745	34.265625	1.3765016
5.6777897	-64.421326	34.294922	1.3764294
5.6772351	-192.1095	34.324219	1.3764559
5.6783528	-212.7043	34.353516	1.3764484
5.6764035	-111.34077	34.382813	1.3765392
5.6764884	47.557873	34.412109	1.3764342
5.6771188	166.32886	34.441406	1.3764336
5.6780043	182.62933	34.470703	1.3764549
5.6767793	85.637321	34.5	1.3764879
5.6751742	-16.547739	34.519531	1.3764675